{
  "version": 8,
  "blockIdVersion": 11,
  "anchorX": 51,
  "anchorY": 11,
  "anchorZ": -50,
  "blocks": [
    {
      "x": 42,
      "y": 12,
      "z": -54,
      "name": "Plant_Leaves_Dead",
      "support": 15
    },
    {
      "x": 42,
      "y": 10,
      "z": -52,
      "name": "Soil_Gravel_Lime"
    },
    {
      "x": 42,
      "y": 11,
      "z": -52,
      "name": "Rock_Lime"
    },
    {
      "x": 42,
      "y": 12,
      "z": -52,
      "name": "Rock_Lime"
    },
    {
      "x": 42,
      "y": 13,
      "z": -52,
      "name": "Rock_Lime"
    },
    {
      "x": 42,
      "y": 14,
      "z": -52,
      "name": "Plant_Coral_Block_Lime"
    },
    {
      "x": 42,
      "y": 15,
      "z": -52,
      "name": "Soil_Clay_Smooth_Lime"
    },
    {
      "x": 42,
      "y": 16,
      "z": -52,
      "name": "Plant_Moss_Rug_Pink",
      "support": 15
    },
    {
      "x": 42,
      "y": 10,
      "z": -51,
      "name": "Rock_Lime"
    },
    {
      "x": 42,
      "y": 11,
      "z": -51,
      "name": "Rock_Lime"
    },
    {
      "x": 42,
      "y": 12,
      "z": -51,
      "name": "Rock_Lime"
    },
    {
      "x": 42,
      "y": 13,
      "z": -51,
      "name": "Rock_Lime"
    },
    {
      "x": 42,
      "y": 14,
      "z": -51,
      "name": "Plant_Coral_Block_Lime"
    },
    {
      "x": 42,
      "y": 15,
      "z": -51,
      "name": "Soil_Clay_Lime"
    },
    {
      "x": 42,
      "y": 16,
      "z": -51,
      "name": "Plant_Moss_Rug_Pink",
      "support": 15
    },
    {
      "x": 42,
      "y": 10,
      "z": -50,
      "name": "Rock_Lime"
    },
    {
      "x": 42,
      "y": 11,
      "z": -50,
      "name": "Rock_Lime"
    },
    {
      "x": 42,
      "y": 12,
      "z": -50,
      "name": "Soil_Gravel_Lime"
    },
    {
      "x": 42,
      "y": 13,
      "z": -50,
      "name": "Soil_Gravel_Lime"
    },
    {
      "x": 42,
      "y": 14,
      "z": -50,
      "name": "Rock_Lime"
    },
    {
      "x": 42,
      "y": 15,
      "z": -50,
      "name": "Plant_Coral_Block_Lime"
    },
    {
      "x": 42,
      "y": 16,
      "z": -50,
      "name": "Soil_Clay_Smooth_Lime"
    },
    {
      "x": 42,
      "y": 10,
      "z": -49,
      "name": "Soil_Gravel_Lime"
    },
    {
      "x": 42,
      "y": 11,
      "z": -49,
      "name": "Rock_Lime"
    },
    {
      "x": 42,
      "y": 12,
      "z": -49,
      "name": "Rock_Lime"
    },
    {
      "x": 42,
      "y": 13,
      "z": -49,
      "name": "Rock_Lime"
    },
    {
      "x": 42,
      "y": 14,
      "z": -49,
      "name": "Rock_Lime"
    },
    {
      "x": 42,
      "y": 15,
      "z": -49,
      "name": "Soil_Clay_Smooth_Lime"
    },
    {
      "x": 42,
      "y": 16,
      "z": -49,
      "name": "Plant_Coral_Block_Lime"
    },
    {
      "x": 42,
      "y": 11,
      "z": -48,
      "name": "Soil_Gravel_Lime"
    },
    {
      "x": 42,
      "y": 12,
      "z": -48,
      "name": "Rock_Lime"
    },
    {
      "x": 42,
      "y": 13,
      "z": -48,
      "name": "Rock_Lime"
    },
    {
      "x": 42,
      "y": 14,
      "z": -48,
      "name": "Rock_Lime"
    },
    {
      "x": 42,
      "y": 15,
      "z": -48,
      "name": "Soil_Clay_Lime"
    },
    {
      "x": 42,
      "y": 13,
      "z": -47,
      "name": "Plant_Leaves_Dead",
      "support": 15
    },
    {
      "x": 43,
      "y": 9,
      "z": -54,
      "name": "Soil_Gravel_Lime"
    },
    {
      "x": 43,
      "y": 10,
      "z": -54,
      "name": "Rock_Lime"
    },
    {
      "x": 43,
      "y": 11,
      "z": -54,
      "name": "Rock_Lime"
    },
    {
      "x": 43,
      "y": 12,
      "z": -54,
      "name": "Soil_Gravel_Lime"
    },
    {
      "x": 43,
      "y": 13,
      "z": -54,
      "name": "Soil_Gravel_Lime"
    },
    {
      "x": 43,
      "y": 14,
      "z": -54,
      "name": "Plant_Coral_Block_Lime"
    },
    {
      "x": 43,
      "y": 15,
      "z": -54,
      "name": "Soil_Clay_Lime"
    },
    {
      "x": 43,
      "y": 16,
      "z": -54,
      "name": "Plant_Moss_Rug_Pink",
      "support": 15
    },
    {
      "x": 43,
      "y": 9,
      "z": -53,
      "name": "Rock_Lime"
    },
    {
      "x": 43,
      "y": 10,
      "z": -53,
      "name": "Soil_Gravel_Lime"
    },
    {
      "x": 43,
      "y": 11,
      "z": -53,
      "name": "Rock_Lime"
    },
    {
      "x": 43,
      "y": 12,
      "z": -53,
      "name": "Rock_Lime"
    },
    {
      "x": 43,
      "y": 13,
      "z": -53,
      "name": "Soil_Gravel_Lime"
    },
    {
      "x": 43,
      "y": 14,
      "z": -53,
      "name": "Plant_Coral_Block_Lime"
    },
    {
      "x": 43,
      "y": 15,
      "z": -53,
      "name": "Soil_Clay_Lime"
    },
    {
      "x": 43,
      "y": 16,
      "z": -53,
      "name": "Plant_Coral_Block_Lime"
    },
    {
      "x": 43,
      "y": 17,
      "z": -53,
      "name": "Plant_Moss_Rug_Pink",
      "support": 15
    },
    {
      "x": 43,
      "y": 9,
      "z": -52,
      "name": "Rock_Lime"
    },
    {
      "x": 43,
      "y": 10,
      "z": -52,
      "name": "Soil_Gravel_Lime"
    },
    {
      "x": 43,
      "y": 11,
      "z": -52,
      "name": "Rock_Lime"
    },
    {
      "x": 43,
      "y": 12,
      "z": -52,
      "name": "Rock_Lime"
    },
    {
      "x": 43,
      "y": 13,
      "z": -52,
      "name": "Soil_Gravel_Lime"
    },
    {
      "x": 43,
      "y": 14,
      "z": -52,
      "name": "Soil_Clay_Smooth_Lime"
    },
    {
      "x": 43,
      "y": 15,
      "z": -52,
      "name": "Soil_Clay_Smooth_Lime"
    },
    {
      "x": 43,
      "y": 16,
      "z": -52,
      "name": "Plant_Coral_Block_Lime"
    },
    {
      "x": 43,
      "y": 17,
      "z": -52,
      "name": "Plant_Moss_Rug_Pink",
      "support": 15
    },
    {
      "x": 43,
      "y": 9,
      "z": -51,
      "name": "Rock_Lime"
    },
    {
      "x": 43,
      "y": 10,
      "z": -51,
      "name": "Rock_Lime"
    },
    {
      "x": 43,
      "y": 11,
      "z": -51,
      "name": "Rock_Lime"
    },
    {
      "x": 43,
      "y": 12,
      "z": -51,
      "name": "Rock_Lime"
    },
    {
      "x": 43,
      "y": 13,
      "z": -51,
      "name": "Rock_Lime"
    },
    {
      "x": 43,
      "y": 14,
      "z": -51,
      "name": "Soil_Clay_Smooth_Lime"
    },
    {
      "x": 43,
      "y": 15,
      "z": -51,
      "name": "Soil_Clay_Lime"
    },
    {
      "x": 43,
      "y": 16,
      "z": -51,
      "name": "Plant_Coral_Block_Lime"
    },
    {
      "x": 43,
      "y": 9,
      "z": -50,
      "name": "Rock_Lime"
    },
    {
      "x": 43,
      "y": 10,
      "z": -50,
      "name": "Rock_Lime"
    },
    {
      "x": 43,
      "y": 11,
      "z": -50,
      "name": "Rock_Lime"
    },
    {
      "x": 43,
      "y": 12,
      "z": -50,
      "name": "Soil_Gravel_Lime"
    },
    {
      "x": 43,
      "y": 13,
      "z": -50,
      "name": "Soil_Gravel_Lime"
    },
    {
      "x": 43,
      "y": 14,
      "z": -50,
      "name": "Soil_Gravel_Lime"
    },
    {
      "x": 43,
      "y": 15,
      "z": -50,
      "name": "Plant_Coral_Block_Lime"
    },
    {
      "x": 43,
      "y": 16,
      "z": -50,
      "name": "Soil_Clay_Lime"
    },
    {
      "x": 43,
      "y": 8,
      "z": -49,
      "name": "Rock_Lime"
    },
    {
      "x": 43,
      "y": 9,
      "z": -49,
      "name": "Rock_Lime"
    },
    {
      "x": 43,
      "y": 10,
      "z": -49,
      "name": "Rock_Lime"
    },
    {
      "x": 43,
      "y": 11,
      "z": -49,
      "name": "Rock_Lime"
    },
    {
      "x": 43,
      "y": 12,
      "z": -49,
      "name": "Rock_Lime"
    },
    {
      "x": 43,
      "y": 13,
      "z": -49,
      "name": "Soil_Gravel_Lime"
    },
    {
      "x": 43,
      "y": 14,
      "z": -49,
      "name": "Rock_Lime"
    },
    {
      "x": 43,
      "y": 15,
      "z": -49,
      "name": "Plant_Coral_Block_Lime"
    },
    {
      "x": 43,
      "y": 16,
      "z": -49,
      "name": "Plant_Coral_Block_Lime"
    },
    {
      "x": 43,
      "y": 9,
      "z": -48,
      "name": "Rock_Lime"
    },
    {
      "x": 43,
      "y": 11,
      "z": -48,
      "name": "Rock_Lime"
    },
    {
      "x": 43,
      "y": 12,
      "z": -48,
      "name": "Soil_Gravel_Lime"
    },
    {
      "x": 43,
      "y": 13,
      "z": -48,
      "name": "Soil_Gravel_Lime"
    },
    {
      "x": 43,
      "y": 14,
      "z": -48,
      "name": "Rock_Lime"
    },
    {
      "x": 43,
      "y": 15,
      "z": -48,
      "name": "Rock_Lime"
    },
    {
      "x": 43,
      "y": 16,
      "z": -48,
      "name": "Soil_Clay_Lime"
    },
    {
      "x": 43,
      "y": 12,
      "z": -47,
      "name": "Rock_Lime"
    },
    {
      "x": 43,
      "y": 13,
      "z": -47,
      "name": "Soil_Gravel_Lime"
    },
    {
      "x": 43,
      "y": 14,
      "z": -47,
      "name": "Plant_Coral_Block_Lime"
    },
    {
      "x": 43,
      "y": 15,
      "z": -47,
      "name": "Soil_Clay_Lime"
    },
    {
      "x": 44,
      "y": 13,
      "z": -56,
      "name": "Plant_Leaves_Dead",
      "support": 15
    },
    {
      "x": 44,
      "y": 10,
      "z": -55,
      "name": "Soil_Gravel_Lime"
    },
    {
      "x": 44,
      "y": 11,
      "z": -55,
      "name": "Rock_Lime"
    },
    {
      "x": 44,
      "y": 12,
      "z": -55,
      "name": "Soil_Gravel_Lime"
    },
    {
      "x": 44,
      "y": 13,
      "z": -55,
      "name": "Soil_Gravel_Lime"
    },
    {
      "x": 44,
      "y": 14,
      "z": -55,
      "name": "Soil_Clay_Smooth_Lime"
    },
    {
      "x": 44,
      "y": 15,
      "z": -55,
      "name": "Plant_Coral_Block_Lime"
    },
    {
      "x": 44,
      "y": 16,
      "z": -55,
      "name": "Plant_Coral_Block_Lime"
    },
    {
      "x": 44,
      "y": 5,
      "z": -54,
      "name": "Soil_Gravel_Lime"
    },
    {
      "x": 44,
      "y": 6,
      "z": -54,
      "name": "Rock_Lime"
    },
    {
      "x": 44,
      "y": 7,
      "z": -54,
      "name": "Soil_Gravel_Lime"
    },
    {
      "x": 44,
      "y": 8,
      "z": -54,
      "name": "Rock_Lime"
    },
    {
      "x": 44,
      "y": 9,
      "z": -54,
      "name": "Rock_Lime"
    },
    {
      "x": 44,
      "y": 10,
      "z": -54,
      "name": "Rock_Lime"
    },
    {
      "x": 44,
      "y": 11,
      "z": -54,
      "name": "Rock_Lime"
    },
    {
      "x": 44,
      "y": 12,
      "z": -54,
      "name": "Soil_Gravel_Lime"
    },
    {
      "x": 44,
      "y": 13,
      "z": -54,
      "name": "Rock_Lime"
    },
    {
      "x": 44,
      "y": 14,
      "z": -54,
      "name": "Plant_Coral_Block_Lime"
    },
    {
      "x": 44,
      "y": 15,
      "z": -54,
      "name": "Plant_Coral_Block_Lime"
    },
    {
      "x": 44,
      "y": 16,
      "z": -54,
      "name": "Soil_Clay_Smooth_Lime"
    },
    {
      "x": 44,
      "y": 5,
      "z": -53,
      "name": "Soil_Gravel_Lime"
    },
    {
      "x": 44,
      "y": 6,
      "z": -53,
      "name": "Soil_Gravel_Lime"
    },
    {
      "x": 44,
      "y": 7,
      "z": -53,
      "name": "Soil_Gravel_Lime"
    },
    {
      "x": 44,
      "y": 8,
      "z": -53,
      "name": "Rock_Lime"
    },
    {
      "x": 44,
      "y": 9,
      "z": -53,
      "name": "Rock_Lime"
    },
    {
      "x": 44,
      "y": 10,
      "z": -53,
      "name": "Rock_Lime"
    },
    {
      "x": 44,
      "y": 11,
      "z": -53,
      "name": "Rock_Lime"
    },
    {
      "x": 44,
      "y": 12,
      "z": -53,
      "name": "Rock_Lime"
    },
    {
      "x": 44,
      "y": 13,
      "z": -53,
      "name": "Rock_Lime"
    },
    {
      "x": 44,
      "y": 14,
      "z": -53,
      "name": "Soil_Clay_Lime"
    },
    {
      "x": 44,
      "y": 15,
      "z": -53,
      "name": "Rock_Lime"
    },
    {
      "x": 44,
      "y": 16,
      "z": -53,
      "name": "Soil_Clay_Smooth_Lime"
    },
    {
      "x": 44,
      "y": 17,
      "z": -53,
      "name": "Plant_Flower_Bushy_Poisoned"
    },
    {
      "x": 44,
      "y": 5,
      "z": -52,
      "name": "Rock_Lime"
    },
    {
      "x": 44,
      "y": 6,
      "z": -52,
      "name": "Rock_Lime"
    },
    {
      "x": 44,
      "y": 7,
      "z": -52,
      "name": "Rock_Lime"
    },
    {
      "x": 44,
      "y": 8,
      "z": -52,
      "name": "Rock_Lime"
    },
    {
      "x": 44,
      "y": 9,
      "z": -52,
      "name": "Rock_Lime"
    },
    {
      "x": 44,
      "y": 10,
      "z": -52,
      "name": "Rock_Lime"
    },
    {
      "x": 44,
      "y": 11,
      "z": -52,
      "name": "Rock_Lime"
    },
    {
      "x": 44,
      "y": 12,
      "z": -52,
      "name": "Rock_Lime"
    },
    {
      "x": 44,
      "y": 13,
      "z": -52,
      "name": "Soil_Gravel_Lime"
    },
    {
      "x": 44,
      "y": 14,
      "z": -52,
      "name": "Rock_Lime"
    },
    {
      "x": 44,
      "y": 15,
      "z": -52,
      "name": "Soil_Gravel_Lime"
    },
    {
      "x": 44,
      "y": 16,
      "z": -52,
      "name": "Empty"
    },
    {
      "x": 44,
      "y": 6,
      "z": -51,
      "name": "Rock_Lime"
    },
    {
      "x": 44,
      "y": 7,
      "z": -51,
      "name": "Rock_Lime"
    },
    {
      "x": 44,
      "y": 8,
      "z": -51,
      "name": "Rock_Lime"
    },
    {
      "x": 44,
      "y": 9,
      "z": -51,
      "name": "Rock_Lime"
    },
    {
      "x": 44,
      "y": 10,
      "z": -51,
      "name": "Rock_Lime"
    },
    {
      "x": 44,
      "y": 11,
      "z": -51,
      "name": "Soil_Gravel_Lime"
    },
    {
      "x": 44,
      "y": 12,
      "z": -51,
      "name": "Soil_Gravel_Lime"
    },
    {
      "x": 44,
      "y": 13,
      "z": -51,
      "name": "Soil_Gravel_Lime"
    },
    {
      "x": 44,
      "y": 14,
      "z": -51,
      "name": "Rock_Lime"
    },
    {
      "x": 44,
      "y": 15,
      "z": -51,
      "name": "Rock_Lime"
    },
    {
      "x": 44,
      "y": 16,
      "z": -51,
      "name": "Empty"
    },
    {
      "x": 44,
      "y": 6,
      "z": -50,
      "name": "Rock_Lime"
    },
    {
      "x": 44,
      "y": 7,
      "z": -50,
      "name": "Soil_Gravel_Lime"
    },
    {
      "x": 44,
      "y": 8,
      "z": -50,
      "name": "Soil_Gravel_Lime"
    },
    {
      "x": 44,
      "y": 9,
      "z": -50,
      "name": "Soil_Gravel_Lime"
    },
    {
      "x": 44,
      "y": 10,
      "z": -50,
      "name": "Rock_Lime"
    },
    {
      "x": 44,
      "y": 11,
      "z": -50,
      "name": "Rock_Lime"
    },
    {
      "x": 44,
      "y": 12,
      "z": -50,
      "name": "Rock_Lime"
    },
    {
      "x": 44,
      "y": 13,
      "z": -50,
      "name": "Soil_Gravel_Lime"
    },
    {
      "x": 44,
      "y": 14,
      "z": -50,
      "name": "Soil_Gravel_Lime"
    },
    {
      "x": 44,
      "y": 15,
      "z": -50,
      "name": "Soil_Gravel_Lime"
    },
    {
      "x": 44,
      "y": 16,
      "z": -50,
      "name": "Empty"
    },
    {
      "x": 44,
      "y": 7,
      "z": -49,
      "name": "Rock_Lime"
    },
    {
      "x": 44,
      "y": 8,
      "z": -49,
      "name": "Rock_Lime"
    },
    {
      "x": 44,
      "y": 9,
      "z": -49,
      "name": "Rock_Lime"
    },
    {
      "x": 44,
      "y": 10,
      "z": -49,
      "name": "Rock_Lime"
    },
    {
      "x": 44,
      "y": 11,
      "z": -49,
      "name": "Rock_Lime"
    },
    {
      "x": 44,
      "y": 12,
      "z": -49,
      "name": "Rock_Lime"
    },
    {
      "x": 44,
      "y": 13,
      "z": -49,
      "name": "Rock_Lime"
    },
    {
      "x": 44,
      "y": 14,
      "z": -49,
      "name": "Soil_Gravel_Lime"
    },
    {
      "x": 44,
      "y": 15,
      "z": -49,
      "name": "Rock_Lime"
    },
    {
      "x": 44,
      "y": 16,
      "z": -49,
      "name": "Soil_Clay_Smooth_Lime"
    },
    {
      "x": 44,
      "y": 8,
      "z": -48,
      "name": "Rock_Lime"
    },
    {
      "x": 44,
      "y": 9,
      "z": -48,
      "name": "Soil_Gravel_Lime"
    },
    {
      "x": 44,
      "y": 10,
      "z": -48,
      "name": "Rock_Lime"
    },
    {
      "x": 44,
      "y": 11,
      "z": -48,
      "name": "Rock_Lime"
    },
    {
      "x": 44,
      "y": 12,
      "z": -48,
      "name": "Rock_Lime"
    },
    {
      "x": 44,
      "y": 13,
      "z": -48,
      "name": "Rock_Lime"
    },
    {
      "x": 44,
      "y": 14,
      "z": -48,
      "name": "Soil_Gravel_Lime"
    },
    {
      "x": 44,
      "y": 15,
      "z": -48,
      "name": "Soil_Gravel_Lime"
    },
    {
      "x": 44,
      "y": 16,
      "z": -48,
      "name": "Plant_Coral_Block_Lime"
    },
    {
      "x": 44,
      "y": 17,
      "z": -48,
      "name": "Plant_Moss_Rug_Pink",
      "support": 15
    },
    {
      "x": 44,
      "y": 10,
      "z": -47,
      "name": "Plant_Coral_Block_Lime"
    },
    {
      "x": 44,
      "y": 11,
      "z": -47,
      "name": "Plant_Coral_Block_Lime"
    },
    {
      "x": 44,
      "y": 12,
      "z": -47,
      "name": "Plant_Coral_Block_Lime"
    },
    {
      "x": 44,
      "y": 13,
      "z": -47,
      "name": "Soil_Clay_Lime"
    },
    {
      "x": 44,
      "y": 14,
      "z": -47,
      "name": "Soil_Clay_Smooth_Lime"
    },
    {
      "x": 44,
      "y": 15,
      "z": -47,
      "name": "Plant_Coral_Block_Lime"
    },
    {
      "x": 44,
      "y": 10,
      "z": -46,
      "name": "Plant_Moss_Wall_Green",
      "support": 15
    },
    {
      "x": 44,
      "y": 11,
      "z": -46,
      "name": "Plant_Moss_Wall_Green",
      "support": 15
    },
    {
      "x": 44,
      "y": 12,
      "z": -46,
      "name": "Plant_Moss_Wall_Green",
      "support": 15
    },
    {
      "x": 44,
      "y": 13,
      "z": -46,
      "name": "Plant_Moss_Wall_Green",
      "support": 15
    },
    {
      "x": 44,
      "y": 14,
      "z": -46,
      "name": "Plant_Moss_Wall_Green",
      "support": 15
    },
    {
      "x": 44,
      "y": 15,
      "z": -46,
      "name": "Plant_Moss_Wall_Green",
      "support": 15
    },
    {
      "x": 45,
      "y": 10,
      "z": -57,
      "name": "Soil_Gravel_Lime"
    },
    {
      "x": 45,
      "y": 11,
      "z": -57,
      "name": "Rock_Lime"
    },
    {
      "x": 45,
      "y": 12,
      "z": -57,
      "name": "Rock_Lime"
    },
    {
      "x": 45,
      "y": 13,
      "z": -57,
      "name": "Rock_Lime"
    },
    {
      "x": 45,
      "y": 14,
      "z": -57,
      "name": "Soil_Gravel_Lime"
    },
    {
      "x": 45,
      "y": 15,
      "z": -57,
      "name": "Soil_Clay_Lime"
    },
    {
      "x": 45,
      "y": 7,
      "z": -56,
      "name": "Rock_Lime"
    },
    {
      "x": 45,
      "y": 8,
      "z": -56,
      "name": "Rock_Lime"
    },
    {
      "x": 45,
      "y": 9,
      "z": -56,
      "name": "Rock_Lime"
    },
    {
      "x": 45,
      "y": 10,
      "z": -56,
      "name": "Soil_Gravel_Lime"
    },
    {
      "x": 45,
      "y": 11,
      "z": -56,
      "name": "Rock_Lime"
    },
    {
      "x": 45,
      "y": 12,
      "z": -56,
      "name": "Rock_Lime"
    },
    {
      "x": 45,
      "y": 13,
      "z": -56,
      "name": "Rock_Lime"
    },
    {
      "x": 45,
      "y": 14,
      "z": -56,
      "name": "Soil_Gravel_Lime"
    },
    {
      "x": 45,
      "y": 15,
      "z": -56,
      "name": "Soil_Clay_Smooth_Lime"
    },
    {
      "x": 45,
      "y": 16,
      "z": -56,
      "name": "Soil_Clay_Smooth_Lime"
    },
    {
      "x": 45,
      "y": 5,
      "z": -55,
      "name": "Soil_Gravel_Lime"
    },
    {
      "x": 45,
      "y": 6,
      "z": -55,
      "name": "Rock_Lime"
    },
    {
      "x": 45,
      "y": 7,
      "z": -55,
      "name": "Soil_Gravel_Lime"
    },
    {
      "x": 45,
      "y": 8,
      "z": -55,
      "name": "Rock_Lime"
    },
    {
      "x": 45,
      "y": 9,
      "z": -55,
      "name": "Soil_Gravel_Lime"
    },
    {
      "x": 45,
      "y": 10,
      "z": -55,
      "name": "Rock_Lime"
    },
    {
      "x": 45,
      "y": 11,
      "z": -55,
      "name": "Rock_Lime"
    },
    {
      "x": 45,
      "y": 12,
      "z": -55,
      "name": "Rock_Lime"
    },
    {
      "x": 45,
      "y": 13,
      "z": -55,
      "name": "Rock_Lime"
    },
    {
      "x": 45,
      "y": 14,
      "z": -55,
      "name": "Plant_Coral_Block_Lime"
    },
    {
      "x": 45,
      "y": 15,
      "z": -55,
      "name": "Soil_Clay_Smooth_Lime"
    },
    {
      "x": 45,
      "y": 16,
      "z": -55,
      "name": "Plant_Coral_Block_Lime"
    },
    {
      "x": 45,
      "y": 17,
      "z": -55,
      "name": "Plant_Coral_Block_Lime"
    },
    {
      "x": 45,
      "y": 5,
      "z": -54,
      "name": "Soil_Gravel_Lime"
    },
    {
      "x": 45,
      "y": 6,
      "z": -54,
      "name": "Soil_Gravel_Lime"
    },
    {
      "x": 45,
      "y": 7,
      "z": -54,
      "name": "Soil_Gravel_Lime"
    },
    {
      "x": 45,
      "y": 8,
      "z": -54,
      "name": "Soil_Gravel_Lime"
    },
    {
      "x": 45,
      "y": 9,
      "z": -54,
      "name": "Rock_Lime"
    },
    {
      "x": 45,
      "y": 10,
      "z": -54,
      "name": "Rock_Lime"
    },
    {
      "x": 45,
      "y": 11,
      "z": -54,
      "name": "Soil_Gravel_Lime"
    },
    {
      "x": 45,
      "y": 12,
      "z": -54,
      "name": "Rock_Lime"
    },
    {
      "x": 45,
      "y": 13,
      "z": -54,
      "name": "Soil_Gravel_Lime"
    },
    {
      "x": 45,
      "y": 14,
      "z": -54,
      "name": "Plant_Coral_Block_Lime"
    },
    {
      "x": 45,
      "y": 15,
      "z": -54,
      "name": "Soil_Gravel_Lime"
    },
    {
      "x": 45,
      "y": 16,
      "z": -54,
      "name": "Empty"
    },
    {
      "x": 45,
      "y": 5,
      "z": -53,
      "name": "Rock_Lime"
    },
    {
      "x": 45,
      "y": 6,
      "z": -53,
      "name": "Soil_Gravel_Lime"
    },
    {
      "x": 45,
      "y": 7,
      "z": -53,
      "name": "Rock_Lime"
    },
    {
      "x": 45,
      "y": 8,
      "z": -53,
      "name": "Rock_Lime"
    },
    {
      "x": 45,
      "y": 9,
      "z": -53,
      "name": "Rock_Lime"
    },
    {
      "x": 45,
      "y": 10,
      "z": -53,
      "name": "Rock_Lime"
    },
    {
      "x": 45,
      "y": 11,
      "z": -53,
      "name": "Soil_Gravel_Lime"
    },
    {
      "x": 45,
      "y": 12,
      "z": -53,
      "name": "Soil_Gravel_Lime"
    },
    {
      "x": 45,
      "y": 13,
      "z": -53,
      "name": "Rock_Lime"
    },
    {
      "x": 45,
      "y": 14,
      "z": -53,
      "name": "Soil_Gravel_Lime"
    },
    {
      "x": 45,
      "y": 15,
      "z": -53,
      "name": "Rock_Lime"
    },
    {
      "x": 45,
      "y": 16,
      "z": -53,
      "name": "Empty"
    },
    {
      "x": 45,
      "y": 5,
      "z": -52,
      "name": "Soil_Gravel_Lime"
    },
    {
      "x": 45,
      "y": 6,
      "z": -52,
      "name": "Rock_Lime"
    },
    {
      "x": 45,
      "y": 7,
      "z": -52,
      "name": "Rock_Lime"
    },
    {
      "x": 45,
      "y": 8,
      "z": -52,
      "name": "Rock_Lime"
    },
    {
      "x": 45,
      "y": 9,
      "z": -52,
      "name": "Rock_Lime"
    },
    {
      "x": 45,
      "y": 10,
      "z": -52,
      "name": "Soil_Gravel_Lime"
    },
    {
      "x": 45,
      "y": 11,
      "z": -52,
      "name": "Soil_Gravel_Lime"
    },
    {
      "x": 45,
      "y": 12,
      "z": -52,
      "name": "Soil_Gravel_Lime"
    },
    {
      "x": 45,
      "y": 13,
      "z": -52,
      "name": "Rock_Lime"
    },
    {
      "x": 45,
      "y": 14,
      "z": -52,
      "name": "Rock_Lime"
    },
    {
      "x": 45,
      "y": 15,
      "z": -52,
      "name": "Soil_Gravel_Lime"
    },
    {
      "x": 45,
      "y": 16,
      "z": -52,
      "name": "Empty"
    },
    {
      "x": 45,
      "y": 5,
      "z": -51,
      "name": "Soil_Gravel_Lime"
    },
    {
      "x": 45,
      "y": 6,
      "z": -51,
      "name": "Rock_Lime"
    },
    {
      "x": 45,
      "y": 7,
      "z": -51,
      "name": "Rock_Lime"
    },
    {
      "x": 45,
      "y": 8,
      "z": -51,
      "name": "Rock_Lime"
    },
    {
      "x": 45,
      "y": 9,
      "z": -51,
      "name": "Soil_Gravel_Lime"
    },
    {
      "x": 45,
      "y": 10,
      "z": -51,
      "name": "Soil_Gravel_Lime"
    },
    {
      "x": 45,
      "y": 11,
      "z": -51,
      "name": "Soil_Gravel_Lime"
    },
    {
      "x": 45,
      "y": 12,
      "z": -51,
      "name": "Rock_Lime"
    },
    {
      "x": 45,
      "y": 13,
      "z": -51,
      "name": "Rock_Lime"
    },
    {
      "x": 45,
      "y": 14,
      "z": -51,
      "name": "Rock_Lime"
    },
    {
      "x": 45,
      "y": 15,
      "z": -51,
      "name": "Soil_Gravel_Lime"
    },
    {
      "x": 45,
      "y": 16,
      "z": -51,
      "name": "Empty"
    },
    {
      "x": 45,
      "y": 5,
      "z": -50,
      "name": "Soil_Gravel_Lime"
    },
    {
      "x": 45,
      "y": 6,
      "z": -50,
      "name": "Rock_Lime"
    },
    {
      "x": 45,
      "y": 7,
      "z": -50,
      "name": "Rock_Lime"
    },
    {
      "x": 45,
      "y": 8,
      "z": -50,
      "name": "Rock_Lime"
    },
    {
      "x": 45,
      "y": 9,
      "z": -50,
      "name": "Soil_Gravel_Lime"
    },
    {
      "x": 45,
      "y": 10,
      "z": -50,
      "name": "Rock_Lime"
    },
    {
      "x": 45,
      "y": 11,
      "z": -50,
      "name": "Rock_Lime"
    },
    {
      "x": 45,
      "y": 12,
      "z": -50,
      "name": "Rock_Lime"
    },
    {
      "x": 45,
      "y": 13,
      "z": -50,
      "name": "Rock_Lime"
    },
    {
      "x": 45,
      "y": 14,
      "z": -50,
      "name": "Rock_Lime"
    },
    {
      "x": 45,
      "y": 15,
      "z": -50,
      "name": "Rock_Lime"
    },
    {
      "x": 45,
      "y": 16,
      "z": -50,
      "name": "Empty"
    },
    {
      "x": 45,
      "y": 6,
      "z": -49,
      "name": "Soil_Gravel_Lime"
    },
    {
      "x": 45,
      "y": 7,
      "z": -49,
      "name": "Rock_Lime"
    },
    {
      "x": 45,
      "y": 8,
      "z": -49,
      "name": "Rock_Lime"
    },
    {
      "x": 45,
      "y": 9,
      "z": -49,
      "name": "Soil_Gravel_Lime"
    },
    {
      "x": 45,
      "y": 10,
      "z": -49,
      "name": "Rock_Lime"
    },
    {
      "x": 45,
      "y": 11,
      "z": -49,
      "name": "Rock_Lime"
    },
    {
      "x": 45,
      "y": 12,
      "z": -49,
      "name": "Rock_Lime"
    },
    {
      "x": 45,
      "y": 13,
      "z": -49,
      "name": "Rock_Lime"
    },
    {
      "x": 45,
      "y": 14,
      "z": -49,
      "name": "Rock_Lime"
    },
    {
      "x": 45,
      "y": 15,
      "z": -49,
      "name": "Soil_Gravel_Lime"
    },
    {
      "x": 45,
      "y": 16,
      "z": -49,
      "name": "Empty"
    },
    {
      "x": 45,
      "y": 7,
      "z": -48,
      "name": "Rock_Lime"
    },
    {
      "x": 45,
      "y": 8,
      "z": -48,
      "name": "Rock_Lime"
    },
    {
      "x": 45,
      "y": 9,
      "z": -48,
      "name": "Rock_Lime"
    },
    {
      "x": 45,
      "y": 10,
      "z": -48,
      "name": "Rock_Lime"
    },
    {
      "x": 45,
      "y": 11,
      "z": -48,
      "name": "Soil_Gravel_Lime"
    },
    {
      "x": 45,
      "y": 12,
      "z": -48,
      "name": "Soil_Gravel_Lime"
    },
    {
      "x": 45,
      "y": 13,
      "z": -48,
      "name": "Rock_Lime"
    },
    {
      "x": 45,
      "y": 14,
      "z": -48,
      "name": "Soil_Gravel_Lime"
    },
    {
      "x": 45,
      "y": 15,
      "z": -48,
      "name": "Rock_Lime"
    },
    {
      "x": 45,
      "y": 16,
      "z": -48,
      "name": "Empty"
    },
    {
      "x": 45,
      "y": 7,
      "z": -47,
      "name": "Soil_Clay_Smooth_Lime"
    },
    {
      "x": 45,
      "y": 8,
      "z": -47,
      "name": "Soil_Clay_Smooth_Lime"
    },
    {
      "x": 45,
      "y": 9,
      "z": -47,
      "name": "Plant_Coral_Block_Lime"
    },
    {
      "x": 45,
      "y": 10,
      "z": -47,
      "name": "Plant_Coral_Block_Lime"
    },
    {
      "x": 45,
      "y": 11,
      "z": -47,
      "name": "Plant_Coral_Block_Lime"
    },
    {
      "x": 45,
      "y": 12,
      "z": -47,
      "name": "Plant_Coral_Block_Lime"
    },
    {
      "x": 45,
      "y": 13,
      "z": -47,
      "name": "Soil_Clay_Lime"
    },
    {
      "x": 45,
      "y": 14,
      "z": -47,
      "name": "Plant_Coral_Block_Lime"
    },
    {
      "x": 45,
      "y": 15,
      "z": -47,
      "name": "Plant_Coral_Block_Lime"
    },
    {
      "x": 45,
      "y": 16,
      "z": -47,
      "name": "Plant_Moss_Wall_Green",
      "support": 15,
      "rotation": 3
    },
    {
      "x": 45,
      "y": 7,
      "z": -46,
      "name": "Plant_Moss_Wall_Green",
      "support": 15
    },
    {
      "x": 45,
      "y": 8,
      "z": -46,
      "name": "Plant_Moss_Wall_Green",
      "support": 15
    },
    {
      "x": 45,
      "y": 9,
      "z": -46,
      "name": "Plant_Moss_Wall_Green",
      "support": 15
    },
    {
      "x": 45,
      "y": 10,
      "z": -46,
      "name": "Plant_Moss_Wall_Green",
      "support": 15
    },
    {
      "x": 45,
      "y": 11,
      "z": -46,
      "name": "Plant_Moss_Wall_Green",
      "support": 15
    },
    {
      "x": 45,
      "y": 12,
      "z": -46,
      "name": "Plant_Moss_Wall_Green",
      "support": 15
    },
    {
      "x": 45,
      "y": 13,
      "z": -46,
      "name": "Plant_Moss_Wall_Green",
      "support": 15
    },
    {
      "x": 45,
      "y": 14,
      "z": -46,
      "name": "Plant_Moss_Wall_Green",
      "support": 15
    },
    {
      "x": 45,
      "y": 15,
      "z": -46,
      "name": "Plant_Moss_Wall_Green",
      "support": 15
    },
    {
      "x": 46,
      "y": 10,
      "z": -57,
      "name": "Soil_Gravel_Lime"
    },
    {
      "x": 46,
      "y": 11,
      "z": -57,
      "name": "Soil_Gravel_Lime"
    },
    {
      "x": 46,
      "y": 12,
      "z": -57,
      "name": "Soil_Gravel_Lime"
    },
    {
      "x": 46,
      "y": 13,
      "z": -57,
      "name": "Rock_Lime"
    },
    {
      "x": 46,
      "y": 14,
      "z": -57,
      "name": "Soil_Gravel_Lime"
    },
    {
      "x": 46,
      "y": 15,
      "z": -57,
      "name": "Soil_Clay_Lime"
    },
    {
      "x": 46,
      "y": 5,
      "z": -56,
      "name": "Soil_Gravel_Lime"
    },
    {
      "x": 46,
      "y": 6,
      "z": -56,
      "name": "Rock_Lime"
    },
    {
      "x": 46,
      "y": 7,
      "z": -56,
      "name": "Rock_Lime"
    },
    {
      "x": 46,
      "y": 8,
      "z": -56,
      "name": "Rock_Lime"
    },
    {
      "x": 46,
      "y": 9,
      "z": -56,
      "name": "Rock_Lime"
    },
    {
      "x": 46,
      "y": 10,
      "z": -56,
      "name": "Rock_Lime"
    },
    {
      "x": 46,
      "y": 11,
      "z": -56,
      "name": "Rock_Lime"
    },
    {
      "x": 46,
      "y": 12,
      "z": -56,
      "name": "Rock_Lime"
    },
    {
      "x": 46,
      "y": 13,
      "z": -56,
      "name": "Rock_Lime"
    },
    {
      "x": 46,
      "y": 14,
      "z": -56,
      "name": "Rock_Lime"
    },
    {
      "x": 46,
      "y": 15,
      "z": -56,
      "name": "Soil_Clay_Smooth_Lime"
    },
    {
      "x": 46,
      "y": 16,
      "z": -56,
      "name": "Soil_Clay_Lime"
    },
    {
      "x": 46,
      "y": 17,
      "z": -56,
      "name": "Soil_Clay_Lime"
    },
    {
      "x": 46,
      "y": 5,
      "z": -55,
      "name": "Soil_Gravel_Lime"
    },
    {
      "x": 46,
      "y": 6,
      "z": -55,
      "name": "Rock_Lime"
    },
    {
      "x": 46,
      "y": 7,
      "z": -55,
      "name": "Soil_Gravel_Lime"
    },
    {
      "x": 46,
      "y": 8,
      "z": -55,
      "name": "Rock_Lime"
    },
    {
      "x": 46,
      "y": 9,
      "z": -55,
      "name": "Soil_Gravel_Lime"
    },
    {
      "x": 46,
      "y": 10,
      "z": -55,
      "name": "Soil_Gravel_Lime"
    },
    {
      "x": 46,
      "y": 11,
      "z": -55,
      "name": "Rock_Lime"
    },
    {
      "x": 46,
      "y": 12,
      "z": -55,
      "name": "Rock_Lime"
    },
    {
      "x": 46,
      "y": 13,
      "z": -55,
      "name": "Soil_Gravel_Lime"
    },
    {
      "x": 46,
      "y": 14,
      "z": -55,
      "name": "Soil_Clay_Smooth_Lime"
    },
    {
      "x": 46,
      "y": 15,
      "z": -55,
      "name": "Plant_Coral_Block_Lime"
    },
    {
      "x": 46,
      "y": 16,
      "z": -55,
      "name": "Soil_Clay_Lime"
    },
    {
      "x": 46,
      "y": 5,
      "z": -54,
      "name": "Rock_Lime"
    },
    {
      "x": 46,
      "y": 6,
      "z": -54,
      "name": "Rock_Lime"
    },
    {
      "x": 46,
      "y": 7,
      "z": -54,
      "name": "Soil_Gravel_Lime"
    },
    {
      "x": 46,
      "y": 8,
      "z": -54,
      "name": "Soil_Gravel_Lime"
    },
    {
      "x": 46,
      "y": 9,
      "z": -54,
      "name": "Rock_Lime"
    },
    {
      "x": 46,
      "y": 10,
      "z": -54,
      "name": "Soil_Gravel_Lime"
    },
    {
      "x": 46,
      "y": 11,
      "z": -54,
      "name": "Soil_Gravel_Lime"
    },
    {
      "x": 46,
      "y": 12,
      "z": -54,
      "name": "Rock_Lime"
    },
    {
      "x": 46,
      "y": 13,
      "z": -54,
      "name": "Soil_Gravel_Lime"
    },
    {
      "x": 46,
      "y": 14,
      "z": -54,
      "name": "Soil_Gravel_Lime"
    },
    {
      "x": 46,
      "y": 15,
      "z": -54,
      "name": "Soil_Gravel_Lime"
    },
    {
      "x": 46,
      "y": 16,
      "z": -54,
      "name": "Empty"
    },
    {
      "x": 46,
      "y": 5,
      "z": -53,
      "name": "Rock_Lime"
    },
    {
      "x": 46,
      "y": 6,
      "z": -53,
      "name": "Rock_Lime"
    },
    {
      "x": 46,
      "y": 7,
      "z": -53,
      "name": "Rock_Lime"
    },
    {
      "x": 46,
      "y": 8,
      "z": -53,
      "name": "Soil_Gravel_Lime"
    },
    {
      "x": 46,
      "y": 9,
      "z": -53,
      "name": "Soil_Gravel_Lime"
    },
    {
      "x": 46,
      "y": 10,
      "z": -53,
      "name": "Soil_Gravel_Lime"
    },
    {
      "x": 46,
      "y": 11,
      "z": -53,
      "name": "Soil_Gravel_Lime"
    },
    {
      "x": 46,
      "y": 12,
      "z": -53,
      "name": "Soil_Gravel_Lime"
    },
    {
      "x": 46,
      "y": 13,
      "z": -53,
      "name": "Rock_Lime"
    },
    {
      "x": 46,
      "y": 14,
      "z": -53,
      "name": "Rock_Lime"
    },
    {
      "x": 46,
      "y": 15,
      "z": -53,
      "name": "Soil_Gravel_Lime"
    },
    {
      "x": 46,
      "y": 16,
      "z": -53,
      "name": "Empty"
    },
    {
      "x": 46,
      "y": 5,
      "z": -52,
      "name": "Rock_Lime"
    },
    {
      "x": 46,
      "y": 6,
      "z": -52,
      "name": "Rock_Lime"
    },
    {
      "x": 46,
      "y": 7,
      "z": -52,
      "name": "Rock_Lime"
    },
    {
      "x": 46,
      "y": 8,
      "z": -52,
      "name": "Soil_Gravel_Lime"
    },
    {
      "x": 46,
      "y": 9,
      "z": -52,
      "name": "Soil_Gravel_Lime"
    },
    {
      "x": 46,
      "y": 10,
      "z": -52,
      "name": "Soil_Gravel_Lime"
    },
    {
      "x": 46,
      "y": 11,
      "z": -52,
      "name": "Rock_Lime"
    },
    {
      "x": 46,
      "y": 12,
      "z": -52,
      "name": "Rock_Lime"
    },
    {
      "x": 46,
      "y": 13,
      "z": -52,
      "name": "Soil_Gravel_Lime"
    },
    {
      "x": 46,
      "y": 14,
      "z": -52,
      "name": "Rock_Lime"
    },
    {
      "x": 46,
      "y": 15,
      "z": -52,
      "name": "Soil_Gravel_Lime"
    },
    {
      "x": 46,
      "y": 16,
      "z": -52,
      "name": "Empty"
    },
    {
      "x": 46,
      "y": 5,
      "z": -51,
      "name": "Rock_Lime"
    },
    {
      "x": 46,
      "y": 6,
      "z": -51,
      "name": "Soil_Gravel_Lime"
    },
    {
      "x": 46,
      "y": 7,
      "z": -51,
      "name": "Rock_Lime"
    },
    {
      "x": 46,
      "y": 8,
      "z": -51,
      "name": "Soil_Gravel_Lime"
    },
    {
      "x": 46,
      "y": 9,
      "z": -51,
      "name": "Rock_Lime"
    },
    {
      "x": 46,
      "y": 10,
      "z": -51,
      "name": "Rock_Lime"
    },
    {
      "x": 46,
      "y": 11,
      "z": -51,
      "name": "Rock_Lime"
    },
    {
      "x": 46,
      "y": 12,
      "z": -51,
      "name": "Soil_Gravel_Lime"
    },
    {
      "x": 46,
      "y": 13,
      "z": -51,
      "name": "Soil_Gravel_Lime"
    },
    {
      "x": 46,
      "y": 14,
      "z": -51,
      "name": "Soil_Gravel_Lime"
    },
    {
      "x": 46,
      "y": 15,
      "z": -51,
      "name": "Soil_Gravel_Lime"
    },
    {
      "x": 46,
      "y": 16,
      "z": -51,
      "name": "Empty"
    },
    {
      "x": 46,
      "y": 5,
      "z": -50,
      "name": "Rock_Lime"
    },
    {
      "x": 46,
      "y": 6,
      "z": -50,
      "name": "Rock_Lime"
    },
    {
      "x": 46,
      "y": 7,
      "z": -50,
      "name": "Soil_Gravel_Lime"
    },
    {
      "x": 46,
      "y": 8,
      "z": -50,
      "name": "Rock_Lime"
    },
    {
      "x": 46,
      "y": 9,
      "z": -50,
      "name": "Soil_Gravel_Lime"
    },
    {
      "x": 46,
      "y": 10,
      "z": -50,
      "name": "Rock_Lime"
    },
    {
      "x": 46,
      "y": 11,
      "z": -50,
      "name": "Rock_Lime"
    },
    {
      "x": 46,
      "y": 12,
      "z": -50,
      "name": "Rock_Lime"
    },
    {
      "x": 46,
      "y": 13,
      "z": -50,
      "name": "Soil_Gravel_Lime"
    },
    {
      "x": 46,
      "y": 14,
      "z": -50,
      "name": "Rock_Lime"
    },
    {
      "x": 46,
      "y": 15,
      "z": -50,
      "name": "Rock_Lime"
    },
    {
      "x": 46,
      "y": 16,
      "z": -50,
      "name": "Empty"
    },
    {
      "x": 46,
      "y": 5,
      "z": -49,
      "name": "Soil_Gravel_Lime"
    },
    {
      "x": 46,
      "y": 6,
      "z": -49,
      "name": "Rock_Lime"
    },
    {
      "x": 46,
      "y": 7,
      "z": -49,
      "name": "Rock_Lime"
    },
    {
      "x": 46,
      "y": 8,
      "z": -49,
      "name": "Rock_Lime"
    },
    {
      "x": 46,
      "y": 9,
      "z": -49,
      "name": "Rock_Lime"
    },
    {
      "x": 46,
      "y": 10,
      "z": -49,
      "name": "Soil_Gravel_Lime"
    },
    {
      "x": 46,
      "y": 11,
      "z": -49,
      "name": "Rock_Lime"
    },
    {
      "x": 46,
      "y": 12,
      "z": -49,
      "name": "Rock_Lime"
    },
    {
      "x": 46,
      "y": 13,
      "z": -49,
      "name": "Rock_Lime"
    },
    {
      "x": 46,
      "y": 14,
      "z": -49,
      "name": "Rock_Lime"
    },
    {
      "x": 46,
      "y": 15,
      "z": -49,
      "name": "Soil_Gravel_Lime"
    },
    {
      "x": 46,
      "y": 16,
      "z": -49,
      "name": "Empty"
    },
    {
      "x": 46,
      "y": 6,
      "z": -48,
      "name": "Rock_Lime"
    },
    {
      "x": 46,
      "y": 7,
      "z": -48,
      "name": "Soil_Gravel_Lime"
    },
    {
      "x": 46,
      "y": 8,
      "z": -48,
      "name": "Rock_Lime"
    },
    {
      "x": 46,
      "y": 9,
      "z": -48,
      "name": "Rock_Lime"
    },
    {
      "x": 46,
      "y": 10,
      "z": -48,
      "name": "Soil_Gravel_Lime"
    },
    {
      "x": 46,
      "y": 11,
      "z": -48,
      "name": "Rock_Lime"
    },
    {
      "x": 46,
      "y": 12,
      "z": -48,
      "name": "Rock_Lime"
    },
    {
      "x": 46,
      "y": 13,
      "z": -48,
      "name": "Rock_Lime"
    },
    {
      "x": 46,
      "y": 14,
      "z": -48,
      "name": "Soil_Gravel_Lime"
    },
    {
      "x": 46,
      "y": 15,
      "z": -48,
      "name": "Rock_Lime"
    },
    {
      "x": 46,
      "y": 16,
      "z": -48,
      "name": "Empty"
    },
    {
      "x": 46,
      "y": 6,
      "z": -47,
      "name": "Rock_Lime"
    },
    {
      "x": 46,
      "y": 7,
      "z": -47,
      "name": "Soil_Gravel_Lime"
    },
    {
      "x": 46,
      "y": 8,
      "z": -47,
      "name": "Soil_Gravel_Lime"
    },
    {
      "x": 46,
      "y": 9,
      "z": -47,
      "name": "Rock_Lime"
    },
    {
      "x": 46,
      "y": 10,
      "z": -47,
      "name": "Soil_Gravel_Lime"
    },
    {
      "x": 46,
      "y": 11,
      "z": -47,
      "name": "Soil_Gravel_Lime"
    },
    {
      "x": 46,
      "y": 12,
      "z": -47,
      "name": "Rock_Lime"
    },
    {
      "x": 46,
      "y": 13,
      "z": -47,
      "name": "Soil_Gravel_Lime"
    },
    {
      "x": 46,
      "y": 14,
      "z": -47,
      "name": "Soil_Gravel_Lime"
    },
    {
      "x": 46,
      "y": 15,
      "z": -47,
      "name": "Rock_Lime"
    },
    {
      "x": 46,
      "y": 16,
      "z": -47,
      "name": "Soil_Clay_Smooth_Lime"
    },
    {
      "x": 46,
      "y": 7,
      "z": -46,
      "name": "Soil_Clay_Smooth_Lime"
    },
    {
      "x": 46,
      "y": 8,
      "z": -46,
      "name": "Plant_Coral_Block_Lime"
    },
    {
      "x": 46,
      "y": 9,
      "z": -46,
      "name": "Soil_Clay_Lime"
    },
    {
      "x": 46,
      "y": 10,
      "z": -46,
      "name": "Soil_Clay_Lime"
    },
    {
      "x": 46,
      "y": 11,
      "z": -46,
      "name": "Soil_Clay_Smooth_Lime"
    },
    {
      "x": 46,
      "y": 12,
      "z": -46,
      "name": "Plant_Coral_Block_Lime"
    },
    {
      "x": 46,
      "y": 13,
      "z": -46,
      "name": "Plant_Coral_Block_Lime"
    },
    {
      "x": 46,
      "y": 14,
      "z": -46,
      "name": "Soil_Clay_Smooth_Lime"
    },
    {
      "x": 46,
      "y": 15,
      "z": -46,
      "name": "Plant_Coral_Block_Lime"
    },
    {
      "x": 46,
      "y": 16,
      "z": -46,
      "name": "Plant_Coral_Block_Lime"
    },
    {
      "x": 46,
      "y": 17,
      "z": -46,
      "name": "Plant_Moss_Rug_Pink",
      "support": 15
    },
    {
      "x": 46,
      "y": 12,
      "z": -45,
      "name": "Plant_Moss_Wall_Green",
      "support": 15
    },
    {
      "x": 46,
      "y": 13,
      "z": -45,
      "name": "Plant_Moss_Wall_Green",
      "support": 15
    },
    {
      "x": 46,
      "y": 14,
      "z": -45,
      "name": "Plant_Moss_Wall_Green",
      "support": 15
    },
    {
      "x": 46,
      "y": 15,
      "z": -45,
      "name": "Plant_Moss_Wall_Green",
      "support": 15
    },
    {
      "x": 46,
      "y": 16,
      "z": -45,
      "name": "Plant_Moss_Wall_Green",
      "support": 15
    },
    {
      "x": 47,
      "y": 11,
      "z": -58,
      "name": "Rock_Lime"
    },
    {
      "x": 47,
      "y": 12,
      "z": -58,
      "name": "Rock_Lime"
    },
    {
      "x": 47,
      "y": 13,
      "z": -58,
      "name": "Rock_Lime"
    },
    {
      "x": 47,
      "y": 14,
      "z": -58,
      "name": "Rubble_Lime_Medium",
      "support": 15
    },
    {
      "x": 47,
      "y": 8,
      "z": -57,
      "name": "Soil_Gravel_Lime"
    },
    {
      "x": 47,
      "y": 9,
      "z": -57,
      "name": "Soil_Gravel_Lime"
    },
    {
      "x": 47,
      "y": 10,
      "z": -57,
      "name": "Rock_Lime"
    },
    {
      "x": 47,
      "y": 11,
      "z": -57,
      "name": "Soil_Gravel_Lime"
    },
    {
      "x": 47,
      "y": 12,
      "z": -57,
      "name": "Rock_Lime"
    },
    {
      "x": 47,
      "y": 13,
      "z": -57,
      "name": "Rock_Lime"
    },
    {
      "x": 47,
      "y": 14,
      "z": -57,
      "name": "Soil_Gravel_Lime"
    },
    {
      "x": 47,
      "y": 15,
      "z": -57,
      "name": "Rock_Lime"
    },
    {
      "x": 47,
      "y": 16,
      "z": -57,
      "name": "Plant_Coral_Block_Lime"
    },
    {
      "x": 47,
      "y": 5,
      "z": -56,
      "name": "Rock_Lime"
    },
    {
      "x": 47,
      "y": 6,
      "z": -56,
      "name": "Soil_Gravel_Lime"
    },
    {
      "x": 47,
      "y": 7,
      "z": -56,
      "name": "Rock_Lime"
    },
    {
      "x": 47,
      "y": 8,
      "z": -56,
      "name": "Soil_Gravel_Lime"
    },
    {
      "x": 47,
      "y": 9,
      "z": -56,
      "name": "Rock_Lime"
    },
    {
      "x": 47,
      "y": 10,
      "z": -56,
      "name": "Soil_Gravel_Lime"
    },
    {
      "x": 47,
      "y": 11,
      "z": -56,
      "name": "Rock_Lime"
    },
    {
      "x": 47,
      "y": 12,
      "z": -56,
      "name": "Soil_Gravel_Lime"
    },
    {
      "x": 47,
      "y": 13,
      "z": -56,
      "name": "Soil_Gravel_Lime"
    },
    {
      "x": 47,
      "y": 14,
      "z": -56,
      "name": "Soil_Gravel_Lime"
    },
    {
      "x": 47,
      "y": 15,
      "z": -56,
      "name": "Plant_Coral_Block_Lime"
    },
    {
      "x": 47,
      "y": 16,
      "z": -56,
      "name": "Soil_Clay_Lime"
    },
    {
      "x": 47,
      "y": 17,
      "z": -56,
      "name": "Soil_Clay_Smooth_Lime"
    },
    {
      "x": 47,
      "y": 5,
      "z": -55,
      "name": "Rock_Lime"
    },
    {
      "x": 47,
      "y": 6,
      "z": -55,
      "name": "Rock_Lime"
    },
    {
      "x": 47,
      "y": 7,
      "z": -55,
      "name": "Rock_Lime"
    },
    {
      "x": 47,
      "y": 8,
      "z": -55,
      "name": "Rock_Lime"
    },
    {
      "x": 47,
      "y": 9,
      "z": -55,
      "name": "Soil_Gravel_Lime"
    },
    {
      "x": 47,
      "y": 10,
      "z": -55,
      "name": "Rock_Lime"
    },
    {
      "x": 47,
      "y": 11,
      "z": -55,
      "name": "Rock_Lime"
    },
    {
      "x": 47,
      "y": 12,
      "z": -55,
      "name": "Rock_Lime"
    },
    {
      "x": 47,
      "y": 13,
      "z": -55,
      "name": "Soil_Gravel_Lime"
    },
    {
      "x": 47,
      "y": 14,
      "z": -55,
      "name": "Rock_Lime"
    },
    {
      "x": 47,
      "y": 15,
      "z": -55,
      "name": "Soil_Clay_Lime"
    },
    {
      "x": 47,
      "y": 16,
      "z": -55,
      "name": "Plant_Coral_Block_Lime"
    },
    {
      "x": 47,
      "y": 5,
      "z": -54,
      "name": "Rock_Lime"
    },
    {
      "x": 47,
      "y": 6,
      "z": -54,
      "name": "Rock_Lime"
    },
    {
      "x": 47,
      "y": 7,
      "z": -54,
      "name": "Soil_Gravel_Lime"
    },
    {
      "x": 47,
      "y": 8,
      "z": -54,
      "name": "Rock_Lime"
    },
    {
      "x": 47,
      "y": 9,
      "z": -54,
      "name": "Rock_Lime"
    },
    {
      "x": 47,
      "y": 10,
      "z": -54,
      "name": "Soil_Gravel_Lime"
    },
    {
      "x": 47,
      "y": 11,
      "z": -54,
      "name": "Rock_Lime"
    },
    {
      "x": 47,
      "y": 12,
      "z": -54,
      "name": "Soil_Gravel_Lime"
    },
    {
      "x": 47,
      "y": 13,
      "z": -54,
      "name": "Rock_Lime"
    },
    {
      "x": 47,
      "y": 14,
      "z": -54,
      "name": "Rock_Lime"
    },
    {
      "x": 47,
      "y": 15,
      "z": -54,
      "name": "Rock_Lime"
    },
    {
      "x": 47,
      "y": 16,
      "z": -54,
      "name": "Empty"
    },
    {
      "x": 47,
      "y": 5,
      "z": -53,
      "name": "Rock_Lime"
    },
    {
      "x": 47,
      "y": 6,
      "z": -53,
      "name": "Soil_Gravel_Lime"
    },
    {
      "x": 47,
      "y": 7,
      "z": -53,
      "name": "Soil_Gravel_Lime"
    },
    {
      "x": 47,
      "y": 8,
      "z": -53,
      "name": "Soil_Gravel_Lime"
    },
    {
      "x": 47,
      "y": 9,
      "z": -53,
      "name": "Rock_Lime"
    },
    {
      "x": 47,
      "y": 10,
      "z": -53,
      "name": "Rock_Lime"
    },
    {
      "x": 47,
      "y": 11,
      "z": -53,
      "name": "Soil_Gravel_Lime"
    },
    {
      "x": 47,
      "y": 12,
      "z": -53,
      "name": "Soil_Gravel_Lime"
    },
    {
      "x": 47,
      "y": 13,
      "z": -53,
      "name": "Rock_Lime"
    },
    {
      "x": 47,
      "y": 14,
      "z": -53,
      "name": "Rock_Lime"
    },
    {
      "x": 47,
      "y": 15,
      "z": -53,
      "name": "Rock_Lime"
    },
    {
      "x": 47,
      "y": 16,
      "z": -53,
      "name": "Empty"
    },
    {
      "x": 47,
      "y": 17,
      "z": -53,
      "name": "Plant_Moss_Wall_Green",
      "support": 15,
      "rotation": 3
    },
    {
      "x": 47,
      "y": 5,
      "z": -52,
      "name": "Rock_Lime"
    },
    {
      "x": 47,
      "y": 6,
      "z": -52,
      "name": "Rock_Lime"
    },
    {
      "x": 47,
      "y": 7,
      "z": -52,
      "name": "Rock_Lime"
    },
    {
      "x": 47,
      "y": 8,
      "z": -52,
      "name": "Rock_Lime"
    },
    {
      "x": 47,
      "y": 9,
      "z": -52,
      "name": "Rock_Lime"
    },
    {
      "x": 47,
      "y": 10,
      "z": -52,
      "name": "Soil_Gravel_Lime"
    },
    {
      "x": 47,
      "y": 11,
      "z": -52,
      "name": "Rock_Lime"
    },
    {
      "x": 47,
      "y": 12,
      "z": -52,
      "name": "Soil_Gravel_Lime"
    },
    {
      "x": 47,
      "y": 13,
      "z": -52,
      "name": "Rock_Lime"
    },
    {
      "x": 47,
      "y": 14,
      "z": -52,
      "name": "Rock_Lime"
    },
    {
      "x": 47,
      "y": 15,
      "z": -52,
      "name": "Rock_Lime"
    },
    {
      "x": 47,
      "y": 16,
      "z": -52,
      "name": "Empty"
    },
    {
      "x": 47,
      "y": 5,
      "z": -51,
      "name": "Rock_Lime"
    },
    {
      "x": 47,
      "y": 6,
      "z": -51,
      "name": "Rock_Lime"
    },
    {
      "x": 47,
      "y": 7,
      "z": -51,
      "name": "Rock_Lime"
    },
    {
      "x": 47,
      "y": 8,
      "z": -51,
      "name": "Rock_Lime"
    },
    {
      "x": 47,
      "y": 9,
      "z": -51,
      "name": "Rock_Lime"
    },
    {
      "x": 47,
      "y": 10,
      "z": -51,
      "name": "Rock_Lime"
    },
    {
      "x": 47,
      "y": 11,
      "z": -51,
      "name": "Rock_Lime"
    },
    {
      "x": 47,
      "y": 12,
      "z": -51,
      "name": "Rock_Lime"
    },
    {
      "x": 47,
      "y": 13,
      "z": -51,
      "name": "Soil_Gravel_Lime"
    },
    {
      "x": 47,
      "y": 14,
      "z": -51,
      "name": "Rock_Lime"
    },
    {
      "x": 47,
      "y": 15,
      "z": -51,
      "name": "Rock_Lime"
    },
    {
      "x": 47,
      "y": 16,
      "z": -51,
      "name": "Empty"
    },
    {
      "x": 47,
      "y": 4,
      "z": -50,
      "name": "Rock_Lime"
    },
    {
      "x": 47,
      "y": 5,
      "z": -50,
      "name": "Soil_Gravel_Lime"
    },
    {
      "x": 47,
      "y": 6,
      "z": -50,
      "name": "Soil_Gravel_Lime"
    },
    {
      "x": 47,
      "y": 7,
      "z": -50,
      "name": "Soil_Gravel_Lime"
    },
    {
      "x": 47,
      "y": 8,
      "z": -50,
      "name": "Rock_Lime"
    },
    {
      "x": 47,
      "y": 9,
      "z": -50,
      "name": "Soil_Gravel_Lime"
    },
    {
      "x": 47,
      "y": 10,
      "z": -50,
      "name": "Soil_Gravel_Lime"
    },
    {
      "x": 47,
      "y": 11,
      "z": -50,
      "name": "Rock_Lime"
    },
    {
      "x": 47,
      "y": 12,
      "z": -50,
      "name": "Rock_Lime"
    },
    {
      "x": 47,
      "y": 13,
      "z": -50,
      "name": "Soil_Gravel_Lime"
    },
    {
      "x": 47,
      "y": 14,
      "z": -50,
      "name": "Rock_Lime"
    },
    {
      "x": 47,
      "y": 15,
      "z": -50,
      "name": "Soil_Gravel_Lime"
    },
    {
      "x": 47,
      "y": 16,
      "z": -50,
      "name": "Empty"
    },
    {
      "x": 47,
      "y": 4,
      "z": -49,
      "name": "Soil_Gravel_Lime"
    },
    {
      "x": 47,
      "y": 5,
      "z": -49,
      "name": "Soil_Gravel_Lime"
    },
    {
      "x": 47,
      "y": 6,
      "z": -49,
      "name": "Soil_Gravel_Lime"
    },
    {
      "x": 47,
      "y": 7,
      "z": -49,
      "name": "Rock_Lime"
    },
    {
      "x": 47,
      "y": 8,
      "z": -49,
      "name": "Rock_Lime"
    },
    {
      "x": 47,
      "y": 9,
      "z": -49,
      "name": "Rock_Lime"
    },
    {
      "x": 47,
      "y": 10,
      "z": -49,
      "name": "Rock_Lime"
    },
    {
      "x": 47,
      "y": 11,
      "z": -49,
      "name": "Soil_Gravel_Lime"
    },
    {
      "x": 47,
      "y": 12,
      "z": -49,
      "name": "Rock_Lime"
    },
    {
      "x": 47,
      "y": 13,
      "z": -49,
      "name": "Rock_Lime"
    },
    {
      "x": 47,
      "y": 14,
      "z": -49,
      "name": "Soil_Gravel_Lime"
    },
    {
      "x": 47,
      "y": 15,
      "z": -49,
      "name": "Soil_Gravel_Lime"
    },
    {
      "x": 47,
      "y": 16,
      "z": -49,
      "name": "Empty"
    },
    {
      "x": 47,
      "y": 5,
      "z": -48,
      "name": "Rock_Lime"
    },
    {
      "x": 47,
      "y": 6,
      "z": -48,
      "name": "Rock_Lime"
    },
    {
      "x": 47,
      "y": 7,
      "z": -48,
      "name": "Rock_Lime"
    },
    {
      "x": 47,
      "y": 8,
      "z": -48,
      "name": "Rock_Lime"
    },
    {
      "x": 47,
      "y": 9,
      "z": -48,
      "name": "Rock_Lime"
    },
    {
      "x": 47,
      "y": 10,
      "z": -48,
      "name": "Rock_Lime"
    },
    {
      "x": 47,
      "y": 11,
      "z": -48,
      "name": "Rock_Lime"
    },
    {
      "x": 47,
      "y": 12,
      "z": -48,
      "name": "Rock_Lime"
    },
    {
      "x": 47,
      "y": 13,
      "z": -48,
      "name": "Soil_Gravel_Lime"
    },
    {
      "x": 47,
      "y": 14,
      "z": -48,
      "name": "Rock_Lime"
    },
    {
      "x": 47,
      "y": 15,
      "z": -48,
      "name": "Rock_Lime"
    },
    {
      "x": 47,
      "y": 16,
      "z": -48,
      "name": "Empty"
    },
    {
      "x": 47,
      "y": 5,
      "z": -47,
      "name": "Rock_Lime"
    },
    {
      "x": 47,
      "y": 6,
      "z": -47,
      "name": "Rock_Lime"
    },
    {
      "x": 47,
      "y": 7,
      "z": -47,
      "name": "Rock_Lime"
    },
    {
      "x": 47,
      "y": 8,
      "z": -47,
      "name": "Rock_Lime"
    },
    {
      "x": 47,
      "y": 9,
      "z": -47,
      "name": "Soil_Gravel_Lime"
    },
    {
      "x": 47,
      "y": 10,
      "z": -47,
      "name": "Rock_Lime"
    },
    {
      "x": 47,
      "y": 11,
      "z": -47,
      "name": "Rock_Lime"
    },
    {
      "x": 47,
      "y": 12,
      "z": -47,
      "name": "Rock_Lime"
    },
    {
      "x": 47,
      "y": 13,
      "z": -47,
      "name": "Rock_Lime"
    },
    {
      "x": 47,
      "y": 14,
      "z": -47,
      "name": "Rock_Lime"
    },
    {
      "x": 47,
      "y": 15,
      "z": -47,
      "name": "Soil_Gravel_Lime"
    },
    {
      "x": 47,
      "y": 16,
      "z": -47,
      "name": "Empty"
    },
    {
      "x": 47,
      "y": 6,
      "z": -46,
      "name": "Rock_Lime"
    },
    {
      "x": 47,
      "y": 7,
      "z": -46,
      "name": "Soil_Gravel_Lime"
    },
    {
      "x": 47,
      "y": 8,
      "z": -46,
      "name": "Rock_Lime"
    },
    {
      "x": 47,
      "y": 9,
      "z": -46,
      "name": "Rock_Lime"
    },
    {
      "x": 47,
      "y": 10,
      "z": -46,
      "name": "Rock_Lime"
    },
    {
      "x": 47,
      "y": 11,
      "z": -46,
      "name": "Rock_Lime"
    },
    {
      "x": 47,
      "y": 12,
      "z": -46,
      "name": "Rock_Lime"
    },
    {
      "x": 47,
      "y": 13,
      "z": -46,
      "name": "Soil_Gravel_Lime"
    },
    {
      "x": 47,
      "y": 14,
      "z": -46,
      "name": "Rock_Lime"
    },
    {
      "x": 47,
      "y": 15,
      "z": -46,
      "name": "Soil_Gravel_Lime"
    },
    {
      "x": 47,
      "y": 16,
      "z": -46,
      "name": "Soil_Clay_Lime"
    },
    {
      "x": 47,
      "y": 17,
      "z": -46,
      "name": "Plant_Moss_Rug_Pink",
      "support": 15
    },
    {
      "x": 47,
      "y": 8,
      "z": -45,
      "name": "Rock_Lime"
    },
    {
      "x": 47,
      "y": 9,
      "z": -45,
      "name": "Rock_Lime"
    },
    {
      "x": 47,
      "y": 10,
      "z": -45,
      "name": "Rock_Lime"
    },
    {
      "x": 47,
      "y": 11,
      "z": -45,
      "name": "Rock_Lime"
    },
    {
      "x": 47,
      "y": 12,
      "z": -45,
      "name": "Plant_Coral_Block_Lime"
    },
    {
      "x": 47,
      "y": 13,
      "z": -45,
      "name": "Plant_Coral_Block_Lime"
    },
    {
      "x": 47,
      "y": 14,
      "z": -45,
      "name": "Plant_Coral_Block_Lime"
    },
    {
      "x": 47,
      "y": 15,
      "z": -45,
      "name": "Plant_Coral_Block_Lime"
    },
    {
      "x": 47,
      "y": 16,
      "z": -45,
      "name": "Plant_Moss_Rug_Pink",
      "support": 15
    },
    {
      "x": 48,
      "y": 12,
      "z": -59,
      "name": "Rock_Lime"
    },
    {
      "x": 48,
      "y": 13,
      "z": -59,
      "name": "Soil_Gravel_Lime"
    },
    {
      "x": 48,
      "y": 14,
      "z": -59,
      "name": "Rock_Lime"
    },
    {
      "x": 48,
      "y": 15,
      "z": -59,
      "name": "Soil_Gravel_Lime"
    },
    {
      "x": 48,
      "y": 16,
      "z": -59,
      "name": "Rock_Lime"
    },
    {
      "x": 48,
      "y": 17,
      "z": -59,
      "name": "Rock_Lime_Stalactite_Large"
    },
    {
      "x": 48,
      "y": 18,
      "z": -59,
      "name": "Rock_Lime_Stalactite_Large",
      "filler": 1024
    },
    {
      "x": 48,
      "y": 9,
      "z": -58,
      "name": "Rock_Lime"
    },
    {
      "x": 48,
      "y": 10,
      "z": -58,
      "name": "Soil_Gravel_Lime"
    },
    {
      "x": 48,
      "y": 11,
      "z": -58,
      "name": "Rock_Lime"
    },
    {
      "x": 48,
      "y": 12,
      "z": -58,
      "name": "Rock_Lime"
    },
    {
      "x": 48,
      "y": 13,
      "z": -58,
      "name": "Soil_Gravel_Lime"
    },
    {
      "x": 48,
      "y": 14,
      "z": -58,
      "name": "Soil_Gravel_Lime"
    },
    {
      "x": 48,
      "y": 15,
      "z": -58,
      "name": "Rock_Lime"
    },
    {
      "x": 48,
      "y": 16,
      "z": -58,
      "name": "Soil_Gravel_Lime"
    },
    {
      "x": 48,
      "y": 6,
      "z": -57,
      "name": "Rock_Lime"
    },
    {
      "x": 48,
      "y": 7,
      "z": -57,
      "name": "Rock_Lime"
    },
    {
      "x": 48,
      "y": 8,
      "z": -57,
      "name": "Soil_Gravel_Lime"
    },
    {
      "x": 48,
      "y": 9,
      "z": -57,
      "name": "Rock_Lime"
    },
    {
      "x": 48,
      "y": 10,
      "z": -57,
      "name": "Rock_Lime"
    },
    {
      "x": 48,
      "y": 11,
      "z": -57,
      "name": "Rock_Lime"
    },
    {
      "x": 48,
      "y": 12,
      "z": -57,
      "name": "Rock_Lime"
    },
    {
      "x": 48,
      "y": 13,
      "z": -57,
      "name": "Rock_Lime"
    },
    {
      "x": 48,
      "y": 14,
      "z": -57,
      "name": "Rock_Lime"
    },
    {
      "x": 48,
      "y": 15,
      "z": -57,
      "name": "Rock_Lime"
    },
    {
      "x": 48,
      "y": 16,
      "z": -57,
      "name": "Rock_Lime"
    },
    {
      "x": 48,
      "y": 17,
      "z": -57,
      "name": "Rock_Lime"
    },
    {
      "x": 48,
      "y": 5,
      "z": -56,
      "name": "Rock_Lime"
    },
    {
      "x": 48,
      "y": 6,
      "z": -56,
      "name": "Rock_Lime"
    },
    {
      "x": 48,
      "y": 7,
      "z": -56,
      "name": "Rock_Lime"
    },
    {
      "x": 48,
      "y": 8,
      "z": -56,
      "name": "Rock_Lime"
    },
    {
      "x": 48,
      "y": 9,
      "z": -56,
      "name": "Rock_Lime"
    },
    {
      "x": 48,
      "y": 10,
      "z": -56,
      "name": "Rock_Lime"
    },
    {
      "x": 48,
      "y": 11,
      "z": -56,
      "name": "Rock_Lime"
    },
    {
      "x": 48,
      "y": 12,
      "z": -56,
      "name": "Rock_Lime"
    },
    {
      "x": 48,
      "y": 13,
      "z": -56,
      "name": "Rock_Lime"
    },
    {
      "x": 48,
      "y": 14,
      "z": -56,
      "name": "Rock_Lime"
    },
    {
      "x": 48,
      "y": 15,
      "z": -56,
      "name": "Soil_Gravel_Lime"
    },
    {
      "x": 48,
      "y": 16,
      "z": -56,
      "name": "Soil_Clay_Lime"
    },
    {
      "x": 48,
      "y": 17,
      "z": -56,
      "name": "Plant_Coral_Block_Lime"
    },
    {
      "x": 48,
      "y": 5,
      "z": -55,
      "name": "Rock_Lime"
    },
    {
      "x": 48,
      "y": 6,
      "z": -55,
      "name": "Rock_Lime"
    },
    {
      "x": 48,
      "y": 7,
      "z": -55,
      "name": "Rock_Lime"
    },
    {
      "x": 48,
      "y": 8,
      "z": -55,
      "name": "Rock_Lime"
    },
    {
      "x": 48,
      "y": 9,
      "z": -55,
      "name": "Rock_Lime"
    },
    {
      "x": 48,
      "y": 10,
      "z": -55,
      "name": "Rock_Lime"
    },
    {
      "x": 48,
      "y": 11,
      "z": -55,
      "name": "Rock_Lime"
    },
    {
      "x": 48,
      "y": 12,
      "z": -55,
      "name": "Rock_Lime"
    },
    {
      "x": 48,
      "y": 13,
      "z": -55,
      "name": "Rock_Lime"
    },
    {
      "x": 48,
      "y": 14,
      "z": -55,
      "name": "Rock_Lime"
    },
    {
      "x": 48,
      "y": 15,
      "z": -55,
      "name": "Soil_Clay_Smooth_Lime"
    },
    {
      "x": 48,
      "y": 16,
      "z": -55,
      "name": "Soil_Clay_Lime"
    },
    {
      "x": 48,
      "y": 17,
      "z": -55,
      "name": "Soil_Clay_Smooth_Lime"
    },
    {
      "x": 48,
      "y": 18,
      "z": -55,
      "name": "Plant_Flower_Bushy_Poisoned"
    },
    {
      "x": 48,
      "y": 5,
      "z": -54,
      "name": "Rock_Lime"
    },
    {
      "x": 48,
      "y": 6,
      "z": -54,
      "name": "Soil_Gravel_Lime"
    },
    {
      "x": 48,
      "y": 7,
      "z": -54,
      "name": "Rock_Lime"
    },
    {
      "x": 48,
      "y": 8,
      "z": -54,
      "name": "Rock_Lime"
    },
    {
      "x": 48,
      "y": 9,
      "z": -54,
      "name": "Soil_Gravel_Lime"
    },
    {
      "x": 48,
      "y": 10,
      "z": -54,
      "name": "Rock_Lime"
    },
    {
      "x": 48,
      "y": 11,
      "z": -54,
      "name": "Soil_Gravel_Lime"
    },
    {
      "x": 48,
      "y": 12,
      "z": -54,
      "name": "Rock_Lime"
    },
    {
      "x": 48,
      "y": 13,
      "z": -54,
      "name": "Rock_Lime"
    },
    {
      "x": 48,
      "y": 14,
      "z": -54,
      "name": "Rock_Lime"
    },
    {
      "x": 48,
      "y": 15,
      "z": -54,
      "name": "Soil_Clay_Smooth_Lime"
    },
    {
      "x": 48,
      "y": 16,
      "z": -54,
      "name": "Plant_Coral_Block_Lime"
    },
    {
      "x": 48,
      "y": 17,
      "z": -54,
      "name": "Plant_Coral_Block_Lime"
    },
    {
      "x": 48,
      "y": 5,
      "z": -53,
      "name": "Rock_Lime"
    },
    {
      "x": 48,
      "y": 6,
      "z": -53,
      "name": "Soil_Gravel_Lime"
    },
    {
      "x": 48,
      "y": 7,
      "z": -53,
      "name": "Rock_Lime"
    },
    {
      "x": 48,
      "y": 8,
      "z": -53,
      "name": "Soil_Gravel_Lime"
    },
    {
      "x": 48,
      "y": 9,
      "z": -53,
      "name": "Rock_Lime"
    },
    {
      "x": 48,
      "y": 10,
      "z": -53,
      "name": "Rock_Lime"
    },
    {
      "x": 48,
      "y": 11,
      "z": -53,
      "name": "Rock_Lime"
    },
    {
      "x": 48,
      "y": 12,
      "z": -53,
      "name": "Rock_Lime"
    },
    {
      "x": 48,
      "y": 13,
      "z": -53,
      "name": "Soil_Gravel_Lime"
    },
    {
      "x": 48,
      "y": 14,
      "z": -53,
      "name": "Rock_Lime"
    },
    {
      "x": 48,
      "y": 15,
      "z": -53,
      "name": "Soil_Gravel_Lime"
    },
    {
      "x": 48,
      "y": 16,
      "z": -53,
      "name": "Plant_Coral_Block_Lime"
    },
    {
      "x": 48,
      "y": 17,
      "z": -53,
      "name": "Plant_Coral_Block_Lime"
    },
    {
      "x": 48,
      "y": 5,
      "z": -52,
      "name": "Rock_Lime"
    },
    {
      "x": 48,
      "y": 6,
      "z": -52,
      "name": "Rock_Lime"
    },
    {
      "x": 48,
      "y": 7,
      "z": -52,
      "name": "Rock_Lime"
    },
    {
      "x": 48,
      "y": 8,
      "z": -52,
      "name": "Soil_Gravel_Lime"
    },
    {
      "x": 48,
      "y": 9,
      "z": -52,
      "name": "Rock_Lime"
    },
    {
      "x": 48,
      "y": 10,
      "z": -52,
      "name": "Rock_Lime"
    },
    {
      "x": 48,
      "y": 11,
      "z": -52,
      "name": "Rock_Lime"
    },
    {
      "x": 48,
      "y": 12,
      "z": -52,
      "name": "Rock_Lime"
    },
    {
      "x": 48,
      "y": 13,
      "z": -52,
      "name": "Rock_Lime"
    },
    {
      "x": 48,
      "y": 14,
      "z": -52,
      "name": "Rock_Lime"
    },
    {
      "x": 48,
      "y": 15,
      "z": -52,
      "name": "Rock_Lime"
    },
    {
      "x": 48,
      "y": 16,
      "z": -52,
      "name": "Plant_Coral_Block_Lime"
    },
    {
      "x": 48,
      "y": 17,
      "z": -52,
      "name": "Plant_Moss_Wall_Green",
      "support": 15
    },
    {
      "x": 48,
      "y": 4,
      "z": -51,
      "name": "Rock_Lime"
    },
    {
      "x": 48,
      "y": 5,
      "z": -51,
      "name": "Rock_Lime"
    },
    {
      "x": 48,
      "y": 6,
      "z": -51,
      "name": "Rock_Lime"
    },
    {
      "x": 48,
      "y": 7,
      "z": -51,
      "name": "Soil_Gravel_Lime"
    },
    {
      "x": 48,
      "y": 8,
      "z": -51,
      "name": "Rock_Lime"
    },
    {
      "x": 48,
      "y": 9,
      "z": -51,
      "name": "Rock_Lime"
    },
    {
      "x": 48,
      "y": 10,
      "z": -51,
      "name": "Soil_Gravel_Lime"
    },
    {
      "x": 48,
      "y": 11,
      "z": -51,
      "name": "Soil_Gravel_Lime"
    },
    {
      "x": 48,
      "y": 12,
      "z": -51,
      "name": "Rock_Lime"
    },
    {
      "x": 48,
      "y": 13,
      "z": -51,
      "name": "Rock_Lime"
    },
    {
      "x": 48,
      "y": 14,
      "z": -51,
      "name": "Rock_Lime"
    },
    {
      "x": 48,
      "y": 15,
      "z": -51,
      "name": "Soil_Gravel_Lime"
    },
    {
      "x": 48,
      "y": 16,
      "z": -51,
      "name": "Empty"
    },
    {
      "x": 48,
      "y": 4,
      "z": -50,
      "name": "Rock_Lime"
    },
    {
      "x": 48,
      "y": 5,
      "z": -50,
      "name": "Soil_Gravel_Lime"
    },
    {
      "x": 48,
      "y": 6,
      "z": -50,
      "name": "Rock_Lime"
    },
    {
      "x": 48,
      "y": 7,
      "z": -50,
      "name": "Rock_Lime"
    },
    {
      "x": 48,
      "y": 8,
      "z": -50,
      "name": "Rock_Lime"
    },
    {
      "x": 48,
      "y": 9,
      "z": -50,
      "name": "Soil_Gravel_Lime"
    },
    {
      "x": 48,
      "y": 10,
      "z": -50,
      "name": "Rock_Lime"
    },
    {
      "x": 48,
      "y": 11,
      "z": -50,
      "name": "Soil_Gravel_Lime"
    },
    {
      "x": 48,
      "y": 12,
      "z": -50,
      "name": "Rock_Lime"
    },
    {
      "x": 48,
      "y": 13,
      "z": -50,
      "name": "Soil_Gravel_Lime"
    },
    {
      "x": 48,
      "y": 14,
      "z": -50,
      "name": "Rock_Lime"
    },
    {
      "x": 48,
      "y": 15,
      "z": -50,
      "name": "Soil_Gravel_Lime"
    },
    {
      "x": 48,
      "y": 16,
      "z": -50,
      "name": "Empty"
    },
    {
      "x": 48,
      "y": 4,
      "z": -49,
      "name": "Rock_Lime"
    },
    {
      "x": 48,
      "y": 5,
      "z": -49,
      "name": "Rock_Lime"
    },
    {
      "x": 48,
      "y": 6,
      "z": -49,
      "name": "Soil_Gravel_Lime"
    },
    {
      "x": 48,
      "y": 7,
      "z": -49,
      "name": "Rock_Lime"
    },
    {
      "x": 48,
      "y": 8,
      "z": -49,
      "name": "Soil_Gravel_Lime"
    },
    {
      "x": 48,
      "y": 9,
      "z": -49,
      "name": "Rock_Lime"
    },
    {
      "x": 48,
      "y": 10,
      "z": -49,
      "name": "Rock_Lime"
    },
    {
      "x": 48,
      "y": 11,
      "z": -49,
      "name": "Soil_Gravel_Lime"
    },
    {
      "x": 48,
      "y": 12,
      "z": -49,
      "name": "Soil_Gravel_Lime"
    },
    {
      "x": 48,
      "y": 13,
      "z": -49,
      "name": "Soil_Gravel_Lime"
    },
    {
      "x": 48,
      "y": 14,
      "z": -49,
      "name": "Rock_Lime"
    },
    {
      "x": 48,
      "y": 15,
      "z": -49,
      "name": "Rock_Lime"
    },
    {
      "x": 48,
      "y": 16,
      "z": -49,
      "name": "Empty"
    },
    {
      "x": 48,
      "y": 4,
      "z": -48,
      "name": "Rock_Lime"
    },
    {
      "x": 48,
      "y": 5,
      "z": -48,
      "name": "Rock_Lime"
    },
    {
      "x": 48,
      "y": 6,
      "z": -48,
      "name": "Rock_Lime"
    },
    {
      "x": 48,
      "y": 7,
      "z": -48,
      "name": "Soil_Gravel_Lime"
    },
    {
      "x": 48,
      "y": 8,
      "z": -48,
      "name": "Soil_Gravel_Lime"
    },
    {
      "x": 48,
      "y": 9,
      "z": -48,
      "name": "Soil_Gravel_Lime"
    },
    {
      "x": 48,
      "y": 10,
      "z": -48,
      "name": "Rock_Lime"
    },
    {
      "x": 48,
      "y": 11,
      "z": -48,
      "name": "Soil_Gravel_Lime"
    },
    {
      "x": 48,
      "y": 12,
      "z": -48,
      "name": "Soil_Gravel_Lime"
    },
    {
      "x": 48,
      "y": 13,
      "z": -48,
      "name": "Rock_Lime"
    },
    {
      "x": 48,
      "y": 14,
      "z": -48,
      "name": "Rock_Lime"
    },
    {
      "x": 48,
      "y": 15,
      "z": -48,
      "name": "Rock_Lime"
    },
    {
      "x": 48,
      "y": 16,
      "z": -48,
      "name": "Empty"
    },
    {
      "x": 48,
      "y": 4,
      "z": -47,
      "name": "Rock_Lime"
    },
    {
      "x": 48,
      "y": 5,
      "z": -47,
      "name": "Rock_Lime"
    },
    {
      "x": 48,
      "y": 6,
      "z": -47,
      "name": "Soil_Gravel_Lime"
    },
    {
      "x": 48,
      "y": 7,
      "z": -47,
      "name": "Soil_Gravel_Lime"
    },
    {
      "x": 48,
      "y": 8,
      "z": -47,
      "name": "Rock_Lime"
    },
    {
      "x": 48,
      "y": 9,
      "z": -47,
      "name": "Soil_Gravel_Lime"
    },
    {
      "x": 48,
      "y": 10,
      "z": -47,
      "name": "Rock_Lime"
    },
    {
      "x": 48,
      "y": 11,
      "z": -47,
      "name": "Rock_Lime"
    },
    {
      "x": 48,
      "y": 12,
      "z": -47,
      "name": "Rock_Lime"
    },
    {
      "x": 48,
      "y": 13,
      "z": -47,
      "name": "Rock_Lime"
    },
    {
      "x": 48,
      "y": 14,
      "z": -47,
      "name": "Rock_Lime"
    },
    {
      "x": 48,
      "y": 15,
      "z": -47,
      "name": "Rock_Lime"
    },
    {
      "x": 48,
      "y": 16,
      "z": -47,
      "name": "Empty"
    },
    {
      "x": 48,
      "y": 5,
      "z": -46,
      "name": "Soil_Gravel_Lime"
    },
    {
      "x": 48,
      "y": 6,
      "z": -46,
      "name": "Soil_Gravel_Lime"
    },
    {
      "x": 48,
      "y": 7,
      "z": -46,
      "name": "Soil_Gravel_Lime"
    },
    {
      "x": 48,
      "y": 8,
      "z": -46,
      "name": "Rock_Lime"
    },
    {
      "x": 48,
      "y": 9,
      "z": -46,
      "name": "Rock_Lime"
    },
    {
      "x": 48,
      "y": 10,
      "z": -46,
      "name": "Rock_Lime"
    },
    {
      "x": 48,
      "y": 11,
      "z": -46,
      "name": "Rock_Lime"
    },
    {
      "x": 48,
      "y": 12,
      "z": -46,
      "name": "Soil_Gravel_Lime"
    },
    {
      "x": 48,
      "y": 13,
      "z": -46,
      "name": "Rock_Lime"
    },
    {
      "x": 48,
      "y": 14,
      "z": -46,
      "name": "Rock_Lime"
    },
    {
      "x": 48,
      "y": 15,
      "z": -46,
      "name": "Rock_Lime"
    },
    {
      "x": 48,
      "y": 16,
      "z": -46,
      "name": "Plant_Coral_Block_Lime"
    },
    {
      "x": 48,
      "y": 17,
      "z": -46,
      "name": "Plant_Moss_Rug_Pink",
      "support": 15
    },
    {
      "x": 48,
      "y": 7,
      "z": -45,
      "name": "Soil_Gravel_Lime"
    },
    {
      "x": 48,
      "y": 8,
      "z": -45,
      "name": "Rock_Lime"
    },
    {
      "x": 48,
      "y": 9,
      "z": -45,
      "name": "Soil_Gravel_Lime"
    },
    {
      "x": 48,
      "y": 10,
      "z": -45,
      "name": "Rock_Lime"
    },
    {
      "x": 48,
      "y": 11,
      "z": -45,
      "name": "Rock_Lime"
    },
    {
      "x": 48,
      "y": 12,
      "z": -45,
      "name": "Soil_Gravel_Lime"
    },
    {
      "x": 48,
      "y": 13,
      "z": -45,
      "name": "Rock_Lime"
    },
    {
      "x": 48,
      "y": 14,
      "z": -45,
      "name": "Rock_Lime"
    },
    {
      "x": 48,
      "y": 15,
      "z": -45,
      "name": "Rock_Lime"
    },
    {
      "x": 48,
      "y": 16,
      "z": -45,
      "name": "Plant_Coral_Block_Lime"
    },
    {
      "x": 48,
      "y": 17,
      "z": -45,
      "name": "Plant_Moss_Rug_Pink",
      "support": 15
    },
    {
      "x": 49,
      "y": 15,
      "z": -61,
      "name": "Plant_Leaves_Dead",
      "support": 15
    },
    {
      "x": 49,
      "y": 12,
      "z": -60,
      "name": "Rock_Lime"
    },
    {
      "x": 49,
      "y": 13,
      "z": -60,
      "name": "Soil_Gravel_Lime"
    },
    {
      "x": 49,
      "y": 14,
      "z": -60,
      "name": "Soil_Gravel_Lime"
    },
    {
      "x": 49,
      "y": 15,
      "z": -60,
      "name": "Soil_Gravel_Lime"
    },
    {
      "x": 49,
      "y": 16,
      "z": -60,
      "name": "Rock_Lime"
    },
    {
      "x": 49,
      "y": 17,
      "z": -60,
      "name": "Soil_Gravel_Lime"
    },
    {
      "x": 49,
      "y": 9,
      "z": -59,
      "name": "Rock_Lime"
    },
    {
      "x": 49,
      "y": 10,
      "z": -59,
      "name": "Rock_Lime"
    },
    {
      "x": 49,
      "y": 11,
      "z": -59,
      "name": "Rock_Lime"
    },
    {
      "x": 49,
      "y": 12,
      "z": -59,
      "name": "Soil_Gravel_Lime"
    },
    {
      "x": 49,
      "y": 13,
      "z": -59,
      "name": "Soil_Gravel_Lime"
    },
    {
      "x": 49,
      "y": 14,
      "z": -59,
      "name": "Soil_Gravel_Lime"
    },
    {
      "x": 49,
      "y": 15,
      "z": -59,
      "name": "Rock_Lime"
    },
    {
      "x": 49,
      "y": 16,
      "z": -59,
      "name": "Rock_Lime"
    },
    {
      "x": 49,
      "y": 17,
      "z": -59,
      "name": "Soil_Gravel_Lime"
    },
    {
      "x": 49,
      "y": 19,
      "z": -59,
      "name": "Plant_Leaves_Dead",
      "support": 15
    },
    {
      "x": 49,
      "y": 7,
      "z": -58,
      "name": "Rock_Lime"
    },
    {
      "x": 49,
      "y": 8,
      "z": -58,
      "name": "Rock_Lime"
    },
    {
      "x": 49,
      "y": 9,
      "z": -58,
      "name": "Rock_Lime"
    },
    {
      "x": 49,
      "y": 10,
      "z": -58,
      "name": "Soil_Gravel_Lime"
    },
    {
      "x": 49,
      "y": 11,
      "z": -58,
      "name": "Soil_Gravel_Lime"
    },
    {
      "x": 49,
      "y": 12,
      "z": -58,
      "name": "Rock_Lime"
    },
    {
      "x": 49,
      "y": 13,
      "z": -58,
      "name": "Rock_Lime"
    },
    {
      "x": 49,
      "y": 14,
      "z": -58,
      "name": "Rock_Lime"
    },
    {
      "x": 49,
      "y": 15,
      "z": -58,
      "name": "Soil_Gravel_Lime"
    },
    {
      "x": 49,
      "y": 16,
      "z": -58,
      "name": "Rock_Lime"
    },
    {
      "x": 49,
      "y": 17,
      "z": -58,
      "name": "Rock_Lime"
    },
    {
      "x": 49,
      "y": 18,
      "z": -58,
      "name": "Rock_Lime"
    },
    {
      "x": 49,
      "y": 19,
      "z": -58,
      "name": "Rock_Lime"
    },
    {
      "x": 49,
      "y": 20,
      "z": -58,
      "name": "Plant_Crop_Mushroom_Cap_Poison",
      "components": {
        "Components": {
          "FarmingBlock": {
            "LastTickGameTime": "0001-01-01T12:00:00Z"
          },
          "PlacedByInteraction": {
            "WhoPlacedUuid": {
              "$binary": "HCpUQzdeSaiDYHpoRePv+w==",
              "$type": "04"
            }
          }
        }
      }
    },
    {
      "x": 49,
      "y": 6,
      "z": -57,
      "name": "Rock_Lime"
    },
    {
      "x": 49,
      "y": 7,
      "z": -57,
      "name": "Soil_Gravel_Lime"
    },
    {
      "x": 49,
      "y": 8,
      "z": -57,
      "name": "Rock_Lime"
    },
    {
      "x": 49,
      "y": 9,
      "z": -57,
      "name": "Rock_Lime"
    },
    {
      "x": 49,
      "y": 10,
      "z": -57,
      "name": "Soil_Gravel_Lime"
    },
    {
      "x": 49,
      "y": 11,
      "z": -57,
      "name": "Soil_Gravel_Lime"
    },
    {
      "x": 49,
      "y": 12,
      "z": -57,
      "name": "Rock_Lime"
    },
    {
      "x": 49,
      "y": 13,
      "z": -57,
      "name": "Rock_Lime"
    },
    {
      "x": 49,
      "y": 14,
      "z": -57,
      "name": "Soil_Gravel_Lime"
    },
    {
      "x": 49,
      "y": 15,
      "z": -57,
      "name": "Soil_Gravel_Lime"
    },
    {
      "x": 49,
      "y": 16,
      "z": -57,
      "name": "Soil_Gravel_Lime"
    },
    {
      "x": 49,
      "y": 17,
      "z": -57,
      "name": "Rock_Lime"
    },
    {
      "x": 49,
      "y": 18,
      "z": -57,
      "name": "Rock_Lime"
    },
    {
      "x": 49,
      "y": 19,
      "z": -57,
      "name": "Rock_Lime"
    },
    {
      "x": 49,
      "y": 5,
      "z": -56,
      "name": "Rock_Lime"
    },
    {
      "x": 49,
      "y": 6,
      "z": -56,
      "name": "Rock_Lime"
    },
    {
      "x": 49,
      "y": 7,
      "z": -56,
      "name": "Rock_Lime"
    },
    {
      "x": 49,
      "y": 8,
      "z": -56,
      "name": "Soil_Gravel_Lime"
    },
    {
      "x": 49,
      "y": 9,
      "z": -56,
      "name": "Rock_Lime"
    },
    {
      "x": 49,
      "y": 10,
      "z": -56,
      "name": "Rock_Lime"
    },
    {
      "x": 49,
      "y": 11,
      "z": -56,
      "name": "Soil_Gravel_Lime"
    },
    {
      "x": 49,
      "y": 12,
      "z": -56,
      "name": "Rock_Lime"
    },
    {
      "x": 49,
      "y": 13,
      "z": -56,
      "name": "Rock_Lime"
    },
    {
      "x": 49,
      "y": 14,
      "z": -56,
      "name": "Rock_Lime"
    },
    {
      "x": 49,
      "y": 15,
      "z": -56,
      "name": "Rock_Lime"
    },
    {
      "x": 49,
      "y": 16,
      "z": -56,
      "name": "Soil_Gravel_Lime"
    },
    {
      "x": 49,
      "y": 17,
      "z": -56,
      "name": "Soil_Gravel_Lime"
    },
    {
      "x": 49,
      "y": 18,
      "z": -56,
      "name": "Rock_Lime"
    },
    {
      "x": 49,
      "y": 19,
      "z": -56,
      "name": "Rubble_Lime_Medium",
      "support": 15
    },
    {
      "x": 49,
      "y": 5,
      "z": -55,
      "name": "Soil_Gravel_Lime"
    },
    {
      "x": 49,
      "y": 6,
      "z": -55,
      "name": "Rock_Lime"
    },
    {
      "x": 49,
      "y": 7,
      "z": -55,
      "name": "Rock_Lime"
    },
    {
      "x": 49,
      "y": 8,
      "z": -55,
      "name": "Rock_Lime"
    },
    {
      "x": 49,
      "y": 9,
      "z": -55,
      "name": "Rock_Lime"
    },
    {
      "x": 49,
      "y": 10,
      "z": -55,
      "name": "Soil_Gravel_Lime"
    },
    {
      "x": 49,
      "y": 11,
      "z": -55,
      "name": "Rock_Lime"
    },
    {
      "x": 49,
      "y": 12,
      "z": -55,
      "name": "Rock_Lime"
    },
    {
      "x": 49,
      "y": 13,
      "z": -55,
      "name": "Rock_Lime"
    },
    {
      "x": 49,
      "y": 14,
      "z": -55,
      "name": "Rock_Lime"
    },
    {
      "x": 49,
      "y": 15,
      "z": -55,
      "name": "Rock_Lime"
    },
    {
      "x": 49,
      "y": 16,
      "z": -55,
      "name": "Soil_Clay_Lime"
    },
    {
      "x": 49,
      "y": 17,
      "z": -55,
      "name": "Soil_Gravel_Lime"
    },
    {
      "x": 49,
      "y": 18,
      "z": -55,
      "name": "Rock_Lime"
    },
    {
      "x": 49,
      "y": 5,
      "z": -54,
      "name": "Rock_Lime"
    },
    {
      "x": 49,
      "y": 6,
      "z": -54,
      "name": "Soil_Gravel_Lime"
    },
    {
      "x": 49,
      "y": 7,
      "z": -54,
      "name": "Soil_Gravel_Lime"
    },
    {
      "x": 49,
      "y": 8,
      "z": -54,
      "name": "Soil_Gravel_Lime"
    },
    {
      "x": 49,
      "y": 9,
      "z": -54,
      "name": "Rock_Lime"
    },
    {
      "x": 49,
      "y": 10,
      "z": -54,
      "name": "Rock_Lime"
    },
    {
      "x": 49,
      "y": 11,
      "z": -54,
      "name": "Rock_Lime"
    },
    {
      "x": 49,
      "y": 12,
      "z": -54,
      "name": "Rock_Lime"
    },
    {
      "x": 49,
      "y": 13,
      "z": -54,
      "name": "Rock_Lime"
    },
    {
      "x": 49,
      "y": 14,
      "z": -54,
      "name": "Rock_Lime"
    },
    {
      "x": 49,
      "y": 15,
      "z": -54,
      "name": "Rock_Lime"
    },
    {
      "x": 49,
      "y": 16,
      "z": -54,
      "name": "Plant_Coral_Block_Lime"
    },
    {
      "x": 49,
      "y": 17,
      "z": -54,
      "name": "Soil_Gravel_Lime"
    },
    {
      "x": 49,
      "y": 5,
      "z": -53,
      "name": "Rock_Lime"
    },
    {
      "x": 49,
      "y": 6,
      "z": -53,
      "name": "Soil_Gravel_Lime"
    },
    {
      "x": 49,
      "y": 7,
      "z": -53,
      "name": "Soil_Gravel_Lime"
    },
    {
      "x": 49,
      "y": 8,
      "z": -53,
      "name": "Rock_Lime"
    },
    {
      "x": 49,
      "y": 9,
      "z": -53,
      "name": "Soil_Gravel_Lime"
    },
    {
      "x": 49,
      "y": 10,
      "z": -53,
      "name": "Soil_Gravel_Lime"
    },
    {
      "x": 49,
      "y": 11,
      "z": -53,
      "name": "Rock_Lime"
    },
    {
      "x": 49,
      "y": 12,
      "z": -53,
      "name": "Rock_Lime"
    },
    {
      "x": 49,
      "y": 13,
      "z": -53,
      "name": "Rock_Lime"
    },
    {
      "x": 49,
      "y": 14,
      "z": -53,
      "name": "Soil_Gravel_Lime"
    },
    {
      "x": 49,
      "y": 15,
      "z": -53,
      "name": "Rock_Lime"
    },
    {
      "x": 49,
      "y": 16,
      "z": -53,
      "name": "Soil_Clay_Smooth_Lime"
    },
    {
      "x": 49,
      "y": 17,
      "z": -53,
      "name": "Soil_Clay_Lime"
    },
    {
      "x": 49,
      "y": 3,
      "z": -52,
      "name": "Rock_Lime"
    },
    {
      "x": 49,
      "y": 4,
      "z": -52,
      "name": "Rock_Lime"
    },
    {
      "x": 49,
      "y": 5,
      "z": -52,
      "name": "Soil_Gravel_Lime"
    },
    {
      "x": 49,
      "y": 6,
      "z": -52,
      "name": "Rock_Lime"
    },
    {
      "x": 49,
      "y": 7,
      "z": -52,
      "name": "Rock_Lime"
    },
    {
      "x": 49,
      "y": 8,
      "z": -52,
      "name": "Soil_Gravel_Lime"
    },
    {
      "x": 49,
      "y": 9,
      "z": -52,
      "name": "Rock_Lime"
    },
    {
      "x": 49,
      "y": 10,
      "z": -52,
      "name": "Rock_Lime"
    },
    {
      "x": 49,
      "y": 11,
      "z": -52,
      "name": "Soil_Gravel_Lime"
    },
    {
      "x": 49,
      "y": 12,
      "z": -52,
      "name": "Rock_Lime"
    },
    {
      "x": 49,
      "y": 13,
      "z": -52,
      "name": "Soil_Gravel_Lime"
    },
    {
      "x": 49,
      "y": 14,
      "z": -52,
      "name": "Rock_Lime"
    },
    {
      "x": 49,
      "y": 15,
      "z": -52,
      "name": "Rock_Lime"
    },
    {
      "x": 49,
      "y": 16,
      "z": -52,
      "name": "Plant_Coral_Block_Lime"
    },
    {
      "x": 49,
      "y": 17,
      "z": -52,
      "name": "Plant_Coral_Block_Lime"
    },
    {
      "x": 49,
      "y": 3,
      "z": -51,
      "name": "Rock_Lime"
    },
    {
      "x": 49,
      "y": 4,
      "z": -51,
      "name": "Rock_Lime"
    },
    {
      "x": 49,
      "y": 5,
      "z": -51,
      "name": "Rock_Lime"
    },
    {
      "x": 49,
      "y": 6,
      "z": -51,
      "name": "Rock_Lime"
    },
    {
      "x": 49,
      "y": 7,
      "z": -51,
      "name": "Soil_Gravel_Lime"
    },
    {
      "x": 49,
      "y": 8,
      "z": -51,
      "name": "Soil_Gravel_Lime"
    },
    {
      "x": 49,
      "y": 9,
      "z": -51,
      "name": "Soil_Gravel_Lime"
    },
    {
      "x": 49,
      "y": 10,
      "z": -51,
      "name": "Soil_Gravel_Lime"
    },
    {
      "x": 49,
      "y": 11,
      "z": -51,
      "name": "Rock_Lime"
    },
    {
      "x": 49,
      "y": 12,
      "z": -51,
      "name": "Rock_Lime"
    },
    {
      "x": 49,
      "y": 13,
      "z": -51,
      "name": "Rock_Lime"
    },
    {
      "x": 49,
      "y": 14,
      "z": -51,
      "name": "Rock_Lime"
    },
    {
      "x": 49,
      "y": 15,
      "z": -51,
      "name": "Rock_Lime"
    },
    {
      "x": 49,
      "y": 16,
      "z": -51,
      "name": "Plant_Coral_Block_Lime"
    },
    {
      "x": 49,
      "y": 17,
      "z": -51,
      "name": "Soil_Clay_Smooth_Lime"
    },
    {
      "x": 49,
      "y": 18,
      "z": -51,
      "name": "Plant_Flower_Bushy_Poisoned"
    },
    {
      "x": 49,
      "y": 4,
      "z": -50,
      "name": "Rock_Lime"
    },
    {
      "x": 49,
      "y": 5,
      "z": -50,
      "name": "Soil_Gravel_Lime"
    },
    {
      "x": 49,
      "y": 6,
      "z": -50,
      "name": "Soil_Gravel_Lime"
    },
    {
      "x": 49,
      "y": 7,
      "z": -50,
      "name": "Rock_Lime"
    },
    {
      "x": 49,
      "y": 8,
      "z": -50,
      "name": "Rock_Lime"
    },
    {
      "x": 49,
      "y": 9,
      "z": -50,
      "name": "Soil_Gravel_Lime"
    },
    {
      "x": 49,
      "y": 10,
      "z": -50,
      "name": "Soil_Gravel_Lime"
    },
    {
      "x": 49,
      "y": 11,
      "z": -50,
      "name": "Rock_Lime"
    },
    {
      "x": 49,
      "y": 12,
      "z": -50,
      "name": "Soil_Gravel_Lime"
    },
    {
      "x": 49,
      "y": 13,
      "z": -50,
      "name": "Rock_Lime"
    },
    {
      "x": 49,
      "y": 14,
      "z": -50,
      "name": "Rock_Lime"
    },
    {
      "x": 49,
      "y": 15,
      "z": -50,
      "name": "Rock_Lime"
    },
    {
      "x": 49,
      "y": 16,
      "z": -50,
      "name": "Empty"
    },
    {
      "x": 49,
      "y": 17,
      "z": -50,
      "name": "Plant_Moss_Wall_Green",
      "support": 15
    },
    {
      "x": 49,
      "y": 4,
      "z": -49,
      "name": "Rock_Lime"
    },
    {
      "x": 49,
      "y": 5,
      "z": -49,
      "name": "Rock_Lime"
    },
    {
      "x": 49,
      "y": 6,
      "z": -49,
      "name": "Soil_Gravel_Lime"
    },
    {
      "x": 49,
      "y": 7,
      "z": -49,
      "name": "Rock_Lime"
    },
    {
      "x": 49,
      "y": 8,
      "z": -49,
      "name": "Rock_Lime"
    },
    {
      "x": 49,
      "y": 9,
      "z": -49,
      "name": "Rock_Lime"
    },
    {
      "x": 49,
      "y": 10,
      "z": -49,
      "name": "Soil_Gravel_Lime"
    },
    {
      "x": 49,
      "y": 11,
      "z": -49,
      "name": "Rock_Lime"
    },
    {
      "x": 49,
      "y": 12,
      "z": -49,
      "name": "Soil_Gravel_Lime"
    },
    {
      "x": 49,
      "y": 13,
      "z": -49,
      "name": "Soil_Gravel_Lime"
    },
    {
      "x": 49,
      "y": 14,
      "z": -49,
      "name": "Soil_Gravel_Lime"
    },
    {
      "x": 49,
      "y": 15,
      "z": -49,
      "name": "Rock_Lime"
    },
    {
      "x": 49,
      "y": 16,
      "z": -49,
      "name": "Empty"
    },
    {
      "x": 49,
      "y": 4,
      "z": -48,
      "name": "Rock_Lime"
    },
    {
      "x": 49,
      "y": 5,
      "z": -48,
      "name": "Soil_Gravel_Lime"
    },
    {
      "x": 49,
      "y": 6,
      "z": -48,
      "name": "Soil_Gravel_Lime"
    },
    {
      "x": 49,
      "y": 7,
      "z": -48,
      "name": "Rock_Lime"
    },
    {
      "x": 49,
      "y": 8,
      "z": -48,
      "name": "Rock_Lime"
    },
    {
      "x": 49,
      "y": 9,
      "z": -48,
      "name": "Rock_Lime"
    },
    {
      "x": 49,
      "y": 10,
      "z": -48,
      "name": "Rock_Lime"
    },
    {
      "x": 49,
      "y": 11,
      "z": -48,
      "name": "Rock_Lime"
    },
    {
      "x": 49,
      "y": 12,
      "z": -48,
      "name": "Rock_Lime"
    },
    {
      "x": 49,
      "y": 13,
      "z": -48,
      "name": "Rock_Lime"
    },
    {
      "x": 49,
      "y": 14,
      "z": -48,
      "name": "Soil_Gravel_Lime"
    },
    {
      "x": 49,
      "y": 15,
      "z": -48,
      "name": "Soil_Gravel_Lime"
    },
    {
      "x": 49,
      "y": 16,
      "z": -48,
      "name": "Empty"
    },
    {
      "x": 49,
      "y": 4,
      "z": -47,
      "name": "Soil_Gravel_Lime"
    },
    {
      "x": 49,
      "y": 5,
      "z": -47,
      "name": "Rock_Lime"
    },
    {
      "x": 49,
      "y": 6,
      "z": -47,
      "name": "Rock_Lime"
    },
    {
      "x": 49,
      "y": 7,
      "z": -47,
      "name": "Rock_Lime"
    },
    {
      "x": 49,
      "y": 8,
      "z": -47,
      "name": "Soil_Gravel_Lime"
    },
    {
      "x": 49,
      "y": 9,
      "z": -47,
      "name": "Rock_Lime"
    },
    {
      "x": 49,
      "y": 10,
      "z": -47,
      "name": "Soil_Gravel_Lime"
    },
    {
      "x": 49,
      "y": 11,
      "z": -47,
      "name": "Rock_Lime"
    },
    {
      "x": 49,
      "y": 12,
      "z": -47,
      "name": "Soil_Gravel_Lime"
    },
    {
      "x": 49,
      "y": 13,
      "z": -47,
      "name": "Rock_Lime"
    },
    {
      "x": 49,
      "y": 14,
      "z": -47,
      "name": "Rock_Lime"
    },
    {
      "x": 49,
      "y": 15,
      "z": -47,
      "name": "Rock_Lime"
    },
    {
      "x": 49,
      "y": 16,
      "z": -47,
      "name": "Empty"
    },
    {
      "x": 49,
      "y": 5,
      "z": -46,
      "name": "Soil_Gravel_Lime"
    },
    {
      "x": 49,
      "y": 6,
      "z": -46,
      "name": "Soil_Gravel_Lime"
    },
    {
      "x": 49,
      "y": 7,
      "z": -46,
      "name": "Soil_Gravel_Lime"
    },
    {
      "x": 49,
      "y": 8,
      "z": -46,
      "name": "Soil_Gravel_Lime"
    },
    {
      "x": 49,
      "y": 9,
      "z": -46,
      "name": "Soil_Gravel_Lime"
    },
    {
      "x": 49,
      "y": 10,
      "z": -46,
      "name": "Soil_Gravel_Lime"
    },
    {
      "x": 49,
      "y": 11,
      "z": -46,
      "name": "Soil_Gravel_Lime"
    },
    {
      "x": 49,
      "y": 12,
      "z": -46,
      "name": "Soil_Gravel_Lime"
    },
    {
      "x": 49,
      "y": 13,
      "z": -46,
      "name": "Soil_Gravel_Lime"
    },
    {
      "x": 49,
      "y": 14,
      "z": -46,
      "name": "Soil_Gravel_Lime"
    },
    {
      "x": 49,
      "y": 15,
      "z": -46,
      "name": "Soil_Gravel_Lime"
    },
    {
      "x": 49,
      "y": 16,
      "z": -46,
      "name": "Rock_Lime"
    },
    {
      "x": 49,
      "y": 17,
      "z": -46,
      "name": "Soil_Clay_Smooth_Lime"
    },
    {
      "x": 49,
      "y": 6,
      "z": -45,
      "name": "Rock_Lime"
    },
    {
      "x": 49,
      "y": 7,
      "z": -45,
      "name": "Soil_Gravel_Lime"
    },
    {
      "x": 49,
      "y": 8,
      "z": -45,
      "name": "Soil_Gravel_Lime"
    },
    {
      "x": 49,
      "y": 9,
      "z": -45,
      "name": "Soil_Gravel_Lime"
    },
    {
      "x": 49,
      "y": 10,
      "z": -45,
      "name": "Soil_Gravel_Lime"
    },
    {
      "x": 49,
      "y": 11,
      "z": -45,
      "name": "Rock_Lime"
    },
    {
      "x": 49,
      "y": 12,
      "z": -45,
      "name": "Soil_Gravel_Lime"
    },
    {
      "x": 49,
      "y": 13,
      "z": -45,
      "name": "Rock_Lime"
    },
    {
      "x": 49,
      "y": 14,
      "z": -45,
      "name": "Soil_Gravel_Lime"
    },
    {
      "x": 49,
      "y": 15,
      "z": -45,
      "name": "Rock_Lime"
    },
    {
      "x": 49,
      "y": 16,
      "z": -45,
      "name": "Plant_Coral_Block_Lime"
    },
    {
      "x": 49,
      "y": 8,
      "z": -44,
      "name": "Soil_Gravel_Lime"
    },
    {
      "x": 49,
      "y": 9,
      "z": -44,
      "name": "Soil_Gravel_Lime"
    },
    {
      "x": 49,
      "y": 10,
      "z": -44,
      "name": "Soil_Gravel_Lime"
    },
    {
      "x": 49,
      "y": 11,
      "z": -44,
      "name": "Soil_Gravel_Lime"
    },
    {
      "x": 49,
      "y": 12,
      "z": -44,
      "name": "Rock_Lime"
    },
    {
      "x": 49,
      "y": 13,
      "z": -44,
      "name": "Plant_Coral_Block_Lime"
    },
    {
      "x": 49,
      "y": 14,
      "z": -44,
      "name": "Plant_Coral_Block_Lime"
    },
    {
      "x": 49,
      "y": 15,
      "z": -44,
      "name": "Plant_Coral_Block_Lime"
    },
    {
      "x": 49,
      "y": 16,
      "z": -44,
      "name": "Plant_Coral_Block_Lime"
    },
    {
      "x": 49,
      "y": 11,
      "z": -43,
      "name": "Plant_Leaves_Dead",
      "support": 15
    },
    {
      "x": 50,
      "y": 12,
      "z": -61,
      "name": "Rock_Lime"
    },
    {
      "x": 50,
      "y": 13,
      "z": -61,
      "name": "Rock_Lime"
    },
    {
      "x": 50,
      "y": 14,
      "z": -61,
      "name": "Rock_Lime"
    },
    {
      "x": 50,
      "y": 15,
      "z": -61,
      "name": "Rock_Lime"
    },
    {
      "x": 50,
      "y": 16,
      "z": -61,
      "name": "Rock_Lime_Stalactite_Large"
    },
    {
      "x": 50,
      "y": 17,
      "z": -61,
      "name": "Rock_Lime_Stalactite_Large",
      "filler": 1024
    },
    {
      "x": 50,
      "y": 9,
      "z": -60,
      "name": "Rock_Lime"
    },
    {
      "x": 50,
      "y": 10,
      "z": -60,
      "name": "Soil_Gravel_Lime"
    },
    {
      "x": 50,
      "y": 11,
      "z": -60,
      "name": "Rock_Lime"
    },
    {
      "x": 50,
      "y": 12,
      "z": -60,
      "name": "Rock_Lime"
    },
    {
      "x": 50,
      "y": 13,
      "z": -60,
      "name": "Rock_Lime"
    },
    {
      "x": 50,
      "y": 14,
      "z": -60,
      "name": "Soil_Gravel_Lime"
    },
    {
      "x": 50,
      "y": 15,
      "z": -60,
      "name": "Soil_Gravel_Lime"
    },
    {
      "x": 50,
      "y": 16,
      "z": -60,
      "name": "Rock_Lime"
    },
    {
      "x": 50,
      "y": 17,
      "z": -60,
      "name": "Rock_Lime"
    },
    {
      "x": 50,
      "y": 18,
      "z": -60,
      "name": "Rock_Lime"
    },
    {
      "x": 50,
      "y": 7,
      "z": -59,
      "name": "Rock_Lime"
    },
    {
      "x": 50,
      "y": 8,
      "z": -59,
      "name": "Rock_Lime"
    },
    {
      "x": 50,
      "y": 9,
      "z": -59,
      "name": "Rock_Lime"
    },
    {
      "x": 50,
      "y": 10,
      "z": -59,
      "name": "Rock_Lime"
    },
    {
      "x": 50,
      "y": 11,
      "z": -59,
      "name": "Rock_Lime"
    },
    {
      "x": 50,
      "y": 12,
      "z": -59,
      "name": "Soil_Gravel_Lime"
    },
    {
      "x": 50,
      "y": 13,
      "z": -59,
      "name": "Rock_Lime"
    },
    {
      "x": 50,
      "y": 14,
      "z": -59,
      "name": "Rock_Lime"
    },
    {
      "x": 50,
      "y": 15,
      "z": -59,
      "name": "Rock_Lime"
    },
    {
      "x": 50,
      "y": 16,
      "z": -59,
      "name": "Rock_Lime"
    },
    {
      "x": 50,
      "y": 17,
      "z": -59,
      "name": "Rock_Lime"
    },
    {
      "x": 50,
      "y": 18,
      "z": -59,
      "name": "Soil_Gravel_Lime"
    },
    {
      "x": 50,
      "y": 19,
      "z": -59,
      "name": "Soil_Gravel_Lime"
    },
    {
      "x": 50,
      "y": 6,
      "z": -58,
      "name": "Soil_Gravel_Lime"
    },
    {
      "x": 50,
      "y": 7,
      "z": -58,
      "name": "Rock_Lime"
    },
    {
      "x": 50,
      "y": 8,
      "z": -58,
      "name": "Rock_Lime"
    },
    {
      "x": 50,
      "y": 9,
      "z": -58,
      "name": "Soil_Gravel_Lime"
    },
    {
      "x": 50,
      "y": 10,
      "z": -58,
      "name": "Soil_Gravel_Lime"
    },
    {
      "x": 50,
      "y": 11,
      "z": -58,
      "name": "Rock_Lime"
    },
    {
      "x": 50,
      "y": 12,
      "z": -58,
      "name": "Rock_Lime"
    },
    {
      "x": 50,
      "y": 13,
      "z": -58,
      "name": "Rock_Lime"
    },
    {
      "x": 50,
      "y": 14,
      "z": -58,
      "name": "Soil_Gravel_Lime"
    },
    {
      "x": 50,
      "y": 15,
      "z": -58,
      "name": "Soil_Gravel_Lime"
    },
    {
      "x": 50,
      "y": 16,
      "z": -58,
      "name": "Rock_Lime"
    },
    {
      "x": 50,
      "y": 17,
      "z": -58,
      "name": "Rock_Lime"
    },
    {
      "x": 50,
      "y": 18,
      "z": -58,
      "name": "Rock_Lime"
    },
    {
      "x": 50,
      "y": 19,
      "z": -58,
      "name": "Soil_Gravel_Lime"
    },
    {
      "x": 50,
      "y": 5,
      "z": -57,
      "name": "Rock_Lime"
    },
    {
      "x": 50,
      "y": 6,
      "z": -57,
      "name": "Rock_Lime"
    },
    {
      "x": 50,
      "y": 7,
      "z": -57,
      "name": "Soil_Gravel_Lime"
    },
    {
      "x": 50,
      "y": 8,
      "z": -57,
      "name": "Rock_Lime"
    },
    {
      "x": 50,
      "y": 9,
      "z": -57,
      "name": "Rock_Lime"
    },
    {
      "x": 50,
      "y": 10,
      "z": -57,
      "name": "Rock_Lime"
    },
    {
      "x": 50,
      "y": 11,
      "z": -57,
      "name": "Rock_Lime"
    },
    {
      "x": 50,
      "y": 12,
      "z": -57,
      "name": "Rock_Lime"
    },
    {
      "x": 50,
      "y": 13,
      "z": -57,
      "name": "Soil_Gravel_Lime"
    },
    {
      "x": 50,
      "y": 14,
      "z": -57,
      "name": "Rock_Lime"
    },
    {
      "x": 50,
      "y": 15,
      "z": -57,
      "name": "Rock_Lime"
    },
    {
      "x": 50,
      "y": 16,
      "z": -57,
      "name": "Rock_Lime"
    },
    {
      "x": 50,
      "y": 17,
      "z": -57,
      "name": "Soil_Gravel_Lime"
    },
    {
      "x": 50,
      "y": 18,
      "z": -57,
      "name": "Soil_Gravel_Lime"
    },
    {
      "x": 50,
      "y": 19,
      "z": -57,
      "name": "Soil_Gravel_Lime"
    },
    {
      "x": 50,
      "y": 20,
      "z": -57,
      "name": "Rubble_Lime_Medium",
      "support": 15
    },
    {
      "x": 50,
      "y": 5,
      "z": -56,
      "name": "Rock_Lime"
    },
    {
      "x": 50,
      "y": 6,
      "z": -56,
      "name": "Rock_Lime"
    },
    {
      "x": 50,
      "y": 7,
      "z": -56,
      "name": "Soil_Gravel_Lime"
    },
    {
      "x": 50,
      "y": 8,
      "z": -56,
      "name": "Rock_Lime"
    },
    {
      "x": 50,
      "y": 9,
      "z": -56,
      "name": "Rock_Lime"
    },
    {
      "x": 50,
      "y": 10,
      "z": -56,
      "name": "Rock_Lime"
    },
    {
      "x": 50,
      "y": 11,
      "z": -56,
      "name": "Rock_Lime"
    },
    {
      "x": 50,
      "y": 12,
      "z": -56,
      "name": "Rock_Lime"
    },
    {
      "x": 50,
      "y": 13,
      "z": -56,
      "name": "Rock_Lime"
    },
    {
      "x": 50,
      "y": 14,
      "z": -56,
      "name": "Soil_Gravel_Lime"
    },
    {
      "x": 50,
      "y": 15,
      "z": -56,
      "name": "Rock_Lime"
    },
    {
      "x": 50,
      "y": 16,
      "z": -56,
      "name": "Rock_Lime"
    },
    {
      "x": 50,
      "y": 17,
      "z": -56,
      "name": "Soil_Gravel_Lime"
    },
    {
      "x": 50,
      "y": 18,
      "z": -56,
      "name": "Rock_Lime"
    },
    {
      "x": 50,
      "y": 19,
      "z": -56,
      "name": "Rock_Lime"
    },
    {
      "x": 50,
      "y": 20,
      "z": -56,
      "name": "Rock_Lime"
    },
    {
      "x": 50,
      "y": 21,
      "z": -56,
      "name": "Rock_Lime_Stalactite_Large"
    },
    {
      "x": 50,
      "y": 22,
      "z": -56,
      "name": "Rock_Lime_Stalactite_Large",
      "filler": 1024
    },
    {
      "x": 50,
      "y": 5,
      "z": -55,
      "name": "Soil_Gravel_Lime"
    },
    {
      "x": 50,
      "y": 6,
      "z": -55,
      "name": "Rock_Lime"
    },
    {
      "x": 50,
      "y": 7,
      "z": -55,
      "name": "Soil_Gravel_Lime"
    },
    {
      "x": 50,
      "y": 8,
      "z": -55,
      "name": "Soil_Gravel_Lime"
    },
    {
      "x": 50,
      "y": 9,
      "z": -55,
      "name": "Rock_Lime"
    },
    {
      "x": 50,
      "y": 10,
      "z": -55,
      "name": "Rock_Lime"
    },
    {
      "x": 50,
      "y": 11,
      "z": -55,
      "name": "Soil_Gravel_Lime"
    },
    {
      "x": 50,
      "y": 12,
      "z": -55,
      "name": "Rock_Lime"
    },
    {
      "x": 50,
      "y": 13,
      "z": -55,
      "name": "Soil_Gravel_Lime"
    },
    {
      "x": 50,
      "y": 14,
      "z": -55,
      "name": "Rock_Lime"
    },
    {
      "x": 50,
      "y": 15,
      "z": -55,
      "name": "Rock_Lime"
    },
    {
      "x": 50,
      "y": 16,
      "z": -55,
      "name": "Rock_Lime"
    },
    {
      "x": 50,
      "y": 17,
      "z": -55,
      "name": "Soil_Gravel_Lime"
    },
    {
      "x": 50,
      "y": 18,
      "z": -55,
      "name": "Rock_Lime"
    },
    {
      "x": 50,
      "y": 19,
      "z": -55,
