{
  "version": 8,
  "blockIdVersion": 11,
  "anchorX": -117,
  "anchorY": 13,
  "anchorZ": -82,
  "blocks": [
    {
      "x": -124,
      "y": 9,
      "z": -83,
      "name": "Rock_Lime_Brick_Decorative"
    },
    {
      "x": -124,
      "y": 10,
      "z": -83,
      "name": "Rock_Lime"
    },
    {
      "x": -124,
      "y": 11,
      "z": -83,
      "name": "Rock_Lime_Brick_Decorative"
    },
    {
      "x": -124,
      "y": 12,
      "z": -83,
      "name": "Rock_Lime_Brick_Decorative"
    },
    {
      "x": -124,
      "y": 13,
      "z": -83,
      "name": "Rock_Lime"
    },
    {
      "x": -124,
      "y": 14,
      "z": -83,
      "name": "Rock_Lime_Stalactite_Large"
    },
    {
      "x": -124,
      "y": 15,
      "z": -83,
      "name": "Rock_Lime_Stalactite_Large",
      "filler": 1024
    },
    {
      "x": -124,
      "y": 9,
      "z": -82,
      "name": "Rock_Lime_Brick_Decorative"
    },
    {
      "x": -124,
      "y": 10,
      "z": -82,
      "name": "Rock_Lime"
    },
    {
      "x": -124,
      "y": 11,
      "z": -82,
      "name": "Rock_Lime"
    },
    {
      "x": -124,
      "y": 12,
      "z": -82,
      "name": "Rock_Lime_Brick_Decorative"
    },
    {
      "x": -124,
      "y": 13,
      "z": -82,
      "name": "Rock_Lime_Brick_Decorative"
    },
    {
      "x": -124,
      "y": 14,
      "z": -82,
      "name": "Soil_Gravel_Lime"
    },
    {
      "x": -124,
      "y": 15,
      "z": -82,
      "name": "Soil_Gravel_Lime"
    },
    {
      "x": -124,
      "y": 16,
      "z": -82,
      "name": "Rock_Lime"
    },
    {
      "x": -124,
      "y": 9,
      "z": -81,
      "name": "Soil_Gravel_Lime"
    },
    {
      "x": -124,
      "y": 10,
      "z": -81,
      "name": "Rock_Lime"
    },
    {
      "x": -124,
      "y": 11,
      "z": -81,
      "name": "Rock_Lime"
    },
    {
      "x": -124,
      "y": 12,
      "z": -81,
      "name": "Rock_Lime_Brick_Decorative"
    },
    {
      "x": -124,
      "y": 13,
      "z": -81,
      "name": "Soil_Gravel_Lime"
    },
    {
      "x": -124,
      "y": 14,
      "z": -81,
      "name": "Rock_Lime_Brick_Decorative"
    },
    {
      "x": -124,
      "y": 15,
      "z": -81,
      "name": "Soil_Gravel_Lime"
    },
    {
      "x": -124,
      "y": 16,
      "z": -81,
      "name": "Soil_Gravel_Lime"
    },
    {
      "x": -124,
      "y": 9,
      "z": -80,
      "name": "Rock_Lime_Brick_Decorative"
    },
    {
      "x": -124,
      "y": 10,
      "z": -80,
      "name": "Rock_Lime"
    },
    {
      "x": -124,
      "y": 11,
      "z": -80,
      "name": "Rock_Lime_Brick_Decorative"
    },
    {
      "x": -124,
      "y": 12,
      "z": -80,
      "name": "Rock_Lime_Brick_Decorative"
    },
    {
      "x": -124,
      "y": 13,
      "z": -80,
      "name": "Rock_Lime_Brick_Decorative"
    },
    {
      "x": -124,
      "y": 14,
      "z": -80,
      "name": "Rock_Lime_Brick_Decorative"
    },
    {
      "x": -124,
      "y": 15,
      "z": -80,
      "name": "Rock_Lime"
    },
    {
      "x": -124,
      "y": 16,
      "z": -80,
      "name": "Soil_Gravel_Lime"
    },
    {
      "x": -124,
      "y": 9,
      "z": -79,
      "name": "Rock_Lime_Brick_Decorative"
    },
    {
      "x": -124,
      "y": 10,
      "z": -79,
      "name": "Rock_Lime_Brick_Decorative"
    },
    {
      "x": -124,
      "y": 11,
      "z": -79,
      "name": "Rock_Lime_Brick_Decorative"
    },
    {
      "x": -124,
      "y": 12,
      "z": -79,
      "name": "Rock_Lime"
    },
    {
      "x": -124,
      "y": 13,
      "z": -79,
      "name": "Rock_Lime_Brick_Decorative"
    },
    {
      "x": -124,
      "y": 14,
      "z": -79,
      "name": "Soil_Gravel_Lime"
    },
    {
      "x": -124,
      "y": 15,
      "z": -79,
      "name": "Soil_Gravel_Lime"
    },
    {
      "x": -123,
      "y": 9,
      "z": -85,
      "name": "Rock_Lime_Cobble"
    },
    {
      "x": -123,
      "y": 10,
      "z": -85,
      "name": "Rock_Lime_Brick_Decorative"
    },
    {
      "x": -123,
      "y": 11,
      "z": -85,
      "name": "Soil_Gravel_Lime"
    },
    {
      "x": -123,
      "y": 12,
      "z": -85,
      "name": "Rock_Lime_Brick_Decorative",
      "support": 15
    },
    {
      "x": -123,
      "y": 13,
      "z": -85,
      "name": "Rock_Lime_Brick_Decorative"
    },
    {
      "x": -123,
      "y": 14,
      "z": -85,
      "name": "Rock_Lime_Brick_Decorative"
    },
    {
      "x": -123,
      "y": 15,
      "z": -85,
      "name": "Rock_Lime"
    },
    {
      "x": -123,
      "y": 16,
      "z": -85,
      "name": "Rock_Lime_Brick_Decorative"
    },
    {
      "x": -123,
      "y": 17,
      "z": -85,
      "name": "Rubble_Lime"
    },
    {
      "x": -123,
      "y": 8,
      "z": -84,
      "name": "Rock_Lime_Cobble"
    },
    {
      "x": -123,
      "y": 9,
      "z": -84,
      "name": "Soil_Gravel_Lime"
    },
    {
      "x": -123,
      "y": 10,
      "z": -84,
      "name": "Rock_Lime"
    },
    {
      "x": -123,
      "y": 11,
      "z": -84,
      "name": "Rock_Lime_Brick_Decorative"
    },
    {
      "x": -123,
      "y": 12,
      "z": -84,
      "name": "Rock_Lime_Brick_Decorative"
    },
    {
      "x": -123,
      "y": 13,
      "z": -84,
      "name": "Soil_Gravel_Lime"
    },
    {
      "x": -123,
      "y": 14,
      "z": -84,
      "name": "Rock_Lime_Brick_Decorative"
    },
    {
      "x": -123,
      "y": 15,
      "z": -84,
      "name": "Soil_Gravel_Lime"
    },
    {
      "x": -123,
      "y": 16,
      "z": -84,
      "name": "Plant_Coral_Block_Lime"
    },
    {
      "x": -123,
      "y": 17,
      "z": -84,
      "name": "Plant_Coral_Block_Lime"
    },
    {
      "x": -123,
      "y": 7,
      "z": -83,
      "name": "Rock_Lime"
    },
    {
      "x": -123,
      "y": 8,
      "z": -83,
      "name": "Rock_Lime"
    },
    {
      "x": -123,
      "y": 9,
      "z": -83,
      "name": "Rock_Lime"
    },
    {
      "x": -123,
      "y": 10,
      "z": -83,
      "name": "Rock_Lime"
    },
    {
      "x": -123,
      "y": 11,
      "z": -83,
      "name": "Rock_Lime_Cobble"
    },
    {
      "x": -123,
      "y": 12,
      "z": -83,
      "name": "Soil_Gravel_Lime"
    },
    {
      "x": -123,
      "y": 13,
      "z": -83,
      "name": "Soil_Gravel_Lime"
    },
    {
      "x": -123,
      "y": 14,
      "z": -83,
      "name": "Rock_Lime"
    },
    {
      "x": -123,
      "y": 15,
      "z": -83,
      "name": "Soil_Clay_Smooth_Lime"
    },
    {
      "x": -123,
      "y": 16,
      "z": -83,
      "name": "Plant_Coral_Block_Lime"
    },
    {
      "x": -123,
      "y": 17,
      "z": -83,
      "name": "Plant_Coral_Block_Lime"
    },
    {
      "x": -123,
      "y": 8,
      "z": -82,
      "name": "Rock_Lime"
    },
    {
      "x": -123,
      "y": 9,
      "z": -82,
      "name": "Rock_Lime_Cobble"
    },
    {
      "x": -123,
      "y": 10,
      "z": -82,
      "name": "Rock_Lime_Cobble"
    },
    {
      "x": -123,
      "y": 11,
      "z": -82,
      "name": "Soil_Gravel_Lime"
    },
    {
      "x": -123,
      "y": 12,
      "z": -82,
      "name": "Rock_Lime_Brick_Decorative"
    },
    {
      "x": -123,
      "y": 13,
      "z": -82,
      "name": "Soil_Gravel_Lime"
    },
    {
      "x": -123,
      "y": 14,
      "z": -82,
      "name": "Soil_Gravel_Lime"
    },
    {
      "x": -123,
      "y": 15,
      "z": -82,
      "name": "Rock_Lime"
    },
    {
      "x": -123,
      "y": 16,
      "z": -82,
      "name": "Rock_Lime"
    },
    {
      "x": -123,
      "y": 17,
      "z": -82,
      "name": "Plant_Coral_Block_Lime"
    },
    {
      "x": -123,
      "y": 9,
      "z": -81,
      "name": "Rock_Lime_Cobble"
    },
    {
      "x": -123,
      "y": 10,
      "z": -81,
      "name": "Rock_Lime_Brick_Decorative"
    },
    {
      "x": -123,
      "y": 11,
      "z": -81,
      "name": "Rock_Lime_Brick_Decorative"
    },
    {
      "x": -123,
      "y": 12,
      "z": -81,
      "name": "Rock_Lime_Brick_Decorative"
    },
    {
      "x": -123,
      "y": 13,
      "z": -81,
      "name": "Rock_Lime_Brick_Decorative"
    },
    {
      "x": -123,
      "y": 14,
      "z": -81,
      "name": "Rock_Lime_Brick_Decorative"
    },
    {
      "x": -123,
      "y": 15,
      "z": -81,
      "name": "Rock_Lime"
    },
    {
      "x": -123,
      "y": 16,
      "z": -81,
      "name": "Rock_Lime_Brick_Decorative"
    },
    {
      "x": -123,
      "y": 17,
      "z": -81,
      "name": "Soil_Clay_Smooth_Lime"
    },
    {
      "x": -123,
      "y": 9,
      "z": -80,
      "name": "Rock_Lime_Brick_Decorative"
    },
    {
      "x": -123,
      "y": 10,
      "z": -80,
      "name": "Rock_Lime_Brick_Decorative"
    },
    {
      "x": -123,
      "y": 11,
      "z": -80,
      "name": "Rock_Lime_Brick_Decorative"
    },
    {
      "x": -123,
      "y": 12,
      "z": -80,
      "name": "Rock_Lime_Brick_Decorative"
    },
    {
      "x": -123,
      "y": 13,
      "z": -80,
      "name": "Rock_Lime_Brick_Decorative"
    },
    {
      "x": -123,
      "y": 14,
      "z": -80,
      "name": "Rock_Lime"
    },
    {
      "x": -123,
      "y": 15,
      "z": -80,
      "name": "Rock_Lime_Brick_Decorative"
    },
    {
      "x": -123,
      "y": 16,
      "z": -80,
      "name": "Rock_Lime"
    },
    {
      "x": -123,
      "y": 17,
      "z": -80,
      "name": "Plant_Coral_Block_Lime"
    },
    {
      "x": -123,
      "y": 9,
      "z": -79,
      "name": "Soil_Gravel_Lime"
    },
    {
      "x": -123,
      "y": 10,
      "z": -79,
      "name": "Rock_Lime"
    },
    {
      "x": -123,
      "y": 11,
      "z": -79,
      "name": "Rock_Lime_Brick_Decorative"
    },
    {
      "x": -123,
      "y": 12,
      "z": -79,
      "name": "Rock_Lime_Brick_Decorative",
      "support": 15
    },
    {
      "x": -123,
      "y": 13,
      "z": -79,
      "name": "Rock_Lime"
    },
    {
      "x": -123,
      "y": 14,
      "z": -79,
      "name": "Soil_Gravel_Lime"
    },
    {
      "x": -123,
      "y": 15,
      "z": -79,
      "name": "Rock_Lime_Brick_Decorative"
    },
    {
      "x": -123,
      "y": 16,
      "z": -79,
      "name": "Rock_Lime"
    },
    {
      "x": -123,
      "y": 17,
      "z": -79,
      "name": "Rubble_Lime_Medium"
    },
    {
      "x": -123,
      "y": 9,
      "z": -78,
      "name": "Soil_Gravel_Lime"
    },
    {
      "x": -123,
      "y": 10,
      "z": -78,
      "name": "Rock_Lime_Brick_Decorative"
    },
    {
      "x": -123,
      "y": 11,
      "z": -78,
      "name": "Rock_Lime"
    },
    {
      "x": -123,
      "y": 12,
      "z": -78,
      "name": "Rock_Lime_Brick_Decorative"
    },
    {
      "x": -123,
      "y": 13,
      "z": -78,
      "name": "Rock_Lime"
    },
    {
      "x": -122,
      "y": 7,
      "z": -86,
      "name": "Rock_Lime_Brick_Decorative"
    },
    {
      "x": -122,
      "y": 8,
      "z": -86,
      "name": "Rock_Lime_Cobble"
    },
    {
      "x": -122,
      "y": 9,
      "z": -86,
      "name": "Rock_Lime_Cobble"
    },
    {
      "x": -122,
      "y": 10,
      "z": -86,
      "name": "Soil_Gravel_Lime"
    },
    {
      "x": -122,
      "y": 11,
      "z": -86,
      "name": "Rock_Lime"
    },
    {
      "x": -122,
      "y": 12,
      "z": -86,
      "name": "Rock_Lime"
    },
    {
      "x": -122,
      "y": 13,
      "z": -86,
      "name": "Soil_Gravel_Lime"
    },
    {
      "x": -122,
      "y": 14,
      "z": -86,
      "name": "Rock_Lime_Brick_Decorative"
    },
    {
      "x": -122,
      "y": 15,
      "z": -86,
      "name": "Rock_Lime_Stalactite_Large"
    },
    {
      "x": -122,
      "y": 16,
      "z": -86,
      "name": "Rock_Lime_Stalactite_Large",
      "filler": 1024
    },
    {
      "x": -122,
      "y": 6,
      "z": -85,
      "name": "Soil_Gravel_Lime"
    },
    {
      "x": -122,
      "y": 7,
      "z": -85,
      "name": "Rock_Lime_Cobble"
    },
    {
      "x": -122,
      "y": 8,
      "z": -85,
      "name": "Rock_Lime"
    },
    {
      "x": -122,
      "y": 9,
      "z": -85,
      "name": "Rock_Lime_Brick_Decorative"
    },
    {
      "x": -122,
      "y": 10,
      "z": -85,
      "name": "Rock_Lime_Cobble"
    },
    {
      "x": -122,
      "y": 11,
      "z": -85,
      "name": "Rock_Lime_Cobble"
    },
    {
      "x": -122,
      "y": 12,
      "z": -85,
      "name": "Rock_Lime_Cobble"
    },
    {
      "x": -122,
      "y": 13,
      "z": -85,
      "name": "Rock_Lime_Brick_Decorative"
    },
    {
      "x": -122,
      "y": 14,
      "z": -85,
      "name": "Rock_Lime_Brick_Decorative"
    },
    {
      "x": -122,
      "y": 15,
      "z": -85,
      "name": "Rock_Lime_Brick_Decorative"
    },
    {
      "x": -122,
      "y": 16,
      "z": -85,
      "name": "Soil_Clay_Smooth_Lime"
    },
    {
      "x": -122,
      "y": 17,
      "z": -85,
      "name": "Soil_Clay_Smooth_Lime"
    },
    {
      "x": -122,
      "y": 18,
      "z": -85,
      "name": "Plant_Flower_Bushy_Poisoned"
    },
    {
      "x": -122,
      "y": 6,
      "z": -84,
      "name": "Rock_Lime_Brick_Decorative"
    },
    {
      "x": -122,
      "y": 7,
      "z": -84,
      "name": "Rock_Lime_Brick_Decorative"
    },
    {
      "x": -122,
      "y": 8,
      "z": -84,
      "name": "Rock_Lime"
    },
    {
      "x": -122,
      "y": 9,
      "z": -84,
      "name": "Soil_Gravel_Lime"
    },
    {
      "x": -122,
      "y": 10,
      "z": -84,
      "name": "Soil_Gravel_Lime"
    },
    {
      "x": -122,
      "y": 11,
      "z": -84,
      "name": "Rock_Lime_Cobble"
    },
    {
      "x": -122,
      "y": 12,
      "z": -84,
      "name": "Rock_Lime"
    },
    {
      "x": -122,
      "y": 13,
      "z": -84,
      "name": "Rock_Lime"
    },
    {
      "x": -122,
      "y": 14,
      "z": -84,
      "name": "Rock_Lime"
    },
    {
      "x": -122,
      "y": 15,
      "z": -84,
      "name": "Rock_Lime"
    },
    {
      "x": -122,
      "y": 16,
      "z": -84,
      "name": "Plant_Coral_Block_Lime"
    },
    {
      "x": -122,
      "y": 17,
      "z": -84,
      "name": "Plant_Coral_Block_Lime"
    },
    {
      "x": -122,
      "y": 6,
      "z": -83,
      "name": "Rock_Lime"
    },
    {
      "x": -122,
      "y": 7,
      "z": -83,
      "name": "Rock_Lime"
    },
    {
      "x": -122,
      "y": 8,
      "z": -83,
      "name": "Soil_Gravel_Lime"
    },
    {
      "x": -122,
      "y": 9,
      "z": -83,
      "name": "Rock_Lime_Brick_Decorative"
    },
    {
      "x": -122,
      "y": 10,
      "z": -83,
      "name": "Rock_Lime"
    },
    {
      "x": -122,
      "y": 11,
      "z": -83,
      "name": "Rock_Lime_Brick_Decorative"
    },
    {
      "x": -122,
      "y": 12,
      "z": -83,
      "name": "Rock_Lime_Brick_Decorative"
    },
    {
      "x": -122,
      "y": 13,
      "z": -83,
      "name": "Rock_Lime_Brick_Decorative"
    },
    {
      "x": -122,
      "y": 14,
      "z": -83,
      "name": "Soil_Gravel_Lime"
    },
    {
      "x": -122,
      "y": 15,
      "z": -83,
      "name": "Rock_Lime_Brick_Decorative"
    },
    {
      "x": -122,
      "y": 16,
      "z": -83,
      "name": "Plant_Coral_Block_Lime"
    },
    {
      "x": -122,
      "y": 6,
      "z": -82,
      "name": "Rock_Lime"
    },
    {
      "x": -122,
      "y": 7,
      "z": -82,
      "name": "Rock_Lime_Brick_Decorative"
    },
    {
      "x": -122,
      "y": 8,
      "z": -82,
      "name": "Soil_Gravel_Lime"
    },
    {
      "x": -122,
      "y": 9,
      "z": -82,
      "name": "Rock_Lime"
    },
    {
      "x": -122,
      "y": 10,
      "z": -82,
      "name": "Rock_Lime"
    },
    {
      "x": -122,
      "y": 11,
      "z": -82,
      "name": "Rock_Lime_Cobble"
    },
    {
      "x": -122,
      "y": 12,
      "z": -82,
      "name": "Soil_Gravel_Lime"
    },
    {
      "x": -122,
      "y": 13,
      "z": -82,
      "name": "Rock_Lime_Brick_Decorative"
    },
    {
      "x": -122,
      "y": 14,
      "z": -82,
      "name": "Rock_Lime_Brick_Decorative"
    },
    {
      "x": -122,
      "y": 15,
      "z": -82,
      "name": "Soil_Gravel_Lime"
    },
    {
      "x": -122,
      "y": 16,
      "z": -82,
      "name": "Plant_Coral_Block_Lime"
    },
    {
      "x": -122,
      "y": 6,
      "z": -81,
      "name": "Rock_Lime"
    },
    {
      "x": -122,
      "y": 7,
      "z": -81,
      "name": "Rock_Lime_Brick_Decorative"
    },
    {
      "x": -122,
      "y": 8,
      "z": -81,
      "name": "Rock_Lime_Cobble"
    },
    {
      "x": -122,
      "y": 9,
      "z": -81,
      "name": "Rock_Lime"
    },
    {
      "x": -122,
      "y": 10,
      "z": -81,
      "name": "Rock_Lime_Brick_Decorative"
    },
    {
      "x": -122,
      "y": 11,
      "z": -81,
      "name": "Rock_Lime"
    },
    {
      "x": -122,
      "y": 12,
      "z": -81,
      "name": "Rock_Lime"
    },
    {
      "x": -122,
      "y": 13,
      "z": -81,
      "name": "Rock_Lime_Brick_Decorative"
    },
    {
      "x": -122,
      "y": 14,
      "z": -81,
      "name": "Rock_Lime_Brick_Decorative"
    },
    {
      "x": -122,
      "y": 15,
      "z": -81,
      "name": "Rock_Lime_Brick_Decorative"
    },
    {
      "x": -122,
      "y": 16,
      "z": -81,
      "name": "Soil_Clay_Lime"
    },
    {
      "x": -122,
      "y": 7,
      "z": -80,
      "name": "Soil_Gravel_Lime"
    },
    {
      "x": -122,
      "y": 8,
      "z": -80,
      "name": "Rock_Lime"
    },
    {
      "x": -122,
      "y": 9,
      "z": -80,
      "name": "Rock_Lime_Brick_Decorative"
    },
    {
      "x": -122,
      "y": 10,
      "z": -80,
      "name": "Soil_Gravel_Lime"
    },
    {
      "x": -122,
      "y": 11,
      "z": -80,
      "name": "Rock_Lime_Brick_Decorative"
    },
    {
      "x": -122,
      "y": 12,
      "z": -80,
      "name": "Rock_Lime_Brick_Decorative"
    },
    {
      "x": -122,
      "y": 13,
      "z": -80,
      "name": "Soil_Gravel_Lime"
    },
    {
      "x": -122,
      "y": 14,
      "z": -80,
      "name": "Rock_Lime_Brick_Decorative"
    },
    {
      "x": -122,
      "y": 15,
      "z": -80,
      "name": "Rock_Lime_Brick_Decorative"
    },
    {
      "x": -122,
      "y": 16,
      "z": -80,
      "name": "Soil_Clay_Lime"
    },
    {
      "x": -122,
      "y": 17,
      "z": -80,
      "name": "Plant_Coral_Block_Lime"
    },
    {
      "x": -122,
      "y": 9,
      "z": -79,
      "name": "Rock_Lime_Brick_Decorative"
    },
    {
      "x": -122,
      "y": 10,
      "z": -79,
      "name": "Rock_Lime_Brick_Decorative"
    },
    {
      "x": -122,
      "y": 11,
      "z": -79,
      "name": "Rock_Lime"
    },
    {
      "x": -122,
      "y": 12,
      "z": -79,
      "name": "Soil_Gravel_Lime"
    },
    {
      "x": -122,
      "y": 13,
      "z": -79,
      "name": "Rock_Lime"
    },
    {
      "x": -122,
      "y": 14,
      "z": -79,
      "name": "Rock_Lime"
    },
    {
      "x": -122,
      "y": 15,
      "z": -79,
      "name": "Rock_Lime_Brick_Decorative"
    },
    {
      "x": -122,
      "y": 16,
      "z": -79,
      "name": "Soil_Gravel_Lime"
    },
    {
      "x": -122,
      "y": 17,
      "z": -79,
      "name": "Soil_Clay_Lime"
    },
    {
      "x": -122,
      "y": 9,
      "z": -78,
      "name": "Rock_Lime"
    },
    {
      "x": -122,
      "y": 10,
      "z": -78,
      "name": "Rock_Lime_Brick_Decorative"
    },
    {
      "x": -122,
      "y": 11,
      "z": -78,
      "name": "Rock_Lime_Brick_Decorative"
    },
    {
      "x": -122,
      "y": 12,
      "z": -78,
      "name": "Rock_Lime_Brick_Decorative"
    },
    {
      "x": -122,
      "y": 13,
      "z": -78,
      "name": "Rock_Lime"
    },
    {
      "x": -122,
      "y": 14,
      "z": -78,
      "name": "Rock_Lime_Brick_Decorative"
    },
    {
      "x": -122,
      "y": 15,
      "z": -78,
      "name": "Rock_Lime_Brick_Decorative"
    },
    {
      "x": -122,
      "y": 16,
      "z": -78,
      "name": "Rock_Lime_Brick_Decorative"
    },
    {
      "x": -122,
      "y": 17,
      "z": -78,
      "name": "Plant_Coral_Block_Lime"
    },
    {
      "x": -122,
      "y": 9,
      "z": -77,
      "name": "Soil_Gravel_Lime"
    },
    {
      "x": -122,
      "y": 10,
      "z": -77,
      "name": "Soil_Gravel_Lime"
    },
    {
      "x": -122,
      "y": 11,
      "z": -77,
      "name": "Rock_Lime_Brick_Decorative",
      "support": 15
    },
    {
      "x": -122,
      "y": 12,
      "z": -77,
      "name": "Rock_Lime_Brick_Decorative"
    },
    {
      "x": -122,
      "y": 13,
      "z": -77,
      "name": "Soil_Gravel_Lime"
    },
    {
      "x": -122,
      "y": 14,
      "z": -77,
      "name": "Rock_Lime_Brick_Decorative"
    },
    {
      "x": -122,
      "y": 15,
      "z": -77,
      "name": "Rock_Lime"
    },
    {
      "x": -122,
      "y": 16,
      "z": -77,
      "name": "Rubble_Lime"
    },
    {
      "x": -122,
      "y": 9,
      "z": -76,
      "name": "Rock_Lime_Brick_Decorative"
    },
    {
      "x": -122,
      "y": 10,
      "z": -76,
      "name": "Rock_Lime_Brick_Decorative"
    },
    {
      "x": -122,
      "y": 11,
      "z": -76,
      "name": "Rock_Lime_Brick_Decorative"
    },
    {
      "x": -122,
      "y": 12,
      "z": -76,
      "name": "Rock_Lime"
    },
    {
      "x": -121,
      "y": 9,
      "z": -88,
      "name": "Rock_Lime_Brick_Decorative"
    },
    {
      "x": -121,
      "y": 10,
      "z": -88,
      "name": "Rock_Lime_Brick_Decorative"
    },
    {
      "x": -121,
      "y": 11,
      "z": -88,
      "name": "Soil_Gravel_Lime"
    },
    {
      "x": -121,
      "y": 12,
      "z": -88,
      "name": "Rock_Lime_Brick_Decorative"
    },
    {
      "x": -121,
      "y": 7,
      "z": -87,
      "name": "Soil_Gravel_Lime"
    },
    {
      "x": -121,
      "y": 8,
      "z": -87,
      "name": "Rock_Lime_Brick_Decorative"
    },
    {
      "x": -121,
      "y": 9,
      "z": -87,
      "name": "Rock_Lime_Brick_Decorative"
    },
    {
      "x": -121,
      "y": 10,
      "z": -87,
      "name": "Rock_Lime_Cobble"
    },
    {
      "x": -121,
      "y": 11,
      "z": -87,
      "name": "Rock_Lime_Brick_Decorative",
      "support": 15
    },
    {
      "x": -121,
      "y": 12,
      "z": -87,
      "name": "Rock_Lime_Brick_Decorative"
    },
    {
      "x": -121,
      "y": 13,
      "z": -87,
      "name": "Rock_Lime"
    },
    {
      "x": -121,
      "y": 14,
      "z": -87,
      "name": "Rock_Lime_Brick_Decorative"
    },
    {
      "x": -121,
      "y": 15,
      "z": -87,
      "name": "Rock_Lime"
    },
    {
      "x": -121,
      "y": 16,
      "z": -87,
      "name": "Rubble_Lime"
    },
    {
      "x": -121,
      "y": 6,
      "z": -86,
      "name": "Rock_Lime_Brick_Decorative"
    },
    {
      "x": -121,
      "y": 7,
      "z": -86,
      "name": "Soil_Gravel_Lime"
    },
    {
      "x": -121,
      "y": 8,
      "z": -86,
      "name": "Rock_Lime_Cobble"
    },
    {
      "x": -121,
      "y": 9,
      "z": -86,
      "name": "Rock_Lime_Brick_Decorative"
    },
    {
      "x": -121,
      "y": 10,
      "z": -86,
      "name": "Rock_Lime_Brick_Decorative"
    },
    {
      "x": -121,
      "y": 11,
      "z": -86,
      "name": "Rock_Lime"
    },
    {
      "x": -121,
      "y": 12,
      "z": -86,
      "name": "Rock_Lime_Brick_Decorative"
    },
    {
      "x": -121,
      "y": 13,
      "z": -86,
      "name": "Rock_Lime_Brick_Decorative"
    },
    {
      "x": -121,
      "y": 14,
      "z": -86,
      "name": "Rock_Lime"
    },
    {
      "x": -121,
      "y": 15,
      "z": -86,
      "name": "Plant_Coral_Block_Lime"
    },
    {
      "x": -121,
      "y": 16,
      "z": -86,
      "name": "Plant_Coral_Block_Lime"
    },
    {
      "x": -121,
      "y": 17,
      "z": -86,
      "name": "Plant_Coral_Block_Lime"
    },
    {
      "x": -121,
      "y": 5,
      "z": -85,
      "name": "Rock_Lime_Brick_Decorative"
    },
    {
      "x": -121,
      "y": 6,
      "z": -85,
      "name": "Soil_Gravel_Lime"
    },
    {
      "x": -121,
      "y": 7,
      "z": -85,
      "name": "Rock_Lime"
    },
    {
      "x": -121,
      "y": 8,
      "z": -85,
      "name": "Soil_Gravel_Lime"
    },
    {
      "x": -121,
      "y": 9,
      "z": -85,
      "name": "Rock_Lime_Cobble"
    },
    {
      "x": -121,
      "y": 10,
      "z": -85,
      "name": "Soil_Gravel_Lime"
    },
    {
      "x": -121,
      "y": 11,
      "z": -85,
      "name": "Rock_Lime_Brick_Decorative"
    },
    {
      "x": -121,
      "y": 12,
      "z": -85,
      "name": "Rock_Lime_Cobble"
    },
    {
      "x": -121,
      "y": 13,
      "z": -85,
      "name": "Rock_Lime_Cobble"
    },
    {
      "x": -121,
      "y": 14,
      "z": -85,
      "name": "Rock_Lime_Brick_Decorative"
    },
    {
      "x": -121,
      "y": 15,
      "z": -85,
      "name": "Soil_Gravel_Lime"
    },
    {
      "x": -121,
      "y": 16,
      "z": -85,
      "name": "Rock_Lime_Brick_Decorative"
    },
    {
      "x": -121,
      "y": 17,
      "z": -85,
      "name": "Soil_Clay_Lime"
    },
    {
      "x": -121,
      "y": 5,
      "z": -84,
      "name": "Soil_Gravel_Lime"
    },
    {
      "x": -121,
      "y": 6,
      "z": -84,
      "name": "Rock_Lime"
    },
    {
      "x": -121,
      "y": 7,
      "z": -84,
      "name": "Rock_Lime_Cobble"
    },
    {
      "x": -121,
      "y": 8,
      "z": -84,
      "name": "Soil_Gravel_Lime"
    },
    {
      "x": -121,
      "y": 9,
      "z": -84,
      "name": "Rock_Lime_Brick_Decorative"
    },
    {
      "x": -121,
      "y": 10,
      "z": -84,
      "name": "Rock_Lime_Cobble"
    },
    {
      "x": -121,
      "y": 11,
      "z": -84,
      "name": "Rock_Lime"
    },
    {
      "x": -121,
      "y": 12,
      "z": -84,
      "name": "Rock_Lime_Brick_Decorative"
    },
    {
      "x": -121,
      "y": 13,
      "z": -84,
      "name": "Rock_Lime"
    },
    {
      "x": -121,
      "y": 14,
      "z": -84,
      "name": "Soil_Gravel_Lime"
    },
    {
      "x": -121,
      "y": 15,
      "z": -84,
      "name": "Rock_Lime_Brick_Decorative"
    },
    {
      "x": -121,
      "y": 16,
      "z": -84,
      "name": "Plant_Coral_Block_Lime"
    },
    {
      "x": -121,
      "y": 5,
      "z": -83,
      "name": "Rock_Lime_Brick_Decorative"
    },
    {
      "x": -121,
      "y": 6,
      "z": -83,
      "name": "Soil_Gravel_Lime"
    },
    {
      "x": -121,
      "y": 7,
      "z": -83,
      "name": "Rock_Lime"
    },
    {
      "x": -121,
      "y": 8,
      "z": -83,
      "name": "Rock_Lime_Brick_Decorative"
    },
    {
      "x": -121,
      "y": 9,
      "z": -83,
      "name": "Rock_Lime_Cobble"
    },
    {
      "x": -121,
      "y": 10,
      "z": -83,
      "name": "Rock_Lime_Cobble"
    },
    {
      "x": -121,
      "y": 11,
      "z": -83,
      "name": "Soil_Gravel_Lime"
    },
    {
      "x": -121,
      "y": 12,
      "z": -83,
      "name": "Rock_Lime_Brick_Decorative"
    },
    {
      "x": -121,
      "y": 13,
      "z": -83,
      "name": "Rock_Lime_Brick_Decorative"
    },
    {
      "x": -121,
      "y": 14,
      "z": -83,
      "name": "Rock_Lime_Brick_Decorative"
    },
    {
      "x": -121,
      "y": 15,
      "z": -83,
      "name": "Rock_Lime_Brick_Decorative"
    },
    {
      "x": -121,
      "y": 16,
      "z": -83,
      "name": "Plant_Coral_Block_Lime"
    },
    {
      "x": -121,
      "y": 5,
      "z": -82,
      "name": "Rock_Lime_Cobble"
    },
    {
      "x": -121,
      "y": 6,
      "z": -82,
      "name": "Rock_Lime_Cobble"
    },
    {
      "x": -121,
      "y": 7,
      "z": -82,
      "name": "Rock_Lime"
    },
    {
      "x": -121,
      "y": 8,
      "z": -82,
      "name": "Rock_Lime_Brick_Decorative"
    },
    {
      "x": -121,
      "y": 9,
      "z": -82,
      "name": "Rock_Lime_Brick_Decorative"
    },
    {
      "x": -121,
      "y": 10,
      "z": -82,
      "name": "Rock_Lime_Brick_Decorative"
    },
    {
      "x": -121,
      "y": 11,
      "z": -82,
      "name": "Rock_Lime"
    },
    {
      "x": -121,
      "y": 12,
      "z": -82,
      "name": "Rock_Lime_Cobble"
    },
    {
      "x": -121,
      "y": 13,
      "z": -82,
      "name": "Soil_Gravel_Lime"
    },
    {
      "x": -121,
      "y": 14,
      "z": -82,
      "name": "Rock_Lime_Brick_Decorative"
    },
    {
      "x": -121,
      "y": 15,
      "z": -82,
      "name": "Rock_Lime_Brick_Decorative"
    },
    {
      "x": -121,
      "y": 16,
      "z": -82,
      "name": "Plant_Coral_Block_Lime"
    },
    {
      "x": -121,
      "y": 5,
      "z": -81,
      "name": "Rock_Lime_Cobble"
    },
    {
      "x": -121,
      "y": 6,
      "z": -81,
      "name": "Rock_Lime"
    },
    {
      "x": -121,
      "y": 7,
      "z": -81,
      "name": "Rock_Lime"
    },
    {
      "x": -121,
      "y": 8,
      "z": -81,
      "name": "Rock_Lime_Brick_Decorative"
    },
    {
      "x": -121,
      "y": 9,
      "z": -81,
      "name": "Rock_Lime_Cobble"
    },
    {
      "x": -121,
      "y": 10,
      "z": -81,
      "name": "Rock_Lime_Cobble"
    },
    {
      "x": -121,
      "y": 11,
      "z": -81,
      "name": "Rock_Lime_Brick_Decorative"
    },
    {
      "x": -121,
      "y": 12,
      "z": -81,
      "name": "Soil_Gravel_Lime"
    },
    {
      "x": -121,
      "y": 13,
      "z": -81,
      "name": "Rock_Lime_Cobble"
    },
    {
      "x": -121,
      "y": 14,
      "z": -81,
      "name": "Rock_Lime"
    },
    {
      "x": -121,
      "y": 15,
      "z": -81,
      "name": "Rock_Lime_Brick_Decorative"
    },
    {
      "x": -121,
      "y": 16,
      "z": -81,
      "name": "Soil_Clay_Lime"
    },
    {
      "x": -121,
      "y": 6,
      "z": -80,
      "name": "Rock_Lime_Cobble"
    },
    {
      "x": -121,
      "y": 7,
      "z": -80,
      "name": "Rock_Lime"
    },
    {
      "x": -121,
      "y": 8,
      "z": -80,
      "name": "Rock_Lime_Cobble"
    },
    {
      "x": -121,
      "y": 9,
      "z": -80,
      "name": "Rock_Lime_Brick_Decorative"
    },
    {
      "x": -121,
      "y": 10,
      "z": -80,
      "name": "Rock_Lime_Brick_Decorative"
    },
    {
      "x": -121,
      "y": 11,
      "z": -80,
      "name": "Rock_Lime"
    },
    {
      "x": -121,
      "y": 12,
      "z": -80,
      "name": "Rock_Lime"
    },
    {
      "x": -121,
      "y": 13,
      "z": -80,
      "name": "Rock_Lime_Brick_Decorative"
    },
    {
      "x": -121,
      "y": 14,
      "z": -80,
      "name": "Rock_Lime_Brick_Decorative"
    },
    {
      "x": -121,
      "y": 15,
      "z": -80,
      "name": "Rock_Lime_Brick_Decorative"
    },
    {
      "x": -121,
      "y": 16,
      "z": -80,
      "name": "Plant_Coral_Block_Lime"
    },
    {
      "x": -121,
      "y": 7,
      "z": -79,
      "name": "Rock_Lime_Brick_Decorative"
    },
    {
      "x": -121,
      "y": 8,
      "z": -79,
      "name": "Soil_Gravel_Lime"
    },
    {
      "x": -121,
      "y": 9,
      "z": -79,
      "name": "Soil_Gravel_Lime"
    },
    {
      "x": -121,
      "y": 10,
      "z": -79,
      "name": "Soil_Gravel_Lime"
    },
    {
      "x": -121,
      "y": 11,
      "z": -79,
      "name": "Rock_Lime_Cobble"
    },
    {
      "x": -121,
      "y": 12,
      "z": -79,
      "name": "Rock_Lime_Brick_Decorative"
    },
    {
      "x": -121,
      "y": 13,
      "z": -79,
      "name": "Soil_Gravel_Lime"
    },
    {
      "x": -121,
      "y": 14,
      "z": -79,
      "name": "Rock_Lime"
    },
    {
      "x": -121,
      "y": 15,
      "z": -79,
      "name": "Rock_Lime_Brick_Decorative"
    },
    {
      "x": -121,
      "y": 16,
      "z": -79,
      "name": "Soil_Clay_Smooth_Lime"
    },
    {
      "x": -121,
      "y": 8,
      "z": -78,
      "name": "Rock_Lime_Cobble"
    },
    {
      "x": -121,
      "y": 9,
      "z": -78,
      "name": "Soil_Gravel_Lime"
    },
    {
      "x": -121,
      "y": 10,
      "z": -78,
      "name": "Rock_Lime_Cobble"
    },
    {
      "x": -121,
      "y": 11,
      "z": -78,
      "name": "Rock_Lime_Brick_Decorative"
    },
    {
      "x": -121,
      "y": 12,
      "z": -78,
      "name": "Rock_Lime_Brick_Decorative"
    },
    {
      "x": -121,
      "y": 13,
      "z": -78,
      "name": "Rock_Lime_Brick_Decorative"
    },
    {
      "x": -121,
      "y": 14,
      "z": -78,
      "name": "Soil_Gravel_Lime"
    },
    {
      "x": -121,
      "y": 15,
      "z": -78,
      "name": "Rock_Lime_Brick_Decorative"
    },
    {
      "x": -121,
      "y": 16,
      "z": -78,
      "name": "Rock_Lime"
    },
    {
      "x": -121,
      "y": 17,
      "z": -78,
      "name": "Plant_Coral_Block_Lime"
    },
    {
      "x": -121,
      "y": 7,
      "z": -77,
      "name": "Rock_Lime_Cobble"
    },
    {
      "x": -121,
      "y": 8,
      "z": -77,
      "name": "Soil_Gravel_Lime"
    },
    {
      "x": -121,
      "y": 9,
      "z": -77,
      "name": "Rock_Lime"
    },
    {
      "x": -121,
      "y": 10,
      "z": -77,
      "name": "Soil_Gravel_Lime"
    },
    {
      "x": -121,
      "y": 11,
      "z": -77,
      "name": "Rock_Lime_Brick_Decorative"
    },
    {
      "x": -121,
      "y": 12,
      "z": -77,
      "name": "Rock_Lime_Brick_Decorative"
    },
    {
      "x": -121,
      "y": 13,
      "z": -77,
      "name": "Rock_Lime_Brick_Decorative"
    },
    {
      "x": -121,
      "y": 14,
      "z": -77,
      "name": "Rock_Lime_Brick_Decorative"
    },
    {
      "x": -121,
      "y": 15,
      "z": -77,
      "name": "Rock_Lime_Brick_Decorative"
    },
    {
      "x": -121,
      "y": 16,
      "z": -77,
      "name": "Plant_Coral_Block_Lime"
    },
    {
      "x": -121,
      "y": 17,
      "z": -77,
      "name": "Soil_Clay_Lime"
    },
    {
      "x": -121,
      "y": 8,
      "z": -76,
      "name": "Soil_Gravel_Lime"
    },
    {
      "x": -121,
      "y": 9,
      "z": -76,
      "name": "Rock_Lime"
    },
    {
      "x": -121,
      "y": 10,
      "z": -76,
      "name": "Soil_Gravel_Lime"
    },
    {
      "x": -121,
      "y": 11,
      "z": -76,
      "name": "Rock_Lime_Brick_Decorative"
    },
    {
      "x": -121,
      "y": 12,
      "z": -76,
      "name": "Rock_Lime",
      "support": 15
    },
    {
      "x": -121,
      "y": 13,
      "z": -76,
      "name": "Soil_Gravel_Lime"
    },
    {
      "x": -121,
      "y": 14,
      "z": -76,
      "name": "Rock_Lime"
    },
    {
      "x": -121,
      "y": 15,
      "z": -76,
      "name": "Rock_Lime"
    },
    {
      "x": -121,
      "y": 16,
      "z": -76,
      "name": "Rock_Lime"
    },
    {
      "x": -121,
      "y": 17,
      "z": -76,
      "name": "Rubble_Lime_Medium"
    },
    {
      "x": -121,
      "y": 9,
      "z": -75,
      "name": "Soil_Gravel_Lime"
    },
    {
      "x": -121,
      "y": 10,
      "z": -75,
      "name": "Rock_Lime_Brick_Decorative"
    },
    {
      "x": -121,
      "y": 11,
      "z": -75,
      "name": "Rock_Lime"
    },
    {
      "x": -121,
      "y": 12,
      "z": -75,
      "name": "Rock_Lime"
    },
    {
      "x": -121,
      "y": 13,
      "z": -75,
      "name": "Rock_Lime_Brick_Decorative"
    },
    {
      "x": -121,
      "y": 14,
      "z": -75,
      "name": "Rock_Lime"
    },
    {
      "x": -121,
      "y": 15,
      "z": -75,
      "name": "Rock_Lime"
    },
    {
      "x": -121,
      "y": 16,
      "z": -75,
      "name": "Plant_Crop_Mushroom_Cap_Poison",
      "components": {
        "Components": {
          "FarmingBlock": {
            "LastTickGameTime": "0001-01-01T12:00:00Z"
          }
        }
      }
    },
    {
      "x": -120,
      "y": 9,
      "z": -88,
      "name": "Soil_Gravel_Lime"
    },
    {
      "x": -120,
      "y": 10,
      "z": -88,
      "name": "Rock_Lime_Brick_Decorative"
    },
    {
      "x": -120,
      "y": 11,
      "z": -88,
      "name": "Rock_Lime_Brick_Decorative"
    },
    {
      "x": -120,
      "y": 12,
      "z": -88,
      "name": "Rock_Lime"
    },
    {
      "x": -120,
      "y": 6,
      "z": -87,
      "name": "Soil_Gravel_Lime"
    },
    {
      "x": -120,
      "y": 7,
      "z": -87,
      "name": "Rock_Lime"
    },
    {
      "x": -120,
      "y": 8,
      "z": -87,
      "name": "Soil_Gravel_Lime"
    },
    {
      "x": -120,
      "y": 9,
      "z": -87,
      "name": "Rock_Lime_Brick_Decorative"
    },
    {
      "x": -120,
      "y": 10,
      "z": -87,
      "name": "Rock_Lime_Cobble"
    },
    {
      "x": -120,
      "y": 11,
      "z": -87,
      "name": "Soil_Gravel_Lime"
    },
    {
      "x": -120,
      "y": 12,
      "z": -87,
      "name": "Rock_Lime_Cobble"
    },
    {
      "x": -120,
      "y": 13,
      "z": -87,
      "name": "Rock_Lime_Brick_Decorative"
    },
    {
      "x": -120,
      "y": 14,
      "z": -87,
      "name": "Soil_Gravel_Lime"
    },
    {
      "x": -120,
      "y": 15,
      "z": -87,
      "name": "Rock_Lime_Brick_Decorative"
    },
    {
      "x": -120,
      "y": 16,
      "z": -87,
      "name": "Plant_Coral_Block_Lime"
    },
    {
      "x": -120,
      "y": 17,
      "z": -87,
      "name": "Plant_Coral_Block_Lime"
    },
    {
      "x": -120,
      "y": 5,
      "z": -86,
      "name": "Rock_Lime_Cobble"
    },
    {
      "x": -120,
      "y": 6,
      "z": -86,
      "name": "Rock_Lime_Brick_Decorative"
    },
    {
      "x": -120,
      "y": 7,
      "z": -86,
      "name": "Rock_Lime_Cobble"
    },
    {
      "x": -120,
      "y": 8,
      "z": -86,
      "name": "Soil_Gravel_Lime"
    },
    {
      "x": -120,
      "y": 9,
      "z": -86,
      "name": "Soil_Gravel_Lime"
    },
    {
      "x": -120,
      "y": 10,
      "z": -86,
      "name": "Rock_Lime_Cobble"
    },
    {
      "x": -120,
      "y": 11,
      "z": -86,
      "name": "Rock_Lime"
    },
    {
      "x": -120,
      "y": 12,
      "z": -86,
      "name": "Rock_Lime_Brick_Decorative"
    },
    {
      "x": -120,
      "y": 13,
      "z": -86,
      "name": "Soil_Gravel_Lime"
    },
    {
      "x": -120,
      "y": 14,
      "z": -86,
      "name": "Rock_Lime_Brick_Decorative"
    },
    {
      "x": -120,
      "y": 15,
      "z": -86,
      "name": "Rock_Lime_Brick_Decorative"
    },
    {
      "x": -120,
      "y": 16,
      "z": -86,
      "name": "Rock_Lime_Brick_Decorative"
    },
    {
      "x": -120,
      "y": 17,
      "z": -86,
      "name": "Plant_Coral_Block_Lime"
    },
    {
      "x": -120,
      "y": 5,
      "z": -85,
      "name": "Rock_Lime"
    },
    {
      "x": -120,
      "y": 6,
      "z": -85,
      "name": "Rock_Lime"
    },
    {
      "x": -120,
      "y": 7,
      "z": -85,
      "name": "Rock_Lime_Cobble"
    },
    {
      "x": -120,
      "y": 8,
      "z": -85,
      "name": "Rock_Lime_Brick_Decorative"
    },
    {
      "x": -120,
      "y": 9,
      "z": -85,
      "name": "Rock_Lime_Brick_Decorative"
    },
    {
      "x": -120,
      "y": 10,
      "z": -85,
      "name": "Rock_Lime"
    },
    {
      "x": -120,
      "y": 11,
      "z": -85,
      "name": "Rock_Lime_Brick_Decorative"
    },
    {
      "x": -120,
      "y": 12,
      "z": -85,
      "name": "Soil_Gravel_Lime"
    },
    {
      "x": -120,
      "y": 13,
      "z": -85,
      "name": "Rock_Lime_Cobble"
    },
    {
      "x": -120,
      "y": 14,
      "z": -85,
      "name": "Rock_Lime"
    },
    {
      "x": -120,
      "y": 15,
      "z": -85,
      "name": "Soil_Gravel_Lime"
    },
    {
      "x": -120,
      "y": 16,
      "z": -85,
      "name": "Plant_Coral_Block_Lime"
    },
    {
      "x": -120,
      "y": 5,
      "z": -84,
      "name": "Soil_Gravel_Lime"
    },
    {
      "x": -120,
      "y": 6,
      "z": -84,
      "name": "Rock_Lime"
    },
    {
      "x": -120,
      "y": 7,
      "z": -84,
      "name": "Rock_Lime"
    },
    {
      "x": -120,
      "y": 8,
      "z": -84,
      "name": "Rock_Lime_Brick_Decorative"
    },
    {
      "x": -120,
      "y": 9,
      "z": -84,
      "name": "Rock_Lime_Cobble"
    },
    {
      "x": -120,
      "y": 10,
      "z": -84,
      "name": "Rock_Lime_Cobble"
    },
    {
      "x": -120,
      "y": 11,
      "z": -84,
      "name": "Soil_Gravel_Lime"
    },
    {
      "x": -120,
      "y": 12,
      "z": -84,
      "name": "Rock_Lime"
    },
    {
      "x": -120,
      "y": 13,
      "z": -84,
      "name": "Rock_Lime"
    },
    {
      "x": -120,
      "y": 14,
      "z": -84,
      "name": "Rock_Lime_Brick_Decorative"
    },
    {
      "x": -120,
      "y": 15,
      "z": -84,
      "name": "Rock_Lime_Brick_Decorative"
    },
    {
      "x": -120,
      "y": 16,
      "z": -84,
      "name": "Plant_Coral_Block_Lime"
    },
    {
      "x": -120,
      "y": 4,
      "z": -83,
      "name": "Rock_Lime_Cobble"
    },
    {
      "x": -120,
      "y": 5,
      "z": -83,
      "name": "Rock_Lime_Cobble"
    },
    {
      "x": -120,
      "y": 6,
      "z": -83,
      "name": "Rock_Lime_Cobble"
    },
    {
      "x": -120,
      "y": 7,
      "z": -83,
      "name": "Soil_Gravel_Lime"
    },
    {
      "x": -120,
      "y": 8,
      "z": -83,
      "name": "Rock_Lime_Cobble"
    },
    {
      "x": -120,
      "y": 9,
      "z": -83,
      "name": "Rock_Lime_Cobble"
    },
    {
      "x": -120,
      "y": 10,
      "z": -83,
      "name": "Rock_Lime_Brick_Decorative"
    },
    {
      "x": -120,
      "y": 11,
      "z": -83,
      "name": "Rock_Lime_Cobble"
    },
    {
      "x": -120,
      "y": 12,
      "z": -83,
      "name": "Soil_Gravel_Lime"
    },
    {
      "x": -120,
      "y": 13,
      "z": -83,
      "name": "Rock_Lime_Cobble"
    },
    {
      "x": -120,
      "y": 14,
      "z": -83,
      "name": "Soil_Gravel_Lime"
    },
    {
      "x": -120,
      "y": 15,
      "z": -83,
      "name": "Soil_Gravel_Lime"
    },
    {
      "x": -120,
      "y": 16,
      "z": -83,
      "name": "Plant_Coral_Block_Lime"
    },
    {
      "x": -120,
      "y": 5,
      "z": -82,
      "name": "Rock_Lime"
    },
    {
      "x": -120,
      "y": 6,
      "z": -82,
      "name": "Rock_Lime"
    },
    {
      "x": -120,
      "y": 7,
      "z": -82,
      "name": "Rock_Lime_Brick_Decorative"
    },
    {
      "x": -120,
      "y": 8,
      "z": -82,
      "name": "Soil_Gravel_Lime"
    },
    {
      "x": -120,
      "y": 9,
      "z": -82,
      "name": "Soil_Gravel_Lime"
    },
    {
      "x": -120,
      "y": 10,
      "z": -82,
      "name": "Rock_Lime_Cobble"
    },
    {
      "x": -120,
      "y": 11,
      "z": -82,
      "name": "Soil_Gravel_Lime"
    },
    {
      "x": -120,
      "y": 12,
      "z": -82,
      "name": "Rock_Lime_Cobble"
    },
    {
      "x": -120,
      "y": 13,
      "z": -82,
      "name": "Soil_Gravel_Lime"
    },
    {
      "x": -120,
      "y": 14,
      "z": -82,
      "name": "Rock_Lime_Brick_Decorative"
    },
    {
      "x": -120,
      "y": 15,
      "z": -82,
      "name": "Soil_Gravel_Lime"
    },
    {
      "x": -120,
      "y": 16,
      "z": -82,
      "name": "Plant_Coral_Block_Lime"
    },
    {
      "x": -120,
      "y": 5,
      "z": -81,
      "name": "Rock_Lime_Brick_Decorative"
    },
    {
      "x": -120,
      "y": 6,
      "z": -81,
      "name": "Rock_Lime_Brick_Decorative"
    },
    {
      "x": -120,
      "y": 7,
      "z": -81,
      "name": "Rock_Lime"
    },
    {
      "x": -120,
      "y": 8,
      "z": -81,
      "name": "Rock_Lime"
    },
    {
      "x": -120,
      "y": 9,
      "z": -81,
      "name": "Rock_Lime_Cobble"
    },
    {
      "x": -120,
      "y": 10,
      "z": -81,
      "name": "Rock_Lime"
    },
    {
      "x": -120,
      "y": 11,
      "z": -81,
      "name": "Soil_Gravel_Lime"
    },
    {
      "x": -120,
      "y": 12,
      "z": -81,
      "name": "Rock_Lime_Cobble"
    },
    {
      "x": -120,
      "y": 13,
      "z": -81,
      "name": "Rock_Lime"
    },
    {
      "x": -120,
      "y": 14,
      "z": -81,
      "name": "Rock_Lime_Brick_Decorative"
    },
    {
      "x": -120,
      "y": 15,
      "z": -81,
      "name": "Rock_Lime"
    },
    {
      "x": -120,
      "y": 16,
      "z": -81,
      "name": "Plant_Coral_Block_Lime"
    },
    {
      "x": -120,
      "y": 5,
      "z": -80,
      "name": "Rock_Lime_Brick_Decorative"
    },
    {
      "x": -120,
      "y": 6,
      "z": -80,
      "name": "Rock_Lime_Brick_Decorative"
    },
    {
      "x": -120,
      "y": 7,
      "z": -80,
      "name": "Rock_Lime"
    },
    {
      "x": -120,
      "y": 8,
      "z": -80,
      "name": "Rock_Lime_Brick_Decorative"
    },
    {
      "x": -120,
      "y": 9,
      "z": -80,
      "name": "Rock_Lime_Cobble"
    },
    {
      "x": -120,
      "y": 10,
      "z": -80,
      "name": "Rock_Lime"
    },
    {
      "x": -120,
      "y": 11,
      "z": -80,
      "name": "Soil_Gravel_Lime"
    },
    {
      "x": -120,
      "y": 12,
      "z": -80,
      "name": "Soil_Gravel_Lime"
    },
    {
      "x": -120,
      "y": 13,
      "z": -80,
      "name": "Soil_Gravel_Lime"
    },
    {
      "x": -120,
      "y": 14,
      "z": -80,
      "name": "Rock_Lime"
    },
    {
      "x": -120,
      "y": 15,
      "z": -80,
      "name": "Rock_Lime"
    },
    {
      "x": -120,
      "y": 16,
      "z": -80,
      "name": "Plant_Coral_Block_Lime"
    },
    {
      "x": -120,
      "y": 6,
      "z": -79,
      "name": "Soil_Gravel_Lime"
    },
    {
      "x": -120,
      "y": 7,
      "z": -79,
      "name": "Rock_Lime"
    },
    {
      "x": -120,
      "y": 8,
      "z": -79,
      "name": "Soil_Gravel_Lime"
    },
    {
      "x": -120,
      "y": 9,
      "z": -79,
      "name": "Soil_Gravel_Lime"
    },
    {
      "x": -120,
      "y": 10,
      "z": -79,
      "name": "Rock_Lime_Cobble"
    },
    {
      "x": -120,
      "y": 11,
      "z": -79,
      "name": "Rock_Lime_Cobble"
    },
    {
      "x": -120,
      "y": 12,
      "z": -79,
      "name": "Soil_Gravel_Lime"
    },
    {
      "x": -120,
      "y": 13,
      "z": -79,
      "name": "Soil_Gravel_Lime"
    },
    {
      "x": -120,
      "y": 14,
      "z": -79,
      "name": "Rock_Lime_Brick_Decorative"
    },
    {
      "x": -120,
      "y": 15,
      "z": -79,
      "name": "Rock_Lime_Brick_Decorative"
    },
    {
      "x": -120,
      "y": 16,
      "z": -79,
      "name": "Soil_Clay_Smooth_Lime"
    },
    {
      "x": -120,
      "y": 6,
      "z": -78,
      "name": "Soil_Gravel_Lime"
    },
    {
      "x": -120,
      "y": 7,
      "z": -78,
      "name": "Rock_Lime_Brick_Decorative"
    },
    {
      "x": -120,
      "y": 8,
      "z": -78,
      "name": "Soil_Gravel_Lime"
    },
    {
      "x": -120,
      "y": 9,
      "z": -78,
      "name": "Rock_Lime"
    },
    {
      "x": -120,
      "y": 10,
      "z": -78,
      "name": "Rock_Lime_Brick_Decorative"
    },
    {
      "x": -120,
      "y": 11,
      "z": -78,
      "name": "Rock_Lime_Cobble"
    },
    {
      "x": -120,
      "y": 12,
      "z": -78,
      "name": "Rock_Lime_Cobble"
    },
    {
      "x": -120,
      "y": 13,
      "z": -78,
      "name": "Rock_Lime"
    },
    {
      "x": -120,
      "y": 14,
      "z": -78,
      "name": "Rock_Lime"
    },
    {
      "x": -120,
      "y": 15,
      "z": -78,
      "name": "Rock_Lime_Brick_Decorative"
    },
    {
      "x": -120,
      "y": 16,
      "z": -78,
      "name": "Soil_Clay_Smooth_Lime"
    },
    {
      "x": -120,
      "y": 6,
      "z": -77,
      "name": "Rock_Lime_Cobble"
    },
    {
      "x": -120,
      "y": 7,
      "z": -77,
      "name": "Rock_Lime"
    },
    {
      "x": -120,
      "y": 8,
      "z": -77,
      "name": "Rock_Lime"
    },
    {
      "x": -120,
      "y": 9,
      "z": -77,
      "name": "Rock_Lime_Brick_Decorative"
    },
    {
      "x": -120,
      "y": 10,
      "z": -77,
      "name": "Rock_Lime"
    },
    {
      "x": -120,
      "y": 11,
      "z": -77,
      "name": "Rock_Lime_Brick_Decorative"
    },
    {
      "x": -120,
      "y": 12,
      "z": -77,
      "name": "Soil_Gravel_Lime"
    },
    {
      "x": -120,
      "y": 13,
      "z": -77,
      "name": "Rock_Lime_Brick_Decorative"
    },
    {
      "x": -120,
      "y": 14,
      "z": -77,
      "name": "Rock_Lime_Brick_Decorative"
    },
    {
      "x": -120,
      "y": 15,
      "z": -77,
      "name": "Rock_Lime_Brick_Decorative"
    },
    {
      "x": -120,
      "y": 16,
      "z": -77,
      "name": "Rock_Lime"
    },
    {
      "x": -120,
      "y": 17,
      "z": -77,
      "name": "Plant_Coral_Block_Lime"
    },
    {
      "x": -120,
      "y": 6,
      "z": -76,
      "name": "Rock_Lime_Cobble"
    },
    {
      "x": -120,
      "y": 7,
      "z": -76,
      "name": "Rock_Lime_Brick_Decorative"
    },
    {
      "x": -120,
      "y": 8,
      "z": -76,
      "name": "Rock_Lime_Brick_Decorative"
    },
    {
      "x": -120,
      "y": 9,
      "z": -76,
      "name": "Rock_Lime"
    },
    {
      "x": -120,
      "y": 10,
      "z": -76,
      "name": "Rock_Lime_Brick_Decorative"
    },
    {
      "x": -120,
      "y": 11,
      "z": -76,
      "name": "Rock_Lime"
    },
    {
      "x": -120,
      "y": 12,
      "z": -76,
      "name": "Rock_Lime_Brick_Decorative"
    },
    {
      "x": -120,
      "y": 13,
      "z": -76,
      "name": "Rock_Lime_Brick_Decorative"
    },
    {
      "x": -120,
      "y": 14,
      "z": -76,
      "name": "Soil_Gravel_Lime",
      "support": 15
    },
    {
      "x": -120,
      "y": 15,
      "z": -76,
      "name": "Rock_Lime"
    },
    {
      "x": -120,
      "y": 16,
      "z": -76,
      "name": "Rock_Lime"
    },
    {
      "x": -120,
      "y": 17,
      "z": -76,
      "name": "Rock_Lime_Brick_Decorative"
    },
    {
      "x": -120,
      "y": 18,
      "z": -76,
      "name": "Rock_Lime_Brick_Decorative"
    },
    {
      "x": -120,
      "y": 19,
      "z": -76,
      "name": "Rubble_Lime_Medium"
    },
    {
      "x": -120,
      "y": 7,
      "z": -75,
      "name": "Rock_Lime_Cobble"
    },
    {
      "x": -120,
      "y": 8,
      "z": -75,
      "name": "Rock_Lime"
    },
    {
      "x": -120,
      "y": 9,
      "z": -75,
      "name": "Soil_Gravel_Lime"
    },
    {
      "x": -120,
      "y": 10,
      "z": -75,
      "name": "Rock_Lime"
    },
    {
      "x": -120,
      "y": 11,
      "z": -75,
      "name": "Rock_Lime_Cobble"
    },
    {
      "x": -120,
      "y": 12,
      "z": -75,
      "name": "Rock_Lime_Brick_Decorative"
    },
    {
      "x": -120,
      "y": 13,
      "z": -75,
      "name": "Soil_Gravel_Lime"
    },
    {
      "x": -120,
      "y": 14,
      "z": -75,
      "name": "Rock_Lime_Brick_Decorative"
    },
    {
      "x": -120,
      "y": 15,
      "z": -75,
      "name": "Soil_Gravel_Lime"
    },
    {
      "x": -120,
      "y": 16,
      "z": -75,
      "name": "Rock_Lime_Brick_Decorative"
    },
    {
      "x": -120,
      "y": 17,
      "z": -75,
      "name": "Soil_Gravel_Lime"
    },
    {
      "x": -120,
      "y": 18,
      "z": -75,
      "name": "Rock_Lime_Brick_Decorative"
    },
    {
      "x": -120,
      "y": 19,
      "z": -75,
      "name": "Rock_Lime_Stalactite_Large"
    },
    {
      "x": -120,
      "y": 20,
      "z": -75,
      "name": "Rock_Lime_Stalactite_Large",
      "filler": 1024
    },
    {
      "x": -120,
      "y": 9,
      "z": -74,
      "name": "Soil_Gravel_Lime"
    },
    {
      "x": -120,
      "y": 10,
      "z": -74,
      "name": "Soil_Gravel_Lime"
    },
    {
      "x": -120,
      "y": 11,
      "z": -74,
      "name": "Rock_Lime_Brick_Decorative"
    },
    {
      "x": -120,
      "y": 12,
      "z": -74,
      "name": "Soil_Gravel_Lime"
    },
    {
      "x": -120,
      "y": 13,
      "z": -74,
      "name": "Rock_Lime"
    },
    {
      "x": -120,
      "y": 14,
      "z": -74,
      "name": "Rock_Lime"
    },
    {
      "x": -119,
      "y": 8,
      "z": -88,
      "name": "Soil_Gravel_Lime"
    },
    {
      "x": -119,
      "y": 9,
      "z": -88,
      "name": "Soil_Gravel_Lime",
      "support": 15
    },
    {
      "x": -119,
      "y": 10,
      "z": -88,
      "name": "Rock_Lime_Brick_Decorative"
    },
    {
      "x": -119,
      "y": 11,
      "z": -88,
      "name": "Rock_Lime_Brick_Decorative"
    },
    {
      "x": -119,
      "y": 12,
      "z": -88,
      "name": "Soil_Gravel_Lime"
    },
    {
      "x": -119,
      "y": 13,
      "z": -88,
      "name": "Rock_Lime_Brick_Decorative"
    },
    {
      "x": -119,
      "y": 14,
      "z": -88,
      "name": "Rubble_Lime"
    },
    {
      "x": -119,
      "y": 6,
      "z": -87,
      "name": "Soil_Gravel_Lime"
    },
    {
      "x": -119,
      "y": 7,
      "z": -87,
      "name": "Rock_Lime_Brick_Decorative"
    },
    {
      "x": -119,
      "y": 8,
      "z": -87,
      "name": "Rock_Lime"
    },
    {
      "x": -119,
      "y": 9,
      "z": -87,
      "name": "Rock_Lime"
    },
    {
      "x": -119,
      "y": 10,
      "z": -87,
      "name": "Rock_Lime_Cobble"
    },
    {
      "x": -119,
      "y": 11,
      "z": -87,
      "name": "Soil_Gravel_Lime"
    },
    {
      "x": -119,
      "y": 12,
      "z": -87,
      "name": "Soil_Gravel_Lime"
    },
    {
      "x": -119,
      "y": 13,
      "z": -87,
      "name": "Rock_Lime_Brick_Decorative"
    },
    {
      "x": -119,
      "y": 14,
      "z": -87,
      "name": "Soil_Gravel_Lime"
    },
    {
      "x": -119,
      "y": 15,
      "z": -87,
      "name": "Rock_Lime_Brick_Decorative"
    },
    {
      "x": -119,
      "y": 16,
      "z": -87,
      "name": "Rock_Lime_Brick_Decorative"
    },
    {
      "x": -119,
      "y": 17,
      "z": -87,
      "name": "Plant_Coral_Block_Lime"
    },
    {
      "x": -119,
      "y": 5,
      "z": -86,
      "name": "Rock_Lime_Brick_Decorative"
    },
    {
      "x": -119,
      "y": 6,
      "z": -86,
      "name": "Soil_Gravel_Lime"
    },
    {
      "x": -119,
      "y": 7,
      "z": -86,
      "name": "Rock_Lime"
    },
    {
      "x": -119,
      "y": 8,
      "z": -86,
      "name": "Soil_Gravel_Lime"
    },
    {
      "x": -119,
      "y": 9,
      "z": -86,
      "name": "Rock_Lime_Brick_Decorative"
    },
    {
      "x": -119,
      "y": 10,
      "z": -86,
      "name": "Rock_Lime"
    },
    {
      "x": -119,
      "y": 11,
      "z": -86,
      "name": "Rock_Lime_Brick_Decorative"
    },
    {
      "x": -119,
      "y": 12,
      "z": -86,
      "name": "Rock_Lime"
    },
    {
      "x": -119,
      "y": 13,
      "z": -86,
      "name": "Rock_Lime_Cobble"
    },
    {
      "x": -119,
      "y": 14,
      "z": -86,
      "name": "Rock_Lime_Brick_Decorative"
    },
    {
      "x": -119,
      "y": 15,
      "z": -86,
      "name": "Soil_Gravel_Lime"
    },
    {
      "x": -119,
      "y": 16,
      "z": -86,
      "name": "Plant_Coral_Block_Lime"
    },
    {
      "x": -119,
      "y": 5,
      "z": -85,
      "name": "Rock_Lime_Brick_Decorative"
    },
    {
      "x": -119,
      "y": 6,
      "z": -85,
      "name": "Rock_Lime_Brick_Decorative"
    },
    {
      "x": -119,
      "y": 7,
      "z": -85,
      "name": "Rock_Lime_Cobble"
    },
    {
      "x": -119,
      "y": 8,
      "z": -85,
      "name": "Soil_Gravel_Lime"
    },
    {
      "x": -119,
      "y": 9,
      "z": -85,
      "name": "Rock_Lime"
    },
    {
      "x": -119,
      "y": 10,
      "z": -85,
      "name": "Rock_Lime_Brick_Decorative"
    },
    {
      "x": -119,
      "y": 11,
      "z": -85,
      "name": "Rock_Lime_Cobble"
    },
    {
      "x": -119,
      "y": 12,
      "z": -85,
      "name": "Soil_Gravel_Lime"
    },
    {
      "x": -119,
      "y": 13,
      "z": -85,
      "name": "Rock_Lime_Brick_Decorative"
    },
    {
      "x": -119,
      "y": 14,
      "z": -85,
      "name": "Rock_Lime"
    },
    {
      "x": -119,
      "y": 15,
      "z": -85,
      "name": "Rock_Lime"
    },
    {
      "x": -119,
      "y": 16,
      "z": -85,
      "name": "Plant_Coral_Block_Lime"
    },
    {
      "x": -119,
      "y": 4,
      "z": -84,
      "name": "Rock_Lime_Brick_Decorative"
    },
    {
      "x": -119,
      "y": 5,
      "z": -84,
      "name": "Rock_Lime_Brick_Decorative"
    },
    {
      "x": -119,
      "y": 6,
      "z": -84,
      "name": "Rock_Lime_Brick_Decorative"
    },
    {
      "x": -119,
      "y": 7,
      "z": -84,
      "name": "Soil_Gravel_Lime"
    },
    {
      "x": -119,
      "y": 8,
      "z": -84,
      "name": "Rock_Lime_Brick_Decorative"
    },
    {
      "x": -119,
      "y": 9,
      "z": -84,
      "name": "Rock_Lime"
    },
    {
      "x": -119,
      "y": 10,
      "z": -84,
      "name": "Rock_Lime_Brick_Decorative"
    },
    {
      "x": -119,
      "y": 11,
      "z": -84,
      "name": "Rock_Lime_Brick_Decorative"
    },
    {
      "x": -119,
      "y": 12,
      "z": -84,
      "name": "Soil_Gravel_Lime"
    },
    {
      "x": -119,
      "y": 13,
      "z": -84,
      "name": "Soil_Gravel_Lime"
    },
    {
      "x": -119,
      "y": 14,
      "z": -84,
      "name": "Rock_Lime_Cobble"
    },
    {
      "x": -119,
      "y": 15,
      "z": -84,
      "name": "Rock_Lime_Brick_Decorative"
    },
    {
      "x": -119,
      "y": 16,
      "z": -84,
      "name": "Plant_Coral_Block_Lime"
    },
    {
      "x": -119,
      "y": 4,
      "z": -83,
      "name": "Rock_Lime_Brick_Decorative"
    },
    {
      "x": -119,
      "y": 5,
      "z": -83,
      "name": "Rock_Lime_Brick_Decorative"
    },
    {
      "x": -119,
      "y": 6,
      "z": -83,
      "name": "Rock_Lime_Brick_Decorative"
    },
    {
      "x": -119,
      "y": 7,
      "z": -83,
      "name": "Rock_Lime"
    },
    {
      "x": -119,
      "y": 8,
      "z": -83,
      "name": "Soil_Gravel_Lime"
    },
    {
      "x": -119,
      "y": 9,
      "z": -83,
      "name": "Rock_Lime_Brick_Decorative"
    },
    {
      "x": -119,
      "y": 10,
      "z": -83,
      "name": "Rock_Lime_Brick_Decorative"
    },
    {
      "x": -119,
      "y": 11,
      "z": -83,
      "name": "Soil_Gravel_Lime"
    },
    {
      "x": -119,
      "y": 12,
      "z": -83,
      "name": "Rock_Lime"
    },
    {
      "x": -119,
      "y": 13,
      "z": -83,
      "name": "Soil_Gravel_Lime"
    },
    {
      "x": -119,
      "y": 14,
      "z": -83,
      "name": "Rock_Lime_Cobble"
    },
    {
      "x": -119,
      "y": 15,
      "z": -83,
      "name": "Rock_Lime_Brick_Decorative"
    },
    {
      "x": -119,
      "y": 16,
      "z": -83,
      "name": "Plant_Coral_Block_Lime"
    },
    {
      "x": -119,
      "y": 4,
      "z": -82,
      "name": "Rock_Lime_Cobble"
    },
    {
      "x": -119,
      "y": 5,
      "z": -82,
      "name": "Rock_Lime_Cobble"
    },
    {
      "x": -119,
      "y": 6,
      "z": -82,
      "name": "Soil_Gravel_Lime"
    },
    {
      "x": -119,
      "y": 7,
      "z": -82,
      "name": "Soil_Gravel_Lime"
    },
    {
      "x": -119,
      "y": 8,
      "z": -82,
      "name": "Rock_Lime_Cobble"
    },
    {
      "x": -119,
      "y": 9,
      "z": -82,
      "name": "Rock_Lime_Brick_Decorative"
    },
    {
      "x": -119,
      "y": 10,
      "z": -82,
      "name": "Rock_Lime"
    },
    {
      "x": -119,
      "y": 11,
      "z": -82,
      "name": "Rock_Lime"
    },
    {
      "x": -119,
      "y": 12,
      "z": -82,
      "name": "Rock_Lime_Cobble"
    },
    {
      "x": -119,
      "y": 13,
      "z": -82,
      "name": "Rock_Lime_Cobble"
    },
    {
      "x": -119,
      "y": 14,
      "z": -82,
      "name": "Soil_Gravel_Lime"
    },
    {
      "x": -119,
      "y": 15,
      "z": -82,
      "name": "Rock_Lime_Brick_Decorative"
    },
    {
      "x": -119,
      "y": 16,
      "z": -82,
      "name": "Plant_Coral_Block_Lime"
    },
    {
      "x": -119,
      "y": 5,
      "z": -81,
      "name": "Soil_Gravel_Lime"
    },
    {
      "x": -119,
      "y": 6,
      "z": -81,
      "name": "Rock_Lime_Brick_Decorative"
    },
    {
      "x": -119,
      "y": 7,
      "z": -81,
      "name": "Rock_Lime_Brick_Decorative"
    },
    {
      "x": -119,
      "y": 8,
      "z": -81,
      "name": "Rock_Lime_Cobble"
    },
    {
      "x": -119,
      "y": 9,
      "z": -81,
      "name": "Soil_Gravel_Lime"
    },
    {
      "x": -119,
      "y": 10,
      "z": -81,
      "name": "Rock_Lime_Brick_Decorative"
    },
    {
      "x": -119,
      "y": 11,
      "z": -81,
      "name": "Soil_Gravel_Lime"
    },
    {
      "x": -119,
      "y": 12,
      "z": -81,
      "name": "Rock_Lime_Cobble"
    },
    {
      "x": -119,
      "y": 13,
      "z": -81,
      "name": "Rock_Lime_Cobble"
    },
    {
      "x": -119,
      "y": 14,
      "z": -81,
      "name": "Rock_Lime_Brick_Decorative"
    },
    {
      "x": -119,
      "y": 15,
      "z": -81,
      "name": "Rock_Lime_Brick_Decorative"
    },
    {
      "x": -119,
      "y": 16,
      "z": -81,
      "name": "Soil_Clay_Smooth_Lime"
    },
    {
      "x": -119,
      "y": 5,
      "z": -80,
      "name": "Rock_Lime_Brick_Decorative"
    },
    {
      "x": -119,
      "y": 6,
      "z": -80,
      "name": "Soil_Gravel_Lime"
    },
    {
      "x": -119,
      "y": 7,
      "z": -80,
      "name": "Rock_Lime"
    },
    {
      "x": -119,
      "y": 8,
      "z": -80,
      "name": "Soil_Gravel_Lime"
    },
    {
      "x": -119,
      "y": 9,
      "z": -80,
      "name": "Rock_Lime_Brick_Decorative"
    },
    {
      "x": -119,
      "y": 10,
      "z": -80,
      "name": "Rock_Lime_Cobble"
    },
    {
      "x": -119,
      "y": 11,
      "z": -80,
      "name": "Soil_Gravel_Lime"
    },
    {
      "x": -119,
      "y": 12,
      "z": -80,
      "name": "Rock_Lime"
    },
    {
      "x": -119,
      "y": 13,
      "z": -80,
      "name": "Rock_Lime_Brick_Decorative"
    },
    {
      "x": -119,
      "y": 14,
      "z": -80,
      "name": "Rock_Lime_Brick_Decorative"
    },
    {
      "x": -119,
      "y": 15,
      "z": -80,
      "name": "Rock_Lime_Brick_Decorative"
    },
    {
      "x": -119,
      "y": 16,
      "z": -80,
      "name": "Soil_Clay_Lime"
    },
    {
      "x": -119,
      "y": 6,
      "z": -79,
      "name": "Rock_Lime"
    },
    {
      "x": -119,
      "y": 7,
      "z": -79,
      "name": "Rock_Lime_Brick_Decorative"
    },
    {
      "x": -119,
      "y": 8,
      "z": -79,
      "name": "Rock_Lime"
    },
    {
      "x": -119,
      "y": 9,
      "z": -79,
      "name": "Rock_Lime_Brick_Decorative"
    },
    {
      "x": -119,
      "y": 10,
      "z": -79,
      "name": "Rock_Lime_Cobble"
    },
    {
      "x": -119,
      "y": 11,
      "z": -79,
      "name": "Rock_Lime_Cobble"
    },
    {
      "x": -119,
      "y": 12,
      "z": -79,
      "name": "Rock_Lime"
    },
    {
      "x": -119,
      "y": 13,
      "z": -79,
      "name": "Rock_Lime"
    },
    {
      "x": -119,
      "y": 14,
      "z": -79,
      "name": "Rock_Lime_Brick_Decorative"
    },
    {
      "x": -119,
      "y": 15,
      "z": -79,
      "name": "Soil_Gravel_Lime"
    },
    {
      "x": -119,
      "y": 16,
      "z": -79,
      "name": "Plant_Coral_Block_Lime"
    },
    {
      "x": -119,
      "y": 5,
      "z": -78,
      "name": "Rock_Lime_Brick_Decorative"
    },
    {
      "x": -119,
      "y": 6,
      "z": -78,
      "name": "Rock_Lime_Brick_Decorative"
    },
    {
      "x": -119,
      "y": 7,
      "z": -78,
      "name": "Rock_Lime_Cobble"
    },
    {
      "x": -119,
      "y": 8,
      "z": -78,
      "name": "Rock_Lime_Cobble"
    },
    {
      "x": -119,
      "y": 9,
      "z": -78,
      "name": "Rock_Lime_Brick_Decorative"
    },
    {
      "x": -119,
      "y": 10,
      "z": -78,
      "name": "Soil_Gravel_Lime"
    },
    {
      "x": -119,
      "y": 11,
      "z": -78,
      "name": "Rock_Lime_Cobble"
    },
    {
      "x": -119,
      "y": 12,
      "z": -78,
      "name": "Rock_Lime"
    },
    {
      "x": -119,
      "y": 13,
      "z": -78,
      "name": "Rock_Lime"
    },
    {
      "x": -119,
      "y": 14,
      "z": -78,
      "name": "Rock_Lime"
    },
    {
      "x": -119,
      "y": 15,
      "z": -78,
      "name": "Rock_Lime"
    },
    {
      "x": -119,
      "y": 16,
      "z": -78,
      "name": "Plant_Coral_Block_Lime"
    },
    {
      "x": -119,
      "y": 5,
      "z": -77,
      "name": "Soil_Gravel_Lime"
    },
    {
      "x": -119,
      "y": 6,
      "z": -77,
      "name": "Rock_Lime_Cobble"
    },
    {
      "x": -119,
      "y": 7,
      "z": -77,
      "name": "Soil_Gravel_Lime"
    },
    {
      "x": -119,
      "y": 8,
      "z": -77,
      "name": "Rock_Lime_Cobble"
    },
    {
      "x": -119,
      "y": 9,
      "z": -77,
      "name": "Rock_Lime_Brick_Decorative"
    },
    {
      "x": -119,
      "y": 10,
      "z": -77,
      "name": "Rock_Lime_Brick_Decorative"
    },
    {
      "x": -119,
      "y": 11,
      "z": -77,
      "name": "Soil_Gravel_Lime"
    },
    {
      "x": -119,
      "y": 12,
      "z": -77,
      "name": "Rock_Lime_Brick_Decorative"
    },
    {
      "x": -119,
      "y": 13,
      "z": -77,
      "name": "Soil_Gravel_Lime"
    },
    {
      "x": -119,
      "y": 14,
      "z": -77,
      "name": "Rock_Lime_Brick_Decorative"
    },
    {
      "x": -119,
      "y": 15,
      "z": -77,
      "name": "Rock_Lime_Brick_Decorative"
    },
    {
      "x": -119,
      "y": 16,
      "z": -77,
      "name": "Rock_Lime"
    },
    {
      "x": -119,
      "y": 17,
      "z": -77,
      "name": "Soil_Clay_Smooth_Lime"
    },
    {
      "x": -119,
      "y": 18,
      "z": -77,
      "name": "Plant_Flower_Bushy_Poisoned"
    },
    {
      "x": -119,
      "y": 5,
      "z": -76,
      "name": "Rock_Lime_Brick_Decorative"
    },
    {
      "x": -119,
      "y": 6,
      "z": -76,
      "name": "Rock_Lime"
    },
    {
      "x": -119,
      "y": 7,
      "z": -76,
      "name": "Soil_Gravel_Lime"
    },
    {
      "x": -119,
      "y": 8,
      "z": -76,
      "name": "Rock_Lime"
    },
    {
      "x": -119,
      "y": 9,
      "z": -76,
      "name": "Rock_Lime_Cobble"
    },
    {
      "x": -119,
      "y": 10,
      "z": -76,
      "name": "Rock_Lime_Cobble"
    },
    {
      "x": -119,
      "y": 11,
      "z": -76,
      "name": "Rock_Lime"
    },
    {
      "x": -119,
      "y": 12,
      "z": -76,
      "name": "Rock_Lime_Cobble"
    },
    {
      "x": -119,
      "y": 13,
      "z": -76,
      "name": "Rock_Lime_Brick_Decorative"
    },
    {
      "x": -119,
      "y": 14,
      "z": -76,
      "name": "Soil_Gravel_Lime"
    },
    {
      "x": -119,
      "y": 15,
      "z": -76,
      "name": "Rock_Lime_Brick_Decorative"
    },
    {
      "x": -119,
      "y": 16,
      "z": -76,
      "name": "Rock_Lime_Brick_Decorative"
    },
    {
      "x": -119,
      "y": 17,
      "z": -76,
      "name": "Rock_Lime_Brick_Decorative"
    },
    {
      "x": -119,
      "y": 18,
      "z": -76,
      "name": "Rock_Lime"
    },
    {
      "x": -119,
      "y": 19,
      "z": -76,
      "name": "Soil_Gravel_Lime"
    },
    {
      "x": -119,
      "y": 6,
      "z": -75,
      "name": "Rock_Lime_Brick_Decorative"
    },
    {
      "x": -119,
      "y": 7,
      "z": -75,
      "name": "Rock_Lime_Cobble"
    },
    {
      "x": -119,
      "y": 8,
      "z": -75,
      "name": "Rock_Lime"
    },
    {
      "x": -119,
      "y": 9,
      "z": -75,
      "name": "Rock_Lime_Brick_Decorative"
    },
    {
      "x": -119,
      "y": 10,
      "z": -75,
      "name": "Rock_Lime_Cobble"
    },
    {
      "x": -119,
      "y": 11,
      "z": -75,
      "name": "Rock_Lime_Cobble"
    },
    {
      "x": -119,
      "y": 12,
      "z": -75,
      "name": "Rock_Lime_Brick_Decorative"
    },
    {
      "x": -119,
      "y": 13,
      "z": -75,
      "name": "Soil_Gravel_Lime"
    },
    {
      "x": -119,
      "y": 14,
      "z": -75,
      "name": "Rock_Lime_Brick_Decorative",
      "support": 15
    },
    {
      "x": -119,
      "y": 15,
      "z": -75,
      "name": "Rock_Lime_Brick_Decorative"
    },
    {
      "x": -119,
      "y": 16,
      "z": -75,
      "name": "Soil_Gravel_Lime"
    },
    {
      "x": -119,
      "y": 17,
      "z": -75,
      "name": "Rock_Lime_Brick_Decorative"
    },
    {
      "x": -119,
      "y": 18,
      "z": -75,
      "name": "Rock_Lime_Brick_Decorative"
    },
    {
      "x": -119,
      "y": 19,
      "z": -75,
      "name": "Rubble_Lime"
    },
    {
      "x": -119,
      "y": 8,
      "z": -74,
      "name": "Rock_Lime"
    },
    {
      "x": -119,
      "y": 9,
      "z": -74,
      "name": "Rock_Lime"
    },
    {
      "x": -119,
      "y": 10,
      "z": -74,
      "name": "Rock_Lime"
    },
    {
      "x": -119,
      "y": 11,
      "z": -74,
      "name": "Rock_Lime_Brick_Decorative"
    },
    {
      "x": -119,
      "y": 12,
      "z": -74,
      "name": "Rock_Lime"
    },
    {
      "x": -119,
      "y": 13,
      "z": -74,
      "name": "Rock_Lime_Brick_Decorative"
    },
    {
      "x": -119,
      "y": 14,
      "z": -74,
      "name": "Rock_Lime"
    },
    {
      "x": -119,
      "y": 15,
      "z": -74,
      "name": "Soil_Gravel_Lime"
    },
    {
      "x": -119,
      "y": 16,
      "z": -74,
      "name": "Soil_Gravel_Lime"
    },
    {
      "x": -118,
      "y": 9,
      "z": -89,
      "name": "Rock_Lime_Brick_Decorative"
    },
    {
      "x": -118,
      "y": 10,
      "z": -89,
      "name": "Rock_Lime_Brick_Decorative"
    },
    {
      "x": -118,
      "y": 11,
      "z": -89,
      "name": "Rock_Lime_Brick_Decorative"
    },
    {
      "x": -118,
      "y": 12,
      "z": -89,
      "name": "Soil_Gravel_Lime"
    },
    {
      "x": -118,
      "y": 7,
      "z": -88,
      "name": "Rock_Lime"
    },
    {
      "x": -118,
      "y": 8,
      "z": -88,
      "name": "Soil_Gravel_Lime"
    },
    {
      "x": -118,
      "y": 9,
      "z": -88,
      "name": "Rock_Lime"
    },
    {
      "x": -118,
      "y": 10,
      "z": -88,
      "name": "Soil_Gravel_Lime"
    },
    {
      "x": -118,
      "y": 11,
      "z": -88,
      "name": "Rock_Lime_Cobble"
    },
    {
      "x": -118,
      "y": 12,
      "z": -88,
      "name": "Rock_Lime_Brick_Decorative"
    },
    {
      "x": -118,
      "y": 13,
      "z": -88,
      "name": "Rock_Lime_Brick_Decorative"
    },
    {
      "x": -118,
      "y": 14,
      "z": -88,
      "name": "Rock_Lime_Brick_Decorative"
    },
    {
      "x": -118,
      "y": 15,
      "z": -88,
      "name": "Rock_Lime_Brick_Decorative"
    },
    {
      "x": -118,
      "y": 16,
      "z": -88,
      "name": "Rock_Lime"
    },
    {
      "x": -118,
      "y": 17,
      "z": -88,
      "name": "Rock_Lime_Brick_Decorative"
    },
    {
      "x": -118,
      "y": 18,
      "z": -88,
      "name": "Rock_Lime_Stalactite_Large"
    },
    {
      "x": -118,
      "y": 19,
      "z": -88,
      "name": "Rock_Lime_Stalactite_Large",
      "filler": 1024
    },
    {
      "x": -118,
      "y": 6,
      "z": -87,
      "name": "Soil_Gravel_Lime"
    },
    {
      "x": -118,
      "y": 7,
      "z": -87,
      "name": "Rock_Lime_Brick_Decorative"
    },
    {
      "x": -118,
      "y": 8,
      "z": -87,
      "name": "Rock_Lime"
    },
    {
      "x": -118,
      "y": 9,
      "z": -87,
      "name": "Rock_Lime"
    },
    {
      "x": -118,
      "y": 10,
      "z": -87,
      "name": "Soil_Gravel_Lime"
    },
    {
      "x": -118,
      "y": 11,
      "z": -87,
      "name": "Rock_Lime_Brick_Decorative"
    },
    {
      "x": -118,
      "y": 12,
      "z": -87,
      "name": "Rock_Lime_Brick_Decorative"
    },
    {
      "x": -118,
      "y": 13,
      "z": -87,
      "name": "Rock_Lime"
    },
    {
      "x": -118,
      "y": 14,
      "z": -87,
      "name": "Soil_Gravel_Lime"
    },
    {
      "x": -118,
      "y": 15,
      "z": -87,
      "name": "Rock_Lime_Brick_Decorative"
    },
    {
      "x": -118,
      "y": 16,
      "z": -87,
      "name": "Rock_Lime_Brick_Decorative"
    },
    {
      "x": -118,
      "y": 17,
      "z": -87,
      "name": "Soil_Clay_Lime"
    },
    {
      "x": -118,
      "y": 5,
      "z": -86,
      "name": "Rock_Lime"
    },
    {
      "x": -118,
      "y": 6,
      "z": -86,
      "name": "Soil_Gravel_Lime"
    },
    {
      "x": -118,
      "y": 7,
      "z": -86,
      "name": "Rock_Lime"
    },
    {
      "x": -118,
      "y": 8,
      "z": -86,
      "name": "Rock_Lime_Brick_Decorative"
    },
    {
      "x": -118,
      "y": 9,
      "z": -86,
      "name": "Rock_Lime_Cobble"
    },
    {
      "x": -118,
      "y": 10,
      "z": -86,
      "name": "Rock_Lime_Cobble"
    },
    {
      "x": -118,
      "y": 11,
      "z": -86,
      "name": "Rock_Lime_Brick_Decorative"
    },
    {
      "x": -118,
      "y": 12,
      "z": -86,
      "name": "Rock_Lime_Brick_Decorative"
    },
    {
      "x": -118,
      "y": 13,
      "z": -86,
      "name": "Rock_Lime"
    },
    {
      "x": -118,
      "y": 14,
      "z": -86,
      "name": "Rock_Lime_Brick_Decorative"
    },
    {
      "x": -118,
      "y": 15,
      "z": -86,
      "name": "Rock_Lime_Brick_Decorative"
    },
    {
      "x": -118,
      "y": 16,
      "z": -86,
      "name": "Soil_Clay_Smooth_Lime"
    },
    {
      "x": -118,
      "y": 4,
      "z": -85,
      "name": "Rock_Lime_Cobble"
    },
    {
      "x": -118,
      "y": 5,
      "z": -85,
      "name": "Soil_Gravel_Lime"
    },
    {
      "x": -118,
      "y": 6,
      "z": -85,
      "name": "Rock_Lime_Brick_Decorative"
    },
    {
      "x": -118,
      "y": 7,
      "z": -85,
      "name": "Rock_Lime"
    },
    {
      "x": -118,
      "y": 8,
      "z": -85,
      "name": "Rock_Lime"
    },
    {
      "x": -118,
      "y": 9,
      "z": -85,
      "name": "Rock_Lime_Brick_Decorative"
    },
    {
      "x": -118,
      "y": 10,
      "z": -85,
      "name": "Rock_Lime"
    },
    {
      "x": -118,
      "y": 11,
      "z": -85,
      "name": "Rock_Lime_Cobble"
    },
    {
      "x": -118,
      "y": 12,
      "z": -85,
      "name": "Rock_Lime"
    },
    {
      "x": -118,
      "y": 13,
      "z": -85,
      "name": "Rock_Lime"
    },
    {
      "x": -118,
      "y": 14,
      "z": -85,
      "name": "Rock_Lime_Brick_Decorative"
    },
    {
      "x": -118,
      "y": 15,
      "z": -85,
      "name": "Rock_Lime_Brick_Decorative"
    },
    {
      "x": -118,
      "y": 16,
      "z": -85,
      "name": "Plant_Coral_Block_Lime"
    },
    {
      "x": -118,
      "y": 4,
      "z": -84,
      "name": "Rock_Lime"
    },
    {
      "x": -118,
      "y": 5,
      "z": -84,
      "name": "Rock_Lime_Cobble"
    },
    {
      "x": -118,
      "y": 6,
      "z": -84,
      "name": "Rock_Lime"
    },
    {
      "x": -118,
      "y": 7,
      "z": -84,
      "name": "Soil_Gravel_Lime"
    },
    {
      "x": -118,
      "y": 8,
      "z": -84,
      "name": "Rock_Lime_Cobble"
    },
    {
      "x": -118,
      "y": 9,
      "z": -84,
      "name": "Rock_Lime_Cobble"
    },
    {
      "x": -118,
      "y": 10,
      "z": -84,
      "name": "Rock_Lime_Cobble"
    },
    {
      "x": -118,
      "y": 11,
      "z": -84,
      "name": "Rock_Lime_Brick_Decorative"
    },
    {
      "x": -118,
      "y": 12,
      "z": -84,
      "name": "Soil_Gravel_Lime"
    },
    {
      "x": -118,
      "y": 13,
      "z": -84,
      "name": "Soil_Gravel_Lime"
    },
    {
      "x": -118,
      "y": 14,
      "z": -84,
      "name": "Soil_Gravel_Lime"
    },
    {
      "x": -118,
      "y": 15,
      "z": -84,
      "name": "Rock_Lime_Brick_Decorative"
    },
    {
      "x": -118,
      "y": 16,
      "z": -84,
      "name": "Plant_Coral_Block_Lime"
    },
    {
      "x": -118,
      "y": 4,
      "z": -83,
      "name": "Rock_Lime"
    },
    {
      "x": -118,
      "y": 5,
      "z": -83,
      "name": "Rock_Lime_Brick_Decorative"
    },
    {
      "x": -118,
      "y": 6,
      "z": -83,
      "name": "Rock_Lime_Cobble"
    },
    {
      "x": -118,
      "y": 7,
      "z": -83,
      "name": "Soil_Gravel_Lime"
    },
    {
      "x": -118,
      "y": 8,
      "z": -83,
      "name": "Rock_Lime"
    },
    {
      "x": -118,
      "y": 9,
      "z": -83,
      "name": "Rock_Lime_Cobble"
    },
    {
      "x": -118,
      "y": 10,
      "z": -83,
      "name": "Rock_Lime_Brick_Decorative"
    },
    {
      "x": -118,
      "y": 11,
      "z": -83,
      "name": "Soil_Gravel_Lime"
    },
    {
      "x": -118,
      "y": 12,
      "z": -83,
      "name": "Soil_Gravel_Lime"
    },
    {
      "x": -118,
      "y": 13,
      "z": -83,
      "name": "Rock_Lime"
    },
    {
      "x": -118,
      "y": 14,
      "z": -83,
      "name": "Soil_Gravel_Lime"
    },
    {
      "x": -118,
      "y": 15,
      "z": -83,
      "name": "Rock_Lime"
    },
    {
      "x": -118,
      "y": 16,
      "z": -83,
      "name": "Plant_Coral_Block_Lime"
    },
    {
      "x": -118,
      "y": 4,
      "z": -82,
      "name": "Rock_Lime_Brick_Decorative"
    },
    {
      "x": -118,
      "y": 5,
      "z": -82,
      "name": "Rock_Lime_Cobble"
    },
    {
      "x": -118,
      "y": 6,
      "z": -82,
      "name": "Rock_Lime"
    },
    {
      "x": -118,
      "y": 7,
      "z": -82,
      "name": "Rock_Lime"
    },
    {
      "x": -118,
      "y": 8,
      "z": -82,
      "name": "Rock_Lime"
    },
    {
      "x": -118,
      "y": 9,
      "z": -82,
      "name": "Rock_Lime_Brick_Decorative"
    },
    {
      "x": -118,
      "y": 10,
      "z": -82,
      "name": "Soil_Gravel_Lime"
    },
    {
      "x": -118,
      "y": 11,
      "z": -82,
      "name": "Rock_Lime"
    },
    {
      "x": -118,
      "y": 12,
      "z": -82,
      "name": "Soil_Gravel_Lime"
    },
    {
      "x": -118,
      "y": 13,
      "z": -82,
      "name": "Rock_Lime_Brick_Decorative"
    },
    {
      "x": -118,
      "y": 14,
      "z": -82,
      "name": "Soil_Gravel_Lime"
    },
    {
      "x": -118,
      "y": 15,
      "z": -82,
      "name": "Rock_Lime"
    },
    {
      "x": -118,
      "y": 16,
      "z": -82,
      "name": "Plant_Coral_Block_Lime"
    },
    {
      "x": -118,
      "y": 4,
      "z": -81,
      "name": "Rock_Lime_Brick_Decorative"
    },
    {
      "x": -118,
      "y": 5,
      "z": -81,
      "name": "Rock_Lime"
    },
    {
      "x": -118,
      "y": 6,
      "z": -81,
      "name": "Soil_Gravel_Lime"
    },
    {
      "x": -118,
      "y": 7,
      "z": -81,
      "name": "Rock_Lime_Cobble"
    },
    {
      "x": -118,
      "y": 8,
      "z": -81,
      "name": "Rock_Lime"
    },
    {
      "x": -118,
      "y": 9,
      "z": -81,
      "name": "Rock_Lime_Cobble"
    },
    {
      "x": -118,
      "y": 10,
      "z": -81,
      "name": "Soil_Gravel_Lime"
    },
    {
      "x": -118,
      "y": 11,
      "z": -81,
      "name": "Rock_Lime"
    },
    {
      "x": -118,
      "y": 12,
      "z": -81,
      "name": "Rock_Lime_Brick_Decorative"
    },
    {
      "x": -118,
      "y": 13,
      "z": -81,
      "name": "Rock_Lime_Cobble"
    },
    {
      "x": -118,
      "y": 14,
      "z": -81,
      "name": "Rock_Lime"
    },
    {
      "x": -118,
      "y": 15,
      "z": -81,
      "name": "Soil_Gravel_Lime"
    },
    {
      "x": -118,
      "y": 16,
      "z": -81,
      "name": "Plant_Coral_Block_Lime"
    },
    {
      "x": -118,
      "y": 5,
      "z": -80,
      "name": "Rock_Lime_Brick_Decorative"
    },
    {
      "x": -118,
      "y": 6,
      "z": -80,
      "name": "Soil_Gravel_Lime"
    },
    {
      "x": -118,
      "y": 7,
      "z": -80,
      "name": "Rock_Lime"
    },
    {
      "x": -118,
      "y": 8,
      "z": -80,
      "name": "Rock_Lime_Brick_Decorative"
    },
    {
      "x": -118,
      "y": 9,
      "z": -80,
      "name": "Soil_Gravel_Lime"
    },
    {
      "x": -118,
      "y": 10,
      "z": -80,
      "name": "Rock_Lime_Brick_Decorative"
    },
    {
      "x": -118,
      "y": 11,
      "z": -80,
      "name": "Rock_Lime_Brick_Decorative"
    },
    {
      "x": -118,
      "y": 12,
      "z": -80,
      "name": "Soil_Gravel_Lime"
    },
    {
      "x": -118,
      "y": 13,
      "z": -80,
      "name": "Rock_Lime"
    },
    {
      "x": -118,
      "y": 14,
      "z": -80,
      "name": "Rock_Lime"
    },
    {
      "x": -118,
      "y": 15,
      "z": -80,
      "name": "Soil_Gravel_Lime"
    },
    {
      "x": -118,
      "y": 16,
      "z": -80,
      "name": "Plant_Coral_Block_Lime"
    },
    {
      "x": -118,
      "y": 6,
      "z": -79,
      "name": "Rock_Lime_Cobble"
    },
    {
      "x": -118,
      "y": 7,
      "z": -79,
      "name": "Rock_Lime"
    },
    {
      "x": -118,
      "y": 8,
      "z": -79,
      "name": "Rock_Lime"
    },
    {
      "x": -118,
      "y": 9,
      "z": -79,
      "name": "Soil_Gravel_Lime"
    },
    {
      "x": -118,
      "y": 10,
      "z": -79,
      "name": "Rock_Lime_Cobble"
    },
    {
      "x": -118,
      "y": 11,
      "z": -79,
      "name": "Soil_Gravel_Lime"
    },
    {
      "x": -118,
      "y": 12,
      "z": -79,
      "name": "Rock_Lime"
    },
    {
      "x": -118,
      "y": 13,
      "z": -79,
      "name": "Soil_Gravel_Lime"
    },
    {
      "x": -118,
      "y": 14,
      "z": -79,
      "name": "Rock_Lime"
    },
    {
      "x": -118,
      "y": 15,
      "z": -79,
      "name": "Rock_Lime"
    },
    {
      "x": -118,
      "y": 16,
      "z": -79,
      "name": "Plant_Coral_Block_Lime"
    },
    {
      "x": -118,
      "y": 5,
      "z": -78,
      "name": "Rock_Lime_Cobble"
    },
    {
      "x": -118,
      "y": 6,
      "z": -78,
      "name": "Rock_Lime_Cobble"
    },
    {
      "x": -118,
      "y": 7,
      "z": -78,
      "name": "Rock_Lime_Brick_Decorative"
    },
    {
      "x": -118,
      "y": 8,
      "z": -78,
      "name": "Rock_Lime_Brick_Decorative"
    },
    {
      "x": -118,
      "y": 9,
      "z": -78,
      "name": "Rock_Lime_Brick_Decorative"
    },
    {
      "x": -118,
      "y": 10,
      "z": -78,
      "name": "Rock_Lime"
    },
    {
      "x": -118,
      "y": 11,
      "z": -78,
      "name": "Rock_Lime"
    },
    {
      "x": -118,
      "y": 12,
      "z": -78,
      "name": "Rock_Lime"
    },
    {
      "x": -118,
      "y": 13,
      "z": -78,
      "name": "Rock_Lime"
    },
    {
      "x": -118,
      "y": 14,
      "z": -78,
      "name": "Rock_Lime_Brick_Decorative"
    },
    {
      "x": -118,
      "y": 15,
      "z": -78,
      "name": "Rock_Lime_Brick_Decorative"
    },
    {
      "x": -118,
      "y": 16,
      "z": -78,
      "name": "Plant_Coral_Block_Lime"
    },
    {
      "x": -118,
      "y": 5,
      "z": -77,
      "name": "Rock_Lime"
    },
    {
      "x": -118,
      "y": 6,
      "z": -77,
      "name": "Rock_Lime_Brick_Decorative"
    },
    {
      "x": -118,
      "y": 7,
      "z": -77,
      "name": "Rock_Lime"
    },
    {
      "x": -118,
      "y": 8,
      "z": -77,
      "name": "Rock_Lime"
    },
    {
      "x": -118,
      "y": 9,
      "z": -77,
      "name": "Rock_Lime_Brick_Decorative"
    },
    {
      "x": -118,
      "y": 10,
      "z": -77,
      "name": "Rock_Lime"
    },
    {
      "x": -118,
      "y": 11,
      "z": -77,
      "name": "Soil_Gravel_Lime"
    },
    {
      "x": -118,
      "y": 12,
      "z": -77,
      "name": "Rock_Lime_Brick_Decorative"
    },
    {
      "x": -118,
      "y": 13,
      "z": -77,
      "name": "Rock_Lime"
    },
    {
      "x": -118,
      "y": 14,
      "z": -77,
      "name": "Rock_Lime_Brick_Decorative"
    },
    {
      "x": -118,
      "y": 15,
      "z": -77,
      "name": "Soil_Gravel_Lime"
    },
    {
      "x": -118,
      "y": 16,
      "z": -77,
      "name": "Rock_Lime"
    },
    {
      "x": -118,
      "y": 17,
      "z": -77,
      "name": "Soil_Clay_Smooth_Lime"
    },
    {
      "x": -118,
      "y": 18,
      "z": -77,
      "name": "Plant_Flower_Bushy_Poisoned"
    },
    {
      "x": -118,
      "y": 5,
      "z": -76,
      "name": "Soil_Gravel_Lime"
    },
    {
      "x": -118,
      "y": 6,
      "z": -76,
      "name": "Rock_Lime_Brick_Decorative"
    },
    {
      "x": -118,
      "y": 7,
      "z": -76,
      "name": "Soil_Gravel_Lime"
    },
    {
      "x": -118,
      "y": 8,
      "z": -76,
      "name": "Soil_Gravel_Lime"
    },
    {
      "x": -118,
      "y": 9,
      "z": -76,
      "name": "Rock_Lime"
    },
    {
      "x": -118,
      "y": 10,
      "z": -76,
      "name": "Rock_Lime_Brick_Decorative"
    },
    {
      "x": -118,
      "y": 11,
      "z": -76,
      "name": "Rock_Lime_Cobble"
    },
    {
      "x": -118,
      "y": 12,
      "z": -76,
      "name": "Soil_Gravel_Lime"
    },
    {
      "x": -118,
      "y": 13,
      "z": -76,
      "name": "Rock_Lime_Brick_Decorative"
    },
    {
      "x": -118,
      "y": 14,
      "z": -76,
      "name": "Rock_Lime_Brick_Decorative"
    },
    {
      "x": -118,
      "y": 15,
      "z": -76,
      "name": "Rock_Lime_Brick_Decorative"
    },
    {
      "x": -118,
      "y": 16,
      "z": -76,
      "name": "Rock_Lime"
    },
    {
      "x": -118,
      "y": 17,
      "z": -76,
      "name": "Plant_Coral_Block_Lime"
    },
    {
      "x": -118,
      "y": 6,
      "z": -75,
      "name": "Rock_Lime"
    },
    {
      "x": -118,
      "y": 7,
      "z": -75,
      "name": "Rock_Lime_Cobble"
    },
    {
      "x": -118,
      "y": 8,
      "z": -75,
      "name": "Rock_Lime"
    },
    {
      "x": -118,
      "y": 9,
      "z": -75,
      "name": "Soil_Gravel_Lime"
    },
    {
      "x": -118,
      "y": 10,
      "z": -75,
      "name": "Soil_Gravel_Lime"
    },
    {
      "x": -118,
      "y": 11,
      "z": -75,
      "name": "Soil_Gravel_Lime"
    },
    {
      "x": -118,
      "y": 12,
      "z": -75,
      "name": "Rock_Lime_Cobble"
    },
    {
      "x": -118,
      "y": 13,
      "z": -75,
      "name": "Rock_Lime"
    },
    {
      "x": -118,
      "y": 14,
      "z": -75,
      "name": "Soil_Gravel_Lime"
    },
    {
      "x": -118,
      "y": 15,
      "z": -75,
      "name": "Rock_Lime_Brick_Decorative"
    },
    {
      "x": -118,
      "y": 16,
      "z": -75,
      "name": "Rock_Lime_Brick_Decorative"
    },
    {
      "x": -118,
      "y": 17,
      "z": -75,
      "name": "Rock_Lime_Brick_Decorative"
    },
    {
      "x": -118,
      "y": 7,
      "z": -74,
      "name": "Rock_Lime"
    },
    {
      "x": -118,
      "y": 8,
      "z": -74,
      "name": "Rock_Lime_Cobble"
    },
    {
      "x": -118,
      "y": 9,
      "z": -74,
      "name": "Rock_Lime"
    },
    {
      "x": -118,
      "y": 10,
      "z": -74,
      "name": "Rock_Lime_Brick_Decorative"
    },
    {
      "x": -118,
      "y": 11,
      "z": -74,
      "name": "Soil_Gravel_Lime",
      "support": 15
    },
    {
      "x": -118,
      "y": 12,
      "z": -74,
      "name": "Rock_Lime"
    },
    {
      "x": -118,
      "y": 13,
      "z": -74,
      "name": "Rock_Lime_Brick_Decorative"
    },
    {
      "x": -118,
      "y": 14,
      "z": -74,
      "name": "Soil_Gravel_Lime"
    },
    {
      "x": -118,
      "y": 15,
      "z": -74,
      "name": "Rock_Lime_Brick_Decorative"
    },
    {
      "x": -118,
      "y": 16,
      "z": -74,
      "name": "Rubble_Lime_Medium"
    },
    {
      "x": -117,
      "y": 9,
      "z": -89,
      "name": "Rock_Lime_Brick_Decorative"
    },
    {
      "x": -117,
      "y": 10,
      "z": -89,
      "name": "Rock_Lime"
    },
    {
      "x": -117,
      "y": 11,
      "z": -89,
      "name": "Rock_Lime"
    },
    {
      "x": -117,
      "y": 12,
      "z": -89,
      "name": "Soil_Gravel_Lime"
    },
    {
      "x": -117,
      "y": 13,
      "z": -89,
      "name": "Rock_Lime_Brick_Decorative"
    },
    {
      "x": -117,
      "y": 14,
      "z": -89,
      "name": "Rock_Lime_Brick_Decorative"
    },
    {
      "x": -117,
      "y": 15,
      "z": -89,
      "name": "Rock_Lime_Stalactite_Large"
    },
    {
      "x": -117,
      "y": 16,
      "z": -89,
      "name": "Rock_Lime_Stalactite_Large",
      "filler": 1024
    },
    {
      "x": -117,
      "y": 8,
      "z": -88,
      "name": "Soil_Gravel_Lime"
    },
    {
      "x": -117,
      "y": 9,
      "z": -88,
      "name": "Soil_Gravel_Lime"
    },
    {
      "x": -117,
      "y": 10,
      "z": -88,
      "name": "Rock_Lime"
    },
    {
      "x": -117,
      "y": 11,
      "z": -88,
      "name": "Rock_Lime"
    },
    {
      "x": -117,
      "y": 12,
      "z": -88,
      "name": "Rock_Lime_Brick_Decorative"
    },
    {
      "x": -117,
      "y": 13,
      "z": -88,
      "name": "Rock_Lime"
    },
    {
      "x": -117,
      "y": 14,
      "z": -88,
      "name": "Rock_Lime_Brick_Decorative"
    },
    {
      "x": -117,
      "y": 15,
      "z": -88,
      "name": "Soil_Gravel_Lime"
    },
    {
      "x": -117,
      "y": 16,
      "z": -88,
      "name": "Rock_Lime"
    },
    {
      "x": -117,
      "y": 17,
      "z": -88,
      "name": "Soil_Gravel_Lime"
    },
    {
      "x": -117,
      "y": 6,
      "z": -87,
      "name": "Rock_Lime_Cobble"
    },
    {
      "x": -117,
      "y": 7,
      "z": -87,
      "name": "Rock_Lime"
    },
    {
      "x": -117,
      "y": 8,
      "z": -87,
      "name": "Rock_Lime"
    },
    {
      "x": -117,
      "y": 9,
      "z": -87,
      "name": "Rock_Lime"
    },
    {
      "x": -117,
      "y": 10,
      "z": -87,
      "name": "Rock_Lime"
    },
    {
      "x": -117,
      "y": 11,
      "z": -87,
      "name": "Soil_Gravel_Lime"
    },
    {
      "x": -117,
      "y": 12,
      "z": -87,
      "name": "Soil_Gravel_Lime"
    },
    {
      "x": -117,
      "y": 13,
      "z": -87,
      "name": "Rock_Lime_Brick_Decorative"
    },
    {
      "x": -117,
      "y": 14,
      "z": -87,
      "name": "Rock_Lime_Brick_Decorative"
    },
    {
      "x": -117,
      "y": 15,
      "z": -87,
      "name": "Rock_Lime_Brick_Decorative"
    },
    {
      "x": -117,
      "y": 16,
      "z": -87,
      "name": "Plant_Coral_Block_Lime"
    },
    {
      "x": -117,
      "y": 17,
      "z": -87,
      "name": "Soil_Clay_Lime"
    },
    {
      "x": -117,
      "y": 5,
      "z": -86,
      "name": "Rock_Lime"
    },
    {
      "x": -117,
      "y": 6,
      "z": -86,
      "name": "Rock_Lime"
    },
    {
      "x": -117,
      "y": 7,
      "z": -86,
      "name": "Rock_Lime_Cobble"
    },
    {
      "x": -117,
      "y": 8,
      "z": -86,
      "name": "Rock_Lime_Brick_Decorative"
    },
    {
      "x": -117,
      "y": 9,
      "z": -86,
      "name": "Soil_Gravel_Lime"
    },
    {
      "x": -117,
      "y": 10,
      "z": -86,
      "name": "Rock_Lime_Cobble"
    },
    {
      "x": -117,
      "y": 11,
      "z": -86,
      "name": "Rock_Lime_Brick_Decorative"
    },
    {
      "x": -117,
      "y": 12,
      "z": -86,
      "name": "Soil_Gravel_Lime"
    },
    {
      "x": -117,
      "y": 13,
      "z": -86,
      "name": "Rock_Lime"
    },
    {
      "x": -117,
      "y": 14,
      "z": -86,
      "name": "Rock_Lime_Brick_Decorative"
    },
    {
      "x": -117,
      "y": 15,
      "z": -86,
      "name": "Rock_Lime_Brick_Decorative"
    },
    {
      "x": -117,
      "y": 16,
      "z": -86,
      "name": "Plant_Coral_Block_Lime"
    },
    {
      "x": -117,
      "y": 5,
      "z": -85,
      "name": "Rock_Lime"
    },
    {
      "x": -117,
      "y": 6,
      "z": -85,
      "name": "Soil_Gravel_Lime"
    },
    {
      "x": -117,
      "y": 7,
      "z": -85,
      "name": "Soil_Gravel_Lime"
    },
    {
      "x": -117,
      "y": 8,
      "z": -85,
      "name": "Soil_Gravel_Lime"
    },
    {
      "x": -117,
      "y": 9,
      "z": -85,
      "name": "Soil_Gravel_Lime"
    },
    {
      "x": -117,
      "y": 10,
      "z": -85,
      "name": "Rock_Lime"
    },
    {
      "x": -117,
      "y": 11,
      "z": -85,
      "name": "Soil_Gravel_Lime"
    },
    {
      "x": -117,
      "y": 12,
      "z": -85,
      "name": "Soil_Gravel_Lime"
    },
    {
      "x": -117,
      "y": 13,
      "z": -85,
      "name": "Rock_Lime_Cobble"
    },
    {
      "x": -117,
      "y": 14,
      "z": -85,
      "name": "Rock_Lime"
    },
    {
      "x": -117,
      "y": 15,
      "z": -85,
      "name": "Rock_Lime_Brick_Decorative"
    },
    {
      "x": -117,
      "y": 16,
      "z": -85,
      "name": "Plant_Coral_Block_Lime"
    },
    {
      "x": -117,
      "y": 4,
      "z": -84,
      "name": "Rock_Lime_Brick_Decorative"
    },
    {
      "x": -117,
      "y": 5,
      "z": -84,
      "name": "Rock_Lime"
    },
    {
      "x": -117,
      "y": 6,
      "z": -84,
      "name": "Rock_Lime"
    },
    {
      "x": -117,
      "y": 7,
      "z": -84,
      "name": "Rock_Lime"
    },
    {
      "x": -117,
      "y": 8,
      "z": -84,
      "name": "Rock_Lime"
    },
    {
      "x": -117,
      "y": 9,
      "z": -84,
      "name": "Rock_Lime"
    },
    {
      "x": -117,
      "y": 10,
      "z": -84,
      "name": "Rock_Lime_Cobble"
    },
    {
      "x": -117,
      "y": 11,
      "z": -84,
      "name": "Soil_Gravel_Lime"
    },
    {
      "x": -117,
      "y": 12,
      "z": -84,
      "name": "Soil_Gravel_Lime"
    },
    {
      "x": -117,
      "y": 13,
      "z": -84,
      "name": "Soil_Gravel_Lime"
    },
    {
      "x": -117,
      "y": 14,
      "z": -84,
      "name": "Rock_Lime"
    },
    {
      "x": -117,
      "y": 15,
      "z": -84,
      "name": "Rock_Lime_Brick_Decorative"
    },
    {
      "x": -117,
      "y": 16,
      "z": -84,
      "name": "Soil_Clay_Lime"
    },
    {
      "x": -117,
      "y": 4,
      "z": -83,
      "name": "Rock_Lime"
    },
    {
      "x": -117,
      "y": 5,
      "z": -83,
      "name": "Rock_Lime_Cobble"
    },
    {
      "x": -117,
      "y": 6,
      "z": -83,
      "name": "Rock_Lime_Brick_Decorative"
    },
    {
      "x": -117,
      "y": 7,
      "z": -83,
      "name": "Rock_Lime_Cobble"
    },
    {
      "x": -117,
      "y": 8,
      "z": -83,
      "name": "Rock_Lime"
    },
    {
      "x": -117,
      "y": 9,
      "z": -83,
      "name": "Rock_Lime_Cobble"
    },
    {
      "x": -117,
      "y": 10,
      "z": -83,
      "name": "Soil_Gravel_Lime"
    },
    {
      "x": -117,
      "y": 11,
      "z": -83,
      "name": "Rock_Lime_Cobble"
    },
    {
      "x": -117,
      "y": 12,
      "z": -83,
      "name": "Rock_Lime"
    },
    {
      "x": -117,
      "y": 13,
      "z": -83,
      "name": "Soil_Gravel_Lime"
    },
    {
      "x": -117,
      "y": 14,
      "z": -83,
      "name": "Rock_Lime_Cobble"
    },
    {
      "x": -117,
      "y": 15,
      "z": -83,
      "name": "Rock_Lime_Brick_Decorative"
    },
    {
      "x": -117,
      "y": 16,
      "z": -83,
      "name": "Soil_Clay_Lime"
    },
    {
      "x": -117,
      "y": 4,
      "z": -82,
      "name": "Soil_Gravel_Lime"
    },
    {
      "x": -117,
      "y": 5,
      "z": -82,
      "name": "Soil_Gravel_Lime"
    },
    {
      "x": -117,
      "y": 6,
      "z": -82,
      "name": "Rock_Lime_Brick_Decorative"
    },
    {
      "x": -117,
      "y": 7,
      "z": -82,
      "name": "Rock_Lime_Brick_Decorative"
    },
    {
      "x": -117,
      "y": 8,
      "z": -82,
      "name": "Rock_Lime"
    },
    {
      "x": -117,
      "y": 9,
      "z": -82,
      "name": "Rock_Lime"
    },
    {
      "x": -117,
      "y": 10,
      "z": -82,
      "name": "Rock_Lime_Brick_Decorative"
    },
    {
      "x": -117,
      "y": 11,
      "z": -82,
      "name": "Soil_Gravel_Lime"
    },
    {
      "x": -117,
      "y": 12,
      "z": -82,
      "name": "Rock_Lime"
    },
    {
      "x": -117,
      "y": 13,
      "z": -82,
      "name": "Rock_Lime_Cobble"
    },
    {
      "x": -117,
      "y": 14,
      "z": -82,
      "name": "Rock_Lime_Brick_Decorative"
    },
    {
      "x": -117,
      "y": 15,
      "z": -82,
      "name": "Rock_Lime_Brick_Decorative"
    },
    {
      "x": -117,
      "y": 16,
      "z": -82,
      "name": "Plant_Coral_Block_Lime"
    },
    {
      "x": -117,
      "y": 5,
      "z": -81,
      "name": "Soil_Gravel_Lime"
    },
    {
      "x": -117,
      "y": 6,
      "z": -81,
      "name": "Rock_Lime_Cobble"
    },
    {
      "x": -117,
      "y": 7,
      "z": -81,
      "name": "Rock_Lime"
    },
    {
      "x": -117,
      "y": 8,
      "z": -81,
      "name": "Rock_Lime_Brick_Decorative"
    },
    {
      "x": -117,
      "y": 9,
      "z": -81,
      "name": "Rock_Lime"
    },
    {
      "x": -117,
      "y": 10,
      "z": -81,
      "name": "Rock_Lime"
    },
    {
      "x": -117,
      "y": 11,
      "z": -81,
      "name": "Soil_Gravel_Lime"
    },
    {
      "x": -117,
      "y": 12,
      "z": -81,
      "name": "Soil_Gravel_Lime"
    },
    {
      "x": -117,
      "y": 13,
      "z": -81,
      "name": "Rock_Lime_Brick_Decorative"
    },
    {
      "x": -117,
      "y": 14,
      "z": -81,
      "name": "Rock_Lime"
    },
    {
      "x": -117,
      "y": 15,
      "z": -81,
      "name": "Rock_Lime_Brick_Decorative"
    },
    {
      "x": -117,
      "y": 16,
      "z": -81,
      "name": "Soil_Clay_Lime"
    },
    {
      "x": -117,
      "y": 5,
      "z": -80,
      "name": "Rock_Lime"
    },
    {
      "x": -117,
      "y": 6,
      "z": -80,
      "name": "Soil_Gravel_Lime"
    },
    {
      "x": -117,
      "y": 7,
      "z": -80,
      "name": "Rock_Lime_Cobble"
    },
    {
      "x": -117,
      "y": 8,
      "z": -80,
      "name": "Rock_Lime"
    },
    {
      "x": -117,
      "y": 9,
      "z": -80,
      "name": "Rock_Lime_Brick_Decorative"
    },
    {
      "x": -117,
      "y": 10,
      "z": -80,
      "name": "Rock_Lime_Brick_Decorative"
    },
    {
      "x": -117,
      "y": 11,
      "z": -80,
      "name": "Rock_Lime_Cobble"
    },
    {
      "x": -117,
      "y": 12,
      "z": -80,
      "name": "Rock_Lime_Cobble"
    },
    {
      "x": -117,
      "y": 13,
      "z": -80,
      "name": "Rock_Lime"
    },
    {
      "x": -117,
      "y": 14,
      "z": -80,
      "name": "Rock_Lime_Brick_Decorative"
    },
    {
      "x": -117,
      "y": 15,
      "z": -80,
      "name": "Soil_Gravel_Lime"
    },
    {
      "x": -117,
      "y": 16,
      "z": -80,
      "name": "Plant_Coral_Block_Lime"
    },
    {
      "x": -117,
      "y": 6,
      "z": -79,
      "name": "Soil_Gravel_Lime"
    },
    {
      "x": -117,
      "y": 7,
      "z": -79,
      "name": "Rock_Lime"
    },
    {
      "x": -117,
      "y": 8,
      "z": -79,
      "name": "Rock_Lime_Brick_Decorative"
    },
    {
      "x": -117,
      "y": 9,
      "z": -79,
      "name": "Rock_Lime_Cobble"
    },
    {
      "x": -117,
      "y": 10,
      "z": -79,
      "name": "Rock_Lime_Cobble"
    },
    {
      "x": -117,
      "y": 11,
      "z": -79,
      "name": "Soil_Gravel_Lime"
    },
    {
      "x": -117,
      "y": 12,
      "z": -79,
      "name": "Rock_Lime_Brick_Decorative"
    },
    {
      "x": -117,
      "y": 13,
      "z": -79,
      "name": "Rock_Lime_Brick_Decorative"
    },
    {
      "x": -117,
      "y": 14,
      "z": -79,
      "name": "Rock_Lime_Brick_Decorative"
    },
    {
      "x": -117,
      "y": 15,
      "z": -79,
      "name": "Rock_Lime_Brick_Decorative"
    },
    {
      "x": -117,
      "y": 16,
      "z": -79,
      "name": "Plant_Coral_Block_Lime"
    },
    {
      "x": -117,
      "y": 5,
      "z": -78,
      "name": "Rock_Lime_Brick_Decorative"
    },
    {
      "x": -117,
      "y": 6,
      "z": -78,
      "name": "Soil_Gravel_Lime"
    },
    {
      "x": -117,
      "y": 7,
      "z": -78,
      "name": "Rock_Lime_Brick_Decorative"
    },
    {
      "x": -117,
      "y": 8,
