{
  "version": 8,
  "blockIdVersion": 11,
  "anchorX": -81,
  "anchorY": 16,
  "anchorZ": -84,
  "blocks": [
    {
      "x": -91,
      "y": 17,
      "z": -88,
      "name": "Plant_Leaves_Dead",
      "support": 15
    },
    {
      "x": -90,
      "y": 13,
      "z": -91,
      "name": "Rock_Lime"
    },
    {
      "x": -90,
      "y": 14,
      "z": -91,
      "name": "Rock_Lime"
    },
    {
      "x": -90,
      "y": 15,
      "z": -91,
      "name": "Rock_Lime"
    },
    {
      "x": -90,
      "y": 16,
      "z": -91,
      "name": "Rock_Lime"
    },
    {
      "x": -90,
      "y": 13,
      "z": -90,
      "name": "Rock_Lime"
    },
    {
      "x": -90,
      "y": 14,
      "z": -90,
      "name": "Rock_Lime"
    },
    {
      "x": -90,
      "y": 15,
      "z": -90,
      "name": "Rock_Lime"
    },
    {
      "x": -90,
      "y": 16,
      "z": -90,
      "name": "Soil_Gravel_Lime"
    },
    {
      "x": -90,
      "y": 17,
      "z": -90,
      "name": "Soil_Gravel_Lime"
    },
    {
      "x": -90,
      "y": 18,
      "z": -90,
      "name": "Rock_Lime"
    },
    {
      "x": -90,
      "y": 19,
      "z": -90,
      "name": "Rubble_Lime",
      "support": 15
    },
    {
      "x": -90,
      "y": 21,
      "z": -90,
      "name": "Plant_Leaves_Dead",
      "support": 15
    },
    {
      "x": -90,
      "y": 13,
      "z": -89,
      "name": "Rock_Lime"
    },
    {
      "x": -90,
      "y": 14,
      "z": -89,
      "name": "Rock_Lime"
    },
    {
      "x": -90,
      "y": 15,
      "z": -89,
      "name": "Rock_Lime"
    },
    {
      "x": -90,
      "y": 16,
      "z": -89,
      "name": "Rock_Lime"
    },
    {
      "x": -90,
      "y": 17,
      "z": -89,
      "name": "Rock_Lime"
    },
    {
      "x": -90,
      "y": 18,
      "z": -89,
      "name": "Soil_Gravel_Lime"
    },
    {
      "x": -90,
      "y": 19,
      "z": -89,
      "name": "Rock_Lime"
    },
    {
      "x": -90,
      "y": 20,
      "z": -89,
      "name": "Rubble_Lime_Medium",
      "support": 15
    },
    {
      "x": -90,
      "y": 13,
      "z": -88,
      "name": "Rock_Lime"
    },
    {
      "x": -90,
      "y": 14,
      "z": -88,
      "name": "Rock_Lime"
    },
    {
      "x": -90,
      "y": 15,
      "z": -88,
      "name": "Rock_Lime"
    },
    {
      "x": -90,
      "y": 16,
      "z": -88,
      "name": "Rock_Lime"
    },
    {
      "x": -90,
      "y": 17,
      "z": -88,
      "name": "Soil_Gravel_Lime"
    },
    {
      "x": -90,
      "y": 18,
      "z": -88,
      "name": "Soil_Gravel_Lime"
    },
    {
      "x": -90,
      "y": 19,
      "z": -88,
      "name": "Rock_Lime"
    },
    {
      "x": -90,
      "y": 20,
      "z": -88,
      "name": "Rock_Lime_Stalactite_Large"
    },
    {
      "x": -90,
      "y": 21,
      "z": -88,
      "name": "Rock_Lime_Stalactite_Large",
      "filler": 1024
    },
    {
      "x": -90,
      "y": 14,
      "z": -87,
      "name": "Rock_Lime"
    },
    {
      "x": -90,
      "y": 15,
      "z": -87,
      "name": "Rock_Lime"
    },
    {
      "x": -90,
      "y": 16,
      "z": -87,
      "name": "Rock_Lime"
    },
    {
      "x": -90,
      "y": 17,
      "z": -87,
      "name": "Rock_Lime"
    },
    {
      "x": -90,
      "y": 18,
      "z": -87,
      "name": "Rock_Lime"
    },
    {
      "x": -90,
      "y": 15,
      "z": -86,
      "name": "Soil_Gravel_Lime"
    },
    {
      "x": -90,
      "y": 16,
      "z": -86,
      "name": "Soil_Gravel_Lime"
    },
    {
      "x": -90,
      "y": 17,
      "z": -86,
      "name": "Rock_Lime"
    },
    {
      "x": -89,
      "y": 12,
      "z": -93,
      "name": "Soil_Gravel_Lime"
    },
    {
      "x": -89,
      "y": 13,
      "z": -93,
      "name": "Soil_Gravel_Lime"
    },
    {
      "x": -89,
      "y": 14,
      "z": -93,
      "name": "Rock_Lime"
    },
    {
      "x": -89,
      "y": 15,
      "z": -93,
      "name": "Rock_Lime"
    },
    {
      "x": -89,
      "y": 16,
      "z": -93,
      "name": "Rock_Lime"
    },
    {
      "x": -89,
      "y": 17,
      "z": -93,
      "name": "Rock_Lime"
    },
    {
      "x": -89,
      "y": 18,
      "z": -93,
      "name": "Rock_Lime_Stalactite_Large"
    },
    {
      "x": -89,
      "y": 19,
      "z": -93,
      "name": "Rock_Lime_Stalactite_Large",
      "filler": 1024
    },
    {
      "x": -89,
      "y": 6,
      "z": -92,
      "name": "Soil_Gravel_Lime"
    },
    {
      "x": -89,
      "y": 7,
      "z": -92,
      "name": "Soil_Gravel_Lime"
    },
    {
      "x": -89,
      "y": 8,
      "z": -92,
      "name": "Soil_Gravel_Lime"
    },
    {
      "x": -89,
      "y": 9,
      "z": -92,
      "name": "Rock_Lime"
    },
    {
      "x": -89,
      "y": 10,
      "z": -92,
      "name": "Rock_Lime"
    },
    {
      "x": -89,
      "y": 11,
      "z": -92,
      "name": "Rock_Lime"
    },
    {
      "x": -89,
      "y": 12,
      "z": -92,
      "name": "Soil_Gravel_Lime"
    },
    {
      "x": -89,
      "y": 13,
      "z": -92,
      "name": "Soil_Gravel_Lime"
    },
    {
      "x": -89,
      "y": 14,
      "z": -92,
      "name": "Rock_Lime"
    },
    {
      "x": -89,
      "y": 15,
      "z": -92,
      "name": "Rock_Lime"
    },
    {
      "x": -89,
      "y": 16,
      "z": -92,
      "name": "Soil_Gravel_Lime"
    },
    {
      "x": -89,
      "y": 17,
      "z": -92,
      "name": "Rock_Lime"
    },
    {
      "x": -89,
      "y": 18,
      "z": -92,
      "name": "Rock_Lime"
    },
    {
      "x": -89,
      "y": 19,
      "z": -92,
      "name": "Rock_Lime"
    },
    {
      "x": -89,
      "y": 20,
      "z": -92,
      "name": "Plant_Crop_Mushroom_Cap_Poison",
      "components": {
        "Components": {
          "FarmingBlock": {
            "LastTickGameTime": "0001-01-01T12:00:00Z"
          },
          "PlacedByInteraction": {
            "WhoPlacedUuid": {
              "$binary": "HCpUQzdeSaiDYHpoRePv+w==",
              "$type": "04"
            }
          }
        }
      }
    },
    {
      "x": -89,
      "y": 5,
      "z": -91,
      "name": "Rock_Lime"
    },
    {
      "x": -89,
      "y": 6,
      "z": -91,
      "name": "Soil_Gravel_Lime"
    },
    {
      "x": -89,
      "y": 7,
      "z": -91,
      "name": "Rock_Lime"
    },
    {
      "x": -89,
      "y": 8,
      "z": -91,
      "name": "Soil_Gravel_Lime"
    },
    {
      "x": -89,
      "y": 9,
      "z": -91,
      "name": "Soil_Gravel_Lime"
    },
    {
      "x": -89,
      "y": 10,
      "z": -91,
      "name": "Rock_Lime"
    },
    {
      "x": -89,
      "y": 11,
      "z": -91,
      "name": "Rock_Lime"
    },
    {
      "x": -89,
      "y": 12,
      "z": -91,
      "name": "Soil_Gravel_Lime"
    },
    {
      "x": -89,
      "y": 13,
      "z": -91,
      "name": "Soil_Gravel_Lime"
    },
    {
      "x": -89,
      "y": 14,
      "z": -91,
      "name": "Soil_Gravel_Lime"
    },
    {
      "x": -89,
      "y": 15,
      "z": -91,
      "name": "Rock_Lime"
    },
    {
      "x": -89,
      "y": 16,
      "z": -91,
      "name": "Rock_Lime"
    },
    {
      "x": -89,
      "y": 17,
      "z": -91,
      "name": "Rock_Lime"
    },
    {
      "x": -89,
      "y": 18,
      "z": -91,
      "name": "Rock_Lime"
    },
    {
      "x": -89,
      "y": 19,
      "z": -91,
      "name": "Rock_Lime"
    },
    {
      "x": -89,
      "y": 20,
      "z": -91,
      "name": "Soil_Gravel_Lime"
    },
    {
      "x": -89,
      "y": 21,
      "z": -91,
      "name": "Rock_Lime"
    },
    {
      "x": -89,
      "y": 22,
      "z": -91,
      "name": "Rock_Lime_Stalactite_Large"
    },
    {
      "x": -89,
      "y": 23,
      "z": -91,
      "name": "Rock_Lime_Stalactite_Large",
      "filler": 1024
    },
    {
      "x": -89,
      "y": 5,
      "z": -90,
      "name": "Soil_Gravel_Lime"
    },
    {
      "x": -89,
      "y": 6,
      "z": -90,
      "name": "Rock_Lime"
    },
    {
      "x": -89,
      "y": 7,
      "z": -90,
      "name": "Rock_Lime"
    },
    {
      "x": -89,
      "y": 8,
      "z": -90,
      "name": "Rock_Lime"
    },
    {
      "x": -89,
      "y": 9,
      "z": -90,
      "name": "Soil_Gravel_Lime"
    },
    {
      "x": -89,
      "y": 10,
      "z": -90,
      "name": "Rock_Lime"
    },
    {
      "x": -89,
      "y": 11,
      "z": -90,
      "name": "Soil_Gravel_Lime"
    },
    {
      "x": -89,
      "y": 12,
      "z": -90,
      "name": "Rock_Lime"
    },
    {
      "x": -89,
      "y": 13,
      "z": -90,
      "name": "Rock_Lime"
    },
    {
      "x": -89,
      "y": 14,
      "z": -90,
      "name": "Soil_Gravel_Lime"
    },
    {
      "x": -89,
      "y": 15,
      "z": -90,
      "name": "Rock_Lime"
    },
    {
      "x": -89,
      "y": 16,
      "z": -90,
      "name": "Rock_Lime"
    },
    {
      "x": -89,
      "y": 17,
      "z": -90,
      "name": "Rock_Lime"
    },
    {
      "x": -89,
      "y": 18,
      "z": -90,
      "name": "Soil_Gravel_Lime"
    },
    {
      "x": -89,
      "y": 19,
      "z": -90,
      "name": "Rock_Lime"
    },
    {
      "x": -89,
      "y": 20,
      "z": -90,
      "name": "Soil_Gravel_Lime"
    },
    {
      "x": -89,
      "y": 21,
      "z": -90,
      "name": "Soil_Gravel_Lime"
    },
    {
      "x": -89,
      "y": 22,
      "z": -90,
      "name": "Soil_Gravel_Lime"
    },
    {
      "x": -89,
      "y": 5,
      "z": -89,
      "name": "Soil_Gravel_Lime"
    },
    {
      "x": -89,
      "y": 6,
      "z": -89,
      "name": "Soil_Gravel_Lime"
    },
    {
      "x": -89,
      "y": 7,
      "z": -89,
      "name": "Soil_Gravel_Lime"
    },
    {
      "x": -89,
      "y": 8,
      "z": -89,
      "name": "Soil_Gravel_Lime"
    },
    {
      "x": -89,
      "y": 9,
      "z": -89,
      "name": "Rock_Lime"
    },
    {
      "x": -89,
      "y": 10,
      "z": -89,
      "name": "Rock_Lime"
    },
    {
      "x": -89,
      "y": 11,
      "z": -89,
      "name": "Rock_Lime"
    },
    {
      "x": -89,
      "y": 12,
      "z": -89,
      "name": "Rock_Lime"
    },
    {
      "x": -89,
      "y": 13,
      "z": -89,
      "name": "Rock_Lime"
    },
    {
      "x": -89,
      "y": 14,
      "z": -89,
      "name": "Soil_Gravel_Lime"
    },
    {
      "x": -89,
      "y": 15,
      "z": -89,
      "name": "Rock_Lime"
    },
    {
      "x": -89,
      "y": 16,
      "z": -89,
      "name": "Rock_Lime"
    },
    {
      "x": -89,
      "y": 17,
      "z": -89,
      "name": "Rock_Lime"
    },
    {
      "x": -89,
      "y": 18,
      "z": -89,
      "name": "Rock_Lime"
    },
    {
      "x": -89,
      "y": 19,
      "z": -89,
      "name": "Rock_Lime"
    },
    {
      "x": -89,
      "y": 20,
      "z": -89,
      "name": "Rock_Lime"
    },
    {
      "x": -89,
      "y": 21,
      "z": -89,
      "name": "Soil_Gravel_Lime"
    },
    {
      "x": -89,
      "y": 22,
      "z": -89,
      "name": "Rock_Lime"
    },
    {
      "x": -89,
      "y": 23,
      "z": -89,
      "name": "Rock_Lime"
    },
    {
      "x": -89,
      "y": 24,
      "z": -89,
      "name": "Plant_Crop_Mushroom_Cap_Poison",
      "components": {
        "Components": {
          "FarmingBlock": {
            "LastTickGameTime": "0001-01-01T12:00:00Z"
          },
          "PlacedByInteraction": {
            "WhoPlacedUuid": {
              "$binary": "HCpUQzdeSaiDYHpoRePv+w==",
              "$type": "04"
            }
          }
        }
      }
    },
    {
      "x": -89,
      "y": 5,
      "z": -88,
      "name": "Rock_Lime"
    },
    {
      "x": -89,
      "y": 6,
      "z": -88,
      "name": "Soil_Gravel_Lime"
    },
    {
      "x": -89,
      "y": 7,
      "z": -88,
      "name": "Rock_Lime"
    },
    {
      "x": -89,
      "y": 8,
      "z": -88,
      "name": "Rock_Lime"
    },
    {
      "x": -89,
      "y": 9,
      "z": -88,
      "name": "Soil_Gravel_Lime"
    },
    {
      "x": -89,
      "y": 10,
      "z": -88,
      "name": "Rock_Lime"
    },
    {
      "x": -89,
      "y": 11,
      "z": -88,
      "name": "Rock_Lime"
    },
    {
      "x": -89,
      "y": 12,
      "z": -88,
      "name": "Rock_Lime"
    },
    {
      "x": -89,
      "y": 13,
      "z": -88,
      "name": "Rock_Lime"
    },
    {
      "x": -89,
      "y": 14,
      "z": -88,
      "name": "Soil_Gravel_Lime"
    },
    {
      "x": -89,
      "y": 15,
      "z": -88,
      "name": "Rock_Lime"
    },
    {
      "x": -89,
      "y": 16,
      "z": -88,
      "name": "Soil_Gravel_Lime"
    },
    {
      "x": -89,
      "y": 17,
      "z": -88,
      "name": "Rock_Lime"
    },
    {
      "x": -89,
      "y": 18,
      "z": -88,
      "name": "Soil_Gravel_Lime"
    },
    {
      "x": -89,
      "y": 19,
      "z": -88,
      "name": "Soil_Gravel_Lime"
    },
    {
      "x": -89,
      "y": 20,
      "z": -88,
      "name": "Rock_Lime"
    },
    {
      "x": -89,
      "y": 21,
      "z": -88,
      "name": "Rock_Lime"
    },
    {
      "x": -89,
      "y": 22,
      "z": -88,
      "name": "Rock_Lime"
    },
    {
      "x": -89,
      "y": 23,
      "z": -88,
      "name": "Rock_Lime"
    },
    {
      "x": -89,
      "y": 24,
      "z": -88,
      "name": "Rock_Lime"
    },
    {
      "x": -89,
      "y": 25,
      "z": -88,
      "name": "Rock_Lime"
    },
    {
      "x": -89,
      "y": 26,
      "z": -88,
      "name": "Rubble_Lime_Medium",
      "support": 15
    },
    {
      "x": -89,
      "y": 6,
      "z": -87,
      "name": "Soil_Gravel_Lime"
    },
    {
      "x": -89,
      "y": 7,
      "z": -87,
      "name": "Rock_Lime"
    },
    {
      "x": -89,
      "y": 8,
      "z": -87,
      "name": "Soil_Gravel_Lime"
    },
    {
      "x": -89,
      "y": 9,
      "z": -87,
      "name": "Soil_Gravel_Lime"
    },
    {
      "x": -89,
      "y": 10,
      "z": -87,
      "name": "Soil_Gravel_Lime"
    },
    {
      "x": -89,
      "y": 11,
      "z": -87,
      "name": "Rock_Lime"
    },
    {
      "x": -89,
      "y": 12,
      "z": -87,
      "name": "Rock_Lime"
    },
    {
      "x": -89,
      "y": 13,
      "z": -87,
      "name": "Soil_Gravel_Lime"
    },
    {
      "x": -89,
      "y": 14,
      "z": -87,
      "name": "Rock_Lime"
    },
    {
      "x": -89,
      "y": 15,
      "z": -87,
      "name": "Soil_Gravel_Lime"
    },
    {
      "x": -89,
      "y": 16,
      "z": -87,
      "name": "Rock_Lime"
    },
    {
      "x": -89,
      "y": 17,
      "z": -87,
      "name": "Rock_Lime"
    },
    {
      "x": -89,
      "y": 18,
      "z": -87,
      "name": "Rock_Lime"
    },
    {
      "x": -89,
      "y": 19,
      "z": -87,
      "name": "Soil_Gravel_Lime"
    },
    {
      "x": -89,
      "y": 20,
      "z": -87,
      "name": "Soil_Gravel_Lime"
    },
    {
      "x": -89,
      "y": 21,
      "z": -87,
      "name": "Rock_Lime"
    },
    {
      "x": -89,
      "y": 22,
      "z": -87,
      "name": "Rock_Lime"
    },
    {
      "x": -89,
      "y": 23,
      "z": -87,
      "name": "Rock_Lime"
    },
    {
      "x": -89,
      "y": 24,
      "z": -87,
      "name": "Rock_Lime"
    },
    {
      "x": -89,
      "y": 25,
      "z": -87,
      "name": "Soil_Gravel_Lime"
    },
    {
      "x": -89,
      "y": 6,
      "z": -86,
      "name": "Rock_Lime"
    },
    {
      "x": -89,
      "y": 7,
      "z": -86,
      "name": "Soil_Gravel_Lime"
    },
    {
      "x": -89,
      "y": 8,
      "z": -86,
      "name": "Rock_Lime"
    },
    {
      "x": -89,
      "y": 9,
      "z": -86,
      "name": "Soil_Gravel_Lime"
    },
    {
      "x": -89,
      "y": 10,
      "z": -86,
      "name": "Rock_Lime"
    },
    {
      "x": -89,
      "y": 11,
      "z": -86,
      "name": "Soil_Gravel_Lime"
    },
    {
      "x": -89,
      "y": 12,
      "z": -86,
      "name": "Soil_Gravel_Lime"
    },
    {
      "x": -89,
      "y": 13,
      "z": -86,
      "name": "Soil_Gravel_Lime"
    },
    {
      "x": -89,
      "y": 14,
      "z": -86,
      "name": "Rock_Lime"
    },
    {
      "x": -89,
      "y": 15,
      "z": -86,
      "name": "Soil_Gravel_Lime"
    },
    {
      "x": -89,
      "y": 16,
      "z": -86,
      "name": "Soil_Gravel_Lime"
    },
    {
      "x": -89,
      "y": 17,
      "z": -86,
      "name": "Rock_Lime"
    },
    {
      "x": -89,
      "y": 18,
      "z": -86,
      "name": "Soil_Gravel_Lime"
    },
    {
      "x": -89,
      "y": 19,
      "z": -86,
      "name": "Soil_Gravel_Lime"
    },
    {
      "x": -89,
      "y": 20,
      "z": -86,
      "name": "Rock_Lime"
    },
    {
      "x": -89,
      "y": 21,
      "z": -86,
      "name": "Rock_Lime"
    },
    {
      "x": -89,
      "y": 22,
      "z": -86,
      "name": "Soil_Gravel_Lime"
    },
    {
      "x": -89,
      "y": 23,
      "z": -86,
      "name": "Rock_Lime"
    },
    {
      "x": -89,
      "y": 6,
      "z": -85,
      "name": "Rock_Lime"
    },
    {
      "x": -89,
      "y": 7,
      "z": -85,
      "name": "Rock_Lime"
    },
    {
      "x": -89,
      "y": 8,
      "z": -85,
      "name": "Rock_Lime"
    },
    {
      "x": -89,
      "y": 9,
      "z": -85,
      "name": "Rock_Lime"
    },
    {
      "x": -89,
      "y": 10,
      "z": -85,
      "name": "Rock_Lime"
    },
    {
      "x": -89,
      "y": 11,
      "z": -85,
      "name": "Soil_Gravel_Lime"
    },
    {
      "x": -89,
      "y": 12,
      "z": -85,
      "name": "Soil_Gravel_Lime"
    },
    {
      "x": -89,
      "y": 13,
      "z": -85,
      "name": "Soil_Gravel_Lime"
    },
    {
      "x": -89,
      "y": 14,
      "z": -85,
      "name": "Rock_Lime"
    },
    {
      "x": -89,
      "y": 15,
      "z": -85,
      "name": "Rock_Lime"
    },
    {
      "x": -89,
      "y": 16,
      "z": -85,
      "name": "Rock_Lime"
    },
    {
      "x": -89,
      "y": 17,
      "z": -85,
      "name": "Rock_Lime"
    },
    {
      "x": -89,
      "y": 18,
      "z": -85,
      "name": "Rock_Lime"
    },
    {
      "x": -89,
      "y": 19,
      "z": -85,
      "name": "Rock_Lime"
    },
    {
      "x": -89,
      "y": 20,
      "z": -85,
      "name": "Rock_Lime"
    },
    {
      "x": -89,
      "y": 21,
      "z": -85,
      "name": "Rock_Lime"
    },
    {
      "x": -89,
      "y": 22,
      "z": -85,
      "name": "Rubble_Lime_Medium",
      "support": 15
    },
    {
      "x": -89,
      "y": 6,
      "z": -84,
      "name": "Rock_Lime"
    },
    {
      "x": -89,
      "y": 7,
      "z": -84,
      "name": "Rock_Lime"
    },
    {
      "x": -89,
      "y": 8,
      "z": -84,
      "name": "Rock_Lime"
    },
    {
      "x": -89,
      "y": 9,
      "z": -84,
      "name": "Soil_Gravel_Lime"
    },
    {
      "x": -89,
      "y": 10,
      "z": -84,
      "name": "Soil_Gravel_Lime"
    },
    {
      "x": -89,
      "y": 11,
      "z": -84,
      "name": "Rock_Lime"
    },
    {
      "x": -89,
      "y": 12,
      "z": -84,
      "name": "Rock_Lime"
    },
    {
      "x": -89,
      "y": 13,
      "z": -84,
      "name": "Soil_Gravel_Lime"
    },
    {
      "x": -89,
      "y": 14,
      "z": -84,
      "name": "Soil_Gravel_Lime"
    },
    {
      "x": -89,
      "y": 15,
      "z": -84,
      "name": "Rock_Lime"
    },
    {
      "x": -89,
      "y": 16,
      "z": -84,
      "name": "Soil_Gravel_Lime"
    },
    {
      "x": -89,
      "y": 17,
      "z": -84,
      "name": "Soil_Gravel_Lime"
    },
    {
      "x": -89,
      "y": 5,
      "z": -83,
      "name": "Soil_Gravel_Lime"
    },
    {
      "x": -89,
      "y": 6,
      "z": -83,
      "name": "Rock_Lime"
    },
    {
      "x": -89,
      "y": 7,
      "z": -83,
      "name": "Rock_Lime"
    },
    {
      "x": -89,
      "y": 8,
      "z": -83,
      "name": "Rock_Lime"
    },
    {
      "x": -89,
      "y": 9,
      "z": -83,
      "name": "Rock_Lime"
    },
    {
      "x": -89,
      "y": 10,
      "z": -83,
      "name": "Soil_Gravel_Lime"
    },
    {
      "x": -89,
      "y": 11,
      "z": -83,
      "name": "Rock_Lime"
    },
    {
      "x": -89,
      "y": 12,
      "z": -83,
      "name": "Rock_Lime"
    },
    {
      "x": -89,
      "y": 13,
      "z": -83,
      "name": "Rubble_Lime",
      "support": 15
    },
    {
      "x": -89,
      "y": 15,
      "z": -83,
      "name": "Plant_Leaves_Dead",
      "support": 15
    },
    {
      "x": -89,
      "y": 20,
      "z": -83,
      "name": "Plant_Leaves_Dead",
      "support": 15
    },
    {
      "x": -89,
      "y": 6,
      "z": -82,
      "name": "Rock_Lime"
    },
    {
      "x": -89,
      "y": 7,
      "z": -82,
      "name": "Rock_Lime"
    },
    {
      "x": -89,
      "y": 8,
      "z": -82,
      "name": "Soil_Gravel_Lime"
    },
    {
      "x": -89,
      "y": 9,
      "z": -82,
      "name": "Soil_Gravel_Lime"
    },
    {
      "x": -89,
      "y": 10,
      "z": -82,
      "name": "Rock_Lime"
    },
    {
      "x": -88,
      "y": 18,
      "z": -94,
      "name": "Plant_Leaves_Dead",
      "support": 15
    },
    {
      "x": -88,
      "y": 5,
      "z": -93,
      "name": "Soil_Gravel_Lime"
    },
    {
      "x": -88,
      "y": 6,
      "z": -93,
      "name": "Rock_Lime"
    },
    {
      "x": -88,
      "y": 7,
      "z": -93,
      "name": "Soil_Gravel_Lime"
    },
    {
      "x": -88,
      "y": 8,
      "z": -93,
      "name": "Rock_Lime"
    },
    {
      "x": -88,
      "y": 9,
      "z": -93,
      "name": "Rock_Lime"
    },
    {
      "x": -88,
      "y": 10,
      "z": -93,
      "name": "Soil_Gravel_Lime"
    },
    {
      "x": -88,
      "y": 11,
      "z": -93,
      "name": "Rock_Lime"
    },
    {
      "x": -88,
      "y": 12,
      "z": -93,
      "name": "Rock_Lime"
    },
    {
      "x": -88,
      "y": 13,
      "z": -93,
      "name": "Rock_Lime"
    },
    {
      "x": -88,
      "y": 14,
      "z": -93,
      "name": "Rock_Lime"
    },
    {
      "x": -88,
      "y": 15,
      "z": -93,
      "name": "Soil_Gravel_Lime"
    },
    {
      "x": -88,
      "y": 16,
      "z": -93,
      "name": "Soil_Gravel_Lime"
    },
    {
      "x": -88,
      "y": 17,
      "z": -93,
      "name": "Rock_Lime"
    },
    {
      "x": -88,
      "y": 18,
      "z": -93,
      "name": "Rock_Lime"
    },
    {
      "x": -88,
      "y": 19,
      "z": -93,
      "name": "Soil_Gravel_Lime"
    },
    {
      "x": -88,
      "y": 5,
      "z": -92,
      "name": "Soil_Gravel_Lime"
    },
    {
      "x": -88,
      "y": 6,
      "z": -92,
      "name": "Rock_Lime"
    },
    {
      "x": -88,
      "y": 7,
      "z": -92,
      "name": "Soil_Gravel_Lime"
    },
    {
      "x": -88,
      "y": 8,
      "z": -92,
      "name": "Rock_Lime"
    },
    {
      "x": -88,
      "y": 9,
      "z": -92,
      "name": "Rock_Lime"
    },
    {
      "x": -88,
      "y": 10,
      "z": -92,
      "name": "Rock_Lime"
    },
    {
      "x": -88,
      "y": 11,
      "z": -92,
      "name": "Rock_Lime"
    },
    {
      "x": -88,
      "y": 12,
      "z": -92,
      "name": "Rock_Lime"
    },
    {
      "x": -88,
      "y": 13,
      "z": -92,
      "name": "Rock_Lime"
    },
    {
      "x": -88,
      "y": 14,
      "z": -92,
      "name": "Rock_Lime"
    },
    {
      "x": -88,
      "y": 15,
      "z": -92,
      "name": "Soil_Gravel_Lime"
    },
    {
      "x": -88,
      "y": 16,
      "z": -92,
      "name": "Rock_Lime"
    },
    {
      "x": -88,
      "y": 17,
      "z": -92,
      "name": "Rock_Lime"
    },
    {
      "x": -88,
      "y": 18,
      "z": -92,
      "name": "Soil_Gravel_Lime"
    },
    {
      "x": -88,
      "y": 19,
      "z": -92,
      "name": "Rock_Lime"
    },
    {
      "x": -88,
      "y": 20,
      "z": -92,
      "name": "Rock_Lime"
    },
    {
      "x": -88,
      "y": 21,
      "z": -92,
      "name": "Rock_Lime"
    },
    {
      "x": -88,
      "y": 22,
      "z": -92,
      "name": "Rubble_Lime_Medium",
      "support": 15
    },
    {
      "x": -88,
      "y": 24,
      "z": -92,
      "name": "Plant_Leaves_Dead",
      "support": 15
    },
    {
      "x": -88,
      "y": 4,
      "z": -91,
      "name": "Rock_Lime"
    },
    {
      "x": -88,
      "y": 5,
      "z": -91,
      "name": "Soil_Gravel_Lime"
    },
    {
      "x": -88,
      "y": 6,
      "z": -91,
      "name": "Soil_Gravel_Lime"
    },
    {
      "x": -88,
      "y": 7,
      "z": -91,
      "name": "Rock_Lime"
    },
    {
      "x": -88,
      "y": 8,
      "z": -91,
      "name": "Rock_Lime"
    },
    {
      "x": -88,
      "y": 9,
      "z": -91,
      "name": "Rock_Lime"
    },
    {
      "x": -88,
      "y": 10,
      "z": -91,
      "name": "Soil_Gravel_Lime"
    },
    {
      "x": -88,
      "y": 11,
      "z": -91,
      "name": "Rock_Lime"
    },
    {
      "x": -88,
      "y": 12,
      "z": -91,
      "name": "Rock_Lime"
    },
    {
      "x": -88,
      "y": 13,
      "z": -91,
      "name": "Soil_Gravel_Lime"
    },
    {
      "x": -88,
      "y": 14,
      "z": -91,
      "name": "Soil_Gravel_Lime"
    },
    {
      "x": -88,
      "y": 15,
      "z": -91,
      "name": "Soil_Gravel_Lime"
    },
    {
      "x": -88,
      "y": 16,
      "z": -91,
      "name": "Soil_Gravel_Lime"
    },
    {
      "x": -88,
      "y": 17,
      "z": -91,
      "name": "Rock_Lime"
    },
    {
      "x": -88,
      "y": 18,
      "z": -91,
      "name": "Rock_Lime"
    },
    {
      "x": -88,
      "y": 19,
      "z": -91,
      "name": "Soil_Gravel_Lime"
    },
    {
      "x": -88,
      "y": 20,
      "z": -91,
      "name": "Rock_Lime"
    },
    {
      "x": -88,
      "y": 21,
      "z": -91,
      "name": "Rock_Lime"
    },
    {
      "x": -88,
      "y": 22,
      "z": -91,
      "name": "Soil_Gravel_Lime"
    },
    {
      "x": -88,
      "y": 23,
      "z": -91,
      "name": "Soil_Gravel_Lime"
    },
    {
      "x": -88,
      "y": 4,
      "z": -90,
      "name": "Soil_Gravel_Lime"
    },
    {
      "x": -88,
      "y": 5,
      "z": -90,
      "name": "Soil_Gravel_Lime"
    },
    {
      "x": -88,
      "y": 6,
      "z": -90,
      "name": "Rock_Lime"
    },
    {
      "x": -88,
      "y": 7,
      "z": -90,
      "name": "Soil_Gravel_Lime"
    },
    {
      "x": -88,
      "y": 8,
      "z": -90,
      "name": "Soil_Gravel_Lime"
    },
    {
      "x": -88,
      "y": 9,
      "z": -90,
      "name": "Soil_Gravel_Lime"
    },
    {
      "x": -88,
      "y": 10,
      "z": -90,
      "name": "Rock_Lime"
    },
    {
      "x": -88,
      "y": 11,
      "z": -90,
      "name": "Soil_Gravel_Lime"
    },
    {
      "x": -88,
      "y": 12,
      "z": -90,
      "name": "Rock_Lime"
    },
    {
      "x": -88,
      "y": 13,
      "z": -90,
      "name": "Rock_Lime"
    },
    {
      "x": -88,
      "y": 14,
      "z": -90,
      "name": "Rock_Lime"
    },
    {
      "x": -88,
      "y": 15,
      "z": -90,
      "name": "Soil_Gravel_Lime"
    },
    {
      "x": -88,
      "y": 16,
      "z": -90,
      "name": "Rock_Lime"
    },
    {
      "x": -88,
      "y": 17,
      "z": -90,
      "name": "Rock_Lime"
    },
    {
      "x": -88,
      "y": 18,
      "z": -90,
      "name": "Soil_Gravel_Lime"
    },
    {
      "x": -88,
      "y": 19,
      "z": -90,
      "name": "Soil_Gravel_Lime"
    },
    {
      "x": -88,
      "y": 20,
      "z": -90,
      "name": "Soil_Gravel_Lime"
    },
    {
      "x": -88,
      "y": 21,
      "z": -90,
      "name": "Rock_Lime"
    },
    {
      "x": -88,
      "y": 22,
      "z": -90,
      "name": "Rock_Lime"
    },
    {
      "x": -88,
      "y": 23,
      "z": -90,
      "name": "Soil_Gravel_Lime"
    },
    {
      "x": -88,
      "y": 24,
      "z": -90,
      "name": "Soil_Gravel_Lime"
    },
    {
      "x": -88,
      "y": 25,
      "z": -90,
      "name": "Soil_Gravel_Lime"
    },
    {
      "x": -88,
      "y": 26,
      "z": -90,
      "name": "Soil_Gravel_Lime"
    },
    {
      "x": -88,
      "y": 4,
      "z": -89,
      "name": "Rock_Lime"
    },
    {
      "x": -88,
      "y": 5,
      "z": -89,
      "name": "Rock_Lime"
    },
    {
      "x": -88,
      "y": 6,
      "z": -89,
      "name": "Rock_Lime"
    },
    {
      "x": -88,
      "y": 7,
      "z": -89,
      "name": "Rock_Lime"
    },
    {
      "x": -88,
      "y": 8,
      "z": -89,
      "name": "Rock_Lime"
    },
    {
      "x": -88,
      "y": 9,
      "z": -89,
      "name": "Rock_Lime"
    },
    {
      "x": -88,
      "y": 10,
      "z": -89,
      "name": "Soil_Gravel_Lime"
    },
    {
      "x": -88,
      "y": 11,
      "z": -89,
      "name": "Soil_Gravel_Lime"
    },
    {
      "x": -88,
      "y": 12,
      "z": -89,
      "name": "Rock_Lime"
    },
    {
      "x": -88,
      "y": 13,
      "z": -89,
      "name": "Rock_Lime"
    },
    {
      "x": -88,
      "y": 14,
      "z": -89,
      "name": "Soil_Gravel_Lime"
    },
    {
      "x": -88,
      "y": 15,
      "z": -89,
      "name": "Soil_Gravel_Lime"
    },
    {
      "x": -88,
      "y": 16,
      "z": -89,
      "name": "Rock_Lime"
    },
    {
      "x": -88,
      "y": 17,
      "z": -89,
      "name": "Soil_Gravel_Lime"
    },
    {
      "x": -88,
      "y": 18,
      "z": -89,
      "name": "Rock_Lime"
    },
    {
      "x": -88,
      "y": 19,
      "z": -89,
      "name": "Rock_Lime"
    },
    {
      "x": -88,
      "y": 20,
      "z": -89,
      "name": "Rock_Lime"
    },
    {
      "x": -88,
      "y": 21,
      "z": -89,
      "name": "Rock_Lime"
    },
    {
      "x": -88,
      "y": 22,
      "z": -89,
      "name": "Soil_Gravel_Lime"
    },
    {
      "x": -88,
      "y": 23,
      "z": -89,
      "name": "Rock_Lime"
    },
    {
      "x": -88,
      "y": 24,
      "z": -89,
      "name": "Rock_Lime"
    },
    {
      "x": -88,
      "y": 25,
      "z": -89,
      "name": "Rock_Lime"
    },
    {
      "x": -88,
      "y": 26,
      "z": -89,
      "name": "Rock_Lime"
    },
    {
      "x": -88,
      "y": 27,
      "z": -89,
      "name": "Rock_Lime"
    },
    {
      "x": -88,
      "y": 28,
      "z": -89,
      "name": "Plant_Coral_Block_Lime"
    },
    {
      "x": -88,
      "y": 4,
      "z": -88,
      "name": "Rock_Lime"
    },
    {
      "x": -88,
      "y": 5,
      "z": -88,
      "name": "Rock_Lime"
    },
    {
      "x": -88,
      "y": 6,
      "z": -88,
      "name": "Rock_Lime"
    },
    {
      "x": -88,
      "y": 7,
      "z": -88,
      "name": "Soil_Gravel_Lime"
    },
    {
      "x": -88,
      "y": 8,
      "z": -88,
      "name": "Rock_Lime"
    },
    {
      "x": -88,
      "y": 9,
      "z": -88,
      "name": "Soil_Gravel_Lime"
    },
    {
      "x": -88,
      "y": 10,
      "z": -88,
      "name": "Rock_Lime"
    },
    {
      "x": -88,
      "y": 11,
      "z": -88,
      "name": "Rock_Lime"
    },
    {
      "x": -88,
      "y": 12,
      "z": -88,
      "name": "Soil_Gravel_Lime"
    },
    {
      "x": -88,
      "y": 13,
      "z": -88,
      "name": "Soil_Gravel_Lime"
    },
    {
      "x": -88,
      "y": 14,
      "z": -88,
      "name": "Rock_Lime"
    },
    {
      "x": -88,
      "y": 15,
      "z": -88,
      "name": "Soil_Gravel_Lime"
    },
    {
      "x": -88,
      "y": 16,
      "z": -88,
      "name": "Soil_Gravel_Lime"
    },
    {
      "x": -88,
      "y": 17,
      "z": -88,
      "name": "Soil_Gravel_Lime"
    },
    {
      "x": -88,
      "y": 18,
      "z": -88,
      "name": "Soil_Gravel_Lime"
    },
    {
      "x": -88,
      "y": 19,
      "z": -88,
      "name": "Rock_Lime"
    },
    {
      "x": -88,
      "y": 20,
      "z": -88,
      "name": "Rock_Lime"
    },
    {
      "x": -88,
      "y": 21,
      "z": -88,
      "name": "Rock_Lime"
    },
    {
      "x": -88,
      "y": 22,
      "z": -88,
      "name": "Soil_Gravel_Lime"
    },
    {
      "x": -88,
      "y": 23,
      "z": -88,
      "name": "Soil_Gravel_Lime"
    },
    {
      "x": -88,
      "y": 24,
      "z": -88,
      "name": "Soil_Gravel_Lime"
    },
    {
      "x": -88,
      "y": 25,
      "z": -88,
      "name": "Rock_Lime"
    },
    {
      "x": -88,
      "y": 26,
      "z": -88,
      "name": "Rock_Lime"
    },
    {
      "x": -88,
      "y": 27,
      "z": -88,
      "name": "Plant_Coral_Block_Lime"
    },
    {
      "x": -88,
      "y": 28,
      "z": -88,
      "name": "Plant_Coral_Block_Lime"
    },
    {
      "x": -88,
      "y": 29,
      "z": -88,
      "name": "Plant_Coral_Block_Lime"
    },
    {
      "x": -88,
      "y": 5,
      "z": -87,
      "name": "Rock_Lime"
    },
    {
      "x": -88,
      "y": 6,
      "z": -87,
      "name": "Rock_Lime"
    },
    {
      "x": -88,
      "y": 7,
      "z": -87,
      "name": "Rock_Lime"
    },
    {
      "x": -88,
      "y": 8,
      "z": -87,
      "name": "Soil_Gravel_Lime"
    },
    {
      "x": -88,
      "y": 9,
      "z": -87,
      "name": "Rock_Lime"
    },
    {
      "x": -88,
      "y": 10,
      "z": -87,
      "name": "Rock_Lime"
    },
    {
      "x": -88,
      "y": 11,
      "z": -87,
      "name": "Rock_Lime"
    },
    {
      "x": -88,
      "y": 12,
      "z": -87,
      "name": "Soil_Gravel_Lime"
    },
    {
      "x": -88,
      "y": 13,
      "z": -87,
      "name": "Rock_Lime"
    },
    {
      "x": -88,
      "y": 14,
      "z": -87,
      "name": "Rock_Lime"
    },
    {
      "x": -88,
      "y": 15,
      "z": -87,
      "name": "Soil_Gravel_Lime"
    },
    {
      "x": -88,
      "y": 16,
      "z": -87,
      "name": "Rock_Lime"
    },
    {
      "x": -88,
      "y": 17,
      "z": -87,
      "name": "Rock_Lime"
    },
    {
      "x": -88,
      "y": 18,
      "z": -87,
      "name": "Soil_Gravel_Lime"
    },
    {
      "x": -88,
      "y": 19,
      "z": -87,
      "name": "Rock_Lime"
    },
    {
      "x": -88,
      "y": 20,
      "z": -87,
      "name": "Rock_Lime"
    },
    {
      "x": -88,
      "y": 21,
      "z": -87,
      "name": "Rock_Lime"
    },
    {
      "x": -88,
      "y": 22,
      "z": -87,
      "name": "Rock_Lime"
    },
    {
      "x": -88,
      "y": 23,
      "z": -87,
      "name": "Rock_Lime"
    },
    {
      "x": -88,
      "y": 24,
      "z": -87,
      "name": "Soil_Gravel_Lime"
    },
    {
      "x": -88,
      "y": 25,
      "z": -87,
      "name": "Soil_Gravel_Lime"
    },
    {
      "x": -88,
      "y": 26,
      "z": -87,
      "name": "Soil_Clay_Smooth_Lime"
    },
    {
      "x": -88,
      "y": 27,
      "z": -87,
      "name": "Plant_Coral_Block_Lime"
    },
    {
      "x": -88,
      "y": 28,
      "z": -87,
      "name": "Plant_Coral_Block_Lime"
    },
    {
      "x": -88,
      "y": 5,
      "z": -86,
      "name": "Rock_Lime"
    },
    {
      "x": -88,
      "y": 6,
      "z": -86,
      "name": "Rock_Lime"
    },
    {
      "x": -88,
      "y": 7,
      "z": -86,
      "name": "Rock_Lime"
    },
    {
      "x": -88,
      "y": 8,
      "z": -86,
      "name": "Rock_Lime"
    },
    {
      "x": -88,
      "y": 9,
      "z": -86,
      "name": "Rock_Lime"
    },
    {
      "x": -88,
      "y": 10,
      "z": -86,
      "name": "Rock_Lime"
    },
    {
      "x": -88,
      "y": 11,
      "z": -86,
      "name": "Rock_Lime"
    },
    {
      "x": -88,
      "y": 12,
      "z": -86,
      "name": "Rock_Lime"
    },
    {
      "x": -88,
      "y": 13,
      "z": -86,
      "name": "Rock_Lime"
    },
    {
      "x": -88,
      "y": 14,
      "z": -86,
      "name": "Rock_Lime"
    },
    {
      "x": -88,
      "y": 15,
      "z": -86,
      "name": "Rock_Lime"
    },
    {
      "x": -88,
      "y": 16,
      "z": -86,
      "name": "Rock_Lime"
    },
    {
      "x": -88,
      "y": 17,
      "z": -86,
      "name": "Rock_Lime"
    },
    {
      "x": -88,
      "y": 18,
      "z": -86,
      "name": "Soil_Gravel_Lime"
    },
    {
      "x": -88,
      "y": 19,
      "z": -86,
      "name": "Rock_Lime"
    },
    {
      "x": -88,
      "y": 20,
      "z": -86,
      "name": "Rock_Lime"
    },
    {
      "x": -88,
      "y": 21,
      "z": -86,
      "name": "Soil_Gravel_Lime"
    },
    {
      "x": -88,
      "y": 22,
      "z": -86,
      "name": "Rock_Lime"
    },
    {
      "x": -88,
      "y": 23,
      "z": -86,
      "name": "Rock_Lime"
    },
    {
      "x": -88,
      "y": 24,
      "z": -86,
      "name": "Plant_Coral_Block_Lime"
    },
    {
      "x": -88,
      "y": 25,
      "z": -86,
      "name": "Plant_Coral_Block_Lime"
    },
    {
      "x": -88,
      "y": 26,
      "z": -86,
      "name": "Plant_Coral_Block_Lime"
    },
    {
      "x": -88,
      "y": 27,
      "z": -86,
      "name": "Soil_Clay_Lime"
    },
    {
      "x": -88,
      "y": 4,
      "z": -85,
      "name": "Rock_Lime"
    },
    {
      "x": -88,
      "y": 5,
      "z": -85,
      "name": "Rock_Lime"
    },
    {
      "x": -88,
      "y": 6,
      "z": -85,
      "name": "Soil_Gravel_Lime"
    },
    {
      "x": -88,
      "y": 7,
      "z": -85,
      "name": "Rock_Lime"
    },
    {
      "x": -88,
      "y": 8,
      "z": -85,
      "name": "Rock_Lime"
    },
    {
      "x": -88,
      "y": 9,
      "z": -85,
      "name": "Soil_Gravel_Lime"
    },
    {
      "x": -88,
      "y": 10,
      "z": -85,
      "name": "Soil_Gravel_Lime"
    },
    {
      "x": -88,
      "y": 11,
      "z": -85,
      "name": "Rock_Lime"
    },
    {
      "x": -88,
      "y": 12,
      "z": -85,
      "name": "Rock_Lime"
    },
    {
      "x": -88,
      "y": 13,
      "z": -85,
      "name": "Rock_Lime"
    },
    {
      "x": -88,
      "y": 14,
      "z": -85,
      "name": "Soil_Gravel_Lime"
    },
    {
      "x": -88,
      "y": 15,
      "z": -85,
      "name": "Rock_Lime"
    },
    {
      "x": -88,
      "y": 16,
      "z": -85,
      "name": "Rock_Lime"
    },
    {
      "x": -88,
      "y": 17,
      "z": -85,
      "name": "Soil_Gravel_Lime"
    },
    {
      "x": -88,
      "y": 18,
      "z": -85,
      "name": "Rock_Lime"
    },
    {
      "x": -88,
      "y": 19,
      "z": -85,
      "name": "Soil_Gravel_Lime"
    },
    {
      "x": -88,
      "y": 20,
      "z": -85,
      "name": "Rock_Lime"
    },
    {
      "x": -88,
      "y": 21,
      "z": -85,
      "name": "Soil_Gravel_Lime"
    },
    {
      "x": -88,
      "y": 22,
      "z": -85,
      "name": "Soil_Gravel_Lime"
    },
    {
      "x": -88,
      "y": 23,
      "z": -85,
      "name": "Soil_Clay_Smooth_Lime"
    },
    {
      "x": -88,
      "y": 24,
      "z": -85,
      "name": "Plant_Coral_Block_Lime"
    },
    {
      "x": -88,
      "y": 25,
      "z": -85,
      "name": "Plant_Coral_Block_Lime"
    },
    {
      "x": -88,
      "y": 4,
      "z": -84,
      "name": "Soil_Gravel_Lime"
    },
    {
      "x": -88,
      "y": 5,
      "z": -84,
      "name": "Rock_Lime"
    },
    {
      "x": -88,
      "y": 6,
      "z": -84,
      "name": "Soil_Gravel_Lime"
    },
    {
      "x": -88,
      "y": 7,
      "z": -84,
      "name": "Rock_Lime"
    },
    {
      "x": -88,
      "y": 8,
      "z": -84,
      "name": "Soil_Gravel_Lime"
    },
    {
      "x": -88,
      "y": 9,
      "z": -84,
      "name": "Soil_Gravel_Lime"
    },
    {
      "x": -88,
      "y": 10,
      "z": -84,
      "name": "Soil_Gravel_Lime"
    },
    {
      "x": -88,
      "y": 11,
      "z": -84,
      "name": "Soil_Gravel_Lime"
    },
    {
      "x": -88,
      "y": 12,
      "z": -84,
      "name": "Rock_Lime"
    },
    {
      "x": -88,
      "y": 13,
      "z": -84,
      "name": "Soil_Gravel_Lime"
    },
    {
      "x": -88,
      "y": 14,
      "z": -84,
      "name": "Rock_Lime"
    },
    {
      "x": -88,
      "y": 15,
      "z": -84,
      "name": "Rock_Lime"
    },
    {
      "x": -88,
      "y": 16,
      "z": -84,
      "name": "Rock_Lime"
    },
    {
      "x": -88,
      "y": 17,
      "z": -84,
      "name": "Soil_Gravel_Lime"
    },
    {
      "x": -88,
      "y": 18,
      "z": -84,
      "name": "Rock_Lime"
    },
    {
      "x": -88,
      "y": 19,
      "z": -84,
      "name": "Soil_Gravel_Lime"
    },
    {
      "x": -88,
      "y": 20,
      "z": -84,
      "name": "Rock_Lime"
    },
    {
      "x": -88,
      "y": 21,
      "z": -84,
      "name": "Soil_Gravel_Lime"
    },
    {
      "x": -88,
      "y": 22,
      "z": -84,
      "name": "Soil_Gravel_Lime"
    },
    {
      "x": -88,
      "y": 4,
      "z": -83,
      "name": "Soil_Gravel_Lime"
    },
    {
      "x": -88,
      "y": 5,
      "z": -83,
      "name": "Soil_Gravel_Lime"
    },
    {
      "x": -88,
      "y": 6,
      "z": -83,
      "name": "Rock_Lime"
    },
    {
      "x": -88,
      "y": 7,
      "z": -83,
      "name": "Rock_Lime"
    },
    {
      "x": -88,
      "y": 8,
      "z": -83,
      "name": "Soil_Gravel_Lime"
    },
    {
      "x": -88,
      "y": 9,
      "z": -83,
      "name": "Rock_Lime"
    },
    {
      "x": -88,
      "y": 10,
      "z": -83,
      "name": "Rock_Lime"
    },
    {
      "x": -88,
      "y": 11,
      "z": -83,
      "name": "Rock_Lime"
    },
    {
      "x": -88,
      "y": 12,
      "z": -83,
      "name": "Rock_Lime"
    },
    {
      "x": -88,
      "y": 13,
      "z": -83,
      "name": "Rock_Lime"
    },
    {
      "x": -88,
      "y": 14,
      "z": -83,
      "name": "Rock_Lime"
    },
    {
      "x": -88,
      "y": 15,
      "z": -83,
      "name": "Soil_Gravel_Lime"
    },
    {
      "x": -88,
      "y": 16,
      "z": -83,
      "name": "Soil_Gravel_Lime"
    },
    {
      "x": -88,
      "y": 17,
      "z": -83,
      "name": "Rock_Lime"
    },
    {
      "x": -88,
      "y": 18,
      "z": -83,
      "name": "Rock_Lime"
    },
    {
      "x": -88,
      "y": 19,
      "z": -83,
      "name": "Rock_Lime"
    },
    {
      "x": -88,
      "y": 20,
      "z": -83,
      "name": "Soil_Gravel_Lime"
    },
    {
      "x": -88,
      "y": 4,
      "z": -82,
      "name": "Rock_Lime"
    },
    {
      "x": -88,
      "y": 5,
      "z": -82,
      "name": "Soil_Gravel_Lime"
    },
    {
      "x": -88,
      "y": 6,
      "z": -82,
      "name": "Soil_Gravel_Lime"
    },
    {
      "x": -88,
      "y": 7,
      "z": -82,
      "name": "Rock_Lime"
    },
    {
      "x": -88,
      "y": 8,
      "z": -82,
      "name": "Soil_Gravel_Lime"
    },
    {
      "x": -88,
      "y": 9,
      "z": -82,
      "name": "Soil_Gravel_Lime"
    },
    {
      "x": -88,
      "y": 10,
      "z": -82,
      "name": "Rock_Lime"
    },
    {
      "x": -88,
      "y": 11,
      "z": -82,
      "name": "Rock_Lime"
    },
    {
      "x": -88,
      "y": 12,
      "z": -82,
      "name": "Soil_Gravel_Lime"
    },
    {
      "x": -88,
      "y": 13,
      "z": -82,
      "name": "Rock_Lime"
    },
    {
      "x": -88,
      "y": 14,
      "z": -82,
      "name": "Soil_Gravel_Lime"
    },
    {
      "x": -88,
      "y": 15,
      "z": -82,
      "name": "Rock_Lime"
    },
    {
      "x": -88,
      "y": 16,
      "z": -82,
      "name": "Soil_Gravel_Lime"
    },
    {
      "x": -88,
      "y": 5,
      "z": -81,
      "name": "Rock_Lime"
    },
    {
      "x": -88,
      "y": 6,
      "z": -81,
      "name": "Rock_Lime"
    },
    {
      "x": -88,
      "y": 7,
      "z": -81,
      "name": "Rock_Lime"
    },
    {
      "x": -88,
      "y": 8,
      "z": -81,
      "name": "Rock_Lime"
    },
    {
      "x": -88,
      "y": 9,
      "z": -81,
      "name": "Soil_Gravel_Lime"
    },
    {
      "x": -88,
      "y": 10,
      "z": -81,
      "name": "Rock_Lime"
    },
    {
      "x": -88,
      "y": 11,
      "z": -81,
      "name": "Rock_Lime"
    },
    {
      "x": -88,
      "y": 12,
      "z": -81,
      "name": "Plant_Coral_Block_Lime"
    },
    {
      "x": -88,
      "y": 14,
      "z": -81,
      "name": "Plant_Moss_Wall_Green",
      "support": 15,
      "rotation": 3
    },
    {
      "x": -88,
      "y": 15,
      "z": -81,
      "name": "Plant_Moss_Wall_Green",
      "support": 15,
      "rotation": 3
    },
    {
      "x": -88,
      "y": 5,
      "z": -80,
      "name": "Rock_Lime"
    },
    {
      "x": -88,
      "y": 6,
      "z": -80,
      "name": "Soil_Gravel_Lime"
    },
    {
      "x": -88,
      "y": 7,
      "z": -80,
      "name": "Rock_Lime"
    },
    {
      "x": -88,
      "y": 8,
      "z": -80,
      "name": "Rock_Lime"
    },
    {
      "x": -88,
      "y": 9,
      "z": -80,
      "name": "Rock_Lime"
    },
    {
      "x": -87,
      "y": 9,
      "z": -94,
      "name": "Rock_Lime"
    },
    {
      "x": -87,
      "y": 10,
      "z": -94,
      "name": "Rock_Lime"
    },
    {
      "x": -87,
      "y": 11,
      "z": -94,
      "name": "Soil_Gravel_Lime"
    },
    {
      "x": -87,
      "y": 12,
      "z": -94,
      "name": "Rock_Lime"
    },
    {
      "x": -87,
      "y": 13,
      "z": -94,
      "name": "Soil_Gravel_Lime"
    },
    {
      "x": -87,
      "y": 14,
      "z": -94,
      "name": "Rock_Lime"
    },
    {
      "x": -87,
      "y": 15,
      "z": -94,
      "name": "Soil_Gravel_Lime"
    },
    {
      "x": -87,
      "y": 16,
      "z": -94,
      "name": "Rock_Lime"
    },
    {
      "x": -87,
      "y": 17,
      "z": -94,
      "name": "Soil_Gravel_Lime"
    },
    {
      "x": -87,
      "y": 18,
      "z": -94,
      "name": "Soil_Gravel_Lime"
    },
    {
      "x": -87,
      "y": 5,
      "z": -93,
      "name": "Rock_Lime"
    },
    {
      "x": -87,
      "y": 6,
      "z": -93,
      "name": "Rock_Lime"
    },
    {
      "x": -87,
      "y": 7,
      "z": -93,
      "name": "Rock_Lime"
    },
    {
      "x": -87,
      "y": 8,
      "z": -93,
      "name": "Rock_Lime"
    },
    {
      "x": -87,
      "y": 9,
      "z": -93,
      "name": "Rock_Lime"
    },
    {
      "x": -87,
      "y": 10,
      "z": -93,
      "name": "Rock_Lime"
    },
    {
      "x": -87,
      "y": 11,
      "z": -93,
      "name": "Rock_Lime"
    },
    {
      "x": -87,
      "y": 12,
      "z": -93,
      "name": "Soil_Gravel_Lime"
    },
    {
      "x": -87,
      "y": 13,
      "z": -93,
      "name": "Rock_Lime"
    },
    {
      "x": -87,
      "y": 14,
      "z": -93,
      "name": "Rock_Lime"
    },
    {
      "x": -87,
      "y": 15,
      "z": -93,
      "name": "Rock_Lime"
    },
    {
      "x": -87,
      "y": 16,
      "z": -93,
      "name": "Rock_Lime"
    },
    {
      "x": -87,
      "y": 17,
      "z": -93,
      "name": "Soil_Gravel_Lime"
    },
    {
      "x": -87,
      "y": 18,
      "z": -93,
      "name": "Rock_Lime"
    },
    {
      "x": -87,
      "y": 19,
      "z": -93,
      "name": "Soil_Gravel_Lime"
    },
    {
      "x": -87,
      "y": 20,
      "z": -93,
      "name": "Soil_Gravel_Lime"
    },
    {
      "x": -87,
      "y": 21,
      "z": -93,
      "name": "Rock_Lime"
    },
    {
      "x": -87,
      "y": 22,
      "z": -93,
      "name": "Rubble_Lime",
      "support": 15
    },
    {
      "x": -87,
      "y": 4,
      "z": -92,
      "name": "Rock_Lime"
    },
    {
      "x": -87,
      "y": 5,
      "z": -92,
      "name": "Rock_Lime"
    },
    {
      "x": -87,
      "y": 6,
      "z": -92,
      "name": "Rock_Lime"
    },
    {
      "x": -87,
      "y": 7,
      "z": -92,
      "name": "Rock_Lime"
    },
    {
      "x": -87,
      "y": 8,
      "z": -92,
      "name": "Rock_Lime"
    },
    {
      "x": -87,
      "y": 9,
      "z": -92,
      "name": "Soil_Gravel_Lime"
    },
    {
      "x": -87,
      "y": 10,
      "z": -92,
      "name": "Soil_Gravel_Lime"
    },
    {
      "x": -87,
      "y": 11,
      "z": -92,
      "name": "Soil_Gravel_Lime"
    },
    {
      "x": -87,
      "y": 12,
      "z": -92,
      "name": "Soil_Gravel_Lime"
    },
    {
      "x": -87,
      "y": 13,
      "z": -92,
      "name": "Soil_Gravel_Lime"
    },
    {
      "x": -87,
      "y": 14,
      "z": -92,
      "name": "Rock_Lime"
    },
    {
      "x": -87,
      "y": 15,
      "z": -92,
      "name": "Soil_Gravel_Lime"
    },
    {
      "x": -87,
      "y": 16,
      "z": -92,
      "name": "Soil_Gravel_Lime"
    },
    {
      "x": -87,
      "y": 17,
      "z": -92,
      "name": "Soil_Gravel_Lime"
    },
    {
      "x": -87,
      "y": 18,
      "z": -92,
      "name": "Rock_Lime"
    },
    {
      "x": -87,
      "y": 19,
      "z": -92,
      "name": "Soil_Gravel_Lime"
    },
    {
      "x": -87,
      "y": 20,
      "z": -92,
      "name": "Soil_Gravel_Lime"
    },
    {
      "x": -87,
      "y": 21,
      "z": -92,
      "name": "Rock_Lime"
    },
    {
      "x": -87,
      "y": 22,
      "z": -92,
      "name": "Soil_Gravel_Lime"
    },
    {
      "x": -87,
      "y": 23,
      "z": -92,
      "name": "Soil_Gravel_Lime"
    },
    {
      "x": -87,
      "y": 24,
      "z": -92,
      "name": "Soil_Gravel_Lime"
    },
    {
      "x": -87,
      "y": 4,
      "z": -91,
      "name": "Rock_Lime"
    },
    {
      "x": -87,
      "y": 5,
      "z": -91,
      "name": "Rock_Lime"
    },
    {
      "x": -87,
      "y": 6,
      "z": -91,
      "name": "Rock_Lime"
    },
    {
      "x": -87,
      "y": 7,
      "z": -91,
      "name": "Rock_Lime"
    },
    {
      "x": -87,
      "y": 8,
      "z": -91,
      "name": "Rock_Lime"
    },
    {
      "x": -87,
      "y": 9,
      "z": -91,
      "name": "Soil_Gravel_Lime"
    },
    {
      "x": -87,
      "y": 10,
      "z": -91,
      "name": "Rock_Lime"
    },
    {
      "x": -87,
      "y": 11,
      "z": -91,
      "name": "Rock_Lime"
    },
    {
      "x": -87,
      "y": 12,
      "z": -91,
      "name": "Soil_Gravel_Lime"
    },
    {
      "x": -87,
      "y": 13,
      "z": -91,
      "name": "Rock_Lime"
    },
    {
      "x": -87,
      "y": 14,
      "z": -91,
      "name": "Rock_Lime"
    },
    {
      "x": -87,
      "y": 15,
      "z": -91,
      "name": "Soil_Gravel_Lime"
    },
    {
      "x": -87,
      "y": 16,
      "z": -91,
      "name": "Soil_Gravel_Lime"
    },
    {
      "x": -87,
      "y": 17,
      "z": -91,
      "name": "Rock_Lime"
    },
    {
      "x": -87,
      "y": 18,
      "z": -91,
      "name": "Rock_Lime"
    },
    {
      "x": -87,
      "y": 19,
      "z": -91,
      "name": "Rock_Lime"
    },
    {
      "x": -87,
      "y": 20,
      "z": -91,
      "name": "Soil_Gravel_Lime"
    },
    {
      "x": -87,
      "y": 21,
      "z": -91,
      "name": "Rock_Lime"
    },
    {
      "x": -87,
      "y": 22,
      "z": -91,
      "name": "Soil_Gravel_Lime"
    },
    {
      "x": -87,
      "y": 23,
      "z": -91,
      "name": "Soil_Gravel_Lime"
    },
    {
      "x": -87,
      "y": 24,
      "z": -91,
      "name": "Rock_Lime"
    },
    {
      "x": -87,
      "y": 25,
      "z": -91,
      "name": "Soil_Gravel_Lime"
    },
    {
      "x": -87,
      "y": 26,
      "z": -91,
      "name": "Rock_Lime"
    },
    {
      "x": -87,
      "y": 27,
      "z": -91,
      "name": "Plant_Coral_Block_Lime"
    },
    {
      "x": -87,
      "y": 4,
      "z": -90,
      "name": "Soil_Gravel_Lime"
    },
    {
      "x": -87,
      "y": 5,
      "z": -90,
      "name": "Soil_Gravel_Lime"
    },
    {
      "x": -87,
      "y": 6,
      "z": -90,
      "name": "Soil_Gravel_Lime"
    },
    {
      "x": -87,
      "y": 7,
      "z": -90,
      "name": "Soil_Gravel_Lime"
    },
    {
      "x": -87,
      "y": 8,
      "z": -90,
      "name": "Rock_Lime"
    },
    {
      "x": -87,
      "y": 9,
      "z": -90,
      "name": "Soil_Gravel_Lime"
    },
    {
      "x": -87,
      "y": 10,
      "z": -90,
      "name": "Rock_Lime"
    },
    {
      "x": -87,
      "y": 11,
      "z": -90,
      "name": "Rock_Lime"
    },
    {
      "x": -87,
      "y": 12,
      "z": -90,
      "name": "Rock_Lime"
    },
    {
      "x": -87,
      "y": 13,
      "z": -90,
      "name": "Rock_Lime"
    },
    {
      "x": -87,
      "y": 14,
      "z": -90,
      "name": "Rock_Lime"
    },
    {
      "x": -87,
      "y": 15,
      "z": -90,
      "name": "Rock_Lime"
    },
    {
      "x": -87,
      "y": 16,
      "z": -90,
      "name": "Rock_Lime"
    },
    {
      "x": -87,
      "y": 17,
      "z": -90,
      "name": "Rock_Lime"
    },
    {
      "x": -87,
      "y": 18,
      "z": -90,
      "name": "Soil_Gravel_Lime"
    },
    {
      "x": -87,
      "y": 19,
      "z": -90,
      "name": "Rock_Lime"
    },
    {
      "x": -87,
      "y": 20,
      "z": -90,
      "name": "Rock_Lime"
    },
    {
      "x": -87,
      "y": 21,
      "z": -90,
      "name": "Rock_Lime"
    },
    {
      "x": -87,
      "y": 22,
      "z": -90,
      "name": "Soil_Gravel_Lime"
    },
    {
      "x": -87,
      "y": 23,
      "z": -90,
      "name": "Rock_Lime"
    },
    {
      "x": -87,
      "y": 24,
      "z": -90,
      "name": "Soil_Gravel_Lime"
    },
    {
      "x": -87,
      "y": 25,
      "z": -90,
      "name": "Rock_Lime"
    },
    {
      "x": -87,
      "y": 26,
      "z": -90,
      "name": "Rock_Lime"
    },
    {
      "x": -87,
      "y": 27,
      "z": -90,
      "name": "Rock_Lime"
    },
    {
      "x": -87,
      "y": 28,
      "z": -90,
      "name": "Soil_Clay_Smooth_Lime"
    },
    {
      "x": -87,
      "y": 29,
      "z": -90,
      "name": "Plant_Coral_Block_Lime"
    },
    {
      "x": -87,
      "y": 4,
      "z": -89,
      "name": "Soil_Gravel_Lime"
    },
    {
      "x": -87,
      "y": 5,
      "z": -89,
      "name": "Rock_Lime"
    },
    {
      "x": -87,
      "y": 6,
      "z": -89,
      "name": "Rock_Lime"
    },
    {
      "x": -87,
      "y": 7,
      "z": -89,
      "name": "Rock_Lime"
    },
    {
      "x": -87,
      "y": 8,
      "z": -89,
      "name": "Rock_Lime"
    },
    {
      "x": -87,
      "y": 9,
      "z": -89,
      "name": "Rock_Lime"
    },
    {
      "x": -87,
      "y": 10,
      "z": -89,
      "name": "Soil_Gravel_Lime"
    },
    {
      "x": -87,
      "y": 11,
      "z": -89,
      "name": "Rock_Lime"
    },
    {
      "x": -87,
      "y": 12,
      "z": -89,
      "name": "Soil_Gravel_Lime"
    },
    {
      "x": -87,
      "y": 13,
      "z": -89,
      "name": "Soil_Gravel_Lime"
    },
    {
      "x": -87,
      "y": 14,
      "z": -89,
      "name": "Soil_Gravel_Lime"
    },
    {
      "x": -87,
      "y": 15,
      "z": -89,
      "name": "Soil_Gravel_Lime"
    },
    {
      "x": -87,
      "y": 16,
      "z": -89,
      "name": "Rock_Lime"
    },
    {
      "x": -87,
      "y": 17,
      "z": -89,
      "name": "Rock_Lime"
    },
    {
      "x": -87,
      "y": 18,
      "z": -89,
      "name": "Rock_Lime"
    },
    {
      "x": -87,
      "y": 19,
      "z": -89,
      "name": "Rock_Lime"
    },
    {
      "x": -87,
      "y": 20,
      "z": -89,
      "name": "Rock_Lime"
    },
    {
      "x": -87,
      "y": 21,
      "z": -89,
      "name": "Rock_Lime"
    },
    {
      "x": -87,
      "y": 22,
      "z": -89,
      "name": "Rock_Lime"
    },
    {
      "x": -87,
      "y": 23,
      "z": -89,
      "name": "Rock_Lime"
    },
    {
      "x": -87,
      "y": 24,
      "z": -89,
      "name": "Rock_Lime"
    },
    {
      "x": -87,
      "y": 25,
      "z": -89,
      "name": "Rock_Lime"
    },
    {
      "x": -87,
      "y": 26,
      "z": -89,
      "name": "Rock_Lime"
    },
    {
      "x": -87,
      "y": 27,
      "z": -89,
      "name": "Rock_Lime"
    },
    {
      "x": -87,
      "y": 28,
      "z": -89,
      "name": "Rock_Lime"
    },
    {
      "x": -87,
      "y": 29,
      "z": -89,
      "name": "Soil_Clay_Lime"
    },
    {
      "x": -87,
      "y": 30,
      "z": -89,
      "name": "Plant_Coral_Block_Lime"
    },
    {
      "x": -87,
      "y": 31,
      "z": -89,
      "name": "Plant_Coral_Block_Lime"
    },
    {
      "x": -87,
      "y": 4,
      "z": -88,
      "name": "Rock_Lime"
    },
    {
      "x": -87,
      "y": 5,
      "z": -88,
      "name": "Soil_Gravel_Lime"
    },
    {
      "x": -87,
      "y": 6,
      "z": -88,
      "name": "Rock_Lime"
    },
    {
      "x": -87,
      "y": 7,
      "z": -88,
      "name": "Rock_Lime"
    },
    {
      "x": -87,
      "y": 8,
      "z": -88,
      "name": "Rock_Lime"
    },
    {
      "x": -87,
      "y": 9,
      "z": -88,
      "name": "Rock_Lime"
    },
    {
      "x": -87,
      "y": 10,
      "z": -88,
      "name": "Rock_Lime"
    },
    {
      "x": -87,
      "y": 11,
      "z": -88,
      "name": "Rock_Lime"
    },
    {
      "x": -87,
      "y": 12,
      "z": -88,
      "name": "Soil_Gravel_Lime"
    },
    {
      "x": -87,
      "y": 13,
      "z": -88,
      "name": "Rock_Lime"
    },
    {
      "x": -87,
      "y": 14,
      "z": -88,
      "name": "Soil_Gravel_Lime"
    },
    {
      "x": -87,
      "y": 15,
      "z": -88,
      "name": "Soil_Gravel_Lime"
    },
    {
      "x": -87,
      "y": 16,
      "z": -88,
      "name": "Soil_Gravel_Lime"
    },
    {
      "x": -87,
      "y": 17,
      "z": -88,
      "name": "Rock_Lime"
    },
    {
      "x": -87,
      "y": 18,
      "z": -88,
      "name": "Soil_Gravel_Lime"
    },
    {
      "x": -87,
      "y": 19,
      "z": -88,
      "name": "Rock_Lime"
    },
    {
      "x": -87,
      "y": 20,
      "z": -88,
      "name": "Soil_Gravel_Lime"
    },
    {
      "x": -87,
      "y": 21,
      "z": -88,
      "name": "Soil_Gravel_Lime"
    },
    {
      "x": -87,
      "y": 22,
      "z": -88,
      "name": "Soil_Gravel_Lime"
    },
    {
      "x": -87,
      "y": 23,
      "z": -88,
      "name": "Rock_Lime"
    },
    {
      "x": -87,
      "y": 24,
      "z": -88,
      "name": "Rock_Lime"
    },
    {
      "x": -87,
      "y": 25,
      "z": -88,
      "name": "Soil_Gravel_Lime"
    },
    {
      "x": -87,
      "y": 26,
      "z": -88,
      "name": "Rock_Lime"
    },
    {
      "x": -87,
      "y": 27,
      "z": -88,
      "name": "Rock_Lime"
    },
    {
      "x": -87,
      "y": 28,
      "z": -88,
      "name": "Plant_Coral_Block_Lime"
    },
    {
      "x": -87,
      "y": 29,
      "z": -88,
      "name": "Soil_Clay_Lime"
    },
    {
      "x": -87,
      "y": 30,
      "z": -88,
      "name": "Plant_Coral_Block_Lime"
    },
    {
      "x": -87,
      "y": 31,
      "z": -88,
      "name": "Plant_Coral_Block_Lime"
    },
    {
      "x": -87,
      "y": 4,
      "z": -87,
      "name": "Soil_Gravel_Lime"
    },
    {
      "x": -87,
      "y": 5,
      "z": -87,
      "name": "Soil_Gravel_Lime"
    },
    {
      "x": -87,
      "y": 6,
      "z": -87,
      "name": "Rock_Lime"
    },
    {
      "x": -87,
      "y": 7,
      "z": -87,
      "name": "Soil_Gravel_Lime"
    },
    {
      "x": -87,
      "y": 8,
      "z": -87,
      "name": "Soil_Gravel_Lime"
    },
    {
      "x": -87,
      "y": 9,
      "z": -87,
      "name": "Rock_Lime"
    },
    {
      "x": -87,
      "y": 10,
      "z": -87,
      "name": "Soil_Gravel_Lime"
    },
    {
      "x": -87,
      "y": 11,
      "z": -87,
      "name": "Rock_Lime"
    },
    {
      "x": -87,
      "y": 12,
      "z": -87,
      "name": "Rock_Lime"
    },
    {
      "x": -87,
      "y": 13,
      "z": -87,
      "name": "Soil_Gravel_Lime"
    },
    {
      "x": -87,
      "y": 14,
      "z": -87,
      "name": "Soil_Gravel_Lime"
    },
    {
      "x": -87,
      "y": 15,
      "z": -87,
      "name": "Rock_Lime"
    },
    {
      "x": -87,
      "y": 16,
      "z": -87,
      "name": "Rock_Lime"
    },
    {
      "x": -87,
      "y": 17,
      "z": -87,
      "name": "Rock_Lime"
    },
    {
      "x": -87,
      "y": 18,
      "z": -87,
      "name": "Rock_Lime"
    },
    {
      "x": -87,
      "y": 19,
      "z": -87,
      "name": "Soil_Gravel_Lime"
    },
    {
      "x": -87,
      "y": 20,
      "z": -87,
      "name": "Rock_Lime"
    },
    {
      "x": -87,
      "y": 21,
      "z": -87,
      "name": "Soil_Gravel_Lime"
    },
    {
      "x": -87,
      "y": 22,
      "z": -87,
      "name": "Rock_Lime"
    },
    {
      "x": -87,
      "y": 23,
      "z": -87,
      "name": "Rock_Lime"
    },
    {
      "x": -87,
      "y": 24,
      "z": -87,
      "name": "Rock_Lime"
    },
    {
      "x": -87,
      "y": 25,
      "z": -87,
      "name": "Soil_Gravel_Lime"
    },
    {
      "x": -87,
      "y": 26,
      "z": -87,
      "name": "Soil_Gravel_Lime"
    },
    {
      "x": -87,
      "y": 27,
      "z": -87,
      "name": "Soil_Gravel_Lime"
    },
    {
      "x": -87,
      "y": 28,
      "z": -87,
      "name": "Rock_Lime"
    },
    {
      "x": -87,
      "y": 29,
      "z": -87,
      "name": "Plant_Coral_Block_Lime"
    },
    {
      "x": -87,
      "y": 30,
      "z": -87,
      "name": "Plant_Coral_Block_Lime"
    },
    {
      "x": -87,
      "y": 31,
      "z": -87,
      "name": "Soil_Clay_Lime"
    },
    {
      "x": -87,
      "y": 4,
      "z": -86,
      "name": "Rock_Lime"
    },
    {
      "x": -87,
      "y": 5,
      "z": -86,
      "name": "Rock_Lime"
    },
    {
      "x": -87,
      "y": 6,
      "z": -86,
      "name": "Rock_Lime"
    },
    {
      "x": -87,
      "y": 7,
      "z": -86,
      "name": "Soil_Gravel_Lime"
    },
    {
      "x": -87,
      "y": 8,
      "z": -86,
      "name": "Rock_Lime"
    },
    {
      "x": -87,
      "y": 9,
      "z": -86,
      "name": "Rock_Lime"
    },
    {
      "x": -87,
      "y": 10,
      "z": -86,
      "name": "Rock_Lime"
    },
    {
      "x": -87,
      "y": 11,
      "z": -86,
      "name": "Soil_Gravel_Lime"
    },
    {
      "x": -87,
      "y": 12,
      "z": -86,
      "name": "Rock_Lime"
    },
    {
      "x": -87,
      "y": 13,
      "z": -86,
      "name": "Soil_Gravel_Lime"
    },
    {
      "x": -87,
      "y": 14,
      "z": -86,
      "name": "Rock_Lime"
    },
    {
      "x": -87,
      "y": 15,
      "z": -86,
      "name": "Soil_Gravel_Lime"
    },
    {
      "x": -87,
      "y": 16,
      "z": -86,
      "name": "Soil_Gravel_Lime"
    },
    {
      "x": -87,
      "y": 17,
      "z": -86,
      "name": "Soil_Gravel_Lime"
    },
    {
      "x": -87,
      "y": 18,
      "z": -86,
      "name": "Soil_Gravel_Lime"
    },
    {
      "x": -87,
      "y": 19,
      "z": -86,
      "name": "Rock_Lime"
    },
    {
      "x": -87,
      "y": 20,
      "z": -86,
      "name": "Rock_Lime"
    },
    {
      "x": -87,
      "y": 21,
      "z": -86,
      "name": "Rock_Lime"
    },
    {
      "x": -87,
      "y": 22,
      "z": -86,
      "name": "Soil_Gravel_Lime"
    },
    {
      "x": -87,
      "y": 23,
      "z": -86,
      "name": "Soil_Gravel_Lime"
    },
    {
      "x": -87,
      "y": 24,
      "z": -86,
      "name": "Soil_Gravel_Lime"
    },
    {
      "x": -87,
      "y": 25,
      "z": -86,
      "name": "Soil_Clay_Lime"
    },
    {
      "x": -87,
      "y": 26,
      "z": -86,
      "name": "Plant_Coral_Block_Lime"
    },
    {
      "x": -87,
      "y": 27,
      "z": -86,
      "name": "Soil_Clay_Lime"
    },
    {
      "x": -87,
      "y": 28,
      "z": -86,
      "name": "Plant_Coral_Block_Lime"
    },
    {
      "x": -87,
      "y": 29,
      "z": -86,
      "name": "Soil_Clay_Smooth_Lime"
    },
    {
      "x": -87,
      "y": 30,
      "z": -86,
      "name": "Soil_Clay_Smooth_Lime"
    },
    {
      "x": -87,
      "y": 4,
      "z": -85,
      "name": "Rock_Lime"
    },
    {
      "x": -87,
      "y": 5,
      "z": -85,
      "name": "Rock_Lime"
    },
    {
      "x": -87,
      "y": 6,
      "z": -85,
      "name": "Rock_Lime"
    },
    {
      "x": -87,
      "y": 7,
      "z": -85,
      "name": "Rock_Lime"
    },
    {
      "x": -87,
      "y": 8,
      "z": -85,
      "name": "Rock_Lime"
    },
    {
      "x": -87,
      "y": 9,
      "z": -85,
      "name": "Rock_Lime"
    },
    {
      "x": -87,
      "y": 10,
      "z": -85,
      "name": "Rock_Lime"
    },
    {
      "x": -87,
      "y": 11,
      "z": -85,
      "name": "Soil_Gravel_Lime"
    },
    {
      "x": -87,
      "y": 12,
      "z": -85,
      "name": "Soil_Gravel_Lime"
    },
    {
      "x": -87,
      "y": 13,
      "z": -85,
      "name": "Soil_Gravel_Lime"
    },
    {
      "x": -87,
      "y": 14,
      "z": -85,
      "name": "Soil_Gravel_Lime"
    },
    {
      "x": -87,
      "y": 15,
      "z": -85,
      "name": "Soil_Gravel_Lime"
    },
    {
      "x": -87,
      "y": 16,
      "z": -85,
      "name": "Soil_Gravel_Lime"
    },
    {
      "x": -87,
      "y": 17,
      "z": -85,
      "name": "Rock_Lime"
    },
    {
      "x": -87,
      "y": 18,
      "z": -85,
      "name": "Rock_Lime"
    },
    {
      "x": -87,
      "y": 19,
      "z": -85,
      "name": "Rock_Lime"
    },
    {
      "x": -87,
      "y": 20,
      "z": -85,
      "name": "Rock_Lime"
    },
    {
      "x": -87,
      "y": 21,
      "z": -85,
      "name": "Rock_Lime"
    },
    {
      "x": -87,
      "y": 22,
      "z": -85,
      "name": "Soil_Gravel_Lime"
    },
    {
      "x": -87,
      "y": 23,
      "z": -85,
      "name": "Soil_Gravel_Lime"
    },
    {
      "x": -87,
      "y": 24,
      "z": -85,
      "name": "Soil_Clay_Smooth_Lime"
    },
    {
      "x": -87,
      "y": 25,
      "z": -85,
      "name": "Plant_Coral_Block_Lime"
    },
    {
      "x": -87,
      "y": 26,
      "z": -85,
      "name": "Soil_Clay_Smooth_Lime"
    },
    {
      "x": -87,
      "y": 27,
      "z": -85,
      "name": "Soil_Clay_Lime"
    },
    {
      "x": -87,
      "y": 28,
      "z": -85,
      "name": "Plant_Coral_Block_Lime"
    },
    {
      "x": -87,
      "y": 4,
      "z": -84,
      "name": "Rock_Lime"
    },
    {
      "x": -87,
      "y": 5,
      "z": -84,
      "name": "Rock_Lime"
    },
    {
      "x": -87,
      "y": 6,
      "z": -84,
      "name": "Soil_Gravel_Lime"
    },
    {
      "x": -87,
      "y": 7,
      "z": -84,
      "name": "Soil_Gravel_Lime"
    },
    {
      "x": -87,
      "y": 8,
      "z": -84,
      "name": "Soil_Gravel_Lime"
    },
    {
      "x": -87,
      "y": 9,
      "z": -84,
      "name": "Rock_Lime"
    },
    {
      "x": -87,
      "y": 10,
      "z": -84,
      "name": "Rock_Lime"
    },
    {
      "x": -87,
      "y": 11,
      "z": -84,
      "name": "Soil_Gravel_Lime"
    },
    {
      "x": -87,
      "y": 12,
      "z": -84,
      "name": "Soil_Gravel_Lime"
    },
    {
      "x": -87,
      "y": 13,
      "z": -84,
      "name": "Rock_Lime"
    },
    {
      "x": -87,
      "y": 14,
      "z": -84,
      "name": "Soil_Gravel_Lime"
    },
    {
      "x": -87,
      "y": 15,
      "z": -84,
      "name": "Rock_Lime"
    },
    {
      "x": -87,
      "y": 16,
      "z": -84,
      "name": "Rock_Lime"
    },
    {
      "x": -87,
      "y": 17,
      "z": -84,
      "name": "Soil_Gravel_Lime"
    },
    {
      "x": -87,
      "y": 18,
      "z": -84,
      "name": "Rock_Lime"
    },
    {
      "x": -87,
      "y": 19,
      "z": -84,
      "name": "Soil_Gravel_Lime"
    },
    {
      "x": -87,
      "y": 20,
      "z": -84,
      "name": "Rock_Lime"
    },
    {
      "x": -87,
      "y": 21,
      "z": -84,
      "name": "Soil_Gravel_Lime"
    },
    {
      "x": -87,
      "y": 22,
      "z": -84,
      "name": "Rock_Lime"
    },
    {
      "x": -87,
      "y": 23,
      "z": -84,
      "name": "Rock_Lime"
    },
    {
      "x": -87,
      "y": 24,
      "z": -84,
      "name": "Soil_Gravel_Lime"
    },
    {
      "x": -87,
      "y": 25,
      "z": -84,
      "name": "Plant_Coral_Block_Lime"
    },
    {
      "x": -87,
      "y": 4,
      "z": -83,
      "name": "Rock_Lime"
    },
    {
      "x": -87,
      "y": 5,
      "z": -83,
      "name": "Soil_Gravel_Lime"
    },
    {
      "x": -87,
      "y": 6,
      "z": -83,
      "name": "Soil_Gravel_Lime"
    },
    {
      "x": -87,
      "y": 7,
      "z": -83,
      "name": "Soil_Gravel_Lime"
    },
    {
      "x": -87,
      "y": 8,
      "z": -83,
      "name": "Rock_Lime"
    },
    {
      "x": -87,
      "y": 9,
      "z": -83,
      "name": "Rock_Lime"
    },
    {
      "x": -87,
      "y": 10,
      "z": -83,
      "name": "Rock_Lime"
    },
    {
      "x": -87,
      "y": 11,
      "z": -83,
      "name": "Soil_Gravel_Lime"
    },
    {
      "x": -87,
      "y": 12,
      "z": -83,
      "name": "Rock_Lime"
    },
    {
      "x": -87,
      "y": 13,
      "z": -83,
      "name": "Rock_Lime"
    },
    {
      "x": -87,
      "y": 14,
      "z": -83,
      "name": "Rock_Lime"
    },
    {
      "x": -87,
      "y": 15,
      "z": -83,
      "name": "Soil_Gravel_Lime"
    },
    {
      "x": -87,
      "y": 16,
      "z": -83,
      "name": "Rock_Lime"
    },
    {
      "x": -87,
      "y": 17,
      "z": -83,
      "name": "Rock_Lime"
    },
    {
      "x": -87,
      "y": 18,
      "z": -83,
      "name": "Rock_Lime"
    },
    {
      "x": -87,
      "y": 19,
      "z": -83,
      "name": "Rock_Lime"
    },
    {
      "x": -87,
      "y": 20,
      "z": -83,
      "name": "Rock_Lime"
    },
    {
      "x": -87,
      "y": 21,
      "z": -83,
      "name": "Rock_Lime"
    },
    {
      "x": -87,
      "y": 22,
      "z": -83,
      "name": "Soil_Gravel_Lime"
    },
    {
      "x": -87,
      "y": 23,
      "z": -83,
      "name": "Rock_Lime"
    },
    {
      "x": -87,
      "y": 24,
      "z": -83,
      "name": "Rock_Lime_Stalactite_Large"
    },
    {
      "x": -87,
      "y": 25,
      "z": -83,
      "name": "Rock_Lime_Stalactite_Large",
      "filler": 1024
    },
    {
      "x": -87,
      "y": 4,
      "z": -82,
      "name": "Soil_Gravel_Lime"
    },
    {
      "x": -87,
      "y": 5,
      "z": -82,
      "name": "Rock_Lime"
    },
    {
      "x": -87,
      "y": 6,
      "z": -82,
      "name": "Rock_Lime"
    },
    {
      "x": -87,
      "y": 7,
      "z": -82,
      "name": "Soil_Gravel_Lime"
    },
    {
      "x": -87,
      "y": 8,
      "z": -82,
      "name": "Soil_Gravel_Lime"
    },
    {
      "x": -87,
      "y": 9,
      "z": -82,
      "name": "Rock_Lime"
    },
    {
      "x": -87,
      "y": 10,
      "z": -82,
      "name": "Rock_Lime"
    },
    {
      "x": -87,
      "y": 11,
      "z": -82,
      "name": "Rock_Lime"
    },
    {
      "x": -87,
      "y": 12,
      "z": -82,
      "name": "Rock_Lime"
    },
    {
      "x": -87,
      "y": 13,
      "z": -82,
      "name": "Rock_Lime"
    },
    {
      "x": -87,
      "y": 14,
      "z": -82,
      "name": "Soil_Gravel_Lime"
    },
    {
      "x": -87,
      "y": 15,
      "z": -82,
      "name": "Rock_Lime"
    },
    {
      "x": -87,
      "y": 16,
      "z": -82,
      "name": "Soil_Gravel_Lime"
    },
    {
      "x": -87,
      "y": 17,
      "z": -82,
      "name": "Rock_Lime"
    },
    {
      "x": -87,
      "y": 18,
      "z": -82,
      "name": "Rock_Lime"
    },
    {
      "x": -87,
      "y": 19,
      "z": -82,
      "name": "Plant_Crop_Mushroom_Cap_Poison",
      "components": {
        "Components": {
          "FarmingBlock": {
            "LastTickGameTime": "0001-01-01T12:00:00Z"
          },
          "PlacedByInteraction": {
            "WhoPlacedUuid": {
              "$binary": "HCpUQzdeSaiDYHpoRePv+w==",
              "$type": "04"
            }
          }
        }
      }
    },
    {
      "x": -87,
      "y": 4,
      "z": -81,
      "name": "Rock_Lime"
    },
    {
      "x": -87,
      "y": 5,
      "z": -81,
      "name": "Soil_Gravel_Lime"
    },
    {
      "x": -87,
      "y": 6,
      "z": -81,
      "name": "Rock_Lime"
    },
    {
      "x": -87,
      "y": 7,
      "z": -81,
      "name": "Rock_Lime"
    },
    {
      "x": -87,
      "y": 8,
      "z": -81,
      "name": "Rock_Lime"
    },
    {
      "x": -87,
      "y": 9,
      "z": -81,
      "name": "Soil_Gravel_Lime"
    },
    {
      "x": -87,
      "y": 10,
      "z": -81,
      "name": "Rock_Lime"
    },
    {
      "x": -87,
      "y": 11,
      "z": -81,
      "name": "Rock_Lime"
    },
    {
      "x": -87,
      "y": 12,
      "z": -81,
      "name": "Soil_Gravel_Lime"
    },
    {
      "x": -87,
      "y": 13,
      "z": -81,
      "name": "Plant_Coral_Block_Lime"
    },
    {
      "x": -87,
      "y": 14,
      "z": -81,
      "name": "Plant_Coral_Block_Lime"
    },
    {
      "x": -87,
      "y": 15,
      "z": -81,
      "name": "Soil_Clay_Lime"
    },
    {
      "x": -87,
      "y": 16,
      "z": -81,
      "name": "Plant_Moss_Wall_Green",
      "support": 15,
      "rotation": 3
    },
    {
      "x": -87,
      "y": 17,
      "z": -81,
      "name": "Plant_Moss_Wall_Green",
      "support": 15,
      "rotation": 3
    },
    {
      "x": -87,
      "y": 18,
      "z": -81,
      "name": "Plant_Moss_Wall_Green",
      "support": 15,
      "rotation": 3
    },
    {
      "x": -87,
      "y": 19,
      "z": -81,
      "name": "Plant_Moss_Wall_Green",
      "support": 15,
      "rotation": 3
    },
    {
      "x": -87,
      "y": 20,
      "z": -81,
      "name": "Plant_Moss_Wall_Green",
      "support": 15,
      "rotation": 3
    },
    {
      "x": -87,
      "y": 4,
      "z": -80,
      "name": "Rock_Lime"
    },
    {
      "x": -87,
      "y": 5,
      "z": -80,
      "name": "Soil_Gravel_Lime"
    },
    {
      "x": -87,
      "y": 6,
      "z": -80,
      "name": "Soil_Gravel_Lime"
    },
    {
      "x": -87,
      "y": 7,
      "z": -80,
      "name": "Rock_Lime"
    },
    {
      "x": -87,
      "y": 8,
      "z": -80,
      "name": "Rock_Lime"
    },
    {
      "x": -87,
      "y": 9,
      "z": -80,
      "name": "Rock_Lime"
    },
    {
      "x": -87,
      "y": 10,
      "z": -80,
      "name": "Rock_Lime"
    },
    {
      "x": -87,
      "y": 11,
      "z": -80,
      "name": "Rock_Lime"
    },
    {
      "x": -87,
      "y": 12,
      "z": -80,
      "name": "Plant_Coral_Block_Lime"
    },
    {
      "x": -87,
      "y": 13,
      "z": -80,
      "name": "Soil_Clay_Smooth_Lime"
    },
    {
      "x": -87,
      "y": 14,
      "z": -80,
      "name": "Plant_Moss_Wall_Green",
      "support": 15,
      "rotation": 3
    },
    {
      "x": -87,
      "y": 15,
      "z": -80,
      "name": "Plant_Moss_Wall_Green",
      "support": 15,
      "rotation": 3
    },
    {
      "x": -87,
      "y": 16,
      "z": -80,
      "name": "Plant_Moss_Wall_Green",
      "support": 15,
      "rotation": 3
    },
    {
      "x": -87,
      "y": 17,
      "z": -80,
      "name": "Plant_Moss_Wall_Green",
      "support": 15,
      "rotation": 3
    },
    {
      "x": -87,
      "y": 18,
      "z": -80,
      "name": "Plant_Moss_Wall_Green",
      "support": 15,
      "rotation": 3
    },
    {
      "x": -87,
      "y": 19,
      "z": -80,
      "name": "Plant_Moss_Wall_Green",
      "support": 15,
      "rotation": 3
    },
    {
      "x": -87,
      "y": 4,
      "z": -79,
      "name": "Rock_Lime"
    },
    {
      "x": -87,
      "y": 5,
      "z": -79,
      "name": "Rock_Lime"
    },
    {
      "x": -87,
      "y": 6,
      "z": -79,
      "name": "Soil_Gravel_Lime"
    },
    {
      "x": -87,
      "y": 7,
      "z": -79,
      "name": "Rock_Lime"
    },
    {
      "x": -87,
      "y": 8,
      "z": -79,
      "name": "Rock_Lime"
    },
    {
      "x": -87,
      "y": 9,
      "z": -79,
      "name": "Rock_Lime"
    },
    {
      "x": -87,
      "y": 10,
      "z": -79,
      "name": "Rock_Lime"
    },
    {
      "x": -87,
      "y": 11,
      "z": -79,
      "name": "Soil_Gravel_Lime"
    },
    {
      "x": -86,
      "y": 9,
      "z": -94,
      "name": "Soil_Gravel_Lime"
    },
    {
      "x": -86,
      "y": 10,
      "z": -94,
      "name": "Soil_Gravel_Lime"
    },
    {
      "x": -86,
      "y": 11,
      "z": -94,
      "name": "Soil_Gravel_Lime"
    },
    {
      "x": -86,
      "y": 12,
      "z": -94,
      "name": "Rock_Lime"
    },
    {
      "x": -86,
      "y": 13,
      "z": -94,
      "name": "Soil_Gravel_Lime"
    },
    {
      "x": -86,
      "y": 14,
      "z": -94,
      "name": "Rock_Lime"
    },
    {
      "x": -86,
      "y": 15,
      "z": -94,
      "name": "Rock_Lime"
    },
    {
      "x": -86,
      "y": 16,
      "z": -94,
      "name": "Soil_Gravel_Lime"
    },
    {
      "x": -86,
      "y": 17,
      "z": -94,
      "name": "Rock_Lime"
    },
    {
      "x": -86,
      "y": 18,
      "z": -94,
      "name": "Rock_Lime"
    },
    {
      "x": -86,
      "y": 19,
      "z": -94,
      "name": "Rock_Lime"
    },
    {
      "x": -86,
      "y": 20,
      "z": -94,
      "name": "Rock_Lime"
    },
    {
      "x": -86,
      "y": 21,
      "z": -94,
      "name": "Rock_Lime_Stalactite_Large"
    },
    {
      "x": -86,
      "y": 22,
      "z": -94,
      "name": "Rock_Lime_Stalactite_Large",
      "filler": 1024
    },
    {
      "x": -86,
      "y": 6,
      "z": -93,
      "name": "Soil_Gravel_Lime"
    },
    {
      "x": -86,
      "y": 7,
      "z": -93,
      "name": "Rock_Lime"
    },
    {
      "x": -86,
      "y": 8,
      "z": -93,
      "name": "Rock_Lime"
    },
    {
      "x": -86,
      "y": 9,
      "z": -93,
      "name": "Soil_Gravel_Lime"
    },
    {
      "x": -86,
      "y": 10,
      "z": -93,
      "name": "Soil_Gravel_Lime"
    },
    {
      "x": -86,
      "y": 11,
      "z": -93,
      "name": "Soil_Gravel_Lime"
    },
    {
      "x": -86,
      "y": 12,
      "z": -93,
      "name": "Rock_Lime"
    },
    {
      "x": -86,
      "y": 13,
      "z": -93,
      "name": "Soil_Gravel_Lime"
    },
    {
      "x": -86,
      "y": 14,
      "z": -93,
      "name": "Rock_Lime"
    },
    {
      "x": -86,
      "y": 15,
      "z": -93,
      "name": "Rock_Lime"
    },
    {
      "x": -86,
      "y": 16,
      "z": -93,
      "name": "Soil_Gravel_Lime"
    },
    {
      "x": -86,
      "y": 17,
      "z": -93,
      "name": "Rock_Lime"
    },
    {
      "x": -86,
      "y": 18,
      "z": -93,
      "name": "Rock_Lime"
    },
    {
      "x": -86,
      "y": 19,
      "z": -93,
      "name": "Soil_Gravel_Lime"
    },
    {
      "x": -86,
      "y": 20,
      "z": -93,
      "name": "Rock_Lime"
    },
    {
      "x": -86,
      "y": 21,
      "z": -93,
      "name": "Soil_Gravel_Lime"
    },
    {
      "x": -86,
      "y": 22,
      "z": -93,
      "name": "Soil_Gravel_Lime"
    },
    {
      "x": -86,
      "y": 23,
      "z": -93,
      "name": "Rock_Lime"
    },
    {
      "x": -86,
      "y": 24,
      "z": -93,
      "name": "Rock_Lime"
    },
    {
      "x": -86,
      "y": 25,
      "z": -93,
      "name": "Soil_Gravel_Lime"
    },
    {
      "x": -86,
      "y": 26,
      "z": -93,
      "name": "Rock_Lime"
    },
    {
      "x": -86,
      "y": 27,
      "z": -93,
      "name": "Rock_Lime_Stalactite_Large"
    },
    {
      "x": -86,
      "y": 28,
      "z": -93,
      "name": "Rock_Lime_Stalactite_Large",
      "filler": 1024
    },
    {
      "x": -86,
      "y": 4,
      "z": -92,
      "name": "Soil_Gravel_Lime"
    },
    {
      "x": -86,
      "y": 5,
      "z": -92,
      "name": "Soil_Gravel_Lime"
    },
    {
      "x": -86,
      "y": 6,
      "z": -92,
      "name": "Soil_Gravel_Lime"
    },
    {
      "x": -86,
      "y": 7,
      "z": -92,
      "name": "Rock_Lime"
    },
    {
      "x": -86,
      "y": 8,
      "z": -92,
      "name": "Rock_Lime"
    },
    {
      "x": -86,
      "y": 9,
      "z": -92,
      "name": "Rock_Lime"
    },
    {
      "x": -86,
      "y": 10,
      "z": -92,
      "name": "Rock_Lime"
    },
    {
      "x": -86,
      "y": 11,
      "z": -92,
      "name": "Rock_Lime"
    },
    {
      "x": -86,
      "y": 12,
      "z": -92,
      "name": "Rock_Lime"
    },
    {
      "x": -86,
      "y": 13,
      "z": -92,
      "name": "Rock_Lime"
    },
    {
      "x": -86,
      "y": 14,
      "z": -92,
      "name": "Soil_Gravel_Lime"
    },
    {
      "x": -86,
      "y": 15,
      "z": -92,
      "name": "Rock_Lime"
    },
    {
      "x": -86,
      "y": 16,
      "z": -92,
      "name": "Soil_Gravel_Lime"
    },
    {
      "x": -86,
      "y": 17,
      "z": -92,
      "name": "Rock_Lime"
    },
    {
      "x": -86,
      "y": 18,
      "z": -92,
      "name": "Rock_Lime"
    },
    {
      "x": -86,
      "y": 19,
      "z": -92,
      "name": "Rock_Lime"
    },
    {
      "x": -86,
      "y": 20,
      "z": -92,
      "name": "Rock_Lime"
    },
    {
      "x": -86,
      "y": 21,
      "z": -92,
      "name": "Rock_Lime"
    },
    {
      "x": -86,
      "y": 22,
      "z": -92,
      "name": "Soil_Gravel_Lime"
    },
    {
      "x": -86,
      "y": 23,
      "z": -92,
      "name": "Soil_Gravel_Lime"
    },
    {
      "x": -86,
      "y": 24,
      "z": -92,
      "name": "Soil_Gravel_Lime"
    },
    {
      "x": -86,
      "y": 25,
      "z": -92,
      "name": "Soil_Gravel_Lime"
    },
    {
      "x": -86,
      "y": 26,
      "z": -92,
      "name": "Rock_Lime"
    },
    {
      "x": -86,
      "y": 27,
      "z": -92,
      "name": "Plant_Coral_Block_Lime"
    },
    {
      "x": -86,
      "y": 28,
      "z": -92,
      "name": "Plant_Coral_Block_Lime"
    },
    {
      "x": -86,
      "y": 29,
      "z": -92,
      "name": "Plant_Coral_Block_Lime"
    },
    {
      "x": -86,
      "y": 4,
      "z": -91,
      "name": "Rock_Lime"
    },
    {
      "x": -86,
      "y": 5,
      "z": -91,
      "name": "Rock_Lime"
    },
    {
      "x": -86,
      "y": 6,
      "z": -91,
      "name": "Rock_Lime"
    },
    {
      "x": -86,
      "y": 7,
      "z": -91,
      "name": "Soil_Gravel_Lime"
    },
    {
      "x": -86,
      "y": 8,
      "z": -91,
      "name": "Rock_Lime"
    },
    {
      "x": -86,
      "y": 9,
      "z": -91,
      "name": "Rock_Lime"
    },
    {
      "x": -86,
      "y": 10,
      "z": -91,
      "name": "Soil_Gravel_Lime"
    },
    {
      "x": -86,
      "y": 11,
      "z": -91,
      "name": "Rock_Lime"
    },
    {
      "x": -86,
      "y": 12,
      "z": -91,
      "name": "Soil_Gravel_Lime"
    },
    {
      "x": -86,
      "y": 13,
      "z": -91,
      "name": "Soil_Gravel_Lime"
    },
    {
      "x": -86,
      "y": 14,
      "z": -91,
      "name": "Soil_Gravel_Lime"
    },
    {
      "x": -86,
      "y": 15,
      "z": -91,
      "name": "Soil_Gravel_Lime"
    },
    {
      "x": -86,
      "y": 16,
      "z": -91,
      "name": "Soil_Gravel_Lime"
    },
    {
      "x": -86,
      "y": 17,
      "z": -91,
      "name": "Rock_Lime"
    },
    {
      "x": -86,
      "y": 18,
      "z": -91,
      "name": "Soil_Gravel_Lime"
    },
    {
      "x": -86,
      "y": 19,
      "z": -91,
      "name": "Soil_Gravel_Lime"
    },
    {
      "x": -86,
      "y": 20,
      "z": -91,
      "name": "Rock_Lime"
    },
    {
      "x": -86,
      "y": 21,
      "z": -91,
      "name": "Rock_Lime"
    },
    {
      "x": -86,
      "y": 22,
      "z": -91,
      "name": "Rock_Lime"
    },
    {
      "x": -86,
      "y": 23,
      "z": -91,
      "name": "Rock_Lime"
    },
    {
      "x": -86,
      "y": 24,
      "z": -91,
      "name": "Rock_Lime"
    },
    {
      "x": -86,
      "y": 25,
      "z": -91,
      "name": "Soil_Gravel_Lime"
    },
    {
      "x": -86,
      "y": 26,
      "z": -91,
      "name": "Soil_Gravel_Lime"
    },
    {
      "x": -86,
      "y": 27,
      "z": -91,
      "name": "Plant_Coral_Block_Lime"
    },
    {
      "x": -86,
      "y": 28,
      "z": -91,
      "name": "Soil_Clay_Smooth_Lime"
    },
    {
      "x": -86,
      "y": 29,
      "z": -91,
      "name": "Soil_Clay_Smooth_Lime"
    },
    {
      "x": -86,
      "y": 4,
      "z": -90,
      "name": "Rock_Lime"
    },
    {
      "x": -86,
      "y": 5,
      "z": -90,
      "name": "Soil_Gravel_Lime"
    },
    {
      "x": -86,
      "y": 6,
      "z": -90,
      "name": "Rock_Lime"
    },
    {
      "x": -86,
      "y": 7,
      "z": -90,
      "name": "Rock_Lime"
    },
    {
      "x": -86,
      "y": 8,
      "z": -90,
      "name": "Rock_Lime"
    },
    {
      "x": -86,
      "y": 9,
      "z": -90,
      "name": "Soil_Gravel_Lime"
    },
    {
      "x": -86,
      "y": 10,
      "z": -90,
      "name": "Rock_Lime"
    },
    {
      "x": -86,
      "y": 11,
      "z": -90,
      "name": "Rock_Lime"
    },
    {
      "x": -86,
      "y": 12,
      "z": -90,
      "name": "Rock_Lime"
    },
    {
      "x": -86,
      "y": 13,
      "z": -90,
      "name": "Soil_Gravel_Lime"
    },
    {
      "x": -86,
      "y": 14,
      "z": -90,
      "name": "Rock_Lime"
    },
    {
      "x": -86,
      "y": 15,
      "z": -90,
      "name": "Rock_Lime"
    },
    {
      "x": -86,
      "y": 16,
      "z": -90,
      "name": "Rock_Lime"
    },
    {
      "x": -86,
      "y": 17,
      "z": -90,
      "name": "Rock_Lime"
    },
    {
      "x": -86,
      "y": 18,
      "z": -90,
      "name": "Rock_Lime"
    },
    {
      "x": -86,
      "y": 19,
      "z": -90,
      "name": "Rock_Lime"
    },
    {
      "x": -86,
      "y": 20,
      "z": -90,
      "name": "Soil_Gravel_Lime"
    },
    {
      "x": -86,
      "y": 21,
      "z": -90,
      "name": "Rock_Lime"
    },
    {
      "x": -86,
      "y": 22,
      "z": -90,
      "name": "Soil_Gravel_Lime"
    },
    {
      "x": -86,
      "y": 23,
      "z": -90,
      "name": "Soil_Gravel_Lime"
    },
    {
      "x": -86,
      "y": 24,
      "z": -90,
      "name": "Rock_Lime"
    },
    {
      "x": -86,
      "y": 25,
      "z": -90,
      "name": "Soil_Gravel_Lime"
    },
    {
      "x": -86,
      "y": 26,
      "z": -90,
      "name": "Rock_Lime"
    },
    {
      "x": -86,
      "y": 27,
      "z": -90,
      "name": "Plant_Coral_Block_Lime"
    },
    {
      "x": -86,
      "y": 28,
      "z": -90,
      "name": "Plant_Coral_Block_Lime"
    },
    {
      "x": -86,
      "y": 29,
      "z": -90,
      "name": "Plant_Coral_Block_Lime"
    },
    {
      "x": -86,
      "y": 30,
      "z": -90,
      "name": "Soil_Clay_Lime"
    },
    {
      "x": -86,
      "y": 31,
      "z": -90,
      "name": "Plant_Coral_Block_Lime"
    },
    {
      "x": -86,
      "y": 32,
      "z": -90,
      "name": "Soil_Clay_Smooth_Lime"
    },
    {
      "x": -86,
      "y": 4,
      "z": -89,
      "name": "Rock_Lime"
    },
    {
      "x": -86,
      "y": 5,
      "z": -89,
      "name": "Rock_Lime"
    },
    {
      "x": -86,
      "y": 6,
      "z": -89,
      "name": "Rock_Lime"
    },
    {
      "x": -86,
      "y": 7,
      "z": -89,
      "name": "Rock_Lime"
    },
    {
      "x": -86,
      "y": 8,
      "z": -89,
      "name": "Soil_Gravel_Lime"
    },
    {
      "x": -86,
      "y": 9,
      "z": -89,
      "name": "Rock_Lime"
    },
    {
      "x": -86,
      "y": 10,
      "z": -89,
      "name": "Rock_Lime"
    },
    {
      "x": -86,
      "y": 11,
      "z": -89,
      "name": "Soil_Gravel_Lime"
    },
    {
      "x": -86,
      "y": 12,
      "z": -89,
      "name": "Rock_Lime"
    },
    {
      "x": -86,
      "y": 13,
      "z": -89,
      "name": "Rock_Lime"
    },
    {
      "x": -86,
      "y": 14,
      "z": -89,
      "name": "Rock_Lime"
    },
    {
      "x": -86,
      "y": 15,
      "z": -89,
      "name": "Rock_Lime"
    },
    {
      "x": -86,
      "y": 16,
      "z": -89,
      "name": "Soil_Gravel_Lime"
    },
    {
      "x": -86,
      "y": 17,
      "z": -89,
      "name": "Soil_Gravel_Lime"
    },
    {
      "x": -86,
      "y": 18,
      "z": -89,
      "name": "Soil_Gravel_Lime"
    },
    {
      "x": -86,
      "y": 19,
      "z": -89,
      "name": "Rock_Lime"
    },
    {
      "x": -86,
      "y": 20,
      "z": -89,
      "name": "Soil_Gravel_Lime"
    },
    {
      "x": -86,
      "y": 21,
      "z": -89,
      "name": "Rock_Lime"
    },
    {
      "x": -86,
      "y": 22,
      "z": -89,
      "name": "Rock_Lime"
    },
    {
      "x": -86,
      "y": 23,
      "z": -89,
      "name": "Rock_Lime"
    },
    {
      "x": -86,
      "y": 24,
      "z": -89,
      "name": "Rock_Lime"
    },
    {
      "x": -86,
      "y": 25,
      "z": -89,
      "name": "Soil_Gravel_Lime"
    },
    {
      "x": -86,
      "y": 26,
      "z": -89,
      "name": "Soil_Gravel_Lime"
    },
    {
      "x": -86,
      "y": 27,
      "z": -89,
      "name": "Soil_Gravel_Lime"
    },
    {
      "x": -86,
      "y": 28,
      "z": -89,
      "name": "Soil_Clay_Lime"
    },
    {
      "x": -86,
      "y": 29,
      "z": -89,
      "name": "Plant_Coral_Block_Lime"
    },
    {
      "x": -86,
      "y": 30,
      "z": -89,
      "name": "Plant_Coral_Block_Lime"
    },
    {
      "x": -86,
      "y": 31,
      "z": -89,
      "name": "Plant_Coral_Block_Lime"
    },
    {
      "x": -86,
      "y": 32,
      "z": -89,
      "name": "Soil_Clay_Smooth_Lime"
    },
    {
      "x": -86,
      "y": 33,
      "z": -89,
      "name": "Soil_Clay_Lime"
    },
    {
      "x": -86,
      "y": 34,
      "z": -89,
      "name": "Plant_Coral_Block_Lime"
    },
    {
      "x": -86,
      "y": 35,
      "z": -89,
      "name": "Soil_Clay_Smooth_Lime"
    },
    {
      "x": -86,
      "y": 36,
      "z": -89,
      "name": "Soil_Clay_Smooth_Lime"
    },
    {
      "x": -86,
      "y": 37,
      "z": -89,
      "name": "Soil_Clay_Lime"
    },
    {
      "x": -86,
      "y": 4,
      "z": -88,
      "name": "Soil_Gravel_Lime"
    },
    {
      "x": -86,
      "y": 5,
      "z": -88,
      "name": "Rock_Lime"
    },
    {
      "x": -86,
      "y": 6,
      "z": -88,
      "name": "Rock_Lime"
    },
    {
      "x": -86,
      "y": 7,
      "z": -88,
      "name": "Rock_Lime"
    },
    {
      "x": -86,
      "y": 8,
      "z": -88,
      "name": "Rock_Lime"
    },
    {
      "x": -86,
      "y": 9,
      "z": -88,
      "name": "Soil_Gravel_Lime"
    },
    {
      "x": -86,
      "y": 10,
      "z": -88,
      "name": "Rock_Lime"
    },
    {
      "x": -86,
      "y": 11,
      "z": -88,
      "name": "Rock_Lime"
    },
    {
      "x": -86,
      "y": 12,
      "z": -88,
      "name": "Rock_Lime"
    },
    {
      "x": -86,
      "y": 13,
      "z": -88,
      "name": "Rock_Lime"
    },
    {
      "x": -86,
      "y": 14,
      "z": -88,
      "name": "Rock_Lime"
    },
    {
      "x": -86,
      "y": 15,
      "z": -88,
      "name": "Soil_Gravel_Lime"
    },
    {
      "x": -86,
      "y": 16,
      "z": -88,
      "name": "Rock_Lime"
    },
    {
      "x": -86,
      "y": 17,
      "z": -88,
      "name": "Rock_Lime"
    },
    {
      "x": -86,
      "y": 18,
      "z": -88,
      "name": "Soil_Gravel_Lime"
    },
    {
      "x": -86,
      "y": 19,
      "z": -88,
      "name": "Rock_Lime"
    },
    {
      "x": -86,
      "y": 20,
      "z": -88,
      "name": "Rock_Lime"
    },
    {
      "x": -86,
      "y": 21,
      "z": -88,
      "name": "Soil_Gravel_Lime"
    },
    {
      "x": -86,
      "y": 22,
      "z": -88,
      "name": "Rock_Lime"
    },
    {
      "x": -86,
      "y": 23,
      "z": -88,
      "name": "Soil_Gravel_Lime"
    },
    {
      "x": -86,
      "y": 24,
      "z": -88,
      "name": "Rock_Lime"
    },
    {
      "x": -86,
      "y": 25,
      "z": -88,
      "name": "Rock_Lime"
    },
    {
      "x": -86,
      "y": 26,
      "z": -88,
      "name": "Rock_Lime"
    },
    {
      "x": -86,
      "y": 27,
      "z": -88,
      "name": "Soil_Gravel_Lime"
    },
    {
      "x": -86,
      "y": 28,
      "z": -88,
      "name": "Rock_Lime"
    },
    {
      "x": -86,
      "y": 29,
      "z": -88,
      "name": "Rock_Lime"
    },
    {
      "x": -86,
      "y": 30,
      "z": -88,
      "name": "Plant_Coral_Block_Lime"
    },
    {
      "x": -86,
      "y": 31,
      "z": -88,
      "name": "Soil_Clay_Smooth_Lime"
    },
    {
      "x": -86,
      "y": 32,
      "z": -88,
      "name": "Soil_Clay_Smooth_Lime"
    },
    {
      "x": -86,
      "y": 33,
      "z": -88,
      "name": "Plant_Coral_Block_Lime"
    },
    {
      "x": -86,
      "y": 34,
      "z": -88,
      "name": "Plant_Coral_Block_Lime"
    },
    {
      "x": -86,
      "y": 35,
      "z": -88,
      "name": "Plant_Coral_Block_Lime"
    },
    {
      "x": -86,
      "y": 36,
      "z": -88,
      "name": "Plant_Coral_Block_Lime"
    },
    {
      "x": -86,
      "y": 37,
      "z": -88,
      "name": "Soil_Clay_Smooth_Lime"
    },
    {
      "x": -86,
      "y": 38,
      "z": -88,
      "name": "Plant_Moss_Rug_Pink",
      "support": 15
    },
    {
      "x": -86,
      "y": 4,
      "z": -87,
      "name": "Rock_Lime"
    },
    {
      "x": -86,
      "y": 5,
      "z": -87,
      "name": "Soil_Gravel_Lime"
    },
    {
      "x": -86,
      "y": 6,
      "z": -87,
      "name": "Rock_Lime"
    },
    {
      "x": -86,
      "y": 7,
      "z": -87,
      "name": "Rock_Lime"
    },
    {
      "x": -86,
      "y": 8,
      "z": -87,
      "name": "Soil_Gravel_Lime"
    },
    {
      "x": -86,
      "y": 9,
      "z": -87,
      "name": "Rock_Lime"
    },
    {
      "x": -86,
      "y": 10,
      "z": -87,
      "name": "Rock_Lime"
    },
    {
      "x": -86,
      "y": 11,
      "z": -87,
      "name": "Rock_Lime"
    },
    {
      "x": -86,
      "y": 12,
      "z": -87,
      "name": "Soil_Gravel_Lime"
    },
    {
      "x": -86,
      "y": 13,
      "z": -87,
      "name": "Rock_Lime"
    },
    {
      "x": -86,
      "y": 14,
      "z": -87,
      "name": "Rock_Lime"
    },
    {
      "x": -86,
      "y": 15,
      "z": -87,
      "name": "Soil_Gravel_Lime"
    },
    {
      "x": -86,
      "y": 16,
      "z": -87,
      "name": "Rock_Lime"
    },
    {
      "x": -86,
      "y": 17,
      "z": -87,
      "name": "Rock_Lime"
    },
    {
      "x": -86,
      "y": 18,
      "z": -87,
      "name": "Rock_Lime"
    },
    {
      "x": -86,
      "y": 19,
      "z": -87,
      "name": "Rock_Lime"
    },
    {
      "x": -86,
      "y": 20,
      "z": -87,
      "name": "Rock_Lime"
    },
    {
      "x": -86,
      "y": 21,
      "z": -87,
      "name": "Soil_Gravel_Lime"
    },
    {
      "x": -86,
      "y": 22,
      "z": -87,
      "name": "Rock_Lime"
    },
    {
      "x": -86,
      "y": 23,
      "z": -87,
      "name": "Soil_Gravel_Lime"
    },
    {
      "x": -86,
      "y": 24,
      "z": -87,
      "name": "Rock_Lime"
    },
    {
      "x": -86,
      "y": 25,
      "z": -87,
      "name": "Soil_Gravel_Lime"
    },
    {
      "x": -86,
      "y": 26,
      "z": -87,
      "name": "Rock_Lime"
    },
    {
      "x": -86,
      "y": 27,
      "z": -87,
      "name": "Rock_Lime"
    },
    {
      "x": -86,
      "y": 28,
      "z": -87,
      "name": "Soil_Gravel_Lime"
    },
    {
      "x": -86,
      "y": 29,
      "z": -87,
      "name": "Rock_Lime"
    },
    {
      "x": -86,
      "y": 30,
      "z": -87,
      "name": "Plant_Coral_Block_Lime"
    },
    {
      "x": -86,
      "y": 31,
      "z": -87,
      "name": "Plant_Coral_Block_Lime"
    },
    {
      "x": -86,
      "y": 32,
      "z": -87,
      "name": "Plant_Coral_Block_Lime"
    },
    {
      "x": -86,
      "y": 33,
      "z": -87,
      "name": "Soil_Clay_Smooth_Lime"
    },
    {
      "x": -86,
      "y": 34,
      "z": -87,
      "name": "Plant_Coral_Block_Lime"
    },
    {
      "x": -86,
      "y": 35,
      "z": -87,
      "name": "Soil_Clay_Lime"
    },
    {
      "x": -86,
      "y": 36,
      "z": -87,
      "name": "Soil_Clay_Lime"
    },
    {
      "x": -86,
      "y": 37,
      "z": -87,
      "name": "Plant_Coral_Block_Lime"
    },
    {
      "x": -86,
      "y": 38,
      "z": -87,
      "name": "Plant_Moss_Rug_Pink",
      "support": 15
    },
    {
      "x": -86,
      "y": 4,
      "z": -86,
      "name": "Rock_Lime"
    },
    {
      "x": -86,
      "y": 5,
      "z": -86,
      "name": "Rock_Lime"
    },
    {
      "x": -86,
      "y": 6,
      "z": -86,
      "name": "Rock_Lime"
    },
    {
      "x": -86,
      "y": 7,
      "z": -86,
      "name": "Rock_Lime"
    },
    {
      "x": -86,
      "y": 8,
      "z": -86,
      "name": "Rock_Lime"
    },
    {
      "x": -86,
      "y": 9,
      "z": -86,
      "name": "Rock_Lime"
    },
    {
      "x": -86,
      "y": 10,
      "z": -86,
      "name": "Soil_Gravel_Lime"
    },
    {
      "x": -86,
      "y": 11,
      "z": -86,
      "name": "Soil_Gravel_Lime"
    },
    {
      "x": -86,
      "y": 12,
      "z": -86,
      "name": "Rock_Lime"
    },
    {
      "x": -86,
      "y": 13,
      "z": -86,
      "name": "Rock_Lime"
    },
    {
      "x": -86,
      "y": 14,
      "z": -86,
      "name": "Rock_Lime"
    },
    {
      "x": -86,
      "y": 15,
      "z": -86,
      "name": "Soil_Gravel_Lime"
    },
    {
      "x": -86,
      "y": 16,
      "z": -86,
      "name": "Soil_Gravel_Lime"
    },
    {
      "x": -86,
      "y": 17,
      "z": -86,
      "name": "Rock_Lime"
    },
    {
      "x": -86,
      "y": 18,
      "z": -86,
      "name": "Rock_Lime"
    },
    {
      "x": -86,
      "y": 19,
      "z": -86,
      "name": "Rock_Lime"
    },
    {
      "x": -86,
      "y": 20,
      "z": -86,
      "name": "Rock_Lime"
    },
    {
      "x": -86,
      "y": 21,
      "z": -86,
      "name": "Rock_Lime"
    },
    {
      "x": -86,
      "y": 22,
      "z": -86,
      "name": "Rock_Lime"
    },
    {
      "x": -86,
      "y": 23,
      "z": -86,
      "name": "Soil_Gravel_Lime"
    },
    {
      "x": -86,
      "y": 24,
      "z": -86,
      "name": "Rock_Lime"
    },
    {
      "x": -86,
      "y": 25,
      "z": -86,
      "name": "Rock_Lime"
    },
    {
      "x": -86,
      "y": 26,
      "z": -86,
      "name": "Soil_Gravel_Lime"
    },
    {
      "x": -86,
      "y": 27,
      "z": -86,
      "name": "Rock_Lime"
    },
    {
      "x": -86,
      "y": 28,
      "z": -86,
      "name": "Soil_Clay_Lime"
    },
    {
      "x": -86,
      "y": 29,
      "z": -86,
      "name": "Soil_Clay_Smooth_Lime"
    },
    {
      "x": -86,
      "y": 30,
      "z": -86,
      "name": "Plant_Coral_Block_Lime"
    },
    {
      "x": -86,
      "y": 31,
      "z": -86,
      "name": "Plant_Coral_Block_Lime"
    },
    {
      "x": -86,
      "y": 32,
      "z": -86,
      "name": "Soil_Clay_Lime"
    },
    {
      "x": -86,
      "y": 33,
      "z": -86,
      "name": "Soil_Clay_Smooth_Lime"
    },
    {
      "x": -86,
      "y": 34,
      "z": -86,
      "name": "Soil_Clay_Lime"
    },
    {
      "x": -86,
      "y": 4,
      "z": -85,
      "name": "Soil_Gravel_Lime"
    },
    {
      "x": -86,
      "y": 5,
      "z": -85,
      "name": "Rock_Lime"
    },
    {
      "x": -86,
      "y": 6,
      "z": -85,
      "name": "Soil_Gravel_Lime"
    },
    {
      "x": -86,
      "y": 7,
      "z": -85,
      "name": "Rock_Lime"
    },
    {
      "x": -86,
      "y": 8,
      "z": -85,
      "name": "Rock_Lime"
    },
    {
      "x": -86,
      "y": 9,
      "z": -85,
      "name": "Rock_Lime"
    },
    {
      "x": -86,
      "y": 10,
      "z": -85,
      "name": "Rock_Lime"
    },
    {
      "x": -86,
      "y": 11,
      "z": -85,
      "name": "Soil_Gravel_Lime"
    },
    {
      "x": -86,
      "y": 12,
      "z": -85,
      "name": "Soil_Gravel_Lime"
    },
    {
      "x": -86,
      "y": 13,
      "z": -85,
      "name": "Soil_Gravel_Lime"
    },
    {
      "x": -86,
      "y": 14,
      "z": -85,
      "name": "Rock_Lime"
    },
    {
      "x": -86,
      "y": 15,
      "z": -85,
      "name": "Rock_Lime"
    },
    {
      "x": -86,
      "y": 16,
      "z": -85,
      "name": "Rock_Lime"
    },
    {
      "x": -86,
      "y": 17,
      "z": -85,
      "name": "Soil_Gravel_Lime"
    },
    {
      "x": -86,
      "y": 18,
      "z": -85,
      "name": "Rock_Lime"
    },
    {
      "x": -86,
      "y": 19,
      "z": -85,
      "name": "Soil_Gravel_Lime"
    },
    {
      "x": -86,
      "y": 20,
      "z": -85,
      "name": "Rock_Lime"
    },
    {
      "x": -86,
      "y": 21,
      "z": -85,
      "name": "Rock_Lime"
    },
    {
      "x": -86,
      "y": 22,
      "z": -85,
      "name": "Soil_Gravel_Lime"
    },
    {
      "x": -86,
      "y": 23,
      "z": -85,
      "name": "Rock_Lime"
    },
    {
      "x": -86,
