{
  "version": 8,
  "blockIdVersion": 11,
  "anchorX": -52,
  "anchorY": 16,
  "anchorZ": -84,
  "blocks": [
    {
      "x": -62,
      "y": 13,
      "z": -93,
      "name": "Rock_Lime"
    },
    {
      "x": -62,
      "y": 14,
      "z": -93,
      "name": "Soil_Gravel_Lime"
    },
    {
      "x": -62,
      "y": 15,
      "z": -93,
      "name": "Soil_Gravel_Lime"
    },
    {
      "x": -62,
      "y": 16,
      "z": -93,
      "name": "Rock_Lime"
    },
    {
      "x": -62,
      "y": 17,
      "z": -93,
      "name": "Rock_Lime_Stalactite_Large"
    },
    {
      "x": -62,
      "y": 18,
      "z": -93,
      "name": "Rock_Lime_Stalactite_Large",
      "filler": 1024
    },
    {
      "x": -62,
      "y": 13,
      "z": -92,
      "name": "Rock_Lime"
    },
    {
      "x": -62,
      "y": 14,
      "z": -92,
      "name": "Soil_Gravel_Lime"
    },
    {
      "x": -62,
      "y": 15,
      "z": -92,
      "name": "Rock_Lime"
    },
    {
      "x": -62,
      "y": 16,
      "z": -92,
      "name": "Rock_Lime"
    },
    {
      "x": -62,
      "y": 17,
      "z": -92,
      "name": "Soil_Gravel_Lime"
    },
    {
      "x": -62,
      "y": 18,
      "z": -92,
      "name": "Rock_Lime"
    },
    {
      "x": -62,
      "y": 13,
      "z": -91,
      "name": "Rock_Lime"
    },
    {
      "x": -62,
      "y": 14,
      "z": -91,
      "name": "Rock_Lime"
    },
    {
      "x": -62,
      "y": 15,
      "z": -91,
      "name": "Soil_Gravel_Lime"
    },
    {
      "x": -62,
      "y": 16,
      "z": -91,
      "name": "Soil_Gravel_Lime"
    },
    {
      "x": -62,
      "y": 17,
      "z": -91,
      "name": "Soil_Gravel_Lime"
    },
    {
      "x": -62,
      "y": 18,
      "z": -91,
      "name": "Rock_Lime"
    },
    {
      "x": -62,
      "y": 19,
      "z": -91,
      "name": "Rock_Lime"
    },
    {
      "x": -62,
      "y": 13,
      "z": -90,
      "name": "Rock_Lime"
    },
    {
      "x": -62,
      "y": 14,
      "z": -90,
      "name": "Rock_Lime"
    },
    {
      "x": -62,
      "y": 15,
      "z": -90,
      "name": "Rock_Lime"
    },
    {
      "x": -62,
      "y": 16,
      "z": -90,
      "name": "Soil_Gravel_Lime"
    },
    {
      "x": -62,
      "y": 17,
      "z": -90,
      "name": "Soil_Gravel_Lime"
    },
    {
      "x": -62,
      "y": 18,
      "z": -90,
      "name": "Rock_Lime"
    },
    {
      "x": -62,
      "y": 19,
      "z": -90,
      "name": "Rock_Lime"
    },
    {
      "x": -62,
      "y": 20,
      "z": -90,
      "name": "Rock_Lime_Stalactite_Large"
    },
    {
      "x": -62,
      "y": 21,
      "z": -90,
      "name": "Rock_Lime_Stalactite_Large",
      "filler": 1024
    },
    {
      "x": -62,
      "y": 14,
      "z": -89,
      "name": "Rock_Lime"
    },
    {
      "x": -62,
      "y": 15,
      "z": -89,
      "name": "Soil_Gravel_Lime"
    },
    {
      "x": -62,
      "y": 16,
      "z": -89,
      "name": "Soil_Gravel_Lime"
    },
    {
      "x": -62,
      "y": 17,
      "z": -89,
      "name": "Soil_Gravel_Lime"
    },
    {
      "x": -62,
      "y": 18,
      "z": -89,
      "name": "Soil_Gravel_Lime"
    },
    {
      "x": -62,
      "y": 21,
      "z": -89,
      "name": "Plant_Leaves_Dead",
      "support": 15
    },
    {
      "x": -62,
      "y": 23,
      "z": -89,
      "name": "Plant_Leaves_Dead",
      "support": 15
    },
    {
      "x": -62,
      "y": 15,
      "z": -88,
      "name": "Rock_Lime"
    },
    {
      "x": -62,
      "y": 16,
      "z": -88,
      "name": "Soil_Gravel_Lime"
    },
    {
      "x": -62,
      "y": 17,
      "z": -88,
      "name": "Rock_Lime"
    },
    {
      "x": -62,
      "y": 18,
      "z": -88,
      "name": "Rubble_Lime_Medium",
      "support": 15
    },
    {
      "x": -62,
      "y": 15,
      "z": -86,
      "name": "Plant_Leaves_Dead",
      "support": 15
    },
    {
      "x": -61,
      "y": 12,
      "z": -95,
      "name": "Rock_Lime"
    },
    {
      "x": -61,
      "y": 13,
      "z": -95,
      "name": "Soil_Gravel_Lime"
    },
    {
      "x": -61,
      "y": 14,
      "z": -95,
      "name": "Rock_Lime"
    },
    {
      "x": -61,
      "y": 15,
      "z": -95,
      "name": "Soil_Gravel_Lime"
    },
    {
      "x": -61,
      "y": 16,
      "z": -95,
      "name": "Rock_Lime"
    },
    {
      "x": -61,
      "y": 17,
      "z": -95,
      "name": "Soil_Gravel_Lime"
    },
    {
      "x": -61,
      "y": 6,
      "z": -94,
      "name": "Soil_Gravel_Lime"
    },
    {
      "x": -61,
      "y": 7,
      "z": -94,
      "name": "Soil_Gravel_Lime"
    },
    {
      "x": -61,
      "y": 8,
      "z": -94,
      "name": "Soil_Gravel_Lime"
    },
    {
      "x": -61,
      "y": 9,
      "z": -94,
      "name": "Rock_Lime"
    },
    {
      "x": -61,
      "y": 10,
      "z": -94,
      "name": "Rock_Lime"
    },
    {
      "x": -61,
      "y": 11,
      "z": -94,
      "name": "Rock_Lime"
    },
    {
      "x": -61,
      "y": 12,
      "z": -94,
      "name": "Rock_Lime"
    },
    {
      "x": -61,
      "y": 13,
      "z": -94,
      "name": "Soil_Gravel_Lime"
    },
    {
      "x": -61,
      "y": 14,
      "z": -94,
      "name": "Soil_Gravel_Lime"
    },
    {
      "x": -61,
      "y": 15,
      "z": -94,
      "name": "Soil_Gravel_Lime"
    },
    {
      "x": -61,
      "y": 16,
      "z": -94,
      "name": "Soil_Gravel_Lime"
    },
    {
      "x": -61,
      "y": 17,
      "z": -94,
      "name": "Soil_Gravel_Lime"
    },
    {
      "x": -61,
      "y": 18,
      "z": -94,
      "name": "Rock_Lime"
    },
    {
      "x": -61,
      "y": 19,
      "z": -94,
      "name": "Soil_Gravel_Lime"
    },
    {
      "x": -61,
      "y": 5,
      "z": -93,
      "name": "Rock_Lime"
    },
    {
      "x": -61,
      "y": 6,
      "z": -93,
      "name": "Soil_Gravel_Lime"
    },
    {
      "x": -61,
      "y": 7,
      "z": -93,
      "name": "Rock_Lime"
    },
    {
      "x": -61,
      "y": 8,
      "z": -93,
      "name": "Rock_Lime"
    },
    {
      "x": -61,
      "y": 9,
      "z": -93,
      "name": "Rock_Lime"
    },
    {
      "x": -61,
      "y": 10,
      "z": -93,
      "name": "Soil_Gravel_Lime"
    },
    {
      "x": -61,
      "y": 11,
      "z": -93,
      "name": "Rock_Lime"
    },
    {
      "x": -61,
      "y": 12,
      "z": -93,
      "name": "Soil_Gravel_Lime"
    },
    {
      "x": -61,
      "y": 13,
      "z": -93,
      "name": "Soil_Gravel_Lime"
    },
    {
      "x": -61,
      "y": 14,
      "z": -93,
      "name": "Rock_Lime"
    },
    {
      "x": -61,
      "y": 15,
      "z": -93,
      "name": "Rock_Lime"
    },
    {
      "x": -61,
      "y": 16,
      "z": -93,
      "name": "Soil_Gravel_Lime"
    },
    {
      "x": -61,
      "y": 17,
      "z": -93,
      "name": "Rock_Lime"
    },
    {
      "x": -61,
      "y": 18,
      "z": -93,
      "name": "Rock_Lime"
    },
    {
      "x": -61,
      "y": 19,
      "z": -93,
      "name": "Soil_Gravel_Lime"
    },
    {
      "x": -61,
      "y": 20,
      "z": -93,
      "name": "Soil_Gravel_Lime"
    },
    {
      "x": -61,
      "y": 21,
      "z": -93,
      "name": "Rock_Lime"
    },
    {
      "x": -61,
      "y": 5,
      "z": -92,
      "name": "Rock_Lime"
    },
    {
      "x": -61,
      "y": 6,
      "z": -92,
      "name": "Rock_Lime"
    },
    {
      "x": -61,
      "y": 7,
      "z": -92,
      "name": "Rock_Lime"
    },
    {
      "x": -61,
      "y": 8,
      "z": -92,
      "name": "Soil_Gravel_Lime"
    },
    {
      "x": -61,
      "y": 9,
      "z": -92,
      "name": "Soil_Gravel_Lime"
    },
    {
      "x": -61,
      "y": 10,
      "z": -92,
      "name": "Soil_Gravel_Lime"
    },
    {
      "x": -61,
      "y": 11,
      "z": -92,
      "name": "Soil_Gravel_Lime"
    },
    {
      "x": -61,
      "y": 12,
      "z": -92,
      "name": "Soil_Gravel_Lime"
    },
    {
      "x": -61,
      "y": 13,
      "z": -92,
      "name": "Soil_Gravel_Lime"
    },
    {
      "x": -61,
      "y": 14,
      "z": -92,
      "name": "Soil_Gravel_Lime"
    },
    {
      "x": -61,
      "y": 15,
      "z": -92,
      "name": "Soil_Gravel_Lime"
    },
    {
      "x": -61,
      "y": 16,
      "z": -92,
      "name": "Soil_Gravel_Lime"
    },
    {
      "x": -61,
      "y": 17,
      "z": -92,
      "name": "Rock_Lime"
    },
    {
      "x": -61,
      "y": 18,
      "z": -92,
      "name": "Rock_Lime"
    },
    {
      "x": -61,
      "y": 19,
      "z": -92,
      "name": "Rock_Lime"
    },
    {
      "x": -61,
      "y": 20,
      "z": -92,
      "name": "Rock_Lime"
    },
    {
      "x": -61,
      "y": 21,
      "z": -92,
      "name": "Rock_Lime"
    },
    {
      "x": -61,
      "y": 22,
      "z": -92,
      "name": "Rock_Lime"
    },
    {
      "x": -61,
      "y": 23,
      "z": -92,
      "name": "Rubble_Lime_Medium",
      "support": 15
    },
    {
      "x": -61,
      "y": 5,
      "z": -91,
      "name": "Rock_Lime"
    },
    {
      "x": -61,
      "y": 6,
      "z": -91,
      "name": "Rock_Lime"
    },
    {
      "x": -61,
      "y": 7,
      "z": -91,
      "name": "Rock_Lime"
    },
    {
      "x": -61,
      "y": 8,
      "z": -91,
      "name": "Rock_Lime"
    },
    {
      "x": -61,
      "y": 9,
      "z": -91,
      "name": "Soil_Gravel_Lime"
    },
    {
      "x": -61,
      "y": 10,
      "z": -91,
      "name": "Rock_Lime"
    },
    {
      "x": -61,
      "y": 11,
      "z": -91,
      "name": "Rock_Lime"
    },
    {
      "x": -61,
      "y": 12,
      "z": -91,
      "name": "Soil_Gravel_Lime"
    },
    {
      "x": -61,
      "y": 13,
      "z": -91,
      "name": "Rock_Lime"
    },
    {
      "x": -61,
      "y": 14,
      "z": -91,
      "name": "Rock_Lime"
    },
    {
      "x": -61,
      "y": 15,
      "z": -91,
      "name": "Soil_Gravel_Lime"
    },
    {
      "x": -61,
      "y": 16,
      "z": -91,
      "name": "Rock_Lime"
    },
    {
      "x": -61,
      "y": 17,
      "z": -91,
      "name": "Soil_Gravel_Lime"
    },
    {
      "x": -61,
      "y": 18,
      "z": -91,
      "name": "Soil_Gravel_Lime"
    },
    {
      "x": -61,
      "y": 19,
      "z": -91,
      "name": "Rock_Lime"
    },
    {
      "x": -61,
      "y": 20,
      "z": -91,
      "name": "Rock_Lime"
    },
    {
      "x": -61,
      "y": 21,
      "z": -91,
      "name": "Soil_Gravel_Lime"
    },
    {
      "x": -61,
      "y": 22,
      "z": -91,
      "name": "Soil_Gravel_Lime"
    },
    {
      "x": -61,
      "y": 23,
      "z": -91,
      "name": "Rock_Lime"
    },
    {
      "x": -61,
      "y": 24,
      "z": -91,
      "name": "Plant_Crop_Mushroom_Cap_Poison",
      "components": {
        "Components": {
          "FarmingBlock": {
            "LastTickGameTime": "0001-01-01T12:00:00Z"
          },
          "PlacedByInteraction": {
            "WhoPlacedUuid": {
              "$binary": "HCpUQzdeSaiDYHpoRePv+w==",
              "$type": "04"
            }
          }
        }
      }
    },
    {
      "x": -61,
      "y": 5,
      "z": -90,
      "name": "Rock_Lime"
    },
    {
      "x": -61,
      "y": 6,
      "z": -90,
      "name": "Rock_Lime"
    },
    {
      "x": -61,
      "y": 7,
      "z": -90,
      "name": "Soil_Gravel_Lime"
    },
    {
      "x": -61,
      "y": 8,
      "z": -90,
      "name": "Rock_Lime"
    },
    {
      "x": -61,
      "y": 9,
      "z": -90,
      "name": "Rock_Lime"
    },
    {
      "x": -61,
      "y": 10,
      "z": -90,
      "name": "Soil_Gravel_Lime"
    },
    {
      "x": -61,
      "y": 11,
      "z": -90,
      "name": "Soil_Gravel_Lime"
    },
    {
      "x": -61,
      "y": 12,
      "z": -90,
      "name": "Soil_Gravel_Lime"
    },
    {
      "x": -61,
      "y": 13,
      "z": -90,
      "name": "Rock_Lime"
    },
    {
      "x": -61,
      "y": 14,
      "z": -90,
      "name": "Rock_Lime"
    },
    {
      "x": -61,
      "y": 15,
      "z": -90,
      "name": "Rock_Lime"
    },
    {
      "x": -61,
      "y": 16,
      "z": -90,
      "name": "Soil_Gravel_Lime"
    },
    {
      "x": -61,
      "y": 17,
      "z": -90,
      "name": "Soil_Gravel_Lime"
    },
    {
      "x": -61,
      "y": 18,
      "z": -90,
      "name": "Rock_Lime"
    },
    {
      "x": -61,
      "y": 19,
      "z": -90,
      "name": "Rock_Lime"
    },
    {
      "x": -61,
      "y": 20,
      "z": -90,
      "name": "Rock_Lime"
    },
    {
      "x": -61,
      "y": 21,
      "z": -90,
      "name": "Rock_Lime"
    },
    {
      "x": -61,
      "y": 22,
      "z": -90,
      "name": "Rock_Lime"
    },
    {
      "x": -61,
      "y": 23,
      "z": -90,
      "name": "Rock_Lime"
    },
    {
      "x": -61,
      "y": 24,
      "z": -90,
      "name": "Soil_Gravel_Lime"
    },
    {
      "x": -61,
      "y": 25,
      "z": -90,
      "name": "Rock_Lime"
    },
    {
      "x": -61,
      "y": 26,
      "z": -90,
      "name": "Rock_Lime_Stalactite_Large"
    },
    {
      "x": -61,
      "y": 27,
      "z": -90,
      "name": "Rock_Lime_Stalactite_Large",
      "filler": 1024
    },
    {
      "x": -61,
      "y": 6,
      "z": -89,
      "name": "Soil_Gravel_Lime"
    },
    {
      "x": -61,
      "y": 7,
      "z": -89,
      "name": "Soil_Gravel_Lime"
    },
    {
      "x": -61,
      "y": 8,
      "z": -89,
      "name": "Soil_Gravel_Lime"
    },
    {
      "x": -61,
      "y": 9,
      "z": -89,
      "name": "Soil_Gravel_Lime"
    },
    {
      "x": -61,
      "y": 10,
      "z": -89,
      "name": "Soil_Gravel_Lime"
    },
    {
      "x": -61,
      "y": 11,
      "z": -89,
      "name": "Rock_Lime"
    },
    {
      "x": -61,
      "y": 12,
      "z": -89,
      "name": "Soil_Gravel_Lime"
    },
    {
      "x": -61,
      "y": 13,
      "z": -89,
      "name": "Soil_Gravel_Lime"
    },
    {
      "x": -61,
      "y": 14,
      "z": -89,
      "name": "Rock_Lime"
    },
    {
      "x": -61,
      "y": 15,
      "z": -89,
      "name": "Rock_Lime"
    },
    {
      "x": -61,
      "y": 16,
      "z": -89,
      "name": "Rock_Lime"
    },
    {
      "x": -61,
      "y": 17,
      "z": -89,
      "name": "Rock_Lime"
    },
    {
      "x": -61,
      "y": 18,
      "z": -89,
      "name": "Rock_Lime"
    },
    {
      "x": -61,
      "y": 19,
      "z": -89,
      "name": "Soil_Gravel_Lime"
    },
    {
      "x": -61,
      "y": 20,
      "z": -89,
      "name": "Rock_Lime"
    },
    {
      "x": -61,
      "y": 21,
      "z": -89,
      "name": "Soil_Gravel_Lime"
    },
    {
      "x": -61,
      "y": 22,
      "z": -89,
      "name": "Soil_Gravel_Lime"
    },
    {
      "x": -61,
      "y": 23,
      "z": -89,
      "name": "Soil_Gravel_Lime"
    },
    {
      "x": -61,
      "y": 24,
      "z": -89,
      "name": "Soil_Gravel_Lime"
    },
    {
      "x": -61,
      "y": 25,
      "z": -89,
      "name": "Soil_Gravel_Lime"
    },
    {
      "x": -61,
      "y": 6,
      "z": -88,
      "name": "Rock_Lime"
    },
    {
      "x": -61,
      "y": 7,
      "z": -88,
      "name": "Rock_Lime"
    },
    {
      "x": -61,
      "y": 8,
      "z": -88,
      "name": "Rock_Lime"
    },
    {
      "x": -61,
      "y": 9,
      "z": -88,
      "name": "Rock_Lime"
    },
    {
      "x": -61,
      "y": 10,
      "z": -88,
      "name": "Soil_Gravel_Lime"
    },
    {
      "x": -61,
      "y": 11,
      "z": -88,
      "name": "Rock_Lime"
    },
    {
      "x": -61,
      "y": 12,
      "z": -88,
      "name": "Rock_Lime"
    },
    {
      "x": -61,
      "y": 13,
      "z": -88,
      "name": "Soil_Gravel_Lime"
    },
    {
      "x": -61,
      "y": 14,
      "z": -88,
      "name": "Soil_Gravel_Lime"
    },
    {
      "x": -61,
      "y": 15,
      "z": -88,
      "name": "Rock_Lime"
    },
    {
      "x": -61,
      "y": 16,
      "z": -88,
      "name": "Soil_Gravel_Lime"
    },
    {
      "x": -61,
      "y": 17,
      "z": -88,
      "name": "Soil_Gravel_Lime"
    },
    {
      "x": -61,
      "y": 18,
      "z": -88,
      "name": "Soil_Gravel_Lime"
    },
    {
      "x": -61,
      "y": 19,
      "z": -88,
      "name": "Rock_Lime"
    },
    {
      "x": -61,
      "y": 20,
      "z": -88,
      "name": "Soil_Gravel_Lime"
    },
    {
      "x": -61,
      "y": 21,
      "z": -88,
      "name": "Soil_Gravel_Lime"
    },
    {
      "x": -61,
      "y": 22,
      "z": -88,
      "name": "Rock_Lime"
    },
    {
      "x": -61,
      "y": 23,
      "z": -88,
      "name": "Soil_Gravel_Lime"
    },
    {
      "x": -61,
      "y": 6,
      "z": -87,
      "name": "Soil_Gravel_Lime"
    },
    {
      "x": -61,
      "y": 7,
      "z": -87,
      "name": "Rock_Lime"
    },
    {
      "x": -61,
      "y": 8,
      "z": -87,
      "name": "Rock_Lime"
    },
    {
      "x": -61,
      "y": 9,
      "z": -87,
      "name": "Soil_Gravel_Lime"
    },
    {
      "x": -61,
      "y": 10,
      "z": -87,
      "name": "Soil_Gravel_Lime"
    },
    {
      "x": -61,
      "y": 11,
      "z": -87,
      "name": "Rock_Lime"
    },
    {
      "x": -61,
      "y": 12,
      "z": -87,
      "name": "Rock_Lime"
    },
    {
      "x": -61,
      "y": 13,
      "z": -87,
      "name": "Rock_Lime"
    },
    {
      "x": -61,
      "y": 14,
      "z": -87,
      "name": "Rock_Lime"
    },
    {
      "x": -61,
      "y": 15,
      "z": -87,
      "name": "Soil_Gravel_Lime"
    },
    {
      "x": -61,
      "y": 16,
      "z": -87,
      "name": "Soil_Gravel_Lime"
    },
    {
      "x": -61,
      "y": 17,
      "z": -87,
      "name": "Rock_Lime"
    },
    {
      "x": -61,
      "y": 18,
      "z": -87,
      "name": "Rock_Lime"
    },
    {
      "x": -61,
      "y": 19,
      "z": -87,
      "name": "Rock_Lime"
    },
    {
      "x": -61,
      "y": 20,
      "z": -87,
      "name": "Soil_Gravel_Lime"
    },
    {
      "x": -61,
      "y": 21,
      "z": -87,
      "name": "Rock_Lime"
    },
    {
      "x": -61,
      "y": 22,
      "z": -87,
      "name": "Plant_Crop_Mushroom_Cap_Poison",
      "components": {
        "Components": {
          "FarmingBlock": {
            "LastTickGameTime": "0001-01-01T12:00:00Z"
          },
          "PlacedByInteraction": {
            "WhoPlacedUuid": {
              "$binary": "HCpUQzdeSaiDYHpoRePv+w==",
              "$type": "04"
            }
          }
        }
      }
    },
    {
      "x": -61,
      "y": 6,
      "z": -86,
      "name": "Soil_Gravel_Lime"
    },
    {
      "x": -61,
      "y": 7,
      "z": -86,
      "name": "Soil_Gravel_Lime"
    },
    {
      "x": -61,
      "y": 8,
      "z": -86,
      "name": "Soil_Gravel_Lime"
    },
    {
      "x": -61,
      "y": 9,
      "z": -86,
      "name": "Soil_Gravel_Lime"
    },
    {
      "x": -61,
      "y": 10,
      "z": -86,
      "name": "Rock_Lime"
    },
    {
      "x": -61,
      "y": 11,
      "z": -86,
      "name": "Rock_Lime"
    },
    {
      "x": -61,
      "y": 12,
      "z": -86,
      "name": "Rock_Lime"
    },
    {
      "x": -61,
      "y": 13,
      "z": -86,
      "name": "Rock_Lime"
    },
    {
      "x": -61,
      "y": 14,
      "z": -86,
      "name": "Rock_Lime"
    },
    {
      "x": -61,
      "y": 15,
      "z": -86,
      "name": "Soil_Gravel_Lime"
    },
    {
      "x": -61,
      "y": 16,
      "z": -86,
      "name": "Rock_Lime"
    },
    {
      "x": -61,
      "y": 17,
      "z": -86,
      "name": "Rock_Lime"
    },
    {
      "x": -61,
      "y": 18,
      "z": -86,
      "name": "Rubble_Lime_Medium",
      "support": 15
    },
    {
      "x": -61,
      "y": 5,
      "z": -85,
      "name": "Rock_Lime"
    },
    {
      "x": -61,
      "y": 6,
      "z": -85,
      "name": "Rock_Lime"
    },
    {
      "x": -61,
      "y": 7,
      "z": -85,
      "name": "Soil_Gravel_Lime"
    },
    {
      "x": -61,
      "y": 8,
      "z": -85,
      "name": "Rock_Lime"
    },
    {
      "x": -61,
      "y": 9,
      "z": -85,
      "name": "Rock_Lime"
    },
    {
      "x": -61,
      "y": 10,
      "z": -85,
      "name": "Rock_Lime"
    },
    {
      "x": -61,
      "y": 11,
      "z": -85,
      "name": "Rock_Lime"
    },
    {
      "x": -61,
      "y": 12,
      "z": -85,
      "name": "Rock_Lime"
    },
    {
      "x": -61,
      "y": 13,
      "z": -85,
      "name": "Rubble_Lime_Medium",
      "support": 15
    },
    {
      "x": -61,
      "y": 6,
      "z": -84,
      "name": "Rock_Lime"
    },
    {
      "x": -61,
      "y": 7,
      "z": -84,
      "name": "Rock_Lime"
    },
    {
      "x": -61,
      "y": 8,
      "z": -84,
      "name": "Soil_Gravel_Lime"
    },
    {
      "x": -61,
      "y": 9,
      "z": -84,
      "name": "Soil_Gravel_Lime"
    },
    {
      "x": -61,
      "y": 10,
      "z": -84,
      "name": "Rock_Lime"
    },
    {
      "x": -60,
      "y": 5,
      "z": -95,
      "name": "Soil_Gravel_Lime"
    },
    {
      "x": -60,
      "y": 6,
      "z": -95,
      "name": "Rock_Lime"
    },
    {
      "x": -60,
      "y": 7,
      "z": -95,
      "name": "Rock_Lime"
    },
    {
      "x": -60,
      "y": 8,
      "z": -95,
      "name": "Rock_Lime"
    },
    {
      "x": -60,
      "y": 9,
      "z": -95,
      "name": "Soil_Gravel_Lime"
    },
    {
      "x": -60,
      "y": 10,
      "z": -95,
      "name": "Rock_Lime"
    },
    {
      "x": -60,
      "y": 11,
      "z": -95,
      "name": "Soil_Gravel_Lime"
    },
    {
      "x": -60,
      "y": 12,
      "z": -95,
      "name": "Rock_Lime"
    },
    {
      "x": -60,
      "y": 13,
      "z": -95,
      "name": "Soil_Gravel_Lime"
    },
    {
      "x": -60,
      "y": 14,
      "z": -95,
      "name": "Rock_Lime"
    },
    {
      "x": -60,
      "y": 15,
      "z": -95,
      "name": "Rock_Lime"
    },
    {
      "x": -60,
      "y": 16,
      "z": -95,
      "name": "Soil_Gravel_Lime"
    },
    {
      "x": -60,
      "y": 17,
      "z": -95,
      "name": "Soil_Gravel_Lime"
    },
    {
      "x": -60,
      "y": 18,
      "z": -95,
      "name": "Rock_Lime"
    },
    {
      "x": -60,
      "y": 19,
      "z": -95,
      "name": "Rock_Lime"
    },
    {
      "x": -60,
      "y": 5,
      "z": -94,
      "name": "Soil_Gravel_Lime"
    },
    {
      "x": -60,
      "y": 6,
      "z": -94,
      "name": "Soil_Gravel_Lime"
    },
    {
      "x": -60,
      "y": 7,
      "z": -94,
      "name": "Soil_Gravel_Lime"
    },
    {
      "x": -60,
      "y": 8,
      "z": -94,
      "name": "Rock_Lime"
    },
    {
      "x": -60,
      "y": 9,
      "z": -94,
      "name": "Rock_Lime"
    },
    {
      "x": -60,
      "y": 10,
      "z": -94,
      "name": "Rock_Lime"
    },
    {
      "x": -60,
      "y": 11,
      "z": -94,
      "name": "Rock_Lime"
    },
    {
      "x": -60,
      "y": 12,
      "z": -94,
      "name": "Rock_Lime"
    },
    {
      "x": -60,
      "y": 13,
      "z": -94,
      "name": "Rock_Lime"
    },
    {
      "x": -60,
      "y": 14,
      "z": -94,
      "name": "Rock_Lime"
    },
    {
      "x": -60,
      "y": 15,
      "z": -94,
      "name": "Rock_Lime"
    },
    {
      "x": -60,
      "y": 16,
      "z": -94,
      "name": "Rock_Lime"
    },
    {
      "x": -60,
      "y": 17,
      "z": -94,
      "name": "Soil_Gravel_Lime"
    },
    {
      "x": -60,
      "y": 18,
      "z": -94,
      "name": "Soil_Gravel_Lime"
    },
    {
      "x": -60,
      "y": 19,
      "z": -94,
      "name": "Rock_Lime"
    },
    {
      "x": -60,
      "y": 20,
      "z": -94,
      "name": "Rock_Lime"
    },
    {
      "x": -60,
      "y": 21,
      "z": -94,
      "name": "Soil_Gravel_Lime"
    },
    {
      "x": -60,
      "y": 4,
      "z": -93,
      "name": "Soil_Gravel_Lime"
    },
    {
      "x": -60,
      "y": 5,
      "z": -93,
      "name": "Soil_Gravel_Lime"
    },
    {
      "x": -60,
      "y": 6,
      "z": -93,
      "name": "Rock_Lime"
    },
    {
      "x": -60,
      "y": 7,
      "z": -93,
      "name": "Rock_Lime"
    },
    {
      "x": -60,
      "y": 8,
      "z": -93,
      "name": "Soil_Gravel_Lime"
    },
    {
      "x": -60,
      "y": 9,
      "z": -93,
      "name": "Rock_Lime"
    },
    {
      "x": -60,
      "y": 10,
      "z": -93,
      "name": "Rock_Lime"
    },
    {
      "x": -60,
      "y": 11,
      "z": -93,
      "name": "Soil_Gravel_Lime"
    },
    {
      "x": -60,
      "y": 12,
      "z": -93,
      "name": "Soil_Gravel_Lime"
    },
    {
      "x": -60,
      "y": 13,
      "z": -93,
      "name": "Rock_Lime"
    },
    {
      "x": -60,
      "y": 14,
      "z": -93,
      "name": "Rock_Lime"
    },
    {
      "x": -60,
      "y": 15,
      "z": -93,
      "name": "Rock_Lime"
    },
    {
      "x": -60,
      "y": 16,
      "z": -93,
      "name": "Soil_Gravel_Lime"
    },
    {
      "x": -60,
      "y": 17,
      "z": -93,
      "name": "Soil_Gravel_Lime"
    },
    {
      "x": -60,
      "y": 18,
      "z": -93,
      "name": "Soil_Gravel_Lime"
    },
    {
      "x": -60,
      "y": 19,
      "z": -93,
      "name": "Soil_Gravel_Lime"
    },
    {
      "x": -60,
      "y": 20,
      "z": -93,
      "name": "Soil_Gravel_Lime"
    },
    {
      "x": -60,
      "y": 21,
      "z": -93,
      "name": "Soil_Gravel_Lime"
    },
    {
      "x": -60,
      "y": 22,
      "z": -93,
      "name": "Soil_Gravel_Lime"
    },
    {
      "x": -60,
      "y": 23,
      "z": -93,
      "name": "Rock_Lime"
    },
    {
      "x": -60,
      "y": 24,
      "z": -93,
      "name": "Rock_Lime_Stalactite_Large"
    },
    {
      "x": -60,
      "y": 25,
      "z": -93,
      "name": "Rock_Lime_Stalactite_Large",
      "filler": 1024
    },
    {
      "x": -60,
      "y": 4,
      "z": -92,
      "name": "Soil_Gravel_Lime"
    },
    {
      "x": -60,
      "y": 5,
      "z": -92,
      "name": "Rock_Lime"
    },
    {
      "x": -60,
      "y": 6,
      "z": -92,
      "name": "Rock_Lime"
    },
    {
      "x": -60,
      "y": 7,
      "z": -92,
      "name": "Rock_Lime"
    },
    {
      "x": -60,
      "y": 8,
      "z": -92,
      "name": "Soil_Gravel_Lime"
    },
    {
      "x": -60,
      "y": 9,
      "z": -92,
      "name": "Soil_Gravel_Lime"
    },
    {
      "x": -60,
      "y": 10,
      "z": -92,
      "name": "Soil_Gravel_Lime"
    },
    {
      "x": -60,
      "y": 11,
      "z": -92,
      "name": "Soil_Gravel_Lime"
    },
    {
      "x": -60,
      "y": 12,
      "z": -92,
      "name": "Rock_Lime"
    },
    {
      "x": -60,
      "y": 13,
      "z": -92,
      "name": "Rock_Lime"
    },
    {
      "x": -60,
      "y": 14,
      "z": -92,
      "name": "Rock_Lime"
    },
    {
      "x": -60,
      "y": 15,
      "z": -92,
      "name": "Soil_Gravel_Lime"
    },
    {
      "x": -60,
      "y": 16,
      "z": -92,
      "name": "Rock_Lime"
    },
    {
      "x": -60,
      "y": 17,
      "z": -92,
      "name": "Rock_Lime"
    },
    {
      "x": -60,
      "y": 18,
      "z": -92,
      "name": "Soil_Gravel_Lime"
    },
    {
      "x": -60,
      "y": 19,
      "z": -92,
      "name": "Soil_Gravel_Lime"
    },
    {
      "x": -60,
      "y": 20,
      "z": -92,
      "name": "Rock_Lime"
    },
    {
      "x": -60,
      "y": 21,
      "z": -92,
      "name": "Rock_Lime"
    },
    {
      "x": -60,
      "y": 22,
      "z": -92,
      "name": "Soil_Gravel_Lime"
    },
    {
      "x": -60,
      "y": 23,
      "z": -92,
      "name": "Soil_Gravel_Lime"
    },
    {
      "x": -60,
      "y": 24,
      "z": -92,
      "name": "Rock_Lime"
    },
    {
      "x": -60,
      "y": 25,
      "z": -92,
      "name": "Rock_Lime"
    },
    {
      "x": -60,
      "y": 26,
      "z": -92,
      "name": "Soil_Gravel_Lime"
    },
    {
      "x": -60,
      "y": 4,
      "z": -91,
      "name": "Rock_Lime"
    },
    {
      "x": -60,
      "y": 5,
      "z": -91,
      "name": "Rock_Lime"
    },
    {
      "x": -60,
      "y": 6,
      "z": -91,
      "name": "Rock_Lime"
    },
    {
      "x": -60,
      "y": 7,
      "z": -91,
      "name": "Soil_Gravel_Lime"
    },
    {
      "x": -60,
      "y": 8,
      "z": -91,
      "name": "Rock_Lime"
    },
    {
      "x": -60,
      "y": 9,
      "z": -91,
      "name": "Soil_Gravel_Lime"
    },
    {
      "x": -60,
      "y": 10,
      "z": -91,
      "name": "Rock_Lime"
    },
    {
      "x": -60,
      "y": 11,
      "z": -91,
      "name": "Rock_Lime"
    },
    {
      "x": -60,
      "y": 12,
      "z": -91,
      "name": "Soil_Gravel_Lime"
    },
    {
      "x": -60,
      "y": 13,
      "z": -91,
      "name": "Soil_Gravel_Lime"
    },
    {
      "x": -60,
      "y": 14,
      "z": -91,
      "name": "Soil_Gravel_Lime"
    },
    {
      "x": -60,
      "y": 15,
      "z": -91,
      "name": "Soil_Gravel_Lime"
    },
    {
      "x": -60,
      "y": 16,
      "z": -91,
      "name": "Soil_Gravel_Lime"
    },
    {
      "x": -60,
      "y": 17,
      "z": -91,
      "name": "Rock_Lime"
    },
    {
      "x": -60,
      "y": 18,
      "z": -91,
      "name": "Rock_Lime"
    },
    {
      "x": -60,
      "y": 19,
      "z": -91,
      "name": "Rock_Lime"
    },
    {
      "x": -60,
      "y": 20,
      "z": -91,
      "name": "Rock_Lime"
    },
    {
      "x": -60,
      "y": 21,
      "z": -91,
      "name": "Soil_Gravel_Lime"
    },
    {
      "x": -60,
      "y": 22,
      "z": -91,
      "name": "Rock_Lime"
    },
    {
      "x": -60,
      "y": 23,
      "z": -91,
      "name": "Soil_Gravel_Lime"
    },
    {
      "x": -60,
      "y": 24,
      "z": -91,
      "name": "Soil_Gravel_Lime"
    },
    {
      "x": -60,
      "y": 25,
      "z": -91,
      "name": "Rock_Lime"
    },
    {
      "x": -60,
      "y": 26,
      "z": -91,
      "name": "Rock_Lime"
    },
    {
      "x": -60,
      "y": 27,
      "z": -91,
      "name": "Rock_Lime"
    },
    {
      "x": -60,
      "y": 28,
      "z": -91,
      "name": "Plant_Coral_Block_Lime"
    },
    {
      "x": -60,
      "y": 4,
      "z": -90,
      "name": "Rock_Lime"
    },
    {
      "x": -60,
      "y": 5,
      "z": -90,
      "name": "Rock_Lime"
    },
    {
      "x": -60,
      "y": 6,
      "z": -90,
      "name": "Soil_Gravel_Lime"
    },
    {
      "x": -60,
      "y": 7,
      "z": -90,
      "name": "Rock_Lime"
    },
    {
      "x": -60,
      "y": 8,
      "z": -90,
      "name": "Rock_Lime"
    },
    {
      "x": -60,
      "y": 9,
      "z": -90,
      "name": "Rock_Lime"
    },
    {
      "x": -60,
      "y": 10,
      "z": -90,
      "name": "Soil_Gravel_Lime"
    },
    {
      "x": -60,
      "y": 11,
      "z": -90,
      "name": "Soil_Gravel_Lime"
    },
    {
      "x": -60,
      "y": 12,
      "z": -90,
      "name": "Soil_Gravel_Lime"
    },
    {
      "x": -60,
      "y": 13,
      "z": -90,
      "name": "Soil_Gravel_Lime"
    },
    {
      "x": -60,
      "y": 14,
      "z": -90,
      "name": "Rock_Lime"
    },
    {
      "x": -60,
      "y": 15,
      "z": -90,
      "name": "Rock_Lime"
    },
    {
      "x": -60,
      "y": 16,
      "z": -90,
      "name": "Soil_Gravel_Lime"
    },
    {
      "x": -60,
      "y": 17,
      "z": -90,
      "name": "Rock_Lime"
    },
    {
      "x": -60,
      "y": 18,
      "z": -90,
      "name": "Soil_Gravel_Lime"
    },
    {
      "x": -60,
      "y": 19,
      "z": -90,
      "name": "Soil_Gravel_Lime"
    },
    {
      "x": -60,
      "y": 20,
      "z": -90,
      "name": "Rock_Lime"
    },
    {
      "x": -60,
      "y": 21,
      "z": -90,
      "name": "Soil_Gravel_Lime"
    },
    {
      "x": -60,
      "y": 22,
      "z": -90,
      "name": "Soil_Gravel_Lime"
    },
    {
      "x": -60,
      "y": 23,
      "z": -90,
      "name": "Rock_Lime"
    },
    {
      "x": -60,
      "y": 24,
      "z": -90,
      "name": "Soil_Gravel_Lime"
    },
    {
      "x": -60,
      "y": 25,
      "z": -90,
      "name": "Soil_Gravel_Lime"
    },
    {
      "x": -60,
      "y": 26,
      "z": -90,
      "name": "Rock_Lime"
    },
    {
      "x": -60,
      "y": 27,
      "z": -90,
      "name": "Plant_Coral_Block_Lime"
    },
    {
      "x": -60,
      "y": 28,
      "z": -90,
      "name": "Plant_Coral_Block_Lime"
    },
    {
      "x": -60,
      "y": 29,
      "z": -90,
      "name": "Plant_Coral_Block_Lime"
    },
    {
      "x": -60,
      "y": 5,
      "z": -89,
      "name": "Soil_Gravel_Lime"
    },
    {
      "x": -60,
      "y": 6,
      "z": -89,
      "name": "Soil_Gravel_Lime"
    },
    {
      "x": -60,
      "y": 7,
      "z": -89,
      "name": "Rock_Lime"
    },
    {
      "x": -60,
      "y": 8,
      "z": -89,
      "name": "Rock_Lime"
    },
    {
      "x": -60,
      "y": 9,
      "z": -89,
      "name": "Soil_Gravel_Lime"
    },
    {
      "x": -60,
      "y": 10,
      "z": -89,
      "name": "Soil_Gravel_Lime"
    },
    {
      "x": -60,
      "y": 11,
      "z": -89,
      "name": "Soil_Gravel_Lime"
    },
    {
      "x": -60,
      "y": 12,
      "z": -89,
      "name": "Rock_Lime"
    },
    {
      "x": -60,
      "y": 13,
      "z": -89,
      "name": "Rock_Lime"
    },
    {
      "x": -60,
      "y": 14,
      "z": -89,
      "name": "Soil_Gravel_Lime"
    },
    {
      "x": -60,
      "y": 15,
      "z": -89,
      "name": "Rock_Lime"
    },
    {
      "x": -60,
      "y": 16,
      "z": -89,
      "name": "Soil_Gravel_Lime"
    },
    {
      "x": -60,
      "y": 17,
      "z": -89,
      "name": "Soil_Gravel_Lime"
    },
    {
      "x": -60,
      "y": 18,
      "z": -89,
      "name": "Rock_Lime"
    },
    {
      "x": -60,
      "y": 19,
      "z": -89,
      "name": "Soil_Gravel_Lime"
    },
    {
      "x": -60,
      "y": 20,
      "z": -89,
      "name": "Rock_Lime"
    },
    {
      "x": -60,
      "y": 21,
      "z": -89,
      "name": "Soil_Gravel_Lime"
    },
    {
      "x": -60,
      "y": 22,
      "z": -89,
      "name": "Soil_Gravel_Lime"
    },
    {
      "x": -60,
      "y": 23,
      "z": -89,
      "name": "Rock_Lime"
    },
    {
      "x": -60,
      "y": 24,
      "z": -89,
      "name": "Rock_Lime"
    },
    {
      "x": -60,
      "y": 25,
      "z": -89,
      "name": "Soil_Gravel_Lime"
    },
    {
      "x": -60,
      "y": 26,
      "z": -89,
      "name": "Plant_Coral_Block_Lime"
    },
    {
      "x": -60,
      "y": 27,
      "z": -89,
      "name": "Plant_Coral_Block_Lime"
    },
    {
      "x": -60,
      "y": 28,
      "z": -89,
      "name": "Plant_Coral_Block_Lime"
    },
    {
      "x": -60,
      "y": 5,
      "z": -88,
      "name": "Soil_Gravel_Lime"
    },
    {
      "x": -60,
      "y": 6,
      "z": -88,
      "name": "Soil_Gravel_Lime"
    },
    {
      "x": -60,
      "y": 7,
      "z": -88,
      "name": "Rock_Lime"
    },
    {
      "x": -60,
      "y": 8,
      "z": -88,
      "name": "Soil_Gravel_Lime"
    },
    {
      "x": -60,
      "y": 9,
      "z": -88,
      "name": "Soil_Gravel_Lime"
    },
    {
      "x": -60,
      "y": 10,
      "z": -88,
      "name": "Rock_Lime"
    },
    {
      "x": -60,
      "y": 11,
      "z": -88,
      "name": "Rock_Lime"
    },
    {
      "x": -60,
      "y": 12,
      "z": -88,
      "name": "Rock_Lime"
    },
    {
      "x": -60,
      "y": 13,
      "z": -88,
      "name": "Rock_Lime"
    },
    {
      "x": -60,
      "y": 14,
      "z": -88,
      "name": "Soil_Gravel_Lime"
    },
    {
      "x": -60,
      "y": 15,
      "z": -88,
      "name": "Soil_Gravel_Lime"
    },
    {
      "x": -60,
      "y": 16,
      "z": -88,
      "name": "Rock_Lime"
    },
    {
      "x": -60,
      "y": 17,
      "z": -88,
      "name": "Rock_Lime"
    },
    {
      "x": -60,
      "y": 18,
      "z": -88,
      "name": "Rock_Lime"
    },
    {
      "x": -60,
      "y": 19,
      "z": -88,
      "name": "Rock_Lime"
    },
    {
      "x": -60,
      "y": 20,
      "z": -88,
      "name": "Soil_Gravel_Lime"
    },
    {
      "x": -60,
      "y": 21,
      "z": -88,
      "name": "Rock_Lime"
    },
    {
      "x": -60,
      "y": 22,
      "z": -88,
      "name": "Rock_Lime"
    },
    {
      "x": -60,
      "y": 23,
      "z": -88,
      "name": "Soil_Gravel_Lime"
    },
    {
      "x": -60,
      "y": 24,
      "z": -88,
      "name": "Soil_Clay_Smooth_Lime"
    },
    {
      "x": -60,
      "y": 25,
      "z": -88,
      "name": "Soil_Clay_Lime"
    },
    {
      "x": -60,
      "y": 26,
      "z": -88,
      "name": "Soil_Clay_Smooth_Lime"
    },
    {
      "x": -60,
      "y": 27,
      "z": -88,
      "name": "Plant_Coral_Block_Lime"
    },
    {
      "x": -60,
      "y": 4,
      "z": -87,
      "name": "Soil_Gravel_Lime"
    },
    {
      "x": -60,
      "y": 5,
      "z": -87,
      "name": "Rock_Lime"
    },
    {
      "x": -60,
      "y": 6,
      "z": -87,
      "name": "Rock_Lime"
    },
    {
      "x": -60,
      "y": 7,
      "z": -87,
      "name": "Rock_Lime"
    },
    {
      "x": -60,
      "y": 8,
      "z": -87,
      "name": "Rock_Lime"
    },
    {
      "x": -60,
      "y": 9,
      "z": -87,
      "name": "Rock_Lime"
    },
    {
      "x": -60,
      "y": 10,
      "z": -87,
      "name": "Soil_Gravel_Lime"
    },
    {
      "x": -60,
      "y": 11,
      "z": -87,
      "name": "Rock_Lime"
    },
    {
      "x": -60,
      "y": 12,
      "z": -87,
      "name": "Rock_Lime"
    },
    {
      "x": -60,
      "y": 13,
      "z": -87,
      "name": "Rock_Lime"
    },
    {
      "x": -60,
      "y": 14,
      "z": -87,
      "name": "Soil_Gravel_Lime"
    },
    {
      "x": -60,
      "y": 15,
      "z": -87,
      "name": "Rock_Lime"
    },
    {
      "x": -60,
      "y": 16,
      "z": -87,
      "name": "Soil_Gravel_Lime"
    },
    {
      "x": -60,
      "y": 17,
      "z": -87,
      "name": "Soil_Gravel_Lime"
    },
    {
      "x": -60,
      "y": 18,
      "z": -87,
      "name": "Rock_Lime"
    },
    {
      "x": -60,
      "y": 19,
      "z": -87,
      "name": "Rock_Lime"
    },
    {
      "x": -60,
      "y": 20,
      "z": -87,
      "name": "Soil_Gravel_Lime"
    },
    {
      "x": -60,
      "y": 21,
      "z": -87,
      "name": "Rock_Lime"
    },
    {
      "x": -60,
      "y": 22,
      "z": -87,
      "name": "Soil_Gravel_Lime"
    },
    {
      "x": -60,
      "y": 23,
      "z": -87,
      "name": "Soil_Clay_Smooth_Lime"
    },
    {
      "x": -60,
      "y": 24,
      "z": -87,
      "name": "Plant_Coral_Block_Lime"
    },
    {
      "x": -60,
      "y": 25,
      "z": -87,
      "name": "Plant_Coral_Block_Lime"
    },
    {
      "x": -60,
      "y": 4,
      "z": -86,
      "name": "Soil_Gravel_Lime"
    },
    {
      "x": -60,
      "y": 5,
      "z": -86,
      "name": "Rock_Lime"
    },
    {
      "x": -60,
      "y": 6,
      "z": -86,
      "name": "Rock_Lime"
    },
    {
      "x": -60,
      "y": 7,
      "z": -86,
      "name": "Rock_Lime"
    },
    {
      "x": -60,
      "y": 8,
      "z": -86,
      "name": "Rock_Lime"
    },
    {
      "x": -60,
      "y": 9,
      "z": -86,
      "name": "Rock_Lime"
    },
    {
      "x": -60,
      "y": 10,
      "z": -86,
      "name": "Rock_Lime"
    },
    {
      "x": -60,
      "y": 11,
      "z": -86,
      "name": "Rock_Lime"
    },
    {
      "x": -60,
      "y": 12,
      "z": -86,
      "name": "Rock_Lime"
    },
    {
      "x": -60,
      "y": 13,
      "z": -86,
      "name": "Rock_Lime"
    },
    {
      "x": -60,
      "y": 14,
      "z": -86,
      "name": "Soil_Gravel_Lime"
    },
    {
      "x": -60,
      "y": 15,
      "z": -86,
      "name": "Rock_Lime"
    },
    {
      "x": -60,
      "y": 16,
      "z": -86,
      "name": "Soil_Gravel_Lime"
    },
    {
      "x": -60,
      "y": 17,
      "z": -86,
      "name": "Rock_Lime"
    },
    {
      "x": -60,
      "y": 18,
      "z": -86,
      "name": "Rock_Lime"
    },
    {
      "x": -60,
      "y": 19,
      "z": -86,
      "name": "Rock_Lime"
    },
    {
      "x": -60,
      "y": 20,
      "z": -86,
      "name": "Soil_Gravel_Lime"
    },
    {
      "x": -60,
      "y": 21,
      "z": -86,
      "name": "Rock_Lime"
    },
    {
      "x": -60,
      "y": 22,
      "z": -86,
      "name": "Rock_Lime"
    },
    {
      "x": -60,
      "y": 23,
      "z": -86,
      "name": "Rock_Lime_Stalactite_Large"
    },
    {
      "x": -60,
      "y": 24,
      "z": -86,
      "name": "Rock_Lime_Stalactite_Large",
      "filler": 1024
    },
    {
      "x": -60,
      "y": 4,
      "z": -85,
      "name": "Rock_Lime"
    },
    {
      "x": -60,
      "y": 5,
      "z": -85,
      "name": "Rock_Lime"
    },
    {
      "x": -60,
      "y": 6,
      "z": -85,
      "name": "Soil_Gravel_Lime"
    },
    {
      "x": -60,
      "y": 7,
      "z": -85,
      "name": "Rock_Lime"
    },
    {
      "x": -60,
      "y": 8,
      "z": -85,
      "name": "Soil_Gravel_Lime"
    },
    {
      "x": -60,
      "y": 9,
      "z": -85,
      "name": "Rock_Lime"
    },
    {
      "x": -60,
      "y": 10,
      "z": -85,
      "name": "Soil_Gravel_Lime"
    },
    {
      "x": -60,
      "y": 11,
      "z": -85,
      "name": "Rock_Lime"
    },
    {
      "x": -60,
      "y": 12,
      "z": -85,
      "name": "Rock_Lime"
    },
    {
      "x": -60,
      "y": 13,
      "z": -85,
      "name": "Rock_Lime"
    },
    {
      "x": -60,
      "y": 14,
      "z": -85,
      "name": "Soil_Gravel_Lime"
    },
    {
      "x": -60,
      "y": 15,
      "z": -85,
      "name": "Soil_Gravel_Lime"
    },
    {
      "x": -60,
      "y": 16,
      "z": -85,
      "name": "Soil_Gravel_Lime"
    },
    {
      "x": -60,
      "y": 17,
      "z": -85,
      "name": "Soil_Gravel_Lime"
    },
    {
      "x": -60,
      "y": 18,
      "z": -85,
      "name": "Rock_Lime"
    },
    {
      "x": -60,
      "y": 19,
      "z": -85,
      "name": "Soil_Gravel_Lime"
    },
    {
      "x": -60,
      "y": 20,
      "z": -85,
      "name": "Rock_Lime"
    },
    {
      "x": -60,
      "y": 4,
      "z": -84,
      "name": "Rock_Lime"
    },
    {
      "x": -60,
      "y": 5,
      "z": -84,
      "name": "Rock_Lime"
    },
    {
      "x": -60,
      "y": 6,
      "z": -84,
      "name": "Rock_Lime"
    },
    {
      "x": -60,
      "y": 7,
      "z": -84,
      "name": "Rock_Lime"
    },
    {
      "x": -60,
      "y": 8,
      "z": -84,
      "name": "Rock_Lime"
    },
    {
      "x": -60,
      "y": 9,
      "z": -84,
      "name": "Rock_Lime"
    },
    {
      "x": -60,
      "y": 10,
      "z": -84,
      "name": "Rock_Lime"
    },
    {
      "x": -60,
      "y": 11,
      "z": -84,
      "name": "Soil_Gravel_Lime"
    },
    {
      "x": -60,
      "y": 12,
      "z": -84,
      "name": "Soil_Gravel_Lime"
    },
    {
      "x": -60,
      "y": 13,
      "z": -84,
      "name": "Rock_Lime"
    },
    {
      "x": -60,
      "y": 14,
      "z": -84,
      "name": "Rock_Lime"
    },
    {
      "x": -60,
      "y": 15,
      "z": -84,
      "name": "Soil_Gravel_Lime"
    },
    {
      "x": -60,
      "y": 16,
      "z": -84,
      "name": "Rock_Lime"
    },
    {
      "x": -60,
      "y": 17,
      "z": -84,
      "name": "Rock_Lime_Stalactite_Large"
    },
    {
      "x": -60,
      "y": 18,
      "z": -84,
      "name": "Rock_Lime_Stalactite_Large",
      "filler": 1024
    },
    {
      "x": -60,
      "y": 5,
      "z": -83,
      "name": "Rock_Lime"
    },
    {
      "x": -60,
      "y": 6,
      "z": -83,
      "name": "Soil_Gravel_Lime"
    },
    {
      "x": -60,
      "y": 7,
      "z": -83,
      "name": "Soil_Gravel_Lime"
    },
    {
      "x": -60,
      "y": 8,
      "z": -83,
      "name": "Rock_Lime"
    },
    {
      "x": -60,
      "y": 9,
      "z": -83,
      "name": "Soil_Gravel_Lime"
    },
    {
      "x": -60,
      "y": 10,
      "z": -83,
      "name": "Rock_Lime"
    },
    {
      "x": -60,
      "y": 11,
      "z": -83,
      "name": "Rock_Lime"
    },
    {
      "x": -60,
      "y": 12,
      "z": -83,
      "name": "Soil_Gravel_Lime"
    },
    {
      "x": -60,
      "y": 5,
      "z": -82,
      "name": "Soil_Gravel_Lime"
    },
    {
      "x": -60,
      "y": 6,
      "z": -82,
      "name": "Soil_Gravel_Lime"
    },
    {
      "x": -60,
      "y": 7,
      "z": -82,
      "name": "Rock_Lime"
    },
    {
      "x": -60,
      "y": 8,
      "z": -82,
      "name": "Soil_Gravel_Lime"
    },
    {
      "x": -60,
      "y": 9,
      "z": -82,
      "name": "Soil_Gravel_Lime"
    },
    {
      "x": -59,
      "y": 9,
      "z": -96,
      "name": "Rock_Lime"
    },
    {
      "x": -59,
      "y": 10,
      "z": -96,
      "name": "Rock_Lime"
    },
    {
      "x": -59,
      "y": 11,
      "z": -96,
      "name": "Soil_Gravel_Lime"
    },
    {
      "x": -59,
      "y": 12,
      "z": -96,
      "name": "Soil_Gravel_Lime"
    },
    {
      "x": -59,
      "y": 13,
      "z": -96,
      "name": "Soil_Gravel_Lime"
    },
    {
      "x": -59,
      "y": 14,
      "z": -96,
      "name": "Rock_Lime"
    },
    {
      "x": -59,
      "y": 15,
      "z": -96,
      "name": "Rock_Lime"
    },
    {
      "x": -59,
      "y": 16,
      "z": -96,
      "name": "Rock_Lime"
    },
    {
      "x": -59,
      "y": 17,
      "z": -96,
      "name": "Soil_Gravel_Lime"
    },
    {
      "x": -59,
      "y": 18,
      "z": -96,
      "name": "Soil_Gravel_Lime"
    },
    {
      "x": -59,
      "y": 5,
      "z": -95,
      "name": "Soil_Gravel_Lime"
    },
    {
      "x": -59,
      "y": 6,
      "z": -95,
      "name": "Rock_Lime"
    },
    {
      "x": -59,
      "y": 7,
      "z": -95,
      "name": "Rock_Lime"
    },
    {
      "x": -59,
      "y": 8,
      "z": -95,
      "name": "Rock_Lime"
    },
    {
      "x": -59,
      "y": 9,
      "z": -95,
      "name": "Rock_Lime"
    },
    {
      "x": -59,
      "y": 10,
      "z": -95,
      "name": "Soil_Gravel_Lime"
    },
    {
      "x": -59,
      "y": 11,
      "z": -95,
      "name": "Soil_Gravel_Lime"
    },
    {
      "x": -59,
      "y": 12,
      "z": -95,
      "name": "Rock_Lime"
    },
    {
      "x": -59,
      "y": 13,
      "z": -95,
      "name": "Rock_Lime"
    },
    {
      "x": -59,
      "y": 14,
      "z": -95,
      "name": "Rock_Lime"
    },
    {
      "x": -59,
      "y": 15,
      "z": -95,
      "name": "Rock_Lime"
    },
    {
      "x": -59,
      "y": 16,
      "z": -95,
      "name": "Rock_Lime"
    },
    {
      "x": -59,
      "y": 17,
      "z": -95,
      "name": "Soil_Gravel_Lime"
    },
    {
      "x": -59,
      "y": 18,
      "z": -95,
      "name": "Rock_Lime"
    },
    {
      "x": -59,
      "y": 19,
      "z": -95,
      "name": "Rock_Lime"
    },
    {
      "x": -59,
      "y": 20,
      "z": -95,
      "name": "Rock_Lime"
    },
    {
      "x": -59,
      "y": 21,
      "z": -95,
      "name": "Soil_Gravel_Lime"
    },
    {
      "x": -59,
      "y": 4,
      "z": -94,
      "name": "Rock_Lime"
    },
    {
      "x": -59,
      "y": 5,
      "z": -94,
      "name": "Soil_Gravel_Lime"
    },
    {
      "x": -59,
      "y": 6,
      "z": -94,
      "name": "Soil_Gravel_Lime"
    },
    {
      "x": -59,
      "y": 7,
      "z": -94,
      "name": "Rock_Lime"
    },
    {
      "x": -59,
      "y": 8,
      "z": -94,
      "name": "Rock_Lime"
    },
    {
      "x": -59,
      "y": 9,
      "z": -94,
      "name": "Soil_Gravel_Lime"
    },
    {
      "x": -59,
      "y": 10,
      "z": -94,
      "name": "Soil_Gravel_Lime"
    },
    {
      "x": -59,
      "y": 11,
      "z": -94,
      "name": "Soil_Gravel_Lime"
    },
    {
      "x": -59,
      "y": 12,
      "z": -94,
      "name": "Soil_Gravel_Lime"
    },
    {
      "x": -59,
      "y": 13,
      "z": -94,
      "name": "Soil_Gravel_Lime"
    },
    {
      "x": -59,
      "y": 14,
      "z": -94,
      "name": "Rock_Lime"
    },
    {
      "x": -59,
      "y": 15,
      "z": -94,
      "name": "Soil_Gravel_Lime"
    },
    {
      "x": -59,
      "y": 16,
      "z": -94,
      "name": "Rock_Lime"
    },
    {
      "x": -59,
      "y": 17,
      "z": -94,
      "name": "Rock_Lime"
    },
    {
      "x": -59,
      "y": 18,
      "z": -94,
      "name": "Soil_Gravel_Lime"
    },
    {
      "x": -59,
      "y": 19,
      "z": -94,
      "name": "Rock_Lime"
    },
    {
      "x": -59,
      "y": 20,
      "z": -94,
      "name": "Soil_Gravel_Lime"
    },
    {
      "x": -59,
      "y": 21,
      "z": -94,
      "name": "Soil_Gravel_Lime"
    },
    {
      "x": -59,
      "y": 22,
      "z": -94,
      "name": "Soil_Gravel_Lime"
    },
    {
      "x": -59,
      "y": 23,
      "z": -94,
      "name": "Rock_Lime"
    },
    {
      "x": -59,
      "y": 24,
      "z": -94,
      "name": "Soil_Gravel_Lime"
    },
    {
      "x": -59,
      "y": 26,
      "z": -94,
      "name": "Plant_Leaves_Dead",
      "support": 15
    },
    {
      "x": -59,
      "y": 4,
      "z": -93,
      "name": "Soil_Gravel_Lime"
    },
    {
      "x": -59,
      "y": 5,
      "z": -93,
      "name": "Rock_Lime"
    },
    {
      "x": -59,
      "y": 6,
      "z": -93,
      "name": "Soil_Gravel_Lime"
    },
    {
      "x": -59,
      "y": 7,
      "z": -93,
      "name": "Soil_Gravel_Lime"
    },
    {
      "x": -59,
      "y": 8,
      "z": -93,
      "name": "Rock_Lime"
    },
    {
      "x": -59,
      "y": 9,
      "z": -93,
      "name": "Soil_Gravel_Lime"
    },
    {
      "x": -59,
      "y": 10,
      "z": -93,
      "name": "Rock_Lime"
    },
    {
      "x": -59,
      "y": 11,
      "z": -93,
      "name": "Rock_Lime"
    },
    {
      "x": -59,
      "y": 12,
      "z": -93,
      "name": "Rock_Lime"
    },
    {
      "x": -59,
      "y": 13,
      "z": -93,
      "name": "Rock_Lime"
    },
    {
      "x": -59,
      "y": 14,
      "z": -93,
      "name": "Soil_Gravel_Lime"
    },
    {
      "x": -59,
      "y": 15,
      "z": -93,
      "name": "Soil_Gravel_Lime"
    },
    {
      "x": -59,
      "y": 16,
      "z": -93,
      "name": "Soil_Gravel_Lime"
    },
    {
      "x": -59,
      "y": 17,
      "z": -93,
      "name": "Rock_Lime"
    },
    {
      "x": -59,
      "y": 18,
      "z": -93,
      "name": "Rock_Lime"
    },
    {
      "x": -59,
      "y": 19,
      "z": -93,
      "name": "Rock_Lime"
    },
    {
      "x": -59,
      "y": 20,
      "z": -93,
      "name": "Rock_Lime"
    },
    {
      "x": -59,
      "y": 21,
      "z": -93,
      "name": "Rock_Lime"
    },
    {
      "x": -59,
      "y": 22,
      "z": -93,
      "name": "Rock_Lime"
    },
    {
      "x": -59,
      "y": 23,
      "z": -93,
      "name": "Rock_Lime"
    },
    {
      "x": -59,
      "y": 24,
      "z": -93,
      "name": "Rock_Lime"
    },
    {
      "x": -59,
      "y": 25,
      "z": -93,
      "name": "Soil_Gravel_Lime"
    },
    {
      "x": -59,
      "y": 26,
      "z": -93,
      "name": "Soil_Gravel_Lime"
    },
    {
      "x": -59,
      "y": 27,
      "z": -93,
      "name": "Soil_Clay_Smooth_Lime"
    },
    {
      "x": -59,
      "y": 4,
      "z": -92,
      "name": "Rock_Lime"
    },
    {
      "x": -59,
      "y": 5,
      "z": -92,
      "name": "Rock_Lime"
    },
    {
      "x": -59,
      "y": 6,
      "z": -92,
      "name": "Rock_Lime"
    },
    {
      "x": -59,
      "y": 7,
      "z": -92,
      "name": "Soil_Gravel_Lime"
    },
    {
      "x": -59,
      "y": 8,
      "z": -92,
      "name": "Rock_Lime"
    },
    {
      "x": -59,
      "y": 9,
      "z": -92,
      "name": "Rock_Lime"
    },
    {
      "x": -59,
      "y": 10,
      "z": -92,
      "name": "Soil_Gravel_Lime"
    },
    {
      "x": -59,
      "y": 11,
      "z": -92,
      "name": "Rock_Lime"
    },
    {
      "x": -59,
      "y": 12,
      "z": -92,
      "name": "Rock_Lime"
    },
    {
      "x": -59,
      "y": 13,
      "z": -92,
      "name": "Rock_Lime"
    },
    {
      "x": -59,
      "y": 14,
      "z": -92,
      "name": "Soil_Gravel_Lime"
    },
    {
      "x": -59,
      "y": 15,
      "z": -92,
      "name": "Rock_Lime"
    },
    {
      "x": -59,
      "y": 16,
      "z": -92,
      "name": "Soil_Gravel_Lime"
    },
    {
      "x": -59,
      "y": 17,
      "z": -92,
      "name": "Rock_Lime"
    },
    {
      "x": -59,
      "y": 18,
      "z": -92,
      "name": "Rock_Lime"
    },
    {
      "x": -59,
      "y": 19,
      "z": -92,
      "name": "Soil_Gravel_Lime"
    },
    {
      "x": -59,
      "y": 20,
      "z": -92,
      "name": "Soil_Gravel_Lime"
    },
    {
      "x": -59,
      "y": 21,
      "z": -92,
      "name": "Soil_Gravel_Lime"
    },
    {
      "x": -59,
      "y": 22,
      "z": -92,
      "name": "Rock_Lime"
    },
    {
      "x": -59,
      "y": 23,
      "z": -92,
      "name": "Rock_Lime"
    },
    {
      "x": -59,
      "y": 24,
      "z": -92,
      "name": "Rock_Lime"
    },
    {
      "x": -59,
      "y": 25,
      "z": -92,
      "name": "Soil_Gravel_Lime"
    },
    {
      "x": -59,
      "y": 26,
      "z": -92,
      "name": "Rock_Lime"
    },
    {
      "x": -59,
      "y": 27,
      "z": -92,
      "name": "Soil_Gravel_Lime"
    },
    {
      "x": -59,
      "y": 28,
      "z": -92,
      "name": "Plant_Coral_Block_Lime"
    },
    {
      "x": -59,
      "y": 29,
      "z": -92,
      "name": "Plant_Coral_Block_Lime"
    },
    {
      "x": -59,
      "y": 4,
      "z": -91,
      "name": "Rock_Lime"
    },
    {
      "x": -59,
      "y": 5,
      "z": -91,
      "name": "Rock_Lime"
    },
    {
      "x": -59,
      "y": 6,
      "z": -91,
      "name": "Rock_Lime"
    },
    {
      "x": -59,
      "y": 7,
      "z": -91,
      "name": "Soil_Gravel_Lime"
    },
    {
      "x": -59,
      "y": 8,
      "z": -91,
      "name": "Soil_Gravel_Lime"
    },
    {
      "x": -59,
      "y": 9,
      "z": -91,
      "name": "Rock_Lime"
    },
    {
      "x": -59,
      "y": 10,
      "z": -91,
      "name": "Rock_Lime"
    },
    {
      "x": -59,
      "y": 11,
      "z": -91,
      "name": "Soil_Gravel_Lime"
    },
    {
      "x": -59,
      "y": 12,
      "z": -91,
      "name": "Rock_Lime"
    },
    {
      "x": -59,
      "y": 13,
      "z": -91,
      "name": "Rock_Lime"
    },
    {
      "x": -59,
      "y": 14,
      "z": -91,
      "name": "Rock_Lime"
    },
    {
      "x": -59,
      "y": 15,
      "z": -91,
      "name": "Rock_Lime"
    },
    {
      "x": -59,
      "y": 16,
      "z": -91,
      "name": "Rock_Lime"
    },
    {
      "x": -59,
      "y": 17,
      "z": -91,
      "name": "Soil_Gravel_Lime"
    },
    {
      "x": -59,
      "y": 18,
      "z": -91,
      "name": "Soil_Gravel_Lime"
    },
    {
      "x": -59,
      "y": 19,
      "z": -91,
      "name": "Rock_Lime"
    },
    {
      "x": -59,
      "y": 20,
      "z": -91,
      "name": "Soil_Gravel_Lime"
    },
    {
      "x": -59,
      "y": 21,
      "z": -91,
      "name": "Soil_Gravel_Lime"
    },
    {
      "x": -59,
      "y": 22,
      "z": -91,
      "name": "Rock_Lime"
    },
    {
      "x": -59,
      "y": 23,
      "z": -91,
      "name": "Rock_Lime"
    },
    {
      "x": -59,
      "y": 24,
      "z": -91,
      "name": "Soil_Gravel_Lime"
    },
    {
      "x": -59,
      "y": 25,
      "z": -91,
      "name": "Rock_Lime"
    },
    {
      "x": -59,
      "y": 26,
      "z": -91,
      "name": "Rock_Lime"
    },
    {
      "x": -59,
      "y": 27,
      "z": -91,
      "name": "Rock_Lime"
    },
    {
      "x": -59,
      "y": 28,
      "z": -91,
      "name": "Rock_Lime"
    },
    {
      "x": -59,
      "y": 29,
      "z": -91,
      "name": "Soil_Clay_Lime"
    },
    {
      "x": -59,
      "y": 30,
      "z": -91,
      "name": "Plant_Coral_Block_Lime"
    },
    {
      "x": -59,
      "y": 31,
      "z": -91,
      "name": "Plant_Coral_Block_Lime"
    },
    {
      "x": -59,
      "y": 4,
      "z": -90,
      "name": "Rock_Lime"
    },
    {
      "x": -59,
      "y": 5,
      "z": -90,
      "name": "Rock_Lime"
    },
    {
      "x": -59,
      "y": 6,
      "z": -90,
      "name": "Rock_Lime"
    },
    {
      "x": -59,
      "y": 7,
      "z": -90,
      "name": "Soil_Gravel_Lime"
    },
    {
      "x": -59,
      "y": 8,
      "z": -90,
      "name": "Soil_Gravel_Lime"
    },
    {
      "x": -59,
      "y": 9,
      "z": -90,
      "name": "Rock_Lime"
    },
    {
      "x": -59,
      "y": 10,
      "z": -90,
      "name": "Rock_Lime"
    },
    {
      "x": -59,
      "y": 11,
      "z": -90,
      "name": "Rock_Lime"
    },
    {
      "x": -59,
      "y": 12,
      "z": -90,
      "name": "Rock_Lime"
    },
    {
      "x": -59,
      "y": 13,
      "z": -90,
      "name": "Soil_Gravel_Lime"
    },
    {
      "x": -59,
      "y": 14,
      "z": -90,
      "name": "Soil_Gravel_Lime"
    },
    {
      "x": -59,
      "y": 15,
      "z": -90,
      "name": "Soil_Gravel_Lime"
    },
    {
      "x": -59,
      "y": 16,
      "z": -90,
      "name": "Soil_Gravel_Lime"
    },
    {
      "x": -59,
      "y": 17,
      "z": -90,
      "name": "Soil_Gravel_Lime"
    },
    {
      "x": -59,
      "y": 18,
      "z": -90,
      "name": "Soil_Gravel_Lime"
    },
    {
      "x": -59,
      "y": 19,
      "z": -90,
      "name": "Rock_Lime"
    },
    {
      "x": -59,
      "y": 20,
      "z": -90,
      "name": "Rock_Lime"
    },
    {
      "x": -59,
      "y": 21,
      "z": -90,
      "name": "Rock_Lime"
    },
    {
      "x": -59,
      "y": 22,
      "z": -90,
      "name": "Soil_Gravel_Lime"
    },
    {
      "x": -59,
      "y": 23,
      "z": -90,
      "name": "Soil_Gravel_Lime"
    },
    {
      "x": -59,
      "y": 24,
      "z": -90,
      "name": "Rock_Lime"
    },
    {
      "x": -59,
      "y": 25,
      "z": -90,
      "name": "Soil_Gravel_Lime"
    },
    {
      "x": -59,
      "y": 26,
      "z": -90,
      "name": "Soil_Gravel_Lime"
    },
    {
      "x": -59,
      "y": 27,
      "z": -90,
      "name": "Rock_Lime"
    },
    {
      "x": -59,
      "y": 28,
      "z": -90,
      "name": "Plant_Coral_Block_Lime"
    },
    {
      "x": -59,
      "y": 29,
      "z": -90,
      "name": "Plant_Coral_Block_Lime"
    },
    {
      "x": -59,
      "y": 30,
      "z": -90,
      "name": "Plant_Coral_Block_Lime"
    },
    {
      "x": -59,
      "y": 31,
      "z": -90,
      "name": "Plant_Coral_Block_Lime"
    },
    {
      "x": -59,
      "y": 4,
      "z": -89,
      "name": "Soil_Gravel_Lime"
    },
    {
      "x": -59,
      "y": 5,
      "z": -89,
      "name": "Rock_Lime"
    },
    {
      "x": -59,
      "y": 6,
      "z": -89,
      "name": "Rock_Lime"
    },
    {
      "x": -59,
      "y": 7,
      "z": -89,
      "name": "Rock_Lime"
    },
    {
      "x": -59,
      "y": 8,
      "z": -89,
      "name": "Rock_Lime"
    },
    {
      "x": -59,
      "y": 9,
      "z": -89,
      "name": "Soil_Gravel_Lime"
    },
    {
      "x": -59,
      "y": 10,
      "z": -89,
      "name": "Rock_Lime"
    },
    {
      "x": -59,
      "y": 11,
      "z": -89,
      "name": "Rock_Lime"
    },
    {
      "x": -59,
      "y": 12,
      "z": -89,
      "name": "Rock_Lime"
    },
    {
      "x": -59,
      "y": 13,
      "z": -89,
      "name": "Rock_Lime"
    },
    {
      "x": -59,
      "y": 14,
      "z": -89,
      "name": "Rock_Lime"
    },
    {
      "x": -59,
      "y": 15,
      "z": -89,
      "name": "Rock_Lime"
    },
    {
      "x": -59,
      "y": 16,
      "z": -89,
      "name": "Soil_Gravel_Lime"
    },
    {
      "x": -59,
      "y": 17,
      "z": -89,
      "name": "Rock_Lime"
    },
    {
      "x": -59,
      "y": 18,
      "z": -89,
      "name": "Rock_Lime"
    },
    {
      "x": -59,
      "y": 19,
      "z": -89,
      "name": "Rock_Lime"
    },
    {
      "x": -59,
      "y": 20,
      "z": -89,
      "name": "Rock_Lime"
    },
    {
      "x": -59,
      "y": 21,
      "z": -89,
      "name": "Soil_Gravel_Lime"
    },
    {
      "x": -59,
      "y": 22,
      "z": -89,
      "name": "Rock_Lime"
    },
    {
      "x": -59,
      "y": 23,
      "z": -89,
      "name": "Rock_Lime"
    },
    {
      "x": -59,
      "y": 24,
      "z": -89,
      "name": "Soil_Gravel_Lime"
    },
    {
      "x": -59,
      "y": 25,
      "z": -89,
      "name": "Soil_Gravel_Lime"
    },
    {
      "x": -59,
      "y": 26,
      "z": -89,
      "name": "Soil_Gravel_Lime"
    },
    {
      "x": -59,
      "y": 27,
      "z": -89,
      "name": "Rock_Lime"
    },
    {
      "x": -59,
      "y": 28,
      "z": -89,
      "name": "Soil_Gravel_Lime"
    },
    {
      "x": -59,
      "y": 29,
      "z": -89,
      "name": "Plant_Coral_Block_Lime"
    },
    {
      "x": -59,
      "y": 30,
      "z": -89,
      "name": "Plant_Coral_Block_Lime"
    },
    {
      "x": -59,
      "y": 31,
      "z": -89,
      "name": "Soil_Clay_Smooth_Lime"
    },
    {
      "x": -59,
      "y": 4,
      "z": -88,
      "name": "Rock_Lime"
    },
    {
      "x": -59,
      "y": 5,
      "z": -88,
      "name": "Rock_Lime"
    },
    {
      "x": -59,
      "y": 6,
      "z": -88,
      "name": "Rock_Lime"
    },
    {
      "x": -59,
      "y": 7,
      "z": -88,
      "name": "Rock_Lime"
    },
    {
      "x": -59,
      "y": 8,
      "z": -88,
      "name": "Soil_Gravel_Lime"
    },
    {
      "x": -59,
      "y": 9,
      "z": -88,
      "name": "Soil_Gravel_Lime"
    },
    {
      "x": -59,
      "y": 10,
      "z": -88,
      "name": "Rock_Lime"
    },
    {
      "x": -59,
      "y": 11,
      "z": -88,
      "name": "Soil_Gravel_Lime"
    },
    {
      "x": -59,
      "y": 12,
      "z": -88,
      "name": "Rock_Lime"
    },
    {
      "x": -59,
      "y": 13,
      "z": -88,
      "name": "Soil_Gravel_Lime"
    },
    {
      "x": -59,
      "y": 14,
      "z": -88,
      "name": "Rock_Lime"
    },
    {
      "x": -59,
      "y": 15,
      "z": -88,
      "name": "Rock_Lime"
    },
    {
      "x": -59,
      "y": 16,
      "z": -88,
      "name": "Rock_Lime"
    },
    {
      "x": -59,
      "y": 17,
      "z": -88,
      "name": "Soil_Gravel_Lime"
    },
    {
      "x": -59,
      "y": 18,
      "z": -88,
      "name": "Rock_Lime"
    },
    {
      "x": -59,
      "y": 19,
      "z": -88,
      "name": "Rock_Lime"
    },
    {
      "x": -59,
      "y": 20,
      "z": -88,
      "name": "Rock_Lime"
    },
    {
      "x": -59,
      "y": 21,
      "z": -88,
      "name": "Rock_Lime"
    },
    {
      "x": -59,
      "y": 22,
      "z": -88,
      "name": "Rock_Lime"
    },
    {
      "x": -59,
      "y": 23,
      "z": -88,
      "name": "Soil_Gravel_Lime"
    },
    {
      "x": -59,
      "y": 24,
      "z": -88,
      "name": "Soil_Gravel_Lime"
    },
    {
      "x": -59,
      "y": 25,
      "z": -88,
      "name": "Soil_Clay_Smooth_Lime"
    },
    {
      "x": -59,
      "y": 26,
      "z": -88,
      "name": "Plant_Coral_Block_Lime"
    },
    {
      "x": -59,
      "y": 27,
      "z": -88,
      "name": "Plant_Coral_Block_Lime"
    },
    {
      "x": -59,
      "y": 28,
      "z": -88,
      "name": "Plant_Coral_Block_Lime"
    },
    {
      "x": -59,
      "y": 29,
      "z": -88,
      "name": "Plant_Coral_Block_Lime"
    },
    {
      "x": -59,
      "y": 30,
      "z": -88,
      "name": "Plant_Coral_Block_Lime"
    },
    {
      "x": -59,
      "y": 4,
      "z": -87,
      "name": "Rock_Lime"
    },
    {
      "x": -59,
      "y": 5,
      "z": -87,
      "name": "Rock_Lime"
    },
    {
      "x": -59,
      "y": 6,
      "z": -87,
      "name": "Rock_Lime"
    },
    {
      "x": -59,
      "y": 7,
      "z": -87,
      "name": "Rock_Lime"
    },
    {
      "x": -59,
      "y": 8,
      "z": -87,
      "name": "Rock_Lime"
    },
    {
      "x": -59,
      "y": 9,
      "z": -87,
      "name": "Rock_Lime"
    },
    {
      "x": -59,
      "y": 10,
      "z": -87,
      "name": "Soil_Gravel_Lime"
    },
    {
      "x": -59,
      "y": 11,
      "z": -87,
      "name": "Soil_Gravel_Lime"
    },
    {
      "x": -59,
      "y": 12,
      "z": -87,
      "name": "Soil_Gravel_Lime"
    },
    {
      "x": -59,
      "y": 13,
      "z": -87,
      "name": "Rock_Lime"
    },
    {
      "x": -59,
      "y": 14,
      "z": -87,
      "name": "Soil_Gravel_Lime"
    },
    {
      "x": -59,
      "y": 15,
      "z": -87,
      "name": "Rock_Lime"
    },
    {
      "x": -59,
      "y": 16,
      "z": -87,
      "name": "Rock_Lime"
    },
    {
      "x": -59,
      "y": 17,
      "z": -87,
      "name": "Rock_Lime"
    },
    {
      "x": -59,
      "y": 18,
      "z": -87,
      "name": "Rock_Lime"
    },
    {
      "x": -59,
      "y": 19,
      "z": -87,
      "name": "Rock_Lime"
    },
    {
      "x": -59,
      "y": 20,
      "z": -87,
      "name": "Soil_Gravel_Lime"
    },
    {
      "x": -59,
      "y": 21,
      "z": -87,
      "name": "Rock_Lime"
    },
    {
      "x": -59,
      "y": 22,
      "z": -87,
      "name": "Rock_Lime"
    },
    {
      "x": -59,
      "y": 23,
      "z": -87,
      "name": "Soil_Gravel_Lime"
    },
    {
      "x": -59,
      "y": 24,
      "z": -87,
      "name": "Plant_Coral_Block_Lime"
    },
    {
      "x": -59,
      "y": 25,
      "z": -87,
      "name": "Soil_Clay_Lime"
    },
    {
      "x": -59,
      "y": 26,
      "z": -87,
      "name": "Soil_Clay_Smooth_Lime"
    },
    {
      "x": -59,
      "y": 27,
      "z": -87,
      "name": "Plant_Coral_Block_Lime"
    },
    {
      "x": -59,
      "y": 28,
      "z": -87,
      "name": "Plant_Coral_Block_Lime"
    },
    {
      "x": -59,
      "y": 4,
      "z": -86,
      "name": "Rock_Lime"
    },
    {
      "x": -59,
      "y": 5,
      "z": -86,
      "name": "Rock_Lime"
    },
    {
      "x": -59,
      "y": 6,
      "z": -86,
      "name": "Soil_Gravel_Lime"
    },
    {
      "x": -59,
      "y": 7,
      "z": -86,
      "name": "Rock_Lime"
    },
    {
      "x": -59,
      "y": 8,
      "z": -86,
      "name": "Soil_Gravel_Lime"
    },
    {
      "x": -59,
      "y": 9,
      "z": -86,
      "name": "Rock_Lime"
    },
    {
      "x": -59,
      "y": 10,
      "z": -86,
      "name": "Rock_Lime"
    },
    {
      "x": -59,
      "y": 11,
      "z": -86,
      "name": "Rock_Lime"
    },
    {
      "x": -59,
      "y": 12,
      "z": -86,
      "name": "Rock_Lime"
    },
    {
      "x": -59,
      "y": 13,
      "z": -86,
      "name": "Soil_Gravel_Lime"
    },
    {
      "x": -59,
      "y": 14,
      "z": -86,
      "name": "Rock_Lime"
    },
    {
      "x": -59,
      "y": 15,
      "z": -86,
      "name": "Soil_Gravel_Lime"
    },
    {
      "x": -59,
      "y": 16,
      "z": -86,
      "name": "Soil_Gravel_Lime"
    },
    {
      "x": -59,
      "y": 17,
      "z": -86,
      "name": "Rock_Lime"
    },
    {
      "x": -59,
      "y": 18,
      "z": -86,
      "name": "Rock_Lime"
    },
    {
      "x": -59,
      "y": 19,
      "z": -86,
      "name": "Soil_Gravel_Lime"
    },
    {
      "x": -59,
      "y": 20,
      "z": -86,
      "name": "Rock_Lime"
    },
    {
      "x": -59,
      "y": 21,
      "z": -86,
      "name": "Rock_Lime"
    },
    {
      "x": -59,
      "y": 22,
      "z": -86,
      "name": "Rock_Lime"
    },
    {
      "x": -59,
      "y": 23,
      "z": -86,
      "name": "Rock_Lime"
    },
    {
      "x": -59,
      "y": 24,
      "z": -86,
      "name": "Rock_Lime"
    },
    {
      "x": -59,
      "y": 25,
      "z": -86,
      "name": "Soil_Clay_Smooth_Lime"
    },
    {
      "x": -59,
      "y": 4,
      "z": -85,
      "name": "Soil_Gravel_Lime"
    },
    {
      "x": -59,
      "y": 5,
      "z": -85,
      "name": "Soil_Gravel_Lime"
    },
    {
      "x": -59,
      "y": 6,
      "z": -85,
      "name": "Soil_Gravel_Lime"
    },
    {
      "x": -59,
      "y": 7,
      "z": -85,
      "name": "Soil_Gravel_Lime"
    },
    {
      "x": -59,
      "y": 8,
      "z": -85,
      "name": "Soil_Gravel_Lime"
    },
    {
      "x": -59,
      "y": 9,
      "z": -85,
      "name": "Rock_Lime"
    },
    {
      "x": -59,
      "y": 10,
      "z": -85,
      "name": "Soil_Gravel_Lime"
    },
    {
      "x": -59,
      "y": 11,
      "z": -85,
      "name": "Soil_Gravel_Lime"
    },
    {
      "x": -59,
      "y": 12,
      "z": -85,
      "name": "Rock_Lime"
    },
    {
      "x": -59,
      "y": 13,
      "z": -85,
      "name": "Soil_Gravel_Lime"
    },
    {
      "x": -59,
      "y": 14,
      "z": -85,
      "name": "Rock_Lime"
    },
    {
      "x": -59,
      "y": 15,
      "z": -85,
      "name": "Rock_Lime"
    },
    {
      "x": -59,
      "y": 16,
      "z": -85,
      "name": "Rock_Lime"
    },
    {
      "x": -59,
      "y": 17,
      "z": -85,
      "name": "Soil_Gravel_Lime"
    },
    {
      "x": -59,
      "y": 18,
      "z": -85,
      "name": "Rock_Lime"
    },
    {
      "x": -59,
      "y": 19,
      "z": -85,
      "name": "Rock_Lime"
    },
    {
      "x": -59,
      "y": 20,
      "z": -85,
      "name": "Rock_Lime"
    },
    {
      "x": -59,
      "y": 21,
      "z": -85,
      "name": "Soil_Gravel_Lime"
    },
    {
      "x": -59,
      "y": 22,
      "z": -85,
      "name": "Rock_Lime"
    },
    {
      "x": -59,
      "y": 23,
      "z": -85,
      "name": "Rock_Lime"
    },
    {
      "x": -59,
      "y": 24,
      "z": -85,
      "name": "Rubble_Lime_Medium",
      "support": 15
    },
    {
      "x": -59,
      "y": 4,
      "z": -84,
      "name": "Rock_Lime"
    },
    {
      "x": -59,
      "y": 5,
      "z": -84,
      "name": "Soil_Gravel_Lime"
    },
    {
      "x": -59,
      "y": 6,
      "z": -84,
      "name": "Rock_Lime"
    },
    {
      "x": -59,
      "y": 7,
      "z": -84,
      "name": "Rock_Lime"
    },
    {
      "x": -59,
      "y": 8,
      "z": -84,
      "name": "Soil_Gravel_Lime"
    },
    {
      "x": -59,
      "y": 9,
      "z": -84,
      "name": "Rock_Lime"
    },
    {
      "x": -59,
      "y": 10,
      "z": -84,
      "name": "Soil_Gravel_Lime"
    },
    {
      "x": -59,
      "y": 11,
      "z": -84,
      "name": "Soil_Gravel_Lime"
    },
    {
      "x": -59,
      "y": 12,
      "z": -84,
      "name": "Soil_Gravel_Lime"
    },
    {
      "x": -59,
      "y": 13,
      "z": -84,
      "name": "Soil_Gravel_Lime"
    },
    {
      "x": -59,
      "y": 14,
      "z": -84,
      "name": "Rock_Lime"
    },
    {
      "x": -59,
      "y": 15,
      "z": -84,
      "name": "Rock_Lime"
    },
    {
      "x": -59,
      "y": 16,
      "z": -84,
      "name": "Soil_Gravel_Lime"
    },
    {
      "x": -59,
      "y": 17,
      "z": -84,
      "name": "Rock_Lime"
    },
    {
      "x": -59,
      "y": 18,
      "z": -84,
      "name": "Soil_Gravel_Lime"
    },
    {
      "x": -59,
      "y": 4,
      "z": -83,
      "name": "Rock_Lime"
    },
    {
      "x": -59,
      "y": 5,
      "z": -83,
      "name": "Rock_Lime"
    },
    {
      "x": -59,
      "y": 6,
      "z": -83,
      "name": "Soil_Gravel_Lime"
    },
    {
      "x": -59,
      "y": 7,
      "z": -83,
      "name": "Rock_Lime"
    },
    {
      "x": -59,
      "y": 8,
      "z": -83,
      "name": "Soil_Gravel_Lime"
    },
    {
      "x": -59,
      "y": 9,
      "z": -83,
      "name": "Rock_Lime"
    },
    {
      "x": -59,
      "y": 10,
      "z": -83,
      "name": "Soil_Gravel_Lime"
    },
    {
      "x": -59,
      "y": 11,
      "z": -83,
      "name": "Rock_Lime"
    },
    {
      "x": -59,
      "y": 12,
      "z": -83,
      "name": "Soil_Gravel_Lime"
    },
    {
      "x": -59,
      "y": 13,
      "z": -83,
      "name": "Rock_Lime"
    },
    {
      "x": -59,
      "y": 14,
      "z": -83,
      "name": "Soil_Gravel_Lime"
    },
    {
      "x": -59,
      "y": 15,
      "z": -83,
      "name": "Soil_Gravel_Lime"
    },
    {
      "x": -59,
      "y": 4,
      "z": -82,
      "name": "Rock_Lime"
    },
    {
      "x": -59,
      "y": 5,
      "z": -82,
      "name": "Soil_Gravel_Lime"
    },
    {
      "x": -59,
      "y": 6,
      "z": -82,
      "name": "Soil_Gravel_Lime"
    },
    {
      "x": -59,
      "y": 7,
      "z": -82,
      "name": "Rock_Lime"
    },
    {
      "x": -59,
      "y": 8,
      "z": -82,
      "name": "Rock_Lime"
    },
    {
      "x": -59,
      "y": 9,
      "z": -82,
      "name": "Soil_Gravel_Lime"
    },
    {
      "x": -59,
      "y": 10,
      "z": -82,
      "name": "Soil_Gravel_Lime"
    },
    {
      "x": -59,
      "y": 11,
      "z": -82,
      "name": "Rock_Lime"
    },
    {
      "x": -59,
      "y": 12,
      "z": -82,
      "name": "Rock_Lime"
    },
    {
      "x": -59,
      "y": 13,
      "z": -82,
      "name": "Rock_Lime"
    },
    {
      "x": -59,
      "y": 14,
      "z": -82,
      "name": "Rock_Lime_Stalactite_Large"
    },
    {
      "x": -59,
      "y": 15,
      "z": -82,
      "name": "Rock_Lime_Stalactite_Large",
      "filler": 1024
    },
    {
      "x": -59,
      "y": 4,
      "z": -81,
      "name": "Rock_Lime"
    },
    {
      "x": -59,
      "y": 5,
      "z": -81,
      "name": "Soil_Gravel_Lime"
    },
    {
      "x": -59,
      "y": 6,
      "z": -81,
      "name": "Soil_Gravel_Lime"
    },
    {
      "x": -59,
      "y": 7,
      "z": -81,
      "name": "Soil_Gravel_Lime"
    },
    {
      "x": -59,
      "y": 8,
      "z": -81,
      "name": "Rock_Lime"
    },
    {
      "x": -59,
      "y": 9,
      "z": -81,
      "name": "Rock_Lime"
    },
    {
      "x": -59,
      "y": 10,
      "z": -81,
      "name": "Rock_Lime"
    },
    {
      "x": -59,
      "y": 11,
      "z": -81,
      "name": "Rock_Lime"
    },
    {
      "x": -58,
      "y": 19,
      "z": -97,
      "name": "Plant_Leaves_Dead",
      "support": 15
    },
    {
      "x": -58,
      "y": 9,
      "z": -96,
      "name": "Soil_Gravel_Lime"
    },
    {
      "x": -58,
      "y": 10,
      "z": -96,
      "name": "Rock_Lime"
    },
    {
      "x": -58,
      "y": 11,
      "z": -96,
      "name": "Soil_Gravel_Lime"
    },
    {
      "x": -58,
      "y": 12,
      "z": -96,
      "name": "Soil_Gravel_Lime"
    },
    {
      "x": -58,
      "y": 13,
      "z": -96,
      "name": "Soil_Gravel_Lime"
    },
    {
      "x": -58,
      "y": 14,
      "z": -96,
      "name": "Rock_Lime"
    },
    {
      "x": -58,
      "y": 15,
      "z": -96,
      "name": "Rock_Lime"
    },
    {
      "x": -58,
      "y": 16,
      "z": -96,
      "name": "Rock_Lime"
    },
    {
      "x": -58,
      "y": 17,
      "z": -96,
      "name": "Rock_Lime"
    },
    {
      "x": -58,
      "y": 18,
      "z": -96,
      "name": "Soil_Gravel_Lime"
    },
    {
      "x": -58,
      "y": 19,
      "z": -96,
      "name": "Soil_Gravel_Lime"
    },
    {
      "x": -58,
      "y": 20,
      "z": -96,
      "name": "Rock_Lime"
    },
    {
      "x": -58,
      "y": 21,
      "z": -96,
      "name": "Rock_Lime_Stalactite_Large"
    },
    {
      "x": -58,
      "y": 22,
      "z": -96,
      "name": "Rock_Lime_Stalactite_Large",
      "filler": 1024
    },
    {
      "x": -58,
      "y": 6,
      "z": -95,
      "name": "Soil_Gravel_Lime"
    },
    {
      "x": -58,
      "y": 7,
      "z": -95,
      "name": "Rock_Lime"
    },
    {
      "x": -58,
      "y": 8,
      "z": -95,
      "name": "Rock_Lime"
    },
    {
      "x": -58,
      "y": 9,
      "z": -95,
      "name": "Rock_Lime"
    },
    {
      "x": -58,
      "y": 10,
      "z": -95,
      "name": "Rock_Lime"
    },
    {
      "x": -58,
      "y": 11,
      "z": -95,
      "name": "Rock_Lime"
    },
    {
      "x": -58,
      "y": 12,
      "z": -95,
      "name": "Rock_Lime"
    },
    {
      "x": -58,
      "y": 13,
      "z": -95,
      "name": "Soil_Gravel_Lime"
    },
    {
      "x": -58,
      "y": 14,
      "z": -95,
      "name": "Rock_Lime"
    },
    {
      "x": -58,
      "y": 15,
      "z": -95,
      "name": "Rock_Lime"
    },
    {
      "x": -58,
      "y": 16,
      "z": -95,
      "name": "Rock_Lime"
    },
    {
      "x": -58,
      "y": 17,
      "z": -95,
      "name": "Rock_Lime"
    },
    {
      "x": -58,
      "y": 18,
      "z": -95,
      "name": "Soil_Gravel_Lime"
    },
    {
      "x": -58,
      "y": 19,
      "z": -95,
      "name": "Rock_Lime"
    },
    {
      "x": -58,
      "y": 20,
      "z": -95,
      "name": "Rock_Lime"
    },
    {
      "x": -58,
      "y": 21,
      "z": -95,
      "name": "Rock_Lime"
    },
    {
      "x": -58,
      "y": 22,
      "z": -95,
      "name": "Rock_Lime"
    },
    {
      "x": -58,
      "y": 23,
      "z": -95,
      "name": "Rock_Lime"
    },
    {
      "x": -58,
      "y": 24,
      "z": -95,
      "name": "Rock_Lime"
    },
    {
      "x": -58,
      "y": 25,
      "z": -95,
      "name": "Rock_Lime"
    },
    {
      "x": -58,
      "y": 26,
      "z": -95,
      "name": "Rock_Lime"
    },
    {
      "x": -58,
      "y": 27,
      "z": -95,
      "name": "Plant_Crop_Mushroom_Cap_Poison",
      "components": {
        "Components": {
          "FarmingBlock": {
            "LastTickGameTime": "0001-01-01T12:00:00Z"
          },
          "PlacedByInteraction": {
            "WhoPlacedUuid": {
              "$binary": "HCpUQzdeSaiDYHpoRePv+w==",
              "$type": "04"
            }
          }
        }
      }
    },
    {
      "x": -58,
      "y": 4,
      "z": -94,
      "name": "Rock_Lime"
    },
    {
      "x": -58,
      "y": 5,
      "z": -94,
      "name": "Rock_Lime"
    },
    {
      "x": -58,
      "y": 6,
      "z": -94,
      "name": "Soil_Gravel_Lime"
    },
    {
      "x": -58,
      "y": 7,
      "z": -94,
      "name": "Rock_Lime"
    },
    {
      "x": -58,
      "y": 8,
      "z": -94,
      "name": "Soil_Gravel_Lime"
    },
    {
      "x": -58,
      "y": 9,
      "z": -94,
      "name": "Soil_Gravel_Lime"
    },
    {
      "x": -58,
      "y": 10,
      "z": -94,
      "name": "Rock_Lime"
    },
    {
      "x": -58,
      "y": 11,
      "z": -94,
      "name": "Rock_Lime"
    },
    {
      "x": -58,
      "y": 12,
      "z": -94,
      "name": "Soil_Gravel_Lime"
    },
    {
      "x": -58,
      "y": 13,
      "z": -94,
      "name": "Soil_Gravel_Lime"
    },
    {
      "x": -58,
      "y": 14,
      "z": -94,
      "name": "Rock_Lime"
    },
    {
      "x": -58,
      "y": 15,
      "z": -94,
      "name": "Soil_Gravel_Lime"
    },
    {
      "x": -58,
      "y": 16,
      "z": -94,
      "name": "Rock_Lime"
    },
    {
      "x": -58,
      "y": 17,
      "z": -94,
      "name": "Rock_Lime"
    },
    {
      "x": -58,
      "y": 18,
      "z": -94,
      "name": "Soil_Gravel_Lime"
    },
    {
      "x": -58,
      "y": 19,
      "z": -94,
      "name": "Soil_Gravel_Lime"
    },
    {
      "x": -58,
      "y": 20,
      "z": -94,
      "name": "Rock_Lime"
    },
    {
      "x": -58,
      "y": 21,
      "z": -94,
      "name": "Soil_Gravel_Lime"
    },
    {
      "x": -58,
      "y": 22,
      "z": -94,
      "name": "Rock_Lime"
    },
    {
      "x": -58,
      "y": 23,
      "z": -94,
      "name": "Rock_Lime"
    },
    {
      "x": -58,
      "y": 24,
      "z": -94,
      "name": "Rock_Lime"
    },
    {
      "x": -58,
      "y": 25,
      "z": -94,
      "name": "Rock_Lime"
    },
    {
      "x": -58,
      "y": 26,
      "z": -94,
      "name": "Rock_Lime"
    },
    {
      "x": -58,
      "y": 27,
      "z": -94,
      "name": "Soil_Clay_Lime"
    },
    {
      "x": -58,
      "y": 28,
      "z": -94,
      "name": "Soil_Clay_Lime"
    },
    {
      "x": -58,
      "y": 29,
      "z": -94,
      "name": "Soil_Clay_Lime"
    },
    {
      "x": -58,
      "y": 4,
      "z": -93,
      "name": "Rock_Lime"
    },
    {
      "x": -58,
      "y": 5,
      "z": -93,
      "name": "Soil_Gravel_Lime"
    },
    {
      "x": -58,
      "y": 6,
      "z": -93,
      "name": "Rock_Lime"
    },
    {
      "x": -58,
      "y": 7,
      "z": -93,
      "name": "Soil_Gravel_Lime"
    },
    {
      "x": -58,
      "y": 8,
      "z": -93,
      "name": "Soil_Gravel_Lime"
    },
    {
      "x": -58,
      "y": 9,
      "z": -93,
      "name": "Soil_Gravel_Lime"
    },
    {
      "x": -58,
      "y": 10,
      "z": -93,
      "name": "Soil_Gravel_Lime"
    },
    {
      "x": -58,
      "y": 11,
      "z": -93,
      "name": "Rock_Lime"
    },
    {
      "x": -58,
      "y": 12,
      "z": -93,
      "name": "Soil_Gravel_Lime"
    },
    {
      "x": -58,
      "y": 13,
      "z": -93,
      "name": "Rock_Lime"
    },
    {
      "x": -58,
      "y": 14,
      "z": -93,
      "name": "Rock_Lime"
    },
    {
      "x": -58,
      "y": 15,
      "z": -93,
      "name": "Soil_Gravel_Lime"
    },
    {
      "x": -58,
      "y": 16,
      "z": -93,
      "name": "Rock_Lime"
    },
    {
      "x": -58,
      "y": 17,
      "z": -93,
      "name": "Soil_Gravel_Lime"
    },
    {
      "x": -58,
      "y": 18,
      "z": -93,
      "name": "Rock_Lime"
    },
    {
      "x": -58,
      "y": 19,
      "z": -93,
      "name": "Rock_Lime"
    },
    {
      "x": -58,
      "y": 20,
      "z": -93,
      "name": "Rock_Lime"
    },
    {
      "x": -58,
      "y": 21,
      "z": -93,
      "name": "Rock_Lime"
    },
    {
      "x": -58,
      "y": 22,
      "z": -93,
      "name": "Soil_Gravel_Lime"
    },
    {
      "x": -58,
      "y": 23,
      "z": -93,
      "name": "Rock_Lime"
    },
    {
      "x": -58,
      "y": 24,
      "z": -93,
      "name": "Rock_Lime"
    },
    {
      "x": -58,
      "y": 25,
      "z": -93,
      "name": "Soil_Gravel_Lime"
    },
    {
      "x": -58,
      "y": 26,
      "z": -93,
      "name": "Soil_Gravel_Lime"
    },
    {
      "x": -58,
      "y": 27,
      "z": -93,
      "name": "Soil_Clay_Smooth_Lime"
    },
    {
      "x": -58,
      "y": 28,
      "z": -93,
      "name": "Soil_Clay_Smooth_Lime"
    },
    {
      "x": -58,
      "y": 29,
      "z": -93,
      "name": "Plant_Coral_Block_Lime"
    },
    {
      "x": -58,
      "y": 4,
      "z": -92,
      "name": "Soil_Gravel_Lime"
    },
    {
      "x": -58,
      "y": 5,
      "z": -92,
      "name": "Rock_Lime"
    },
    {
      "x": -58,
      "y": 6,
      "z": -92,
      "name": "Soil_Gravel_Lime"
    },
    {
      "x": -58,
      "y": 7,
      "z": -92,
      "name": "Rock_Lime"
    },
    {
      "x": -58,
      "y": 8,
      "z": -92,
      "name": "Rock_Lime"
    },
    {
      "x": -58,
      "y": 9,
      "z": -92,
      "name": "Rock_Lime"
    },
    {
      "x": -58,
      "y": 10,
      "z": -92,
      "name": "Rock_Lime"
    },
    {
      "x": -58,
      "y": 11,
      "z": -92,
      "name": "Rock_Lime"
    },
    {
      "x": -58,
      "y": 12,
      "z": -92,
      "name": "Soil_Gravel_Lime"
    },
    {
      "x": -58,
      "y": 13,
      "z": -92,
      "name": "Rock_Lime"
    },
    {
      "x": -58,
      "y": 14,
      "z": -92,
      "name": "Rock_Lime"
    },
    {
      "x": -58,
      "y": 15,
      "z": -92,
      "name": "Soil_Gravel_Lime"
    },
    {
      "x": -58,
      "y": 16,
      "z": -92,
      "name": "Rock_Lime"
    },
    {
      "x": -58,
      "y": 17,
      "z": -92,
      "name": "Rock_Lime"
    },
    {
      "x": -58,
      "y": 18,
      "z": -92,
      "name": "Rock_Lime"
    },
    {
      "x": -58,
      "y": 19,
      "z": -92,
      "name": "Rock_Lime"
    },
    {
      "x": -58,
      "y": 20,
      "z": -92,
      "name": "Rock_Lime"
    },
    {
      "x": -58,
      "y": 21,
      "z": -92,
      "name": "Soil_Gravel_Lime"
    },
    {
      "x": -58,
      "y": 22,
      "z": -92,
      "name": "Rock_Lime"
    },
    {
      "x": -58,
      "y": 23,
      "z": -92,
      "name": "Soil_Gravel_Lime"
    },
    {
      "x": -58,
      "y": 24,
      "z": -92,
      "name": "Soil_Gravel_Lime"
    },
    {
      "x": -58,
      "y": 25,
      "z": -92,
      "name": "Soil_Gravel_Lime"
    },
    {
      "x": -58,
      "y": 26,
      "z": -92,
      "name": "Rock_Lime"
    },
    {
      "x": -58,
      "y": 27,
      "z": -92,
      "name": "Plant_Coral_Block_Lime"
    },
    {
      "x": -58,
      "y": 28,
      "z": -92,
      "name": "Plant_Coral_Block_Lime"
    },
    {
      "x": -58,
      "y": 29,
      "z": -92,
      "name": "Plant_Coral_Block_Lime"
    },
    {
      "x": -58,
      "y": 30,
      "z": -92,
      "name": "Plant_Coral_Block_Lime"
    },
    {
      "x": -58,
      "y": 31,
      "z": -92,
      "name": "Soil_Clay_Lime"
    },
    {
      "x": -58,
      "y": 32,
      "z": -92,
      "name": "Plant_Coral_Block_Lime"
    },
    {
      "x": -58,
      "y": 4,
      "z": -91,
      "name": "Rock_Lime"
    },
    {
      "x": -58,
      "y": 5,
      "z": -91,
      "name": "Rock_Lime"
    },
    {
      "x": -58,
      "y": 6,
      "z": -91,
      "name": "Rock_Lime"
    },
    {
      "x": -58,
      "y": 7,
      "z": -91,
      "name": "Soil_Gravel_Lime"
    },
    {
      "x": -58,
      "y": 8,
      "z": -91,
      "name": "Rock_Lime"
    },
    {
      "x": -58,
      "y": 9,
      "z": -91,
      "name": "Rock_Lime"
    },
    {
      "x": -58,
      "y": 10,
      "z": -91,
      "name": "Soil_Gravel_Lime"
    },
    {
      "x": -58,
      "y": 11,
      "z": -91,
      "name": "Rock_Lime"
    },
    {
      "x": -58,
      "y": 12,
      "z": -91,
      "name": "Rock_Lime"
    },
    {
      "x": -58,
      "y": 13,
      "z": -91,
      "name": "Rock_Lime"
    },
    {
      "x": -58,
      "y": 14,
      "z": -91,
      "name": "Rock_Lime"
    },
    {
      "x": -58,
      "y": 15,
      "z": -91,
      "name": "Rock_Lime"
    },
    {
      "x": -58,
      "y": 16,
      "z": -91,
      "name": "Soil_Gravel_Lime"
    },
    {
      "x": -58,
      "y": 17,
      "z": -91,
      "name": "Soil_Gravel_Lime"
    },
    {
      "x": -58,
      "y": 18,
      "z": -91,
      "name": "Rock_Lime"
    },
    {
      "x": -58,
      "y": 19,
      "z": -91,
      "name": "Soil_Gravel_Lime"
    },
    {
      "x": -58,
      "y": 20,
      "z": -91,
      "name": "Rock_Lime"
    },
    {
      "x": -58,
      "y": 21,
      "z": -91,
      "name": "Rock_Lime"
    },
    {
      "x": -58,
      "y": 22,
      "z": -91,
      "name": "Soil_Gravel_Lime"
    },
    {
      "x": -58,
      "y": 23,
      "z": -91,
      "name": "Rock_Lime"
    },
    {
      "x": -58,
      "y": 24,
      "z": -91,
      "name": "Soil_Gravel_Lime"
    },
    {
      "x": -58,
      "y": 25,
      "z": -91,
      "name": "Rock_Lime"
    },
    {
      "x": -58,
      "y": 26,
      "z": -91,
      "name": "Soil_Gravel_Lime"
    },
    {
      "x": -58,
      "y": 27,
      "z": -91,
      "name": "Rock_Lime"
    },
    {
      "x": -58,
      "y": 28,
      "z": -91,
      "name": "Plant_Coral_Block_Lime"
    },
    {
      "x": -58,
      "y": 29,
      "z": -91,
      "name": "Soil_Clay_Smooth_Lime"
    },
    {
      "x": -58,
      "y": 30,
      "z": -91,
      "name": "Plant_Coral_Block_Lime"
    },
    {
      "x": -58,
      "y": 31,
      "z": -91,
      "name": "Soil_Clay_Lime"
    },
    {
      "x": -58,
      "y": 32,
      "z": -91,
      "name": "Plant_Coral_Block_Lime"
    },
    {
      "x": -58,
      "y": 33,
      "z": -91,
      "name": "Plant_Coral_Block_Lime"
    },
    {
      "x": -58,
      "y": 34,
      "z": -91,
      "name": "Soil_Clay_Lime"
    },
    {
      "x": -58,
      "y": 35,
      "z": -91,
      "name": "Plant_Coral_Block_Lime"
    },
    {
      "x": -58,
      "y": 36,
      "z": -91,
      "name": "Plant_Coral_Block_Lime"
    },
    {
      "x": -58,
      "y": 37,
      "z": -91,
      "name": "Plant_Coral_Block_Lime"
    },
    {
      "x": -58,
      "y": 4,
      "z": -90,
      "name": "Soil_Gravel_Lime"
    },
    {
      "x": -58,
      "y": 5,
      "z": -90,
      "name": "Rock_Lime"
    },
    {
      "x": -58,
      "y": 6,
      "z": -90,
      "name": "Rock_Lime"
    },
    {
      "x": -58,
      "y": 7,
      "z": -90,
      "name": "Rock_Lime"
    },
    {
      "x": -58,
      "y": 8,
      "z": -90,
      "name": "Soil_Gravel_Lime"
    },
    {
      "x": -58,
      "y": 9,
      "z": -90,
      "name": "Rock_Lime"
    },
    {
      "x": -58,
      "y": 10,
      "z": -90,
      "name": "Soil_Gravel_Lime"
    },
    {
      "x": -58,
      "y": 11,
      "z": -90,
      "name": "Soil_Gravel_Lime"
    },
    {
      "x": -58,
      "y": 12,
      "z": -90,
      "name": "Rock_Lime"
    },
    {
      "x": -58,
      "y": 13,
      "z": -90,
      "name": "Soil_Gravel_Lime"
    },
    {
      "x": -58,
      "y": 14,
      "z": -90,
      "name": "Rock_Lime"
    },
    {
      "x": -58,
      "y": 15,
      "z": -90,
      "name": "Rock_Lime"
    },
    {
      "x": -58,
      "y": 16,
      "z": -90,
      "name": "Rock_Lime"
    },
    {
      "x": -58,
      "y": 17,
      "z": -90,
      "name": "Rock_Lime"
    },
    {
      "x": -58,
      "y": 18,
      "z": -90,
      "name": "Soil_Gravel_Lime"
    },
    {
      "x": -58,
      "y": 19,
      "z": -90,
      "name": "Rock_Lime"
    },
    {
      "x": -58,
      "y": 20,
      "z": -90,
      "name": "Rock_Lime"
    },
    {
      "x": -58,
      "y": 21,
      "z": -90,
      "name": "Soil_Gravel_Lime"
    },
    {
      "x": -58,
      "y": 22,
      "z": -90,
      "name": "Rock_Lime"
    },
    {
      "x": -58,
      "y": 23,
      "z": -90,
      "name": "Rock_Lime"
    },
    {
      "x": -58,
      "y": 24,
      "z": -90,
      "name": "Rock_Lime"
    },
    {
      "x": -58,
      "y": 25,
      "z": -90,
      "name": "Rock_Lime"
    },
    {
      "x": -58,
      "y": 26,
      "z": -90,
      "name": "Rock_Lime"
    },
    {
      "x": -58,
      "y": 27,
      "z": -90,
      "name": "Rock_Lime"
    },
    {
      "x": -58,
      "y": 28,
      "z": -90,
      "name": "Rock_Lime"
    },
    {
      "x": -58,
      "y": 29,
      "z": -90,
      "name": "Rock_Lime"
    },
    {
      "x": -58,
      "y": 30,
      "z": -90,
      "name": "Plant_Coral_Block_Lime"
    },
    {
      "x": -58,
      "y": 31,
      "z": -90,
      "name": "Soil_Clay_Lime"
    },
    {
      "x": -58,
      "y": 32,
      "z": -90,
      "name": "Soil_Clay_Smooth_Lime"
    },
    {
      "x": -58,
      "y": 33,
      "z": -90,
      "name": "Plant_Coral_Block_Lime"
    },
    {
      "x": -58,
      "y": 34,
      "z": -90,
      "name": "Plant_Coral_Block_Lime"
    },
    {
      "x": -58,
      "y": 35,
      "z": -90,
      "name": "Plant_Coral_Block_Lime"
    },
    {
      "x": -58,
      "y": 36,
      "z": -90,
      "name": "Soil_Clay_Lime"
    },
    {
      "x": -58,
      "y": 37,
      "z": -90,
      "name": "Plant_Coral_Block_Lime"
    },
    {
      "x": -58,
      "y": 4,
      "z": -89,
      "name": "Rock_Lime"
    },
    {
      "x": -58,
      "y": 5,
      "z": -89,
      "name": "Soil_Gravel_Lime"
    },
    {
      "x": -58,
      "y": 6,
      "z": -89,
      "name": "Soil_Gravel_Lime"
    },
    {
      "x": -58,
      "y": 7,
      "z": -89,
      "name": "Soil_Gravel_Lime"
    },
    {
      "x": -58,
      "y": 8,
      "z": -89,
      "name": "Rock_Lime"
    },
    {
      "x": -58,
      "y": 9,
      "z": -89,
      "name": "Rock_Lime"
    },
    {
      "x": -58,
      "y": 10,
      "z": -89,
      "name": "Soil_Gravel_Lime"
    },
    {
      "x": -58,
      "y": 11,
      "z": -89,
      "name": "Soil_Gravel_Lime"
    },
    {
      "x": -58,
      "y": 12,
      "z": -89,
      "name": "Soil_Gravel_Lime"
    },
    {
      "x": -58,
      "y": 13,
      "z": -89,
      "name": "Rock_Lime"
    },
    {
      "x": -58,
      "y": 14,
      "z": -89,
      "name": "Soil_Gravel_Lime"
    },
    {
      "x": -58,
      "y": 15,
      "z": -89,
      "name": "Rock_Lime"
    },
    {
      "x": -58,
      "y": 16,
      "z": -89,
      "name": "Rock_Lime"
    },
    {
      "x": -58,
      "y": 17,
      "z": -89,
      "name": "Rock_Lime"
    },
    {
      "x": -58,
      "y": 18,
      "z": -89,
      "name": "Rock_Lime"
    },
    {
      "x": -58,
      "y": 19,
      "z": -89,
      "name": "Rock_Lime"
    },
    {
      "x": -58,
      "y": 20,
      "z": -89,
      "name": "Rock_Lime"
    },
    {
      "x": -58,
      "y": 21,
      "z": -89,
      "name": "Rock_Lime"
    },
    {
      "x": -58,
      "y": 22,
      "z": -89,
      "name": "Soil_Gravel_Lime"
    },
    {
      "x": -58,
      "y": 23,
      "z": -89,
      "name": "Rock_Lime"
    },
    {
      "x": -58,
      "y": 24,
      "z": -89,
      "name": "Rock_Lime"
    },
    {
      "x": -58,
      "y": 25,
      "z": -89,
      "name": "Rock_Lime"
    },
    {
      "x": -58,
      "y": 26,
      "z": -89,
      "name": "Soil_Gravel_Lime"
    },
    {
      "x": -58,
      "y": 27,
      "z": -89,
      "name": "Rock_Lime"
    },
    {
      "x": -58,
      "y": 28,
      "z": -89,
      "name": "Rock_Lime"
    },
    {
      "x": -58,
      "y": 29,
      "z": -89,
      "name": "Soil_Gravel_Lime"
    },
    {
      "x": -58,
      "y": 30,
      "z": -89,
      "name": "Soil_Clay_Lime"
    },
    {
      "x": -58,
      "y": 31,
      "z": -89,
      "name": "Plant_Coral_Block_Lime"
    },
    {
      "x": -58,
      "y": 32,
      "z": -89,
      "name": "Soil_Clay_Smooth_Lime"
    },
    {
      "x": -58,
      "y": 33,
      "z": -89,
      "name": "Soil_Clay_Smooth_Lime"
    },
    {
      "x": -58,
      "y": 34,
      "z": -89,
      "name": "Plant_Coral_Block_Lime"
    },
    {
      "x": -58,
      "y": 35,
      "z": -89,
      "name": "Soil_Clay_Lime"
    },
    {
      "x": -58,
      "y": 36,
      "z": -89,
      "name": "Plant_Coral_Block_Lime"
    },
    {
      "x": -58,
      "y": 37,
      "z": -89,
      "name": "Plant_Coral_Block_Lime"
    },
    {
      "x": -58,
      "y": 4,
      "z": -88,
      "name": "Rock_Lime"
    },
    {
      "x": -58,
      "y": 5,
      "z": -88,
      "name": "Rock_Lime"
    },
    {
      "x": -58,
      "y": 6,
      "z": -88,
      "name": "Soil_Gravel_Lime"
    },
    {
      "x": -58,
      "y": 7,
      "z": -88,
      "name": "Rock_Lime"
    },
    {
      "x": -58,
      "y": 8,
      "z": -88,
      "name": "Soil_Gravel_Lime"
    },
    {
      "x": -58,
      "y": 9,
      "z": -88,
      "name": "Rock_Lime"
    },
    {
      "x": -58,
      "y": 10,
      "z": -88,
      "name": "Rock_Lime"
    },
    {
      "x": -58,
      "y": 11,
      "z": -88,
      "name": "Rock_Lime"
    },
    {
      "x": -58,
      "y": 12,
      "z": -88,
      "name": "Rock_Lime"
    },
    {
      "x": -58,
      "y": 13,
      "z": -88,
      "name": "Rock_Lime"
    },
    {
      "x": -58,
      "y": 14,
      "z": -88,
      "name": "Rock_Lime"
    },
    {
      "x": -58,
      "y": 15,
      "z": -88,
      "name": "Rock_Lime"
    },
    {
      "x": -58,
      "y": 16,
      "z": -88,
      "name": "Soil_Gravel_Lime"
    },
    {
      "x": -58,
      "y": 17,
      "z": -88,
      "name": "Rock_Lime"
    },
    {
      "x": -58,
      "y": 18,
      "z": -88,
      "name": "Soil_Gravel_Lime"
    },
    {
      "x": -58,
      "y": 19,
      "z": -88,
      "name": "Rock_Lime"
    },
    {
      "x": -58,
      "y": 20,
      "z": -88,
      "name": "Soil_Gravel_Lime"
    },
    {
      "x": -58,
      "y": 21,
      "z": -88,
      "name": "Soil_Gravel_Lime"
    },
    {
      "x": -58,
      "y": 22,
      "z": -88,
      "name": "Soil_Gravel_Lime"
    },
    {
      "x": -58,
      "y": 23,
      "z": -88,
      "name": "Rock_Lime"
    },
    {
      "x": -58,
      "y": 24,
      "z": -88,
      "name": "Rock_Lime"
    },
    {
      "x": -58,
      "y": 25,
      "z": -88,
      "name": "Soil_Gravel_Lime"
    },
    {
      "x": -58,
      "y": 26,
      "z": -88,
      "name": "Rock_Lime"
    },
    {
      "x": -58,
      "y": 27,
      "z": -88,
      "name": "Soil_Gravel_Lime"
    },
    {
      "x": -58,
      "y": 28,
      "z": -88,
      "name": "Plant_Coral_Block_Lime"
    },
    {
      "x": -58,
      "y": 29,
      "z": -88,
      "name": "Soil_Clay_Smooth_Lime"
    },
    {
      "x": -58,
      "y": 30,
      "z": -88,
      "name": "Soil_Clay_Smooth_Lime"
    },
    {
      "x": -58,
      "y": 31,
      "z": -88,
      "name": "Plant_Coral_Block_Lime"
    },
    {
      "x": -58,
      "y": 32,
      "z": -88,
      "name": "Plant_Coral_Block_Lime"
    },
    {
      "x": -58,
      "y": 33,
      "z": -88,
      "name": "Plant_Coral_Block_Lime"
    },
    {
      "x": -58,
      "y": 34,
      "z": -88,
      "name": "Plant_Coral_Block_Lime"
    },
    {
      "x": -58,
      "y": 4,
      "z": -87,
      "name": "Rock_Lime"
    },
    {
      "x": -58,
      "y": 5,
      "z": -87,
      "name": "Soil_Gravel_Lime"
    },
    {
      "x": -58,
      "y": 6,
      "z": -87,
      "name": "Soil_Gravel_Lime"
    },
    {
      "x": -58,
      "y": 7,
      "z": -87,
      "name": "Rock_Lime"
    },
    {
      "x": -58,
      "y": 8,
      "z": -87,
      "name": "Rock_Lime"
    },
    {
      "x": -58,
      "y": 9,
      "z": -87,
      "name": "Soil_Gravel_Lime"
    },
    {
      "x": -58,
      "y": 10,
      "z": -87,
      "name": "Soil_Gravel_Lime"
    },
    {
      "x": -58,
      "y": 11,
      "z": -87,
      "name": "Rock_Lime"
    },
    {
      "x": -58,
      "y": 12,
      "z": -87,
      "name": "Rock_Lime"
    },
    {
      "x": -58,
      "y": 13,
      "z": -87,
      "name": "Soil_Gravel_Lime"
    },
    {
      "x": -58,
      "y": 14,
      "z": -87,
      "name": "Rock_Lime"
    },
    {
      "x": -58,
      "y": 15,
      "z": -87,
      "name": "Rock_Lime"
    },
    {
      "x": -58,
      "y": 16,
      "z": -87,
      "name": "Soil_Gravel_Lime"
    },
    {
      "x": -58,
      "y": 17,
      "z": -87,
      "name": "Rock_Lime"
    },
    {
      "x": -58,
      "y": 18,
      "z": -87,
      "name": "Soil_Gravel_Lime"
    },
    {
      "x": -58,
      "y": 19,
      "z": -87,
      "name": "Rock_Lime"
    },
    {
      "x": -58,
      "y": 20,
      "z": -87,
      "name": "Rock_Lime"
    },
    {
      "x": -58,
      "y": 21,
      "z": -87,
      "name": "Rock_Lime"
    },
    {
      "x": -58,
      "y": 22,
      "z": -87,
      "name": "Rock_Lime"
    },
    {
      "x": -58,
      "y": 23,
      "z": -87,
      "name": "Rock_Lime"
    },
    {
      "x": -58,
      "y": 24,
      "z": -87,
      "name": "Soil_Gravel_Lime"
    },
    {
      "x": -58,
      "y": 25,
      "z": -87,
      "name": "Soil_Clay_Smooth_Lime"
    },
    {
      "x": -58,
      "y": 26,
      "z": -87,
      "name": "Soil_Clay_Lime"
    },
    {
      "x": -58,
      "y": 27,
      "z": -87,
      "name": "Plant_Coral_Block_Lime"
    },
    {
      "x": -58,
      "y": 28,
      "z": -87,
      "name": "Plant_Coral_Block_Lime"
    },
    {
      "x": -58,
      "y": 29,
      "z": -87,
      "name": "Plant_Coral_Block_Lime"
    },
    {
      "x": -58,
      "y": 30,
      "z": -87,
      "name": "Soil_Clay_Lime"
    },
    {
      "x": -58,
      "y": 31,
      "z": -87,
      "name": "Plant_Coral_Block_Lime"
    },
    {
      "x": -58,
      "y": 4,
      "z": -86,
      "name": "Rock_Lime"
    },
    {
      "x": -58,
      "y": 5,
      "z": -86,
      "name": "Rock_Lime"
    },
    {
      "x": -58,
      "y": 6,
      "z": -86,
      "name": "Rock_Lime"
    },
    {
      "x": -58,
      "y": 7,
      "z": -86,
      "name": "Rock_Lime"
    },
    {
      "x": -58,
      "y": 8,
      "z": -86,
      "name": "Rock_Lime"
    },
    {
      "x": -58,
      "y": 9,
      "z": -86,
      "name": "Rock_Lime"
    },
    {
      "x": -58,
      "y": 10,
      "z": -86,
      "name": "Rock_Lime"
    },
    {
      "x": -58,
      "y": 11,
      "z": -86,
      "name": "Rock_Lime"
    },
    {
      "x": -58,
      "y": 12,
      "z": -86,
      "name": "Soil_Gravel_Lime"
    },
    {
      "x": -58,
      "y": 13,
      "z": -86,
      "name": "Soil_Gravel_Lime"
    },
    {
      "x": -58,
      "y": 14,
      "z": -86,
      "name": "Rock_Lime"
    },
    {
